Workbook

Sheet Marco Bezzecchi
A1: 1. Marco BEZZECCHI #72
A3: Team | B3: Aprilia Racing | C3: Manufacturer | D3: APRILIA | E3: Nationality | F3: ITA | G3: Total Laps | H3: 23 | I3: Valid Laps | J3: 22 | K3: Front Tyre | L3: Slick-Medium | M3: Rear Tyre | N3: Slick-Medium
A5: Lap | B5: Lap Time | C5: Lap Seconds | D5: T1 | E5: T2 | F5: T3 | G5: T4 | H5: Speed km/h | I5: Cumulative Seconds | J5: Excel Time | K5: Cancelled | L5: Pit Lane | M5: Partial Timing
A6: 1 | B6: 1:51.109 | C6: 111.109 | D6: 31.616 | E6: 20.034 | F6: 41.3 | G6: 18.159 | H6: 274.1 | I6: 111.109 | J6: 0.0012859838 | K6: FALSE | L6: FALSE | M6: FALSE
A7: 2 | B7: 1:45.934 | C7: 105.934 | D7: 26.46 | E7: 19.847 | F7: 41.432 | G7: 18.195 | H7: 356.4 | I7: 217.043 | J7: 0.001226088 | K7: FALSE | L7: FALSE | M7: FALSE
A8: 3 | B8: 1:45.678 | C8: 105.678 | D8: 26.477 | E8: 19.725 | F8: 41.328 | G8: 18.148 | H8: 349.5 | I8: 322.721 | J8: 0.001223125 | K8: FALSE | L8: FALSE | M8: FALSE
A9: 4 | B9: 1:45.704 | C9: 105.704 | D9: 26.314 | E9: 19.736 | F9: 41.604 | G9: 18.05 | H9: 357.6 | I9: 428.425 | J9: 0.0012234259 | K9: FALSE | L9: FALSE | M9: FALSE
A10: 5 | B10: 1:46.042 | C10: 106.042 | D10: 26.38 | E10: 19.806 | F10: 41.666 | G10: 18.19 | H10: 357.6 | I10: 534.467 | J10: 0.001227338 | K10: FALSE | L10: FALSE | M10: FALSE
A11: 6 | B11: 1:46.222 | C11: 106.222 | D11: 26.526 | E11: 19.83 | F11: 41.74 | G11: 18.126 | H11: 360 | I11: 640.689 | J11: 0.0012294213 | K11: FALSE | L11: FALSE | M11: FALSE
A12: 7 | B12: 1:46.246 | C12: 106.246 | D12: 26.41 | E12: 19.907 | F12: 41.785 | G12: 18.144 | H12: 358.8 | I12: 746.935 | J12: 0.0012296991 | K12: FALSE | L12: FALSE | M12: FALSE
A13: 8 | B13: 1:46.340 | C13: 106.34 | D13: 26.472 | E13: 19.943 | F13: 41.797 | G13: 18.128 | H13: 356.4 | I13: 853.275 | J13: 0.001230787 | K13: FALSE | L13: FALSE | M13: FALSE
A14: 9 | B14: 1:46.346 | C14: 106.346 | D14: 26.5 | E14: 19.881 | F14: 41.802 | G14: 18.163 | H14: 357.6 | I14: 959.621 | J14: 0.0012308565 | K14: FALSE | L14: FALSE | M14: FALSE
A15: 10 | B15: 1:46.432 | C15: 106.432 | D15: 26.591 | E15: 19.913 | F15: 41.775 | G15: 18.153 | H15: 357.6 | I15: 1066.053 | J15: 0.0012318519 | K15: FALSE | L15: FALSE | M15: FALSE
A16: 11 | B16: 1:46.957 | C16: 106.957 | D16: 26.585 | E16: 20.053 | F16: 41.991 | G16: 18.328 | H16: 357.6 | I16: 1173.01 | J16: 0.0012379282 | K16: FALSE | L16: FALSE | M16: FALSE
A17: 12 | B17: 1:46.989 | C17: 106.989 | D17: 26.674 | E17: 20.068 | F17: 41.96 | G17: 18.287 | H17: 361.2 | I17: 1279.999 | J17: 0.0012382986 | K17: FALSE | L17: FALSE | M17: FALSE
... A28: 23 | B28: 1:48.036 | C28: 108.036 | D28: 26.876 | E28: 20.282 | F28: 42.548 | G28: 18.33 | H28: 354 | I28: 2457.347 | J28: 0.0012504167 | K28: FALSE | L28: FALSE | M28: FALSE

Sheet Jorge Martin
A1: 2. Jorge MARTIN #89
A3: Team | B3: Aprilia Racing | C3: Manufacturer | D3: APRILIA | E3: Nationality | F3: SPA | G3: Total Laps | H3: 23 | I3: Valid Laps | J3: 22 | K3: Front Tyre | L3: Slick-Medium | M3: Rear Tyre | N3: Slick-Medium
A5: Lap | B5: Lap Time | C5: Lap Seconds | D5: T1 | E5: T2 | F5: T3 | G5: T4 | H5: Speed km/h | I5: Cumulative Seconds | J5: Excel Time | K5: Cancelled | L5: Pit Lane | M5: Partial Timing
A6: 1 | B6: 1:51.179 | C6: 111.179 | D6: 31.58 | E6: 20.187 | F6: 41.28 | G6: 18.132 | H6: 274.1 | I6: 111.179 | J6: 0.001286794 | K6: FALSE | L6: FALSE | M6: FALSE
A7: 2 | B7: 1:46.071 | C7: 106.071 | D7: 26.739 | E7: 19.778 | F7: 41.423 | G7: 18.131 | H7: 361.2 | I7: 217.25 | J7: 0.0012276736 | K7: FALSE | L7: FALSE | M7: FALSE
A8: 3 | B8: 1:46.001 | C8: 106.001 | D8: 26.449 | E8: 19.768 | F8: 41.678 | G8: 18.106 | H8: 360 | I8: 323.251 | J8: 0.0012268634 | K8: FALSE | L8: FALSE | M8: FALSE
A9: 4 | B9: 1:45.856 | C9: 105.856 | D9: 26.406 | E9: 19.783 | F9: 41.533 | G9: 18.134 | H9: 360 | I9: 429.107 | J9: 0.0012251852 | K9: FALSE | L9: FALSE | M9: FALSE
A10: 5 | B10: 1:46.130 | C10: 106.13 | D10: 26.486 | E10: 19.819 | F10: 41.656 | G10: 18.169 | H10: 356.4 | I10: 535.237 | J10: 0.0012283565 | K10: FALSE | L10: FALSE | M10: FALSE
A11: 6 | B11: 1:46.227 | C11: 106.227 | D11: 26.549 | E11: 19.857 | F11: 41.666 | G11: 18.155 | H11: 360 | I11: 641.464 | J11: 0.0012294792 | K11: FALSE | L11: FALSE | M11: FALSE
A12: 7 | B12: 1:46.664 | C12: 106.664 | D12: 26.818 | E12: 19.894 | F12: 41.809 | G12: 18.143 | H12: 357.6 | I12: 748.128 | J12: 0.001234537 | K12: FALSE | L12: FALSE | M12: FALSE
A13: 8 | B13: 1:46.167 | C13: 106.167 | D13: 26.429 | E13: 19.878 | F13: 41.711 | G13: 18.149 | H13: 356.4 | I13: 854.295 | J13: 0.0012287847 | K13: FALSE | L13: FALSE | M13: FALSE
A14: 9 | B14: 1:46.413 | C14: 106.413 | D14: 26.598 | E14: 19.934 | F14: 41.709 | G14: 18.172 | H14: 357.6 | I14: 960.708 | J14: 0.0012316319 | K14: FALSE | L14: FALSE | M14: FALSE
A15: 10 | B15: 1:46.485 | C15: 106.485 | D15: 26.522 | E15: 19.919 | F15: 41.901 | G15: 18.143 | H15: 356.4 | I15: 1067.193 | J15: 0.0012324653 | K15: FALSE | L15: FALSE | M15: FALSE
A16: 11 | B16: 1:46.547 | C16: 106.547 | D16: 26.61 | E16: 19.974 | F16: 41.756 | G16: 18.207 | H16: 357.6 | I16: 1173.74 | J16: 0.0012331829 | K16: FALSE | L16: FALSE | M16: FALSE
A17: 12 | B17: 1:46.888 | C17: 106.888 | D17: 26.635 | E17: 20.204 | F17: 41.855 | G17: 18.194 | H17: 360 | I17: 1280.628 | J17: 0.0012371296 | K17: FALSE | L17: FALSE | M17: FALSE
... A28: 23 | B28: 1:48.388 | C28: 108.388 | D28: 26.948 | E28: 20.301 | F28: 42.656 | G28: 18.483 | H28: 354 | I28: 2460.906 | J28: 0.0012544907 | K28: FALSE | L28: FALSE | M28: FALSE

Sheet Francesco Bagnaia
A1: 3. Francesco BAGNAIA #63
A3: Team | B3: Ducati Lenovo Team | C3: Manufacturer | D3: DUCATI | E3: Nationality | F3: ITA | G3: Total Laps | H3: 23 | I3: Valid Laps | J3: 22 | K3: Front Tyre | L3: Slick-Medium | M3: Rear Tyre | N3: Slick-Medium
A5: Lap | B5: Lap Time | C5: Lap Seconds | D5: T1 | E5: T2 | F5: T3 | G5: T4 | H5: Speed km/h | I5: Cumulative Seconds | J5: Excel Time | K5: Cancelled | L5: Pit Lane | M5: Partial Timing
A6: 1 | B6: 1:51.427 | C6: 111.427 | D6: 31.841 | E6: 20.023 | F6: 41.438 | G6: 18.125 | H6: 278.3 | I6: 111.427 | J6: 0.0012896644 | K6: FALSE | L6: FALSE | M6: FALSE
A7: 2 | B7: 1:45.634 | C7: 105.634 | D7: 26.299 | E7: 19.834 | F7: 41.375 | G7: 18.126 | H7: 363.6 | I7: 217.061 | J7: 0.0012226157 | K7: FALSE | L7: FALSE | M7: FALSE
A8: 3 | B8: 1:45.470 | C8: 105.47 | D8: 26.163 | E8: 19.761 | F8: 41.367 | G8: 18.179 | H8: 357.6 | I8: 322.531 | J8: 0.0012207176 | K8: FALSE | L8: FALSE | M8: FALSE
A9: 4 | B9: 1:45.616 | C9: 105.616 | D9: 26.177 | E9: 19.755 | F9: 41.522 | G9: 18.162 | H9: 356.4 | I9: 428.147 | J9: 0.0012224074 | K9: FALSE | L9: FALSE | M9: FALSE
A10: 5 | B10: 1:46.068 | C10: 106.068 | D10: 26.352 | E10: 19.802 | F10: 41.727 | G10: 18.187 | H10: 355.2 | I10: 534.215 | J10: 0.0012276389 | K10: FALSE | L10: FALSE | M10: FALSE
A11: 6 | B11: 1:46.185 | C11: 106.185 | D11: 26.399 | E11: 19.867 | F11: 41.691 | G11: 18.228 | H11: 356.4 | I11: 640.4 | J11: 0.0012289931 | K11: FALSE | L11: FALSE | M11: FALSE
A12: 7 | B12: 1:46.250 | C12: 106.25 | D12: 26.374 | E12: 19.904 | F12: 41.771 | G12: 18.201 | H12: 356.4 | I12: 746.65 | J12: 0.0012297454 | K12: FALSE | L12: FALSE | M12: FALSE
A13: 8 | B13: 1:46.233 | C13: 106.233 | D13: 26.419 | E13: 19.843 | F13: 41.776 | G13: 18.195 | H13: 355.2 | I13: 852.883 | J13: 0.0012295486 | K13: FALSE | L13: FALSE | M13: FALSE
A14: 9 | B14: 1:46.499 | C14: 106.499 | D14: 26.401 | E14: 19.946 | F14: 41.902 | G14: 18.25 | H14: 356.4 | I14: 959.382 | J14: 0.0012326273 | K14: FALSE | L14: FALSE | M14: FALSE
A15: 10 | B15: 1:46.568 | C15: 106.568 | D15: 26.52 | E15: 19.89 | F15: 41.952 | G15: 18.206 | H15: 356.4 | I15: 1065.95 | J15: 0.0012334259 | K15: FALSE | L15: FALSE | M15: FALSE
A16: 11 | B16: 1:46.866 | C16: 106.866 | D16: 26.408 | E16: 20.046 | F16: 42.088 | G16: 18.324 | H16: 357.6 | I16: 1172.816 | J16: 0.001236875 | K16: FALSE | L16: FALSE | M16: FALSE
A17: 12 | B17: 1:47.065 | C17: 107.065 | D17: 26.605 | E17: 20.011 | F17: 42.153 | G17: 18.296 | H17: 356.4 | I17: 1279.881 | J17: 0.0012391782 | K17: FALSE | L17: FALSE | M17: FALSE
... A28: 23 | B28: 1:47.788 | C28: 107.788 | D28: 26.771 | E28: 20.161 | F28: 42.406 | G28: 18.45 | H28: 357.6 | I28: 2462.445 | J28: 0.0012475463 | K28: FALSE | L28: FALSE | M28: FALSE

Sheet Ai Ogura
A1: 4. Ai OGURA #79
A3: Team | B3: Trackhouse MotoGP Team | C3: Manufacturer | D3: APRILIA | E3: Nationality | F3: JPN | G3: Total Laps | H3: 23 | I3: Valid Laps | J3: 22 | K3: Front Tyre | L3: Slick-Medium | M3: Rear Tyre | N3: Slick-Medium
A5: Lap | B5: Lap Time | C5: Lap Seconds | D5: T1 | E5: T2 | F5: T3 | G5: T4 | H5: Speed km/h | I5: Cumulative Seconds | J5: Excel Time | K5: Cancelled | L5: Pit Lane | M5: Partial Timing
A6: 1 | B6: 1:52.786 | C6: 112.786 | D6: 32.413 | E6: 20.303 | F6: 41.773 | G6: 18.297 | H6: 287.2 | I6: 112.786 | J6: 0.0013053935 | K6: FALSE | L6: FALSE | M6: FALSE
A7: 2 | B7: 1:46.199 | C7: 106.199 | D7: 26.479 | E7: 19.887 | F7: 41.584 | G7: 18.249 | H7: 363.6 | I7: 218.985 | J7: 0.0012291551 | K7: FALSE | L7: FALSE | M7: FALSE
A8: 3 | B8: 1:46.021 | C8: 106.021 | D8: 26.363 | E8: 19.92 | F8: 41.539 | G8: 18.199 | H8: 360 | I8: 325.006 | J8: 0.0012270949 | K8: FALSE | L8: FALSE | M8: FALSE
A9: 4 | B9: 1:46.028 | C9: 106.028 | D9: 26.343 | E9: 19.814 | F9: 41.654 | G9: 18.217 | H9: 361.2 | I9: 431.034 | J9: 0.0012271759 | K9: FALSE | L9: FALSE | M9: FALSE
A10: 5 | B10: 1:46.413 | C10: 106.413 | D10: 26.459 | E10: 19.903 | F10: 41.817 | G10: 18.234 | H10: 362.4 | I10: 537.447 | J10: 0.0012316319 | K10: FALSE | L10: FALSE | M10: FALSE
A11: 6 | B11: 1:46.574 | C11: 106.574 | D11: 26.563 | E11: 19.901 | F11: 41.854 | G11: 18.256 | H11: 362.4 | I11: 644.021 | J11: 0.0012334954 | K11: FALSE | L11: FALSE | M11: FALSE
A12: 7 | B12: 1:46.818 | C12: 106.818 | D12: 26.581 | E12: 19.866 | F12: 42.11 | G12: 18.261 | H12: 361.2 | I12: 750.839 | J12: 0.0012363194 | K12: FALSE | L12: FALSE | M12: FALSE
A13: 8 | B13: 1:47.107 | C13: 107.107 | D13: 26.624 | E13: 20.115 | F13: 42.036 | G13: 18.332 | H13: 361.2 | I13: 857.946 | J13: 0.0012396644 | K13: FALSE | L13: FALSE | M13: FALSE
A14: 9 | B14: 1:47.148 | C14: 107.148 | D14: 26.709 | E14: 19.989 | F14: 42.11 | G14: 18.34 | H14: 360 | I14: 965.094 | J14: 0.0012401389 | K14: FALSE | L14: FALSE | M14: FALSE
A15: 10 | B15: 1:46.890 | C15: 106.89 | D15: 26.584 | E15: 20.1 | F15: 42.005 | G15: 18.201 | H15: 361.2 | I15: 1071.984 | J15: 0.0012371528 | K15: FALSE | L15: FALSE | M15: FALSE
A16: 11 | B16: 1:47.041 | C16: 107.041 | D16: 26.625 | E16: 19.961 | F16: 42.135 | G16: 18.32 | H16: 363.6 | I16: 1179.025 | J16: 0.0012389005 | K16: FALSE | L16: FALSE | M16: FALSE
A17: 12 | B17: 1:46.632 | C17: 106.632 | D17: 26.619 | E17: 19.882 | F17: 41.926 | G17: 18.205 | H17: 363.6 | I17: 1285.657 | J17: 0.0012341667 | K17: FALSE | L17: FALSE | M17: FALSE
... A28: 23 | B28: 1:46.902 | C28: 106.902 | D28: 26.484 | E28: 19.928 | F28: 42.053 | G28: 18.437 | H28: 360 | I28: 2462.479 | J28: 0.0012372917 | K28: FALSE | L28: FALSE | M28: FALSE

Sheet Fabio Di Giannantonio
A1: 5. Fabio DI GIANNANTONIO #49
A3: Team | B3: Pertamina Enduro VR46 Racing Team | C3: Manufacturer | D3: DUCATI | E3: Nationality | F3: ITA | G3: Total Laps | H3: 23 | I3: Valid Laps | J3: 22 | K3: Front Tyre | L3: Slick-Medium | M3: Rear Tyre | N3: Slick-Medium
A5: Lap | B5: Lap Time | C5: Lap Seconds | D5: T1 | E5: T2 | F5: T3 | G5: T4 | H5: Speed km/h | I5: Cumulative Seconds | J5: Excel Time | K5: Cancelled | L5: Pit Lane | M5: Partial Timing
A6: 1 | B6: 1:53.858 | C6: 113.858 | D6: 32.855 | E6: 20.426 | F6: 42.24 | G6: 18.337 | H6: 271.3 | I6: 113.858 | J6: 0.0013178009 | K6: FALSE | L6: FALSE | M6: FALSE
A7: 2 | B7: 1:46.474 | C7: 106.474 | D7: 26.425 | E7: 19.82 | F7: 41.843 | G7: 18.386 | H7: 358.8 | I7: 220.332 | J7: 0.001232338 | K7: FALSE | L7: FALSE | M7: FALSE
A8: 3 | B8: 1:46.254 | C8: 106.254 | D8: 26.575 | E8: 19.796 | F8: 41.591 | G8: 18.292 | H8: 357.6 | I8: 326.586 | J8: 0.0012297917 | K8: FALSE | L8: FALSE | M8: FALSE
A9: 4 | B9: 1:46.197 | C9: 106.197 | D9: 26.415 | E9: 19.783 | F9: 41.762 | G9: 18.237 | H9: 356.4 | I9: 432.783 | J9: 0.0012291319 | K9: FALSE | L9: FALSE | M9: FALSE
A10: 5 | B10: 1:46.425 | C10: 106.425 | D10: 26.545 | E10: 19.823 | F10: 41.735 | G10: 18.322 | H10: 356.4 | I10: 539.208 | J10: 0.0012317708 | K10: FALSE | L10: FALSE | M10: FALSE
A11: 6 | B11: 1:46.452 | C11: 106.452 | D11: 26.556 | E11: 19.833 | F11: 41.769 | G11: 18.294 | H11: 356.4 | I11: 645.66 | J11: 0.0012320833 | K11: FALSE | L11: FALSE | M11: FALSE
A12: 7 | B12: 1:46.315 | C12: 106.315 | D12: 26.472 | E12: 19.725 | F12: 41.845 | G12: 18.273 | H12: 355.2 | I12: 751.975 | J12: 0.0012304977 | K12: FALSE | L12: FALSE | M12: FALSE
A13: 8 | B13: 1:46.766 | C13: 106.766 | D13: 26.512 | E13: 19.855 | F13: 42.026 | G13: 18.373 | H13: 356.4 | I13: 858.741 | J13: 0.0012357176 | K13: FALSE | L13: FALSE | M13: FALSE
A14: 9 | B14: 1:46.715 | C14: 106.715 | D14: 26.51 | E14: 19.871 | F14: 42.078 | G14: 18.256 | H14: 357.6 | I14: 965.456 | J14: 0.0012351273 | K14: FALSE | L14: FALSE | M14: FALSE
A15: 10 | B15: 1:46.838 | C15: 106.838 | D15: 26.58 | E15: 19.896 | F15: 42.112 | G15: 18.25 | H15: 358.8 | I15: 1072.294 | J15: 0.0012365509 | K15: FALSE | L15: FALSE | M15: FALSE
A16: 11 | B16: 1:46.770 | C16: 106.77 | D16: 26.631 | E16: 19.885 | F16: 42.027 | G16: 18.227 | H16: 360 | I16: 1179.064 | J16: 0.0012357639 | K16: FALSE | L16: FALSE | M16: FALSE
A17: 12 | B17: 1:47.056 | C17: 107.056 | D17: 26.792 | E17: 19.904 | F17: 42.07 | G17: 18.29 | H17: 357.6 | I17: 1286.12 | J17: 0.0012390741 | K17: FALSE | L17: FALSE | M17: FALSE
... A28: 23 | B28: 1:46.816 | C28: 106.816 | D28: 26.594 | E28: 19.947 | F28: 42.079 | G28: 18.196 | H28: 358.8 | I28: 2462.8 | J28: 0.0012362963 | K28: FALSE | L28: FALSE | M28: FALSE

Sheet Pedro Acosta
A1: 6. Pedro ACOSTA #37
A3: Team | B3: Red Bull KTM Factory Racing | C3: Manufacturer | D3: KTM | E3: Nationality | F3: SPA | G3: Total Laps | H3: 23 | I3: Valid Laps | J3: 22 | K3: Front Tyre | L3: Slick-Medium | M3: Rear Tyre | N3: Slick-Medium
A5: Lap | B5: Lap Time | C5: Lap Seconds | D5: T1 | E5: T2 | F5: T3 | G5: T4 | H5: Speed km/h | I5: Cumulative Seconds | J5: Excel Time | K5: Cancelled | L5: Pit Lane | M5: Partial Timing
A6: 1 | B6: 1:52.146 | C6: 112.146 | D6: 32.251 | E6: 20.08 | F6: 41.661 | G6: 18.154 | H6: 279 | I6: 112.146 | J6: 0.0012979861 | K6: FALSE | L6: FALSE | M6: FALSE
A7: 2 | B7: 1:45.563 | C7: 105.563 | D7: 26.328 | E7: 19.741 | F7: 41.441 | G7: 18.053 | H7: 364.8 | I7: 217.709 | J7: 0.001221794 | K7: FALSE | L7: FALSE | M7: FALSE
A8: 3 | B8: 1:46.176 | C8: 106.176 | D8: 26.473 | E8: 19.889 | F8: 41.579 | G8: 18.235 | H8: 361.2 | I8: 323.885 | J8: 0.0012288889 | K8: FALSE | L8: FALSE | M8: FALSE
A9: 4 | B9: 1:46.133 | C9: 106.133 | D9: 26.365 | E9: 19.851 | F9: 41.748 | G9: 18.169 | H9: 360 | I9: 430.018 | J9: 0.0012283912 | K9: FALSE | L9: FALSE | M9: FALSE
A10: 5 | B10: 1:46.710 | C10: 106.71 | D10: 26.551 | E10: 19.966 | F10: 41.831 | G10: 18.362 | H10: 360 | I10: 536.728 | J10: 0.0012350694 | K10: FALSE | L10: FALSE | M10: FALSE
A11: 6 | B11: 1:46.561 | C11: 106.561 | D11: 26.51 | E11: 19.852 | F11: 41.917 | G11: 18.282 | H11: 361.2 | I11: 643.289 | J11: 0.0012333449 | K11: FALSE | L11: FALSE | M11: FALSE
A12: 7 | B12: 1:46.914 | C12: 106.914 | D12: 26.519 | E12: 19.904 | F12: 42.171 | G12: 18.32 | H12: 355.2 | I12: 750.203 | J12: 0.0012374306 | K12: FALSE | L12: FALSE | M12: FALSE
A13: 8 | B13: 1:47.347 | C13: 107.347 | D13: 27.034 | E13: 20.006 | F13: 42.033 | G13: 18.274 | H13: 346.1 | I13: 857.55 | J13: 0.0012424421 | K13: FALSE | L13: FALSE | M13: FALSE
A14: 9 | B14: 1:46.734 | C14: 106.734 | D14: 26.509 | E14: 19.984 | F14: 41.912 | G14: 18.329 | H14: 357.6 | I14: 964.284 | J14: 0.0012353472 | K14: FALSE | L14: FALSE | M14: FALSE
A15: 10 | B15: 1:46.706 | C15: 106.706 | D15: 26.528 | E15: 19.989 | F15: 41.912 | G15: 18.277 | H15: 357.6 | I15: 1070.99 | J15: 0.0012350231 | K15: FALSE | L15: FALSE | M15: FALSE
A16: 11 | B16: 1:46.724 | C16: 106.724 | D16: 26.523 | E16: 19.962 | F16: 41.963 | G16: 18.276 | H16: 357.6 | I16: 1177.714 | J16: 0.0012352315 | K16: FALSE | L16: FALSE | M16: FALSE
A17: 12 | B17: 1:46.952 | C17: 106.952 | D17: 26.558 | E17: 19.997 | F17: 41.951 | G17: 18.446 | H17: 356.4 | I17: 1284.666 | J17: 0.0012378704 | K17: FALSE | L17: FALSE | M17: FALSE
... A28: 23 | B28: 1:47.763 | C28: 107.763 | D28: 26.774 | E28: 20.137 | F28: 42.463 | G28: 18.389 | H28: 355.2 | I28: 2464.814 | J28: 0.0012472569 | K28: FALSE | L28: FALSE | M28: FALSE

Sheet Marc Marquez
A1: 7. Marc MARQUEZ #93
A3: Team | B3: Ducati Lenovo Team | C3: Manufacturer | D3: DUCATI | E3: Nationality | F3: SPA | G3: Total Laps | H3: 23 | I3: Valid Laps | J3: 21 | K3: Front Tyre | L3: Slick-Medium | M3: Rear Tyre | N3: Slick-Medium
A5: Lap | B5: Lap Time | C5: Lap Seconds | D5: T1 | E5: T2 | F5: T3 | G5: T4 | H5: Speed km/h | I5: Cumulative Seconds | J5: Excel Time | K5: Cancelled | L5: Pit Lane | M5: Partial Timing
A6: 1 | B6: 1:51.542 | C6: 111.542 | D6: 31.959 | E6: 20.089 | F6: 41.466 | G6: 18.028 | H6: 275.5 | I6: 111.542 | J6: 0.0012909954 | K6: FALSE | L6: FALSE | M6: FALSE
A7: 2 | B7: 1:46.001 | C7: 106.001 | D7: 26.509 | E7: 19.84 | F7: 41.585 | G7: 18.067 | H7: 364.8 | I7: 217.543 | J7: 0.0012268634 | K7: TRUE | L7: FALSE | M7: FALSE
A8: 3 | B8: 1:46.122 | C8: 106.122 | D8: 26.56 | E8: 19.804 | F8: 41.648 | G8: 18.11 | H8: 363.6 | I8: 323.665 | J8: 0.0012282639 | K8: FALSE | L8: FALSE | M8: FALSE
A9: 4 | B9: 1:46.248 | C9: 106.248 | D9: 26.372 | E9: 19.846 | F9: 41.904 | G9: 18.126 | H9: 362.4 | I9: 429.913 | J9: 0.0012297222 | K9: FALSE | L9: FALSE | M9: FALSE
A10: 5 | B10: 1:46.642 | C10: 106.642 | D10: 26.553 | E10: 19.887 | F10: 41.949 | G10: 18.253 | H10: 358.8 | I10: 536.555 | J10: 0.0012342824 | K10: FALSE | L10: FALSE | M10: FALSE
A11: 6 | B11: 1:46.690 | C11: 106.69 | D11: 26.552 | E11: 19.854 | F11: 42.011 | G11: 18.273 | H11: 358.8 | I11: 643.245 | J11: 0.001234838 | K11: FALSE | L11: FALSE | M11: FALSE
A12: 7 | B12: 1:47.035 | C12: 107.035 | D12: 26.457 | E12: 19.845 | F12: 42.469 | G12: 18.264 | H12: 356.4 | I12: 750.28 | J12: 0.001238831 | K12: FALSE | L12: FALSE | M12: FALSE
A13: 8 | B13: 1:46.967 | C13: 106.967 | D13: 26.539 | E13: 19.983 | F13: 42.227 | G13: 18.218 | H13: 358.8 | I13: 857.247 | J13: 0.001238044 | K13: FALSE | L13: FALSE | M13: FALSE
A14: 9 | B14: 1:46.658 | C14: 106.658 | D14: 26.534 | E14: 19.949 | F14: 42.025 | G14: 18.15 | H14: 355.2 | I14: 963.905 | J14: 0.0012344676 | K14: FALSE | L14: FALSE | M14: FALSE
A15: 10 | B15: 1:46.678 | C15: 106.678 | D15: 26.528 | E15: 19.986 | F15: 42.024 | G15: 18.14 | H15: 355.2 | I15: 1070.583 | J15: 0.0012346991 | K15: FALSE | L15: FALSE | M15: FALSE
A16: 11 | B16: 1:46.689 | C16: 106.689 | D16: 26.524 | E16: 19.937 | F16: 42.09 | G16: 18.138 | H16: 357.6 | I16: 1177.272 | J16: 0.0012348264 | K16: FALSE | L16: FALSE | M16: FALSE
A17: 12 | B17: 1:47.012 | C17: 107.012 | D17: 26.632 | E17: 19.944 | F17: 42.213 | G17: 18.223 | H17: 357.6 | I17: 1284.284 | J17: 0.0012385648 | K17: FALSE | L17: FALSE | M17: FALSE
... A28: 23 | B28: 1:49.007 | C28: 109.007 | D28: 27.066 | E28: 20.386 | F28: 43.165 | G28: 18.39 | H28: 355.2 | I28: 2468.109 | J28: 0.0012616551 | K28: FALSE | L28: FALSE | M28: FALSE

Sheet Raul Fernandez
A1: 8. Raul FERNANDEZ #25
A3: Team | B3: Trackhouse MotoGP Team | C3: Manufacturer | D3: APRILIA | E3: Nationality | F3: SPA | G3: Total Laps | H3: 23 | I3: Valid Laps | J3: 22 | K3: Front Tyre | L3: Slick-Medium | M3: Rear Tyre | N3: Slick-Medium
A5: Lap | B5: Lap Time | C5: Lap Seconds | D5: T1 | E5: T2 | F5: T3 | G5: T4 | H5: Speed km/h | I5: Cumulative Seconds | J5: Excel Time | K5: Cancelled | L5: Pit Lane | M5: Partial Timing
A6: 1 | B6: 1:54.447 | C6: 114.447 | D6: 33.402 | E6: 20.808 | F6: 41.936 | G6: 18.301 | H6: 271.3 | I6: 114.447 | J6: 0.0013246181 | K6: FALSE | L6: FALSE | M6: FALSE
A7: 2 | B7: 1:46.672 | C7: 106.672 | D7: 26.743 | E7: 19.83 | F7: 41.905 | G7: 18.194 | H7: 352.9 | I7: 221.119 | J7: 0.0012346296 | K7: FALSE | L7: FALSE | M7: FALSE
A8: 3 | B8: 1:46.126 | C8: 106.126 | D8: 26.573 | E8: 19.84 | F8: 41.433 | G8: 18.28 | H8: 356.4 | I8: 327.245 | J8: 0.0012283102 | K8: FALSE | L8: FALSE | M8: FALSE
A9: 4 | B9: 1:47.384 | C9: 107.384 | D9: 26.631 | E9: 19.692 | F9: 42.783 | G9: 18.278 | H9: 360 | I9: 434.629 | J9: 0.0012428704 | K9: FALSE | L9: FALSE | M9: FALSE
A10: 5 | B10: 1:46.178 | C10: 106.178 | D10: 26.455 | E10: 19.776 | F10: 41.672 | G10: 18.275 | H10: 358.8 | I10: 540.807 | J10: 0.001228912 | K10: FALSE | L10: FALSE | M10: FALSE
A11: 6 | B11: 1:46.496 | C11: 106.496 | D11: 26.637 | E11: 19.776 | F11: 41.797 | G11: 18.286 | H11: 360 | I11: 647.303 | J11: 0.0012325926 | K11: FALSE | L11: FALSE | M11: FALSE
A12: 7 | B12: 1:46.879 | C12: 106.879 | D12: 26.609 | E12: 19.823 | F12: 42.06 | G12: 18.387 | H12: 360 | I12: 754.182 | J12: 0.0012370255 | K12: FALSE | L12: FALSE | M12: FALSE
A13: 8 | B13: 1:46.526 | C13: 106.526 | D13: 26.666 | E13: 19.762 | F13: 41.816 | G13: 18.282 | H13: 355.2 | I13: 860.708 | J13: 0.0012329398 | K13: FALSE | L13: FALSE | M13: FALSE
A14: 9 | B14: 1:46.604 | C14: 106.604 | D14: 26.595 | E14: 19.782 | F14: 41.935 | G14: 18.292 | H14: 357.6 | I14: 967.312 | J14: 0.0012338426 | K14: FALSE | L14: FALSE | M14: FALSE
A15: 10 | B15: 1:46.340 | C15: 106.34 | D15: 26.509 | E15: 19.813 | F15: 41.789 | G15: 18.229 | H15: 360 | I15: 1073.652 | J15: 0.001230787 | K15: FALSE | L15: FALSE | M15: FALSE
A16: 11 | B16: 1:46.995 | C16: 106.995 | D16: 26.592 | E16: 19.986 | F16: 42.085 | G16: 18.332 | H16: 360 | I16: 1180.647 | J16: 0.0012383681 | K16: FALSE | L16: FALSE | M16: FALSE
A17: 12 | B17: 1:46.801 | C17: 106.801 | D17: 26.706 | E17: 19.87 | F17: 41.898 | G17: 18.327 | H17: 356.4 | I17: 1287.448 | J17: 0.0012361227 | K17: FALSE | L17: FALSE | M17: FALSE
... A28: 23 | B28: 1:48.323 | C28: 108.323 | D28: 26.838 | E28: 20.118 | F28: 42.895 | G28: 18.472 | H28: 352.9 | I28: 2470.727 | J28: 0.0012537384 | K28: FALSE | L28: FALSE | M28: FALSE

Sheet Fermin Aldeguer
A1: 9. Fermin ALDEGUER #54
A3: Team | B3: BK8 Gresini Racing MotoGP | C3: Manufacturer | D3: DUCATI | E3: Nationality | F3: SPA | G3: Total Laps | H3: 23 | I3: Valid Laps | J3: 21 | K3: Front Tyre | L3: Slick-Medium | M3: Rear Tyre | N3: Slick-Medium
A5: Lap | B5: Lap Time | C5: Lap Seconds | D5: T1 | E5: T2 | F5: T3 | G5: T4 | H5: Speed km/h | I5: Cumulative Seconds | J5: Excel Time | K5: Cancelled | L5: Pit Lane | M5: Partial Timing
A6: 1 | B6: 1:52.052 | C6: 112.052 | D6: 32.05 | E6: 20.198 | F6: 41.593 | G6: 18.211 | H6: 273.4 | I6: 112.052 | J6: 0.0012968981 | K6: FALSE | L6: FALSE | M6: FALSE
A7: 2 | B7: 1:45.961 | C7: 105.961 | D7: 26.543 | E7: 19.813 | F7: 41.488 | G7: 18.117 | H7: 357.6 | I7: 218.013 | J7: 0.0012264005 | K7: FALSE | L7: FALSE | M7: FALSE
A8: 3 | B8: 1:46.087 | C8: 106.087 | D8: 26.516 | E8: 19.85 | F8: 41.552 | G8: 18.169 | H8: 360 | I8: 324.1 | J8: 0.0012278588 | K8: FALSE | L8: FALSE | M8: FALSE
A9: 4 | B9: 1:46.393 | C9: 106.393 | D9: 26.408 | E9: 19.872 | F9: 41.956 | G9: 18.157 | H9: 358.8 | I9: 430.493 | J9: 0.0012314005 | K9: FALSE | L9: FALSE | M9: FALSE
A10: 5 | B10: 1:46.378 | C10: 106.378 | D10: 26.531 | E10: 19.826 | F10: 41.726 | G10: 18.295 | H10: 356.4 | I10: 536.871 | J10: 0.0012312269 | K10: FALSE | L10: FALSE | M10: FALSE
A11: 6 | B11: 1:46.528 | C11: 106.528 | D11: 26.545 | E11: 19.862 | F11: 41.849 | G11: 18.272 | H11: 360 | I11: 643.399 | J11: 0.001232963 | K11: FALSE | L11: FALSE | M11: FALSE
A12: 7 | B12: 1:46.841 | C12: 106.841 | D12: 26.718 | E12: 19.81 | F12: 42.136 | G12: 18.177 | H12: 356.4 | I12: 750.24 | J12: 0.0012365856 | K12: FALSE | L12: FALSE | M12: FALSE
A13: 8 | B13: 1:47.469 | C13: 107.469 | D13: 26.89 | E13: 19.949 | F13: 42.342 | G13: 18.288 | H13: 357.6 | I13: 857.709 | J13: 0.0012438542 | K13: FALSE | L13: FALSE | M13: FALSE
A14: 9 | B14: 1:46.943 | C14: 106.943 | D14: 26.748 | E14: 19.924 | F14: 41.991 | G14: 18.28 | H14: 357.6 | I14: 964.652 | J14: 0.0012377662 | K14: FALSE | L14: FALSE | M14: FALSE
A15: 10 | B15: 1:46.955 | C15: 106.955 | D15: 26.66 | E15: 19.948 | F15: 42.112 | G15: 18.235 | H15: 357.6 | I15: 1071.607 | J15: 0.0012379051 | K15: FALSE | L15: FALSE | M15: FALSE
A16: 11 | B16: 1:46.928 | C16: 106.928 | D16: 26.659 | E16: 19.924 | F16: 42.044 | G16: 18.301 | H16: 355.2 | I16: 1178.535 | J16: 0.0012375926 | K16: FALSE | L16: FALSE | M16: FALSE
A17: 12 | B17: 1:46.783 | C17: 106.783 | D17: 26.624 | E17: 19.947 | F17: 41.989 | G17: 18.223 | H17: 355.2 | I17: 1285.318 | J17: 0.0012359144 | K17: FALSE | L17: FALSE | M17: FALSE
... A28: 23 | B28: 1:49.375 | C28: 109.375 | D28: 27.153 | E28: 20.368 | F28: 43.187 | G28: 18.667 | H28: 352.9 | I28: 2471.991 | J28: 0.0012659144 | K28: FALSE | L28: FALSE | M28: FALSE

Sheet Diogo Moreira
A1: 10. Diogo MOREIRA #11
A3: Team | B3: Pro Honda LCR | C3: Manufacturer | D3: HONDA | E3: Nationality | F3: BRA | G3: Total Laps | H3: 23 | I3: Valid Laps | J3: 22 | K3: Front Tyre | L3: Slick-Medium | M3: Rear Tyre | N3: Slick-Medium
A5: Lap | B5: Lap Time | C5: Lap Seconds | D5: T1 | E5: T2 | F5: T3 | G5: T4 | H5: Speed km/h | I5: Cumulative Seconds | J5: Excel Time | K5: Cancelled | L5: Pit Lane | M5: Partial Timing
A6: 1 | B6: 1:53.123 | C6: 113.123 | D6: 32.635 | E6: 20.298 | F6: 41.972 | G6: 18.218 | H6: 276.9 | I6: 113.123 | J6: 0.001309294 | K6: FALSE | L6: FALSE | M6: FALSE
A7: 2 | B7: 1:46.784 | C7: 106.784 | D7: 26.596 | E7: 19.971 | F7: 41.94 | G7: 18.277 | H7: 367.3 | I7: 219.907 | J7: 0.0012359259 | K7: FALSE | L7: FALSE | M7: FALSE
A8: 3 | B8: 1:46.488 | C8: 106.488 | D8: 26.754 | E8: 19.842 | F8: 41.7 | G8: 18.192 | H8: 357.6 | I8: 326.395 | J8: 0.0012325 | K8: FALSE | L8: FALSE | M8: FALSE
A9: 4 | B9: 1:46.671 | C9: 106.671 | D9: 26.46 | E9: 19.834 | F9: 42.18 | G9: 18.197 | H9: 357.6 | I9: 433.066 | J9: 0.0012346181 | K9: FALSE | L9: FALSE | M9: FALSE
A10: 5 | B10: 1:46.969 | C10: 106.969 | D10: 26.666 | E10: 19.918 | F10: 42.101 | G10: 18.284 | H10: 358.8 | I10: 540.035 | J10: 0.0012380671 | K10: FALSE | L10: FALSE | M10: FALSE
A11: 6 | B11: 1:46.927 | C11: 106.927 | D11: 26.624 | E11: 19.963 | F11: 42.08 | G11: 18.26 | H11: 364.8 | I11: 646.962 | J11: 0.001237581 | K11: FALSE | L11: FALSE | M11: FALSE
A12: 7 | B12: 1:47.484 | C12: 107.484 | D12: 26.594 | E12: 20.065 | F12: 42.461 | G12: 18.364 | H12: 360 | I12: 754.446 | J12: 0.0012440278 | K12: FALSE | L12: FALSE | M12: FALSE
A13: 8 | B13: 1:47.328 | C13: 107.328 | D13: 26.704 | E13: 19.997 | F13: 42.199 | G13: 18.428 | H13: 361.2 | I13: 861.774 | J13: 0.0012422222 | K13: FALSE | L13: FALSE | M13: FALSE
A14: 9 | B14: 1:47.461 | C14: 107.461 | D14: 26.772 | E14: 20.022 | F14: 42.251 | G14: 18.416 | H14: 356.4 | I14: 969.235 | J14: 0.0012437616 | K14: FALSE | L14: FALSE | M14: FALSE
A15: 10 | B15: 1:47.467 | C15: 107.467 | D15: 26.858 | E15: 20.079 | F15: 42.227 | G15: 18.303 | H15: 358.8 | I15: 1076.702 | J15: 0.001243831 | K15: FALSE | L15: FALSE | M15: FALSE
A16: 11 | B16: 1:47.616 | C16: 107.616 | D16: 26.753 | E16: 20.165 | F16: 42.32 | G16: 18.378 | H16: 356.4 | I16: 1184.318 | J16: 0.0012455556 | K16: FALSE | L16: FALSE | M16: FALSE
A17: 12 | B17: 1:47.780 | C17: 107.78 | D17: 26.913 | E17: 20.204 | F17: 42.242 | G17: 18.421 | H17: 354 | I17: 1292.098 | J17: 0.0012474537 | K17: FALSE | L17: FALSE | M17: FALSE
... A28: 23 | B28: 1:47.932 | C28: 107.932 | D28: 26.781 | E28: 20.208 | F28: 42.552 | G28: 18.391 | H28: 357.6 | I28: 2478.713 | J28: 0.001249213 | K28: FALSE | L28: FALSE | M28: FALSE

Sheet Brad Binder
A1: 11. Brad BINDER #33
A3: Team | B3: Red Bull KTM Factory Racing | C3: Manufacturer | D3: KTM | E3: Nationality | F3: RSA | G3: Total Laps | H3: 23 | I3: Valid Laps | J3: 21 | K3: Front Tyre | L3: Slick-Medium | M3: Rear Tyre | N3: Slick-Medium
A5: Lap | B5: Lap Time | C5: Lap Seconds | D5: T1 | E5: T2 | F5: T3 | G5: T4 | H5: Speed km/h | I5: Cumulative Seconds | J5: Excel Time | K5: Cancelled | L5: Pit Lane | M5: Partial Timing
A6: 1 | B6: 1:53.659 | C6: 113.659 | D6: 32.769 | E6: 20.448 | F6: 42.202 | G6: 18.24 | H6: 278.3 | I6: 113.659 | J6: 0.0013154977 | K6: FALSE | L6: FALSE | M6: FALSE
A7: 2 | B7: 1:46.557 | C7: 106.557 | D7: 26.471 | E7: 19.88 | F7: 41.865 | G7: 18.341 | H7: 357.6 | I7: 220.216 | J7: 0.0012332986 | K7: FALSE | L7: FALSE | M7: FALSE
A8: 3 | B8: 1:46.697 | C8: 106.697 | D8: 26.784 | E8: 19.991 | F8: 41.642 | G8: 18.28 | H8: 358.8 | I8: 326.913 | J8: 0.001234919 | K8: FALSE | L8: FALSE | M8: FALSE
A9: 4 | B9: 1:46.456 | C9: 106.456 | D9: 26.509 | E9: 19.825 | F9: 41.857 | G9: 18.265 | H9: 358.8 | I9: 433.369 | J9: 0.0012321296 | K9: FALSE | L9: FALSE | M9: FALSE
A10: 5 | B10: 1:46.922 | C10: 106.922 | D10: 26.683 | E10: 19.989 | F10: 41.909 | G10: 18.341 | H10: 358.8 | I10: 540.291 | J10: 0.0012375231 | K10: FALSE | L10: FALSE | M10: FALSE
A11: 6 | B11: 1:46.948 | C11: 106.948 | D11: 26.622 | E11: 19.953 | F11: 42.02 | G11: 18.353 | H11: 358.8 | I11: 647.239 | J11: 0.0012378241 | K11: FALSE | L11: FALSE | M11: FALSE
A12: 7 | B12: 1:47.333 | C12: 107.333 | D12: 26.865 | E12: 19.956 | F12: 42.161 | G12: 18.351 | H12: 354 | I12: 754.572 | J12: 0.0012422801 | K12: FALSE | L12: FALSE | M12: FALSE
A13: 8 | B13: 1:47.364 | C13: 107.364 | D13: 26.761 | E13: 20.021 | F13: 42.156 | G13: 18.426 | H13: 360 | I13: 861.936 | J13: 0.0012426389 | K13: FALSE | L13: FALSE | M13: FALSE
A14: 9 | B14: 1:47.338 | C14: 107.338 | D14: 26.78 | E14: 20.009 | F14: 42.241 | G14: 18.308 | H14: 356.4 | I14: 969.274 | J14: 0.001242338 | K14: FALSE | L14: FALSE | M14: FALSE
A15: 10 | B15: 1:47.289 | C15: 107.289 | D15: 26.648 | E15: 20.059 | F15: 42.211 | G15: 18.371 | H15: 356.4 | I15: 1076.563 | J15: 0.0012417708 | K15: FALSE | L15: FALSE | M15: FALSE
A16: 11 | B16: 1:47.676 | C16: 107.676 | D16: 26.765 | E16: 20.074 | F16: 42.412 | G16: 18.425 | H16: 352.9 | I16: 1184.239 | J16: 0.00124625 | K16: FALSE | L16: FALSE | M16: FALSE
A17: 12 | B17: 1:47.699 | C17: 107.699 | D17: 26.847 | E17: 20.152 | F17: 42.298 | G17: 18.402 | H17: 351.7 | I17: 1291.938 | J17: 0.0012465162 | K17: FALSE | L17: FALSE | M17: FALSE
... A28: 23 | B28: 1:48.374 | C28: 108.374 | D28: 26.933 | E28: 20.249 | F28: 42.655 | G28: 18.537 | H28: 351.7 | I28: 2478.826 | J28: 0.0012543287 | K28: FALSE | L28: FALSE | M28: FALSE

Sheet Joan Mir
A1: 12. Joan MIR #36
A3: Team | B3: Honda HRC Castrol | C3: Manufacturer | D3: HONDA | E3: Nationality | F3: SPA | G3: Total Laps | H3: 23 | I3: Valid Laps | J3: 22 | K3: Front Tyre | L3: Slick-Medium | M3: Rear Tyre | N3: Slick-Medium
A5: Lap | B5: Lap Time | C5: Lap Seconds | D5: T1 | E5: T2 | F5: T3 | G5: T4 | H5: Speed km/h | I5: Cumulative Seconds | J5: Excel Time | K5: Cancelled | L5: Pit Lane | M5: Partial Timing
A6: 1 | B6: 1:54.392 | C6: 114.392 | D6: 33.05 | E6: 20.766 | F6: 42.159 | G6: 18.417 | H6: 282.7 | I6: 114.392 | J6: 0.0013239815 | K6: FALSE | L6: FALSE | M6: FALSE
A7: 2 | B7: 1:47.431 | C7: 107.431 | D7: 26.917 | E7: 20.021 | F7: 42.239 | G7: 18.254 | H7: 343.9 | I7: 221.823 | J7: 0.0012434144 | K7: FALSE | L7: FALSE | M7: FALSE
A8: 3 | B8: 1:46.898 | C8: 106.898 | D8: 26.624 | E8: 19.951 | F8: 41.932 | G8: 18.391 | H8: 356.4 | I8: 328.721 | J8: 0.0012372454 | K8: FALSE | L8: FALSE | M8: FALSE
A9: 4 | B9: 1:46.758 | C9: 106.758 | D9: 26.446 | E9: 19.995 | F9: 41.958 | G9: 18.359 | H9: 357.6 | I9: 435.479 | J9: 0.001235625 | K9: FALSE | L9: FALSE | M9: FALSE
A10: 5 | B10: 1:47.081 | C10: 107.081 | D10: 26.687 | E10: 19.986 | F10: 42.085 | G10: 18.323 | H10: 360 | I10: 542.56 | J10: 0.0012393634 | K10: FALSE | L10: FALSE | M10: FALSE
A11: 6 | B11: 1:47.045 | C11: 107.045 | D11: 26.635 | E11: 19.976 | F11: 42.095 | G11: 18.339 | H11: 360 | I11: 649.605 | J11: 0.0012389468 | K11: FALSE | L11: FALSE | M11: FALSE
A12: 7 | B12: 1:47.115 | C12: 107.115 | D12: 26.739 | E12: 19.935 | F12: 42.203 | G12: 18.238 | H12: 358.8 | I12: 756.72 | J12: 0.0012397569 | K12: FALSE | L12: FALSE | M12: FALSE
A13: 8 | B13: 1:46.913 | C13: 106.913 | D13: 26.588 | E13: 19.969 | F13: 42.087 | G13: 18.269 | H13: 355.2 | I13: 863.633 | J13: 0.001237419 | K13: FALSE | L13: FALSE | M13: FALSE
A14: 9 | B14: 1:46.898 | C14: 106.898 | D14: 26.585 | E14: 19.981 | F14: 42.082 | G14: 18.25 | H14: 356.4 | I14: 970.531 | J14: 0.0012372454 | K14: FALSE | L14: FALSE | M14: FALSE
A15: 10 | B15: 1:47.066 | C15: 107.066 | D15: 26.555 | E15: 20.024 | F15: 42.261 | G15: 18.226 | H15: 356.4 | I15: 1077.597 | J15: 0.0012391898 | K15: FALSE | L15: FALSE | M15: FALSE
A16: 11 | B16: 1:47.393 | C16: 107.393 | D16: 26.634 | E16: 20.099 | F16: 42.319 | G16: 18.341 | H16: 358.8 | I16: 1184.99 | J16: 0.0012429745 | K16: FALSE | L16: FALSE | M16: FALSE
A17: 12 | B17: 1:47.380 | C17: 107.38 | D17: 26.732 | E17: 20.051 | F17: 42.271 | G17: 18.326 | H17: 357.6 | I17: 1292.37 | J17: 0.0012428241 | K17: FALSE | L17: FALSE | M17: FALSE
... A28: 23 | B28: 1:48.397 | C28: 108.397 | D28: 27.027 | E28: 20.304 | F28: 42.702 | G28: 18.364 | H28: 358.8 | I28: 2479.142 | J28: 0.0012545949 | K28: FALSE | L28: FALSE | M28: FALSE

Sheet Luca Marini
A1: 13. Luca MARINI #10
A3: Team | B3: Honda HRC Castrol | C3: Manufacturer | D3: HONDA | E3: Nationality | F3: ITA | G3: Total Laps | H3: 23 | I3: Valid Laps | J3: 22 | K3: Front Tyre | L3: Slick-Medium | M3: Rear Tyre | N3: Slick-Medium
A5: Lap | B5: Lap Time | C5: Lap Seconds | D5: T1 | E5: T2 | F5: T3 | G5: T4 | H5: Speed km/h | I5: Cumulative Seconds | J5: Excel Time | K5: Cancelled | L5: Pit Lane | M5: Partial Timing
A6: 1 | B6: 1:54.065 | C6: 114.065 | D6: 32.92 | E6: 20.504 | F6: 42.241 | G6: 18.4 | H6: 283.4 | I6: 114.065 | J6: 0.0013201968 | K6: FALSE | L6: FALSE | M6: FALSE
A7: 2 | B7: 1:46.585 | C7: 106.585 | D7: 26.494 | E7: 19.86 | F7: 41.831 | G7: 18.4 | H7: 361.2 | I7: 220.65 | J7: 0.0012336227 | K7: FALSE | L7: FALSE | M7: FALSE
A8: 3 | B8: 1:46.515 | C8: 106.515 | D8: 26.579 | E8: 19.908 | F8: 41.712 | G8: 18.316 | H8: 362.4 | I8: 327.165 | J8: 0.0012328125 | K8: FALSE | L8: FALSE | M8: FALSE
A9: 4 | B9: 1:48.930 | C9: 108.93 | D9: 26.488 | E9: 19.865 | F9: 44.263 | G9: 18.314 | H9: 364.8 | I9: 436.095 | J9: 0.0012607639 | K9: FALSE | L9: FALSE | M9: FALSE
A10: 5 | B10: 1:46.567 | C10: 106.567 | D10: 26.509 | E10: 19.876 | F10: 41.862 | G10: 18.32 | H10: 358.8 | I10: 542.662 | J10: 0.0012334144 | K10: FALSE | L10: FALSE | M10: FALSE
A11: 6 | B11: 1:46.977 | C11: 106.977 | D11: 26.634 | E11: 20.032 | F11: 42.031 | G11: 18.28 | H11: 361.2 | I11: 649.639 | J11: 0.0012381597 | K11: FALSE | L11: FALSE | M11: FALSE
A12: 7 | B12: 1:47.717 | C12: 107.717 | D12: 26.972 | E12: 20.004 | F12: 42.406 | G12: 18.335 | H12: 351.7 | I12: 757.356 | J12: 0.0012467245 | K12: FALSE | L12: FALSE | M12: FALSE
A13: 8 | B13: 1:47.421 | C13: 107.421 | D13: 26.757 | E13: 19.983 | F13: 42.328 | G13: 18.353 | H13: 356.4 | I13: 864.777 | J13: 0.0012432986 | K13: FALSE | L13: FALSE | M13: FALSE
A14: 9 | B14: 1:46.875 | C14: 106.875 | D14: 26.606 | E14: 19.924 | F14: 41.999 | G14: 18.346 | H14: 356.4 | I14: 971.652 | J14: 0.0012369792 | K14: FALSE | L14: FALSE | M14: FALSE
A15: 10 | B15: 1:46.756 | C15: 106.756 | D15: 26.541 | E15: 19.941 | F15: 41.979 | G15: 18.295 | H15: 357.6 | I15: 1078.408 | J15: 0.0012356019 | K15: FALSE | L15: FALSE | M15: FALSE
A16: 11 | B16: 1:46.998 | C16: 106.998 | D16: 26.589 | E16: 19.981 | F16: 42.084 | G16: 18.344 | H16: 358.8 | I16: 1185.406 | J16: 0.0012384028 | K16: FALSE | L16: FALSE | M16: FALSE
A17: 12 | B17: 1:47.311 | C17: 107.311 | D17: 26.738 | E17: 20.05 | F17: 42.211 | G17: 18.312 | H17: 358.8 | I17: 1292.717 | J17: 0.0012420255 | K17: FALSE | L17: FALSE | M17: FALSE
... A28: 23 | B28: 1:48.174 | C28: 108.174 | D28: 26.866 | E28: 20.244 | F28: 42.536 | G28: 18.528 | H28: 362.4 | I28: 2479.406 | J28: 0.0012520139 | K28: FALSE | L28: FALSE | M28: FALSE

Sheet Franco Morbidelli
A1: 14. Franco MORBIDELLI #21
A3: Team | B3: Pertamina Enduro VR46 Racing Team | C3: Manufacturer | D3: DUCATI | E3: Nationality | F3: ITA | G3: Total Laps | H3: 23 | I3: Valid Laps | J3: 22 | K3: Front Tyre | L3: Slick-Medium | M3: Rear Tyre | N3: Slick-Medium
A5: Lap | B5: Lap Time | C5: Lap Seconds | D5: T1 | E5: T2 | F5: T3 | G5: T4 | H5: Speed km/h | I5: Cumulative Seconds | J5: Excel Time | K5: Cancelled | L5: Pit Lane | M5: Partial Timing
A6: 1 | B6: 1:55.104 | C6: 115.104 | D6: 33.299 | E6: 21.235 | F6: 42.154 | G6: 18.416 | H6: 274.1 | I6: 115.104 | J6: 0.0013322222 | K6: FALSE | L6: FALSE | M6: FALSE
A7: 2 | B7: 1:47.365 | C7: 107.365 | D7: 26.705 | E7: 20.125 | F7: 42.138 | G7: 18.397 | H7: 357.6 | I7: 222.469 | J7: 0.0012426505 | K7: FALSE | L7: FALSE | M7: FALSE
A8: 3 | B8: 1:47.121 | C8: 107.121 | D8: 26.755 | E8: 20.044 | F8: 42.009 | G8: 18.313 | H8: 357.6 | I8: 329.59 | J8: 0.0012398264 | K8: FALSE | L8: FALSE | M8: FALSE
A9: 4 | B9: 1:47.180 | C9: 107.18 | D9: 26.614 | E9: 19.99 | F9: 42.188 | G9: 18.388 | H9: 357.6 | I9: 436.77 | J9: 0.0012405093 | K9: FALSE | L9: FALSE | M9: FALSE
A10: 5 | B10: 1:47.329 | C10: 107.329 | D10: 26.788 | E10: 20.056 | F10: 42.066 | G10: 18.419 | H10: 360 | I10: 544.099 | J10: 0.0012422338 | K10: FALSE | L10: FALSE | M10: FALSE
A11: 6 | B11: 1:47.357 | C11: 107.357 | D11: 26.77 | E11: 20.112 | F11: 42.139 | G11: 18.336 | H11: 355.2 | I11: 651.456 | J11: 0.0012425579 | K11: FALSE | L11: FALSE | M11: FALSE
A12: 7 | B12: 1:47.430 | C12: 107.43 | D12: 26.758 | E12: 20.05 | F12: 42.214 | G12: 18.408 | H12: 356.4 | I12: 758.886 | J12: 0.0012434028 | K12: FALSE | L12: FALSE | M12: FALSE
A13: 8 | B13: 1:47.480 | C13: 107.48 | D13: 26.724 | E13: 20.065 | F13: 42.304 | G13: 18.387 | H13: 355.2 | I13: 866.366 | J13: 0.0012439815 | K13: FALSE | L13: FALSE | M13: FALSE
A14: 9 | B14: 1:47.504 | C14: 107.504 | D14: 26.794 | E14: 20.077 | F14: 42.247 | G14: 18.386 | H14: 356.4 | I14: 973.87 | J14: 0.0012442593 | K14: FALSE | L14: FALSE | M14: FALSE
A15: 10 | B15: 1:47.659 | C15: 107.659 | D15: 26.8 | E15: 20.136 | F15: 42.302 | G15: 18.421 | H15: 358.8 | I15: 1081.529 | J15: 0.0012460532 | K15: FALSE | L15: FALSE | M15: FALSE
A16: 11 | B16: 1:47.869 | C16: 107.869 | D16: 26.847 | E16: 20.158 | F16: 42.361 | G16: 18.503 | H16: 356.4 | I16: 1189.398 | J16: 0.0012484838 | K16: FALSE | L16: FALSE | M16: FALSE
A17: 12 | B17: 1:47.833 | C17: 107.833 | D17: 26.916 | E17: 20.089 | F17: 42.403 | G17: 18.425 | H17: 352.9 | I17: 1297.231 | J17: 0.0012480671 | K17: FALSE | L17: FALSE | M17: FALSE
... A28: 23 | B28: 1:48.748 | C28: 108.748 | D28: 26.974 | E28: 20.398 | F28: 42.702 | G28: 18.674 | H28: 349.5 | I28: 2487.136 | J28: 0.0012586574 | K28: FALSE | L28: FALSE | M28: FALSE

Sheet Jack Miller
A1: 15. Jack MILLER #43
A3: Team | B3: Prima Pramac Yamaha MotoGP | C3: Manufacturer | D3: YAMAHA | E3: Nationality | F3: AUS | G3: Total Laps | H3: 23 | I3: Valid Laps | J3: 22 | K3: Front Tyre | L3: Slick-Medium | M3: Rear Tyre | N3: Slick-Medium
A5: Lap | B5: Lap Time | C5: Lap Seconds | D5: T1 | E5: T2 | F5: T3 | G5: T4 | H5: Speed km/h | I5: Cumulative Seconds | J5: Excel Time | K5: Cancelled | L5: Pit Lane | M5: Partial Timing
A6: 1 | B6: 1:54.313 | C6: 114.313 | D6: 32.912 | E6: 20.667 | F6: 42.236 | G6: 18.498 | H6: 281.2 | I6: 114.313 | J6: 0.0013230671 | K6: FALSE | L6: FALSE | M6: FALSE
A7: 2 | B7: 1:47.759 | C7: 107.759 | D7: 26.658 | E7: 19.928 | F7: 42.719 | G7: 18.454 | H7: 356.4 | I7: 222.072 | J7: 0.0012472106 | K7: FALSE | L7: FALSE | M7: FALSE
A8: 3 | B8: 1:46.883 | C8: 106.883 | D8: 26.719 | E8: 19.889 | F8: 41.939 | G8: 18.336 | H8: 355.2 | I8: 328.955 | J8: 0.0012370718 | K8: FALSE | L8: FALSE | M8: FALSE
A9: 4 | B9: 1:47.364 | C9: 107.364 | D9: 26.613 | E9: 19.888 | F9: 42.481 | G9: 18.382 | H9: 356.4 | I9: 436.319 | J9: 0.0012426389 | K9: FALSE | L9: FALSE | M9: FALSE
A10: 5 | B10: 1:47.049 | C10: 107.049 | D10: 26.713 | E10: 19.911 | F10: 42.088 | G10: 18.337 | H10: 356.4 | I10: 543.368 | J10: 0.0012389931 | K10: FALSE | L10: FALSE | M10: FALSE
A11: 6 | B11: 1:47.046 | C11: 107.046 | D11: 26.654 | E11: 19.926 | F11: 42.141 | G11: 18.325 | H11: 354 | I11: 650.414 | J11: 0.0012389583 | K11: FALSE | L11: FALSE | M11: FALSE
A12: 7 | B12: 1:47.337 | C12: 107.337 | D12: 26.785 | E12: 19.974 | F12: 42.228 | G12: 18.35 | H12: 354 | I12: 757.751 | J12: 0.0012423264 | K12: FALSE | L12: FALSE | M12: FALSE
A13: 8 | B13: 1:47.625 | C13: 107.625 | D13: 26.884 | E13: 20.009 | F13: 42.429 | G13: 18.303 | H13: 355.2 | I13: 865.376 | J13: 0.0012456597 | K13: FALSE | L13: FALSE | M13: FALSE
A14: 9 | B14: 1:47.705 | C14: 107.705 | D14: 26.905 | E14: 20.084 | F14: 42.372 | G14: 18.344 | H14: 356.4 | I14: 973.081 | J14: 0.0012465856 | K14: FALSE | L14: FALSE | M14: FALSE
A15: 10 | B15: 1:47.555 | C15: 107.555 | D15: 26.805 | E15: 20.107 | F15: 42.318 | G15: 18.325 | H15: 354 | I15: 1080.636 | J15: 0.0012448495 | K15: FALSE | L15: FALSE | M15: FALSE
A16: 11 | B16: 1:47.826 | C16: 107.826 | D16: 26.912 | E16: 20.1 | F16: 42.41 | G16: 18.404 | H16: 352.9 | I16: 1188.462 | J16: 0.0012479861 | K16: FALSE | L16: FALSE | M16: FALSE
A17: 12 | B17: 1:48.433 | C17: 108.433 | D17: 26.924 | E17: 20.128 | F17: 42.882 | G17: 18.499 | H17: 348.3 | I17: 1296.895 | J17: 0.0012550116 | K17: FALSE | L17: FALSE | M17: FALSE
... A28: 23 | B28: 1:48.705 | C28: 108.705 | D28: 27.148 | E28: 20.254 | F28: 42.885 | G28: 18.418 | H28: 355.2 | I28: 2489.636 | J28: 0.0012581597 | K28: FALSE | L28: FALSE | M28: FALSE

Sheet Toprak Razgatlioglu
A1: 16. Toprak RAZGATLIOGLU #7
A3: Team | B3: Prima Pramac Yamaha MotoGP | C3: Manufacturer | D3: YAMAHA | E3: Nationality | F3: TUR | G3: Total Laps | H3: 23 | I3: Valid Laps | J3: 20 | K3: Front Tyre | L3: Slick-Medium | M3: Rear Tyre | N3: Slick-Medium
A5: Lap | B5: Lap Time | C5: Lap Seconds | D5: T1 | E5: T2 | F5: T3 | G5: T4 | H5: Speed km/h | I5: Cumulative Seconds | J5: Excel Time | K5: Cancelled | L5: Pit Lane | M5: Partial Timing
A6: 1 | B6: 1:55.735 | C6: 115.735 | D6: 33.578 | E6: 21.043 | F6: 42.539 | G6: 18.575 | H6: 281.9 | I6: 115.735 | J6: 0.0013395255 | K6: FALSE | L6: FALSE | M6: FALSE
A7: 2 | B7: 1:47.570 | C7: 107.57 | D7: 26.937 | E7: 20.017 | F7: 42.033 | G7: 18.583 | H7: 351.7 | I7: 223.305 | J7: 0.0012450231 | K7: FALSE | L7: FALSE | M7: FALSE
A8: 3 | B8: 1:47.261 | C8: 107.261 | D8: 26.761 | E8: 19.973 | F8: 42.06 | G8: 18.467 | H8: 355.2 | I8: 330.566 | J8: 0.0012414468 | K8: FALSE | L8: FALSE | M8: FALSE
A9: 4 | B9: 1:46.928 | C9: 106.928 | D9: 26.751 | E9: 19.8 | F9: 42 | G9: 18.377 | H9: 347.2 | I9: 437.494 | J9: 0.0012375926 | K9: FALSE | L9: FALSE | M9: FALSE
A10: 5 | B10: 1:47.326 | C10: 107.326 | D10: 26.83 | E10: 19.976 | F10: 42.037 | G10: 18.483 | H10: 352.9 | I10: 544.82 | J10: 0.0012421991 | K10: FALSE | L10: FALSE | M10: FALSE
A11: 6 | B11: 1:47.354 | C11: 107.354 | D11: 26.758 | E11: 19.971 | F11: 42.113 | G11: 18.512 | H11: 357.6 | I11: 652.174 | J11: 0.0012425231 | K11: TRUE | L11: FALSE | M11: FALSE
A12: 7 | B12: 1:47.396 | C12: 107.396 | D12: 26.81 | E12: 19.962 | F12: 42.204 | G12: 18.42 | H12: 357.6 | I12: 759.57 | J12: 0.0012430093 | K12: FALSE | L12: FALSE | M12: FALSE
A13: 8 | B13: 1:47.373 | C13: 107.373 | D13: 26.839 | E13: 19.95 | F13: 42.202 | G13: 18.382 | H13: 356.4 | I13: 866.943 | J13: 0.0012427431 | K13: FALSE | L13: FALSE | M13: FALSE
A14: 9 | B14: 1:47.511 | C14: 107.511 | D14: 26.808 | E14: 19.963 | F14: 42.211 | G14: 18.529 | H14: 357.6 | I14: 974.454 | J14: 0.0012443403 | K14: FALSE | L14: FALSE | M14: FALSE
A15: 10 | B15: 1:47.638 | C15: 107.638 | D15: 26.803 | E15: 20.103 | F15: 42.281 | G15: 18.451 | H15: 355.2 | I15: 1082.092 | J15: 0.0012458102 | K15: FALSE | L15: FALSE | M15: FALSE
A16: 11 | B16: 1:47.664 | C16: 107.664 | D16: 26.823 | E16: 20.1 | F16: 42.293 | G16: 18.448 | H16: 358.8 | I16: 1189.756 | J16: 0.0012461111 | K16: FALSE | L16: FALSE | M16: FALSE
A17: 12 | B17: 1:48.730 | C17: 108.73 | D17: 27.633 | E17: 20.184 | F17: 42.457 | G17: 18.456 | H17: 354 | I17: 1298.486 | J17: 0.0012584491 | K17: FALSE | L17: FALSE | M17: FALSE
... A28: 23 | B28: 1:48.535 | C28: 108.535 | D28: 27.122 | E28: 20.184 | F28: 42.671 | G28: 18.558 | H28: 343.9 | I28: 2489.267 | J28: 0.0012561921 | K28: TRUE | L28: FALSE | M28: FALSE

Sheet Maverick Viñales
A1: 17. Maverick VIÑALES #12
A3: Team | B3: Red Bull KTM Tech3 | C3: Manufacturer | D3: KTM | E3: Nationality | F3: SPA | G3: Total Laps | H3: 23 | I3: Valid Laps | J3: 22 | K3: Front Tyre | L3: Slick-Medium | M3: Rear Tyre | N3: Slick-Medium
A5: Lap | B5: Lap Time | C5: Lap Seconds | D5: T1 | E5: T2 | F5: T3 | G5: T4 | H5: Speed km/h | I5: Cumulative Seconds | J5: Excel Time | K5: Cancelled | L5: Pit Lane | M5: Partial Timing
A6: 1 | B6: 1:55.731 | C6: 115.731 | D6: 33.525 | E6: 20.993 | F6: 42.6 | G6: 18.613 | H6: 279.7 | I6: 115.731 | J6: 0.0013394792 | K6: FALSE | L6: FALSE | M6: FALSE
A7: 2 | B7: 1:47.416 | C7: 107.416 | D7: 26.803 | E7: 20.008 | F7: 42.114 | G7: 18.491 | H7: 355.2 | I7: 223.147 | J7: 0.0012432407 | K7: FALSE | L7: FALSE | M7: FALSE
A8: 3 | B8: 1:47.085 | C8: 107.085 | D8: 26.659 | E8: 19.926 | F8: 42.029 | G8: 18.471 | H8: 355.2 | I8: 330.232 | J8: 0.0012394097 | K8: FALSE | L8: FALSE | M8: FALSE
A9: 4 | B9: 1:47.081 | C9: 107.081 | D9: 26.701 | E9: 19.861 | F9: 42.078 | G9: 18.441 | H9: 355.2 | I9: 437.313 | J9: 0.0012393634 | K9: FALSE | L9: FALSE | M9: FALSE
A10: 5 | B10: 1:47.369 | C10: 107.369 | D10: 26.802 | E10: 20.008 | F10: 42.109 | G10: 18.45 | H10: 357.6 | I10: 544.682 | J10: 0.0012426968 | K10: FALSE | L10: FALSE | M10: FALSE
A11: 6 | B11: 1:47.335 | C11: 107.335 | D11: 26.712 | E11: 19.961 | F11: 42.18 | G11: 18.482 | H11: 356.4 | I11: 652.017 | J11: 0.0012423032 | K11: FALSE | L11: FALSE | M11: FALSE
A12: 7 | B12: 1:47.345 | C12: 107.345 | D12: 26.704 | E12: 19.944 | F12: 42.227 | G12: 18.47 | H12: 357.6 | I12: 759.362 | J12: 0.001242419 | K12: FALSE | L12: FALSE | M12: FALSE
A13: 8 | B13: 1:47.390 | C13: 107.39 | D13: 26.719 | E13: 20.006 | F13: 42.231 | G13: 18.434 | H13: 356.4 | I13: 866.752 | J13: 0.0012429398 | K13: FALSE | L13: FALSE | M13: FALSE
A14: 9 | B14: 1:47.563 | C14: 107.563 | D14: 26.77 | E14: 20.033 | F14: 42.292 | G14: 18.468 | H14: 358.8 | I14: 974.315 | J14: 0.0012449421 | K14: FALSE | L14: FALSE | M14: FALSE
A15: 10 | B15: 1:47.649 | C15: 107.649 | D15: 26.822 | E15: 20.09 | F15: 42.297 | G15: 18.44 | H15: 357.6 | I15: 1081.964 | J15: 0.0012459375 | K15: FALSE | L15: FALSE | M15: FALSE
A16: 11 | B16: 1:48.422 | C16: 108.422 | D16: 27.262 | E16: 20.228 | F16: 42.403 | G16: 18.529 | H16: 357.6 | I16: 1190.386 | J16: 0.0012548843 | K16: FALSE | L16: FALSE | M16: FALSE
A17: 12 | B17: 1:48.592 | C17: 108.592 | D17: 27.092 | E17: 20.396 | F17: 42.612 | G17: 18.492 | H17: 356.4 | I17: 1298.978 | J17: 0.0012568519 | K17: FALSE | L17: FALSE | M17: FALSE
... A28: 23 | B28: 1:48.436 | C28: 108.436 | D28: 26.895 | E28: 20.363 | F28: 42.719 | G28: 18.459 | H28: 360 | I28: 2490.064 | J28: 0.0012550463 | K28: FALSE | L28: FALSE | M28: FALSE

Sheet Fabio Quartararo
A1: 18. Fabio QUARTARARO #20
A3: Team | B3: Monster Energy Yamaha MotoGP Team | C3: Manufacturer | D3: YAMAHA | E3: Nationality | F3: FRA | G3: Total Laps | H3: 23 | I3: Valid Laps | J3: 22 | K3: Front Tyre | L3: Slick-Medium | M3: Rear Tyre | N3: Slick-Medium
A5: Lap | B5: Lap Time | C5: Lap Seconds | D5: T1 | E5: T2 | F5: T3 | G5: T4 | H5: Speed km/h | I5: Cumulative Seconds | J5: Excel Time | K5: Cancelled | L5: Pit Lane | M5: Partial Timing
A6: 1 | B6: 1:54.707 | C6: 114.707 | D6: 33.189 | E6: 20.784 | F6: 42.115 | G6: 18.619 | H6: 279 | I6: 114.707 | J6: 0.0013276273 | K6: FALSE | L6: FALSE | M6: FALSE
A7: 2 | B7: 1:47.539 | C7: 107.539 | D7: 26.874 | E7: 20.116 | F7: 42.133 | G7: 18.416 | H7: 354 | I7: 222.246 | J7: 0.0012446644 | K7: FALSE | L7: FALSE | M7: FALSE
A8: 3 | B8: 1:47.191 | C8: 107.191 | D8: 26.805 | E8: 20.079 | F8: 41.918 | G8: 18.389 | H8: 355.2 | I8: 329.437 | J8: 0.0012406366 | K8: FALSE | L8: FALSE | M8: FALSE
A9: 4 | B9: 1:47.126 | C9: 107.126 | D9: 26.58 | E9: 20.007 | F9: 42.063 | G9: 18.476 | H9: 356.4 | I9: 436.563 | J9: 0.0012398843 | K9: FALSE | L9: FALSE | M9: FALSE
A10: 5 | B10: 1:47.330 | C10: 107.33 | D10: 26.745 | E10: 20.081 | F10: 42.028 | G10: 18.476 | H10: 357.6 | I10: 543.893 | J10: 0.0012422454 | K10: FALSE | L10: FALSE | M10: FALSE
A11: 6 | B11: 1:47.344 | C11: 107.344 | D11: 26.756 | E11: 20.027 | F11: 42.148 | G11: 18.413 | H11: 354 | I11: 651.237 | J11: 0.0012424074 | K11: FALSE | L11: FALSE | M11: FALSE
A12: 7 | B12: 1:47.425 | C12: 107.425 | D12: 26.779 | E12: 20.013 | F12: 42.205 | G12: 18.428 | H12: 352.9 | I12: 758.662 | J12: 0.0012433449 | K12: FALSE | L12: FALSE | M12: FALSE
A13: 8 | B13: 1:47.559 | C13: 107.559 | D13: 26.794 | E13: 20.059 | F13: 42.239 | G13: 18.467 | H13: 352.9 | I13: 866.221 | J13: 0.0012448958 | K13: FALSE | L13: FALSE | M13: FALSE
A14: 9 | B14: 1:47.529 | C14: 107.529 | D14: 26.786 | E14: 20.058 | F14: 42.242 | G14: 18.443 | H14: 354 | I14: 973.75 | J14: 0.0012445486 | K14: FALSE | L14: FALSE | M14: FALSE
A15: 10 | B15: 1:47.402 | C15: 107.402 | D15: 26.736 | E15: 20.048 | F15: 42.192 | G15: 18.426 | H15: 352.9 | I15: 1081.152 | J15: 0.0012430787 | K15: FALSE | L15: FALSE | M15: FALSE
A16: 11 | B16: 1:47.700 | C16: 107.7 | D16: 26.873 | E16: 20.132 | F16: 42.234 | G16: 18.461 | H16: 354 | I16: 1188.852 | J16: 0.0012465278 | K16: FALSE | L16: FALSE | M16: FALSE
A17: 12 | B17: 1:48.205 | C17: 108.205 | D17: 26.904 | E17: 20.177 | F17: 42.533 | G17: 18.591 | H17: 352.9 | I17: 1297.057 | J17: 0.0012523727 | K17: FALSE | L17: FALSE | M17: FALSE
... A28: 23 | B28: 1:50.111 | C28: 110.111 | D28: 27.373 | E28: 20.565 | F28: 43.321 | G28: 18.852 | H28: 339.6 | I28: 2491.682 | J28: 0.0012744329 | K28: FALSE | L28: FALSE | M28: FALSE

Sheet Michele Pirro
A1: 19. Michele PIRRO #51
A3: Team | B3: BK8 Gresini Racing MotoGP | C3: Manufacturer | D3: DUCATI | E3: Nationality | F3: ITA | G3: Total Laps | H3: 23 | I3: Valid Laps | J3: 22 | K3: Front Tyre | L3: Slick-Medium | M3: Rear Tyre | N3: Slick-Medium
A5: Lap | B5: Lap Time | C5: Lap Seconds | D5: T1 | E5: T2 | F5: T3 | G5: T4 | H5: Speed km/h | I5: Cumulative Seconds | J5: Excel Time | K5: Cancelled | L5: Pit Lane | M5: Partial Timing
A6: 1 | B6: 1:55.858 | C6: 115.858 | D6: 33.743 | E6: 21.029 | F6: 42.621 | G6: 18.465 | H6: 281.2 | I6: 115.858 | J6: 0.0013409491 | K6: FALSE | L6: FALSE | M6: FALSE
A7: 2 | B7: 1:47.721 | C7: 107.721 | D7: 26.965 | E7: 20.039 | F7: 42.299 | G7: 18.418 | H7: 356.4 | I7: 223.579 | J7: 0.0012467708 | K7: FALSE | L7: FALSE | M7: FALSE
A8: 3 | B8: 1:47.442 | C8: 107.442 | D8: 26.77 | E8: 20.074 | F8: 42.266 | G8: 18.332 | H8: 357.6 | I8: 331.021 | J8: 0.0012435417 | K8: FALSE | L8: FALSE | M8: FALSE
A9: 4 | B9: 1:47.959 | C9: 107.959 | D9: 27.185 | E9: 20.091 | F9: 42.179 | G9: 18.504 | H9: 352.9 | I9: 438.98 | J9: 0.0012495255 | K9: FALSE | L9: FALSE | M9: FALSE
A10: 5 | B10: 1:48.000 | C10: 108 | D10: 26.853 | E10: 20.192 | F10: 42.429 | G10: 18.526 | H10: 354 | I10: 546.98 | J10: 0.00125 | K10: FALSE | L10: FALSE | M10: FALSE
A11: 6 | B11: 1:48.191 | C11: 108.191 | D11: 27.11 | E11: 20.223 | F11: 42.401 | G11: 18.457 | H11: 354 | I11: 655.171 | J11: 0.0012522106 | K11: FALSE | L11: FALSE | M11: FALSE
A12: 7 | B12: 1:48.136 | C12: 108.136 | D12: 26.863 | E12: 20.26 | F12: 42.6 | G12: 18.413 | H12: 352.9 | I12: 763.307 | J12: 0.0012515741 | K12: FALSE | L12: FALSE | M12: FALSE
A13: 8 | B13: 1:47.963 | C13: 107.963 | D13: 26.868 | E13: 20.146 | F13: 42.446 | G13: 18.503 | H13: 352.9 | I13: 871.27 | J13: 0.0012495718 | K13: FALSE | L13: FALSE | M13: FALSE
A14: 9 | B14: 1:47.810 | C14: 107.81 | D14: 26.822 | E14: 20.217 | F14: 42.331 | G14: 18.44 | H14: 352.9 | I14: 979.08 | J14: 0.0012478009 | K14: FALSE | L14: FALSE | M14: FALSE
A15: 10 | B15: 1:47.943 | C15: 107.943 | D15: 26.85 | E15: 20.253 | F15: 42.427 | G15: 18.413 | H15: 352.9 | I15: 1087.023 | J15: 0.0012493403 | K15: FALSE | L15: FALSE | M15: FALSE
A16: 11 | B16: 1:48.241 | C16: 108.241 | D16: 26.97 | E16: 20.238 | F16: 42.553 | G16: 18.48 | H16: 354 | I16: 1195.264 | J16: 0.0012527894 | K16: FALSE | L16: FALSE | M16: FALSE
A17: 12 | B17: 1:48.537 | C17: 108.537 | D17: 26.897 | E17: 20.199 | F17: 42.953 | G17: 18.488 | H17: 352.9 | I17: 1303.801 | J17: 0.0012562153 | K17: FALSE | L17: FALSE | M17: FALSE
... A28: 23 | B28: 1:49.283 | C28: 109.283 | D28: 27.012 | E28: 20.366 | F28: 43.227 | G28: 18.678 | H28: 350.6 | I28: 2497.9 | J28: 0.0012648495 | K28: FALSE | L28: FALSE | M28: FALSE

Sheet Enea Bastianini
A1: 20. Enea BASTIANINI #23
A3: Team | B3: Red Bull KTM Tech3 | C3: Manufacturer | D3: KTM | E3: Nationality | F3: ITA | G3: Total Laps | H3: 11 | I3: Valid Laps | J3: 10 | K3: Front Tyre | L3: Slick-Medium | M3: Rear Tyre | N3: Slick-Medium
A5: Lap | B5: Lap Time | C5: Lap Seconds | D5: T1 | E5: T2 | F5: T3 | G5: T4 | H5: Speed km/h | I5: Cumulative Seconds | J5: Excel Time | K5: Cancelled | L5: Pit Lane | M5: Partial Timing
A6: 1 | B6: 1:53.042 | C6: 113.042 | D6: 32.539 | E6: 20.25 | F6: 41.944 | G6: 18.309 | H6: 280.5 | I6: 113.042 | J6: 0.0013083565 | K6: FALSE | L6: FALSE | M6: FALSE
A7: 2 | B7: 1:46.975 | C7: 106.975 | D7: 26.831 | E7: 19.919 | F7: 41.899 | G7: 18.326 | H7: 360 | I7: 220.017 | J7: 0.0012381366 | K7: FALSE | L7: FALSE | M7: FALSE
A8: 3 | B8: 1:46.242 | C8: 106.242 | D8: 26.455 | E8: 19.89 | F8: 41.633 | G8: 18.264 | H8: 360 | I8: 326.259 | J8: 0.0012296528 | K8: FALSE | L8: FALSE | M8: FALSE
A9: 4 | B9: 1:46.167 | C9: 106.167 | D9: 26.331 | E9: 19.936 | F9: 41.679 | G9: 18.221 | H9: 354 | I9: 432.426 | J9: 0.0012287847 | K9: FALSE | L9: FALSE | M9: FALSE
A10: 5 | B10: 1:47.210 | C10: 107.21 | D10: 27.062 | E10: 20.042 | F10: 41.839 | G10: 18.267 | H10: 355.2 | I10: 539.636 | J10: 0.0012408565 | K10: FALSE | L10: FALSE | M10: FALSE
A11: 6 | B11: 1:46.678 | C11: 106.678 | D11: 26.489 | E11: 20.065 | F11: 41.88 | G11: 18.244 | H11: 357.6 | I11: 646.314 | J11: 0.0012346991 | K11: FALSE | L11: FALSE | M11: FALSE
A12: 7 | B12: 1:46.581 | C12: 106.581 | D12: 26.544 | E12: 19.922 | F12: 41.88 | G12: 18.235 | H12: 356.4 | I12: 752.895 | J12: 0.0012335764 | K12: FALSE | L12: FALSE | M12: FALSE
A13: 8 | B13: 1:46.981 | C13: 106.981 | D13: 26.569 | E13: 20.019 | F13: 42.102 | G13: 18.291 | H13: 355.2 | I13: 859.876 | J13: 0.001238206 | K13: FALSE | L13: FALSE | M13: FALSE
A14: 9 | B14: 1:46.894 | C14: 106.894 | D14: 26.453 | E14: 20.02 | F14: 42.05 | G14: 18.371 | H14: 357.6 | I14: 966.77 | J14: 0.0012371991 | K14: FALSE | L14: FALSE | M14: FALSE
A15: 10 | B15: 1:46.768 | C15: 106.768 | D15: 26.513 | E15: 20.027 | F15: 41.97 | G15: 18.258 | H15: 356.4 | I15: 1073.538 | J15: 0.0012357407 | K15: FALSE | L15: FALSE | M15: FALSE
A16: 11 | B16: 1:47.289 | C16: 107.289 | D16: 26.565 | E16: 20.085 | F16: 42.292 | G16: 18.347 | H16: 357.6 | I16: 1180.827 | J16: 0.0012417708 | K16: FALSE | L16: FALSE | M16: FALSE

Sheet Alex Rins
A1: 21. Alex RINS #42
A3: Team | B3: Monster Energy Yamaha MotoGP Team | C3: Manufacturer | D3: YAMAHA | E3: Nationality | F3: SPA | G3: Total Laps | H3: 10 | I3: Valid Laps | J3: 9 | K3: Front Tyre | L3: Slick-Medium | M3: Rear Tyre | N3: Slick-Medium
A5: Lap | B5: Lap Time | C5: Lap Seconds | D5: T1 | E5: T2 | F5: T3 | G5: T4 | H5: Speed km/h | I5: Cumulative Seconds | J5: Excel Time | K5: Cancelled | L5: Pit Lane | M5: Partial Timing
A6: 1 | B6: 1:53.945 | C6: 113.945 | D6: 32.665 | E6: 20.378 | F6: 42.54 | G6: 18.362 | H6: 279.7 | I6: 113.945 | J6: 0.0013188079 | K6: FALSE | L6: FALSE | M6: FALSE
A7: 2 | B7: 1:46.893 | C7: 106.893 | D7: 26.814 | E7: 19.819 | F7: 41.893 | G7: 18.367 | H7: 358.8 | I7: 220.838 | J7: 0.0012371875 | K7: FALSE | L7: FALSE | M7: FALSE
A8: 3 | B8: 1:47.013 | C8: 107.013 | D8: 27.102 | E8: 19.934 | F8: 41.71 | G8: 18.267 | H8: 355.2 | I8: 327.851 | J8: 0.0012385764 | K8: FALSE | L8: FALSE | M8: FALSE
A9: 4 | B9: 1:47.104 | C9: 107.104 | D9: 26.741 | E9: 19.868 | F9: 42.114 | G9: 18.381 | H9: 358.8 | I9: 434.955 | J9: 0.0012396296 | K9: FALSE | L9: FALSE | M9: FALSE
A10: 5 | B10: 1:47.052 | C10: 107.052 | D10: 26.688 | E10: 19.836 | F10: 41.972 | G10: 18.556 | H10: 355.2 | I10: 542.007 | J10: 0.0012390278 | K10: FALSE | L10: FALSE | M10: FALSE
A11: 6 | B11: 1:47.391 | C11: 107.391 | D11: 26.748 | E11: 20.027 | F11: 42.207 | G11: 18.409 | H11: 352.9 | I11: 649.398 | J11: 0.0012429514 | K11: FALSE | L11: FALSE | M11: FALSE
A12: 7 | B12: 1:47.867 | C12: 107.867 | D12: 27.096 | E12: 19.94 | F12: 42.477 | G12: 18.354 | H12: 351.7 | I12: 757.265 | J12: 0.0012484606 | K12: FALSE | L12: FALSE | M12: FALSE
A13: 8 | B13: 1:47.726 | C13: 107.726 | D13: 26.716 | E13: 19.985 | F13: 42.711 | G13: 18.314 | H13: 354 | I13: 864.991 | J13: 0.0012468287 | K13: FALSE | L13: FALSE | M13: FALSE
A14: 9 | B14: 1:47.432 | C14: 107.432 | D14: 26.787 | E14: 20.003 | F14: 42.287 | G14: 18.355 | H14: 356.4 | I14: 972.423 | J14: 0.0012434259 | K14: FALSE | L14: FALSE | M14: FALSE
A15: 10 | B15: 1:47.381 | C15: 107.381 | D15: 26.778 | E15: 19.985 | F15: 42.251 | G15: 18.367 | H15: 354 | I15: 1079.804 | J15: 0.0012428356 | K15: FALSE | L15: FALSE | M15: FALSE

Sheet Cal Crutchlow
A1: 22. Cal CRUTCHLOW #35
A3: Team | B3: Castrol Honda LCR | C3: Manufacturer | D3: HONDA | E3: Nationality | F3: GBR | G3: Total Laps | H3: 10 | I3: Valid Laps | J3: 9 | K3: Front Tyre | L3: Slick-Medium | M3: Rear Tyre | N3: Slick-Medium
A5: Lap | B5: Lap Time | C5: Lap Seconds | D5: T1 | E5: T2 | F5: T3 | G5: T4 | H5: Speed km/h | I5: Cumulative Seconds | J5: Excel Time | K5: Cancelled | L5: Pit Lane | M5: Partial Timing
A6: 1 | B6: 1:56.099 | C6: 116.099 | D6: 33.884 | E6: 21.092 | F6: 42.667 | G6: 18.456 | H6: 280.5 | I6: 116.099 | J6: 0.0013437384 | K6: FALSE | L6: FALSE | M6: FALSE
A7: 2 | B7: 1:47.991 | C7: 107.991 | D7: 27.085 | E7: 20.21 | F7: 42.242 | G7: 18.454 | H7: 360 | I7: 224.09 | J7: 0.0012498958 | K7: FALSE | L7: FALSE | M7: FALSE
A8: 3 | B8: 1:47.919 | C8: 107.919 | D8: 26.907 | E8: 20.298 | F8: 42.297 | G8: 18.417 | H8: 357.6 | I8: 332.009 | J8: 0.0012490625 | K8: FALSE | L8: FALSE | M8: FALSE
A9: 4 | B9: 1:48.204 | C9: 108.204 | D9: 26.995 | E9: 20.289 | F9: 42.449 | G9: 18.471 | H9: 354 | I9: 440.213 | J9: 0.0012523611 | K9: FALSE | L9: FALSE | M9: FALSE
A10: 5 | B10: 1:48.263 | C10: 108.263 | D10: 26.944 | E10: 20.325 | F10: 42.51 | G10: 18.484 | H10: 352.9 | I10: 548.476 | J10: 0.001253044 | K10: FALSE | L10: FALSE | M10: FALSE
A11: 6 | B11: 1:48.369 | C11: 108.369 | D11: 27.048 | E11: 20.309 | F11: 42.506 | G11: 18.506 | H11: 351.7 | I11: 656.845 | J11: 0.0012542708 | K11: FALSE | L11: FALSE | M11: FALSE
A12: 7 | B12: 1:48.245 | C12: 108.245 | D12: 26.941 | E12: 20.334 | F12: 42.55 | G12: 18.42 | H12: 350.6 | I12: 765.09 | J12: 0.0012528356 | K12: FALSE | L12: FALSE | M12: FALSE
A13: 8 | B13: 1:48.872 | C13: 108.872 | D13: 27.078 | E13: 20.405 | F13: 42.737 | G13: 18.652 | H13: 349.5 | I13: 873.962 | J13: 0.0012600926 | K13: FALSE | L13: FALSE | M13: FALSE
A14: 9 | B14: 1:50.367 | C14: 110.367 | D14: 27.39 | E14: 20.94 | F14: 43.342 | G14: 18.695 | H14: 346.1 | I14: 984.329 | J14: 0.0012773958 | K14: FALSE | L14: FALSE | M14: FALSE
A15: 10 | B15: 1:48.737 | C15: 108.737 | D15: 26.958 | E15: 20.489 | F15: 42.775 | G15: 18.515 | H15: 347.2 | I15: 1093.066 | J15: 0.0012585301 | K15: FALSE | L15: FALSE | M15: FALSE

Sheet Race Data
A1: Rider | B1: Number | C1: Position | D1: Team | E1: Manufacturer | F1: Nationality | G1: Total Laps | H1: Valid Laps | I1: Lap | J1: Lap Time | K1: Lap Seconds | L1: T1 | M1: T2 | N1: T3 | O1: T4 | P1: Speed km/h | Q1: Cumulative Seconds | R1: Cancelled | S1: Pit Lane | T1: Partial Timing
A2: Marco BEZZECCHI | B2: 72 | C2: 1 | D2: Aprilia Racing | E2: APRILIA | F2: ITA | G2: 23 | H2: 22 | I2: 1 | J2: 1:51.109 | K2: 111.109 | L2: 31.616 | M2: 20.034 | N2: 41.3 | O2: 18.159 | P2: 274.1 | Q2: 111.109 | R2: FALSE | S2: FALSE | T2: FALSE
A3: Marco BEZZECCHI | B3: 72 | C3: 1 | D3: Aprilia Racing | E3: APRILIA | F3: ITA | G3: 23 | H3: 22 | I3: 2 | J3: 1:45.934 | K3: 105.934 | L3: 26.46 | M3: 19.847 | N3: 41.432 | O3: 18.195 | P3: 356.4 | Q3: 217.043 | R3: FALSE | S3: FALSE | T3: FALSE
