Workbook

Sheet Marc Marquez
A1: 1. Marc MARQUEZ #93
A3: Team | B3: Ducati Lenovo Team | C3: Manufacturer | D3: DUCATI | E3: Nationality | F3: SPA | G3: Total Laps | H3: 13 | I3: Valid Laps | J3: 12 | K3: Front Tyre | L3: Slick-Hard | M3: Rear Tyre | N3: Slick-Soft
A5: Lap | B5: Lap Time | C5: Lap Seconds | D5: T1 | E5: T2 | F5: T3 | G5: T4 | H5: Speed km/h | I5: Cumulative Seconds | J5: Excel Time | K5: Cancelled | L5: Pit Lane | M5: Partial Timing
A6: 1 | B6: 1:33.677 | C6: 93.677 | D6: 28.524 | E6: 23.568 | F6: 14.132 | G6: 27.453 | H6: 244 | I6: 93.677 | J6: 0.0010842245 | K6: FALSE | L6: FALSE | M6: FALSE
A7: 2 | B7: 1:28.386 | C7: 88.386 | D7: 23.147 | E7: 23.584 | F7: 14.162 | G7: 27.493 | H7: 342.9 | I7: 182.063 | J7: 0.0010229861 | K7: FALSE | L7: FALSE | M7: FALSE
A8: 3 | B8: 1:28.637 | C8: 88.637 | D8: 23.026 | E8: 23.761 | F8: 14.303 | G8: 27.547 | H8: 342.9 | I8: 270.7 | J8: 0.0010258912 | K8: FALSE | L8: FALSE | M8: FALSE
A9: 4 | B9: 1:27.290 | C9: 87.29 | D9: 22.79 | E9: 23.315 | F9: 14.026 | G9: 27.159 | H9: 347.3 | I9: 357.99 | J9: 0.0010103009 | K9: FALSE | L9: FALSE | M9: FALSE
A10: 5 | B10: 1:27.800 | C10: 87.8 | D10: 22.712 | E10: 23.417 | F10: 14.168 | G10: 27.503 | H10: 348.4 | I10: 445.79 | J10: 0.0010162037 | K10: FALSE | L10: FALSE | M10: FALSE
A11: 6 | B11: 1:28.016 | C11: 88.016 | D11: 22.963 | E11: 23.581 | F11: 14.098 | G11: 27.374 | H11: 342.9 | I11: 533.806 | J11: 0.0010187037 | K11: FALSE | L11: FALSE | M11: FALSE
A12: 7 | B12: 1:27.707 | C12: 87.707 | D12: 22.886 | E12: 23.365 | F12: 14.071 | G12: 27.385 | H12: 342.9 | I12: 621.513 | J12: 0.0010151273 | K12: FALSE | L12: FALSE | M12: FALSE
A13: 8 | B13: 1:28.251 | C13: 88.251 | D13: 22.89 | E13: 23.833 | F13: 14.178 | G13: 27.35 | H13: 345 | I13: 709.764 | J13: 0.0010214236 | K13: FALSE | L13: FALSE | M13: FALSE
A14: 9 | B14: 1:28.039 | C14: 88.039 | D14: 22.993 | E14: 23.49 | F14: 14.148 | G14: 27.408 | H14: 344 | I14: 797.803 | J14: 0.0010189699 | K14: FALSE | L14: FALSE | M14: FALSE
A15: 10 | B15: 1:27.866 | C15: 87.866 | D15: 22.883 | E15: 23.419 | F15: 14.064 | G15: 27.5 | H15: 344 | I15: 885.669 | J15: 0.0010169676 | K15: FALSE | L15: FALSE | M15: FALSE
A16: 11 | B16: 1:27.916 | C16: 87.916 | D16: 22.902 | E16: 23.414 | F16: 14.148 | G16: 27.452 | H16: 344 | I16: 973.585 | J16: 0.0010175463 | K16: FALSE | L16: FALSE | M16: FALSE
A17: 12 | B17: 1:27.937 | C17: 87.937 | D17: 22.837 | E17: 23.427 | F17: 14.135 | G17: 27.538 | H17: 342.9 | I17: 1061.522 | J17: 0.0010177894 | K17: FALSE | L17: FALSE | M17: FALSE
A18: 13 | B18: 1:27.889 | C18: 87.889 | D18: 22.902 | E18: 23.355 | F18: 14.188 | G18: 27.444 | H18: 344 | I18: 1149.411 | J18: 0.0010172338 | K18: FALSE | L18: FALSE | M18: FALSE

Sheet Alex Marquez
A1: 2. Alex MARQUEZ #73
A3: Team | B3: BK8 Gresini Racing MotoGP | C3: Manufacturer | D3: DUCATI | E3: Nationality | F3: SPA | G3: Total Laps | H3: 13 | I3: Valid Laps | J3: 12 | K3: Front Tyre | L3: Slick-Hard | M3: Rear Tyre | N3: Slick-Soft
A5: Lap | B5: Lap Time | C5: Lap Seconds | D5: T1 | E5: T2 | F5: T3 | G5: T4 | H5: Speed km/h | I5: Cumulative Seconds | J5: Excel Time | K5: Cancelled | L5: Pit Lane | M5: Partial Timing
A6: 1 | B6: 1:34.126 | C6: 94.126 | D6: 28.75 | E6: 24.221 | F6: 14.015 | G6: 27.14 | H6: 241.8 | I6: 94.126 | J6: 0.0010894213 | K6: FALSE | L6: FALSE | M6: FALSE
A7: 2 | B7: 1:28.156 | C7: 88.156 | D7: 22.979 | E7: 23.595 | F7: 14.036 | G7: 27.546 | H7: 344 | I7: 182.282 | J7: 0.0010203241 | K7: FALSE | L7: FALSE | M7: FALSE
A8: 3 | B8: 1:28.877 | C8: 88.877 | D8: 23.012 | E8: 23.768 | F8: 14.238 | G8: 27.859 | H8: 347.3 | I8: 271.159 | J8: 0.001028669 | K8: FALSE | L8: FALSE | M8: FALSE
A9: 4 | B9: 1:28.186 | C9: 88.186 | D9: 22.773 | E9: 23.855 | F9: 14.157 | G9: 27.401 | H9: 345 | I9: 359.345 | J9: 0.0010206713 | K9: FALSE | L9: FALSE | M9: FALSE
A10: 5 | B10: 1:27.777 | C10: 87.777 | D10: 22.766 | E10: 23.517 | F10: 14.234 | G10: 27.26 | H10: 347.3 | I10: 447.122 | J10: 0.0010159375 | K10: FALSE | L10: FALSE | M10: FALSE
A11: 6 | B11: 1:27.478 | C11: 87.478 | D11: 22.745 | E11: 23.466 | F11: 14.009 | G11: 27.258 | H11: 346.1 | I11: 534.6 | J11: 0.0010124769 | K11: FALSE | L11: FALSE | M11: FALSE
A12: 7 | B12: 1:27.600 | C12: 87.6 | D12: 22.712 | E12: 23.542 | F12: 14.085 | G12: 27.261 | H12: 348.4 | I12: 622.2 | J12: 0.0010138889 | K12: FALSE | L12: FALSE | M12: FALSE
A13: 8 | B13: 1:27.883 | C13: 87.883 | D13: 22.78 | E13: 23.704 | F13: 14.121 | G13: 27.278 | H13: 345 | I13: 710.083 | J13: 0.0010171644 | K13: FALSE | L13: FALSE | M13: FALSE
A14: 9 | B14: 1:27.827 | C14: 87.827 | D14: 22.783 | E14: 23.637 | F14: 14.066 | G14: 27.341 | H14: 348.4 | I14: 797.91 | J14: 0.0010165162 | K14: FALSE | L14: FALSE | M14: FALSE
A15: 10 | B15: 1:27.944 | C15: 87.944 | D15: 23.008 | E15: 23.615 | F15: 14.074 | G15: 27.247 | H15: 330.3 | I15: 885.854 | J15: 0.0010178704 | K15: FALSE | L15: FALSE | M15: FALSE
A16: 11 | B16: 1:28.006 | C16: 88.006 | D16: 22.958 | E16: 23.613 | F16: 14.03 | G16: 27.405 | H16: 342.9 | I16: 973.86 | J16: 0.001018588 | K16: FALSE | L16: FALSE | M16: FALSE
A17: 12 | B17: 1:27.928 | C17: 87.928 | D17: 22.811 | E17: 23.656 | F17: 14.035 | G17: 27.426 | H17: 349.5 | I17: 1061.788 | J17: 0.0010176852 | K17: FALSE | L17: FALSE | M17: FALSE
A18: 13 | B18: 1:27.946 | C18: 87.946 | D18: 22.844 | E18: 23.605 | F18: 13.987 | G18: 27.51 | H18: 346.1 | I18: 1149.734 | J18: 0.0010178935 | K18: FALSE | L18: FALSE | M18: FALSE

Sheet Fabio Di Giannantonio
A1: 3. Fabio DI GIANNANTONIO #49
A3: Team | B3: Pertamina Enduro VR46 Racing Team | C3: Manufacturer | D3: DUCATI | E3: Nationality | F3: ITA | G3: Total Laps | H3: 13 | I3: Valid Laps | J3: 12 | K3: Front Tyre | L3: Slick-Hard | M3: Rear Tyre | N3: Slick-Soft
A5: Lap | B5: Lap Time | C5: Lap Seconds | D5: T1 | E5: T2 | F5: T3 | G5: T4 | H5: Speed km/h | I5: Cumulative Seconds | J5: Excel Time | K5: Cancelled | L5: Pit Lane | M5: Partial Timing
A6: 1 | B6: 1:35.380 | C6: 95.38 | D6: 29.371 | E6: 24.344 | F6: 14.224 | G6: 27.441 | H6: 247.3 | I6: 95.38 | J6: 0.0011039352 | K6: FALSE | L6: FALSE | M6: FALSE
A7: 2 | B7: 1:28.502 | C7: 88.502 | D7: 23.313 | E7: 23.895 | F7: 14.091 | G7: 27.203 | H7: 331.3 | I7: 183.882 | J7: 0.0010243287 | K7: FALSE | L7: FALSE | M7: FALSE
A8: 3 | B8: 1:28.008 | C8: 88.008 | D8: 23.033 | E8: 23.602 | F8: 14.08 | G8: 27.293 | H8: 347.3 | I8: 271.89 | J8: 0.0010186111 | K8: FALSE | L8: FALSE | M8: FALSE
A9: 4 | B9: 1:28.015 | C9: 88.015 | D9: 23.002 | E9: 23.592 | F9: 14.104 | G9: 27.317 | H9: 334.4 | I9: 359.905 | J9: 0.0010186921 | K9: FALSE | L9: FALSE | M9: FALSE
A10: 5 | B10: 1:27.901 | C10: 87.901 | D10: 22.934 | E10: 23.604 | F10: 14.09 | G10: 27.273 | H10: 344 | I10: 447.806 | J10: 0.0010173727 | K10: FALSE | L10: FALSE | M10: FALSE
A11: 6 | B11: 1:28.045 | C11: 88.045 | D11: 22.968 | E11: 23.516 | F11: 14.06 | G11: 27.501 | H11: 332.3 | I11: 535.851 | J11: 0.0010190394 | K11: FALSE | L11: FALSE | M11: FALSE
A12: 7 | B12: 1:27.714 | C12: 87.714 | D12: 22.835 | E12: 23.493 | F12: 14.074 | G12: 27.312 | H12: 344 | I12: 623.565 | J12: 0.0010152083 | K12: FALSE | L12: FALSE | M12: FALSE
A13: 8 | B13: 1:27.946 | C13: 87.946 | D13: 22.889 | E13: 23.548 | F13: 14.152 | G13: 27.357 | H13: 345 | I13: 711.511 | J13: 0.0010178935 | K13: FALSE | L13: FALSE | M13: FALSE
A14: 9 | B14: 1:27.797 | C14: 87.797 | D14: 22.819 | E14: 23.454 | F14: 14.181 | G14: 27.343 | H14: 342.9 | I14: 799.308 | J14: 0.001016169 | K14: FALSE | L14: FALSE | M14: FALSE
A15: 10 | B15: 1:27.633 | C15: 87.633 | D15: 22.83 | E15: 23.494 | F15: 14.014 | G15: 27.295 | H15: 344 | I15: 886.941 | J15: 0.0010142708 | K15: FALSE | L15: FALSE | M15: FALSE
A16: 11 | B16: 1:27.674 | C16: 87.674 | D16: 22.852 | E16: 23.381 | F16: 14.082 | G16: 27.359 | H16: 346.1 | I16: 974.615 | J16: 0.0010147454 | K16: FALSE | L16: FALSE | M16: FALSE
A17: 12 | B17: 1:27.612 | C17: 87.612 | D17: 22.767 | E17: 23.465 | F17: 14.094 | G17: 27.286 | H17: 346.1 | I17: 1062.227 | J17: 0.0010140278 | K17: FALSE | L17: FALSE | M17: FALSE
A18: 13 | B18: 1:27.774 | C18: 87.774 | D18: 22.841 | E18: 23.489 | F18: 14.099 | G18: 27.345 | H18: 348.4 | I18: 1150.001 | J18: 0.0010159028 | K18: FALSE | L18: FALSE | M18: FALSE

Sheet Marco Bezzecchi
A1: 4. Marco BEZZECCHI #72
A3: Team | B3: Aprilia Racing | C3: Manufacturer | D3: APRILIA | E3: Nationality | F3: ITA | G3: Total Laps | H3: 13 | I3: Valid Laps | J3: 12 | K3: Front Tyre | L3: Slick-Hard | M3: Rear Tyre | N3: Slick-Soft
A5: Lap | B5: Lap Time | C5: Lap Seconds | D5: T1 | E5: T2 | F5: T3 | G5: T4 | H5: Speed km/h | I5: Cumulative Seconds | J5: Excel Time | K5: Cancelled | L5: Pit Lane | M5: Partial Timing
A6: 1 | B6: 1:36.139 | C6: 96.139 | D6: 29.736 | E6: 24.561 | F6: 14.37 | G6: 27.472 | H6: 252.5 | I6: 96.139 | J6: 0.0011127199 | K6: FALSE | L6: FALSE | M6: FALSE
A7: 2 | B7: 1:27.944 | C7: 87.944 | D7: 23.026 | E7: 23.612 | F7: 14.107 | G7: 27.199 | H7: 348.4 | I7: 184.083 | J7: 0.0010178704 | K7: FALSE | L7: FALSE | M7: FALSE
A8: 3 | B8: 1:28.280 | C8: 88.28 | D8: 23.17 | E8: 23.671 | F8: 14.172 | G8: 27.267 | H8: 335.4 | I8: 272.363 | J8: 0.0010217593 | K8: FALSE | L8: FALSE | M8: FALSE
A9: 4 | B9: 1:28.255 | C9: 88.255 | D9: 22.913 | E9: 23.576 | F9: 14.302 | G9: 27.464 | H9: 342.9 | I9: 360.618 | J9: 0.0010214699 | K9: FALSE | L9: FALSE | M9: FALSE
A10: 5 | B10: 1:28.127 | C10: 88.127 | D10: 22.914 | E10: 23.627 | F10: 14.145 | G10: 27.441 | H10: 350.6 | I10: 448.745 | J10: 0.0010199884 | K10: FALSE | L10: FALSE | M10: FALSE
A11: 6 | B11: 1:27.684 | C11: 87.684 | D11: 22.885 | E11: 23.424 | F11: 14.124 | G11: 27.251 | H11: 351.8 | I11: 536.429 | J11: 0.0010148611 | K11: FALSE | L11: FALSE | M11: FALSE
A12: 7 | B12: 1:27.748 | C12: 87.748 | D12: 22.874 | E12: 23.422 | F12: 14.121 | G12: 27.331 | H12: 349.5 | I12: 624.177 | J12: 0.0010156019 | K12: FALSE | L12: FALSE | M12: FALSE
A13: 8 | B13: 1:27.913 | C13: 87.913 | D13: 22.914 | E13: 23.527 | F13: 14.174 | G13: 27.298 | H13: 349.5 | I13: 712.09 | J13: 0.0010175116 | K13: FALSE | L13: FALSE | M13: FALSE
A14: 9 | B14: 1:27.785 | C14: 87.785 | D14: 22.949 | E14: 23.446 | F14: 14.149 | G14: 27.241 | H14: 347.3 | I14: 799.875 | J14: 0.0010160301 | K14: FALSE | L14: FALSE | M14: FALSE
A15: 10 | B15: 1:27.399 | C15: 87.399 | D15: 22.684 | E15: 23.318 | F15: 14.046 | G15: 27.351 | H15: 351.8 | I15: 887.274 | J15: 0.0010115625 | K15: FALSE | L15: FALSE | M15: FALSE
A16: 11 | B16: 1:27.576 | C16: 87.576 | D16: 22.89 | E16: 23.362 | F16: 14.042 | G16: 27.282 | H16: 341.8 | I16: 974.85 | J16: 0.0010136111 | K16: FALSE | L16: FALSE | M16: FALSE
A17: 12 | B17: 1:27.662 | C17: 87.662 | D17: 22.84 | E17: 23.467 | F17: 14.105 | G17: 27.25 | H17: 351.8 | I17: 1062.512 | J17: 0.0010146065 | K17: FALSE | L17: FALSE | M17: FALSE
A18: 13 | B18: 1:27.973 | C18: 87.973 | D18: 23.045 | E18: 23.507 | F18: 14.112 | G18: 27.309 | H18: 342.9 | I18: 1150.485 | J18: 0.001018206 | K18: FALSE | L18: FALSE | M18: FALSE

Sheet Pedro Acosta
A1: 5. Pedro ACOSTA #37
A3: Team | B3: Red Bull KTM Factory Racing | C3: Manufacturer | D3: KTM | E3: Nationality | F3: SPA | G3: Total Laps | H3: 13 | I3: Valid Laps | J3: 12 | K3: Front Tyre | L3: Slick-Hard | M3: Rear Tyre | N3: Slick-Soft
A5: Lap | B5: Lap Time | C5: Lap Seconds | D5: T1 | E5: T2 | F5: T3 | G5: T4 | H5: Speed km/h | I5: Cumulative Seconds | J5: Excel Time | K5: Cancelled | L5: Pit Lane | M5: Partial Timing
A6: 1 | B6: 1:34.511 | C6: 94.511 | D6: 28.997 | E6: 24.111 | F6: 14.207 | G6: 27.196 | H6: 251.4 | I6: 94.511 | J6: 0.0010938773 | K6: FALSE | L6: FALSE | M6: FALSE
A7: 2 | B7: 1:27.914 | C7: 87.914 | D7: 22.945 | E7: 23.603 | F7: 14.082 | G7: 27.284 | H7: 346.1 | I7: 182.425 | J7: 0.0010175231 | K7: FALSE | L7: FALSE | M7: FALSE
A8: 3 | B8: 1:28.725 | C8: 88.725 | D8: 23.179 | E8: 23.699 | F8: 14.132 | G8: 27.715 | H8: 337.5 | I8: 271.15 | J8: 0.0010269097 | K8: FALSE | L8: FALSE | M8: FALSE
A9: 4 | B9: 1:28.213 | C9: 88.213 | D9: 22.911 | E9: 23.613 | F9: 14.176 | G9: 27.513 | H9: 336.5 | I9: 359.363 | J9: 0.0010209838 | K9: FALSE | L9: FALSE | M9: FALSE
A10: 5 | B10: 1:28.188 | C10: 88.188 | D10: 22.982 | E10: 23.596 | F10: 14.142 | G10: 27.468 | H10: 344 | I10: 447.551 | J10: 0.0010206944 | K10: FALSE | L10: FALSE | M10: FALSE
A11: 6 | B11: 1:28.367 | C11: 88.367 | D11: 22.982 | E11: 23.547 | F11: 14.173 | G11: 27.665 | H11: 348.4 | I11: 535.918 | J11: 0.0010227662 | K11: FALSE | L11: FALSE | M11: FALSE
A12: 7 | B12: 1:28.086 | C12: 88.086 | D12: 22.972 | E12: 23.509 | F12: 14.159 | G12: 27.446 | H12: 344 | I12: 624.004 | J12: 0.0010195139 | K12: FALSE | L12: FALSE | M12: FALSE
A13: 8 | B13: 1:27.982 | C13: 87.982 | D13: 22.902 | E13: 23.416 | F13: 14.173 | G13: 27.491 | H13: 347.3 | I13: 711.986 | J13: 0.0010183102 | K13: FALSE | L13: FALSE | M13: FALSE
A14: 9 | B14: 1:27.826 | C14: 87.826 | D14: 22.938 | E14: 23.376 | F14: 14.166 | G14: 27.346 | H14: 349.5 | I14: 799.812 | J14: 0.0010165046 | K14: FALSE | L14: FALSE | M14: FALSE
A15: 10 | B15: 1:27.973 | C15: 87.973 | D15: 23.015 | E15: 23.424 | F15: 14.117 | G15: 27.417 | H15: 347.3 | I15: 887.785 | J15: 0.001018206 | K15: FALSE | L15: FALSE | M15: FALSE
A16: 11 | B16: 1:28.085 | C16: 88.085 | D16: 22.984 | E16: 23.408 | F16: 14.13 | G16: 27.563 | H16: 349.5 | I16: 975.87 | J16: 0.0010195023 | K16: FALSE | L16: FALSE | M16: FALSE
A17: 12 | B17: 1:28.459 | C17: 88.459 | D17: 23.074 | E17: 23.532 | F17: 14.254 | G17: 27.599 | H17: 348.4 | I17: 1064.329 | J17: 0.001023831 | K17: FALSE | L17: FALSE | M17: FALSE
A18: 13 | B18: 1:28.771 | C18: 88.771 | D18: 23.157 | E18: 23.689 | F18: 14.319 | G18: 27.606 | H18: 346.1 | I18: 1153.1 | J18: 0.0010274421 | K18: FALSE | L18: FALSE | M18: FALSE

Sheet Ai Ogura
A1: 6. Ai OGURA #79
A3: Team | B3: SuperFile Trackhouse MotoGP Team | C3: Manufacturer | D3: APRILIA | E3: Nationality | F3: JPN | G3: Total Laps | H3: 13 | I3: Valid Laps | J3: 12 | K3: Front Tyre | L3: Slick-Hard | M3: Rear Tyre | N3: Slick-Soft
A5: Lap | B5: Lap Time | C5: Lap Seconds | D5: T1 | E5: T2 | F5: T3 | G5: T4 | H5: Speed km/h | I5: Cumulative Seconds | J5: Excel Time | K5: Cancelled | L5: Pit Lane | M5: Partial Timing
A6: 1 | B6: 1:36.434 | C6: 96.434 | D6: 29.971 | E6: 24.502 | F6: 14.537 | G6: 27.424 | H6: 257.3 | I6: 96.434 | J6: 0.0011161343 | K6: FALSE | L6: FALSE | M6: FALSE
A7: 2 | B7: 1:28.949 | C7: 88.949 | D7: 23.399 | E7: 23.852 | F7: 14.353 | G7: 27.345 | H7: 327.3 | I7: 185.383 | J7: 0.0010295023 | K7: FALSE | L7: FALSE | M7: FALSE
A8: 3 | B8: 1:28.428 | C8: 88.428 | D8: 23.119 | E8: 23.718 | F8: 14.28 | G8: 27.311 | H8: 340.7 | I8: 273.811 | J8: 0.0010234722 | K8: FALSE | L8: FALSE | M8: FALSE
A9: 4 | B9: 1:28.131 | C9: 88.131 | D9: 23 | E9: 23.576 | F9: 14.214 | G9: 27.341 | H9: 348.4 | I9: 361.942 | J9: 0.0010200347 | K9: FALSE | L9: FALSE | M9: FALSE
A10: 5 | B10: 1:28.017 | C10: 88.017 | D10: 22.873 | E10: 23.635 | F10: 14.259 | G10: 27.25 | H10: 352.9 | I10: 449.959 | J10: 0.0010187153 | K10: FALSE | L10: FALSE | M10: FALSE
A11: 6 | B11: 1:29.021 | C11: 89.021 | D11: 22.978 | E11: 23.964 | F11: 14.242 | G11: 27.837 | H11: 351.8 | I11: 538.98 | J11: 0.0010303356 | K11: FALSE | L11: FALSE | M11: FALSE
A12: 7 | B12: 1:28.094 | C12: 88.094 | D12: 23.08 | E12: 23.602 | F12: 14.199 | G12: 27.213 | H12: 346.1 | I12: 627.074 | J12: 0.0010196065 | K12: FALSE | L12: FALSE | M12: FALSE
A13: 8 | B13: 1:27.845 | C13: 87.845 | D13: 22.906 | E13: 23.449 | F13: 14.267 | G13: 27.223 | H13: 350.6 | I13: 714.919 | J13: 0.0010167245 | K13: FALSE | L13: FALSE | M13: FALSE
A14: 9 | B14: 1:28.299 | C14: 88.299 | D14: 23.224 | E14: 23.51 | F14: 14.222 | G14: 27.343 | H14: 341.8 | I14: 803.218 | J14: 0.0010219792 | K14: FALSE | L14: FALSE | M14: FALSE
A15: 10 | B15: 1:28.117 | C15: 88.117 | D15: 23.153 | E15: 23.43 | F15: 14.204 | G15: 27.33 | H15: 348.4 | I15: 891.335 | J15: 0.0010198727 | K15: FALSE | L15: FALSE | M15: FALSE
A16: 11 | B16: 1:27.891 | C16: 87.891 | D16: 23.029 | E16: 23.37 | F16: 14.226 | G16: 27.266 | H16: 345 | I16: 979.226 | J16: 0.0010172569 | K16: FALSE | L16: FALSE | M16: FALSE
A17: 12 | B17: 1:28.042 | C17: 88.042 | D17: 23.114 | E17: 23.366 | F17: 14.205 | G17: 27.357 | H17: 347.3 | I17: 1067.268 | J17: 0.0010190046 | K17: FALSE | L17: FALSE | M17: FALSE
A18: 13 | B18: 1:28.289 | C18: 88.289 | D18: 23.148 | E18: 23.421 | F18: 14.273 | G18: 27.447 | H18: 345 | I18: 1155.557 | J18: 0.0010218634 | K18: FALSE | L18: FALSE | M18: FALSE

Sheet Brad Binder
A1: 7. Brad BINDER #33
A3: Team | B3: Red Bull KTM Factory Racing | C3: Manufacturer | D3: KTM | E3: Nationality | F3: RSA | G3: Total Laps | H3: 13 | I3: Valid Laps | J3: 12 | K3: Front Tyre | L3: Slick-Hard | M3: Rear Tyre | N3: Slick-Soft
A5: Lap | B5: Lap Time | C5: Lap Seconds | D5: T1 | E5: T2 | F5: T3 | G5: T4 | H5: Speed km/h | I5: Cumulative Seconds | J5: Excel Time | K5: Cancelled | L5: Pit Lane | M5: Partial Timing
A6: 1 | B6: 1:35.244 | C6: 95.244 | D6: 29.605 | E6: 23.954 | F6: 14.213 | G6: 27.472 | H6: 256.7 | I6: 95.244 | J6: 0.0011023611 | K6: FALSE | L6: FALSE | M6: FALSE
A7: 2 | B7: 1:28.260 | C7: 88.26 | D7: 23.104 | E7: 23.585 | F7: 14.252 | G7: 27.319 | H7: 342.9 | I7: 183.504 | J7: 0.0010215278 | K7: FALSE | L7: FALSE | M7: FALSE
A8: 3 | B8: 1:28.338 | C8: 88.338 | D8: 23.154 | E8: 23.582 | F8: 14.173 | G8: 27.429 | H8: 334.4 | I8: 271.842 | J8: 0.0010224306 | K8: FALSE | L8: FALSE | M8: FALSE
A9: 4 | B9: 1:28.657 | C9: 88.657 | D9: 23.192 | E9: 23.689 | F9: 14.304 | G9: 27.472 | H9: 338.6 | I9: 360.499 | J9: 0.0010261227 | K9: FALSE | L9: FALSE | M9: FALSE
A10: 5 | B10: 1:28.655 | C10: 88.655 | D10: 23.164 | E10: 23.756 | F10: 14.236 | G10: 27.499 | H10: 346.1 | I10: 449.154 | J10: 0.0010260995 | K10: FALSE | L10: FALSE | M10: FALSE
A11: 6 | B11: 1:28.092 | C11: 88.092 | D11: 22.872 | E11: 23.708 | F11: 14.174 | G11: 27.338 | H11: 348.4 | I11: 537.246 | J11: 0.0010195833 | K11: FALSE | L11: FALSE | M11: FALSE
A12: 7 | B12: 1:28.629 | C12: 88.629 | D12: 23.077 | E12: 23.525 | F12: 14.279 | G12: 27.748 | H12: 346.1 | I12: 625.875 | J12: 0.0010257986 | K12: FALSE | L12: FALSE | M12: FALSE
A13: 8 | B13: 1:28.636 | C13: 88.636 | D13: 23.005 | E13: 23.599 | F13: 14.354 | G13: 27.678 | H13: 345 | I13: 714.511 | J13: 0.0010258796 | K13: FALSE | L13: FALSE | M13: FALSE
A14: 9 | B14: 1:28.659 | C14: 88.659 | D14: 23.183 | E14: 23.533 | F14: 14.323 | G14: 27.62 | H14: 346.1 | I14: 803.17 | J14: 0.0010261458 | K14: FALSE | L14: FALSE | M14: FALSE
A15: 10 | B15: 1:28.577 | C15: 88.577 | D15: 23.34 | E15: 23.556 | F15: 14.263 | G15: 27.418 | H15: 342.9 | I15: 891.747 | J15: 0.0010251968 | K15: FALSE | L15: FALSE | M15: FALSE
A16: 11 | B16: 1:28.299 | C16: 88.299 | D16: 22.936 | E16: 23.563 | F16: 14.296 | G16: 27.504 | H16: 349.5 | I16: 980.046 | J16: 0.0010219792 | K16: FALSE | L16: FALSE | M16: FALSE
A17: 12 | B17: 1:28.212 | C17: 88.212 | D17: 23.019 | E17: 23.434 | F17: 14.27 | G17: 27.489 | H17: 347.3 | I17: 1068.258 | J17: 0.0010209722 | K17: FALSE | L17: FALSE | M17: FALSE
A18: 13 | B18: 1:28.586 | C18: 88.586 | D18: 23.002 | E18: 23.591 | F18: 14.323 | G18: 27.67 | H18: 346.1 | I18: 1156.844 | J18: 0.0010253009 | K18: FALSE | L18: FALSE | M18: FALSE

Sheet Jack Miller
A1: 8. Jack MILLER #43
A3: Team | B3: Prima Pramac Yamaha MotoGP | C3: Manufacturer | D3: YAMAHA | E3: Nationality | F3: AUS | G3: Total Laps | H3: 13 | I3: Valid Laps | J3: 12 | K3: Front Tyre | L3: Slick-Hard | M3: Rear Tyre | N3: Slick-Soft
A5: Lap | B5: Lap Time | C5: Lap Seconds | D5: T1 | E5: T2 | F5: T3 | G5: T4 | H5: Speed km/h | I5: Cumulative Seconds | J5: Excel Time | K5: Cancelled | L5: Pit Lane | M5: Partial Timing
A6: 1 | B6: 1:34.877 | C6: 94.877 | D6: 29.172 | E6: 24.055 | F6: 14.262 | G6: 27.388 | H6: 244.6 | I6: 94.877 | J6: 0.0010981134 | K6: FALSE | L6: FALSE | M6: FALSE
A7: 2 | B7: 1:28.441 | C7: 88.441 | D7: 23.214 | E7: 23.467 | F7: 14.366 | G7: 27.394 | H7: 336.5 | I7: 183.318 | J7: 0.0010236227 | K7: FALSE | L7: FALSE | M7: FALSE
A8: 3 | B8: 1:28.212 | C8: 88.212 | D8: 23.115 | E8: 23.49 | F8: 14.129 | G8: 27.478 | H8: 338.6 | I8: 271.53 | J8: 0.0010209722 | K8: FALSE | L8: FALSE | M8: FALSE
A9: 4 | B9: 1:28.354 | C9: 88.354 | D9: 23.086 | E9: 23.597 | F9: 14.178 | G9: 27.493 | H9: 336.5 | I9: 359.884 | J9: 0.0010226157 | K9: FALSE | L9: FALSE | M9: FALSE
A10: 5 | B10: 1:28.854 | C10: 88.854 | D10: 23.479 | E10: 23.554 | F10: 14.3 | G10: 27.521 | H10: 327.3 | I10: 448.738 | J10: 0.0010284028 | K10: FALSE | L10: FALSE | M10: FALSE
A11: 6 | B11: 1:28.434 | C11: 88.434 | D11: 23.199 | E11: 23.585 | F11: 14.18 | G11: 27.47 | H11: 338.6 | I11: 537.172 | J11: 0.0010235417 | K11: FALSE | L11: FALSE | M11: FALSE
A12: 7 | B12: 1:28.915 | C12: 88.915 | D12: 23.572 | E12: 23.652 | F12: 14.172 | G12: 27.519 | H12: 333.4 | I12: 626.087 | J12: 0.0010291088 | K12: FALSE | L12: FALSE | M12: FALSE
A13: 8 | B13: 1:28.795 | C13: 88.795 | D13: 23.314 | E13: 23.51 | F13: 14.271 | G13: 27.7 | H13: 334.4 | I13: 714.882 | J13: 0.0010277199 | K13: FALSE | L13: FALSE | M13: FALSE
A14: 9 | B14: 1:29.070 | C14: 89.07 | D14: 23.531 | E14: 23.895 | F14: 14.227 | G14: 27.417 | H14: 328.3 | I14: 803.952 | J14: 0.0010309028 | K14: FALSE | L14: FALSE | M14: FALSE
A15: 10 | B15: 1:28.182 | C15: 88.182 | D15: 23.077 | E15: 23.49 | F15: 14.17 | G15: 27.445 | H15: 340.7 | I15: 892.134 | J15: 0.001020625 | K15: FALSE | L15: FALSE | M15: FALSE
A16: 11 | B16: 1:28.191 | C16: 88.191 | D16: 23.05 | E16: 23.479 | F16: 14.145 | G16: 27.517 | H16: 341.8 | I16: 980.325 | J16: 0.0010207292 | K16: FALSE | L16: FALSE | M16: FALSE
A17: 12 | B17: 1:28.370 | C17: 88.37 | D17: 23.183 | E17: 23.54 | F17: 14.143 | G17: 27.504 | H17: 341.8 | I17: 1068.695 | J17: 0.0010228009 | K17: FALSE | L17: FALSE | M17: FALSE
A18: 13 | B18: 1:28.498 | C18: 88.498 | D18: 23.182 | E18: 23.589 | F18: 14.189 | G18: 27.538 | H18: 341.8 | I18: 1157.193 | J18: 0.0010242824 | K18: FALSE | L18: FALSE | M18: FALSE

Sheet Diogo Moreira
A1: 9. Diogo MOREIRA #11
A3: Team | B3: Pro Honda LCR | C3: Manufacturer | D3: HONDA | E3: Nationality | F3: BRA | G3: Total Laps | H3: 13 | I3: Valid Laps | J3: 12 | K3: Front Tyre | L3: Slick-Hard | M3: Rear Tyre | N3: Slick-Soft
A5: Lap | B5: Lap Time | C5: Lap Seconds | D5: T1 | E5: T2 | F5: T3 | G5: T4 | H5: Speed km/h | I5: Cumulative Seconds | J5: Excel Time | K5: Cancelled | L5: Pit Lane | M5: Partial Timing
A6: 1 | B6: 1:35.320 | C6: 95.32 | D6: 29.463 | E6: 23.953 | F6: 14.283 | G6: 27.621 | H6: 261.1 | I6: 95.32 | J6: 0.0011032407 | K6: FALSE | L6: FALSE | M6: FALSE
A7: 2 | B7: 1:28.526 | C7: 88.526 | D7: 23.294 | E7: 23.685 | F7: 14.262 | G7: 27.285 | H7: 344 | I7: 183.846 | J7: 0.0010246065 | K7: FALSE | L7: FALSE | M7: FALSE
A8: 3 | B8: 1:28.492 | C8: 88.492 | D8: 23.34 | E8: 23.592 | F8: 14.213 | G8: 27.347 | H8: 338.6 | I8: 272.338 | J8: 0.001024213 | K8: FALSE | L8: FALSE | M8: FALSE
A9: 4 | B9: 1:28.370 | C9: 88.37 | D9: 23.133 | E9: 23.599 | F9: 14.274 | G9: 27.364 | H9: 345 | I9: 360.708 | J9: 0.0010228009 | K9: FALSE | L9: FALSE | M9: FALSE
A10: 5 | B10: 1:28.717 | C10: 88.717 | D10: 23.171 | E10: 23.728 | F10: 14.182 | G10: 27.636 | H10: 335.4 | I10: 449.425 | J10: 0.0010268171 | K10: FALSE | L10: FALSE | M10: FALSE
A11: 6 | B11: 1:29.542 | C11: 89.542 | D11: 23.141 | E11: 24.156 | F11: 14.327 | G11: 27.918 | H11: 341.8 | I11: 538.967 | J11: 0.0010363657 | K11: FALSE | L11: FALSE | M11: FALSE
A12: 7 | B12: 1:28.623 | C12: 88.623 | D12: 23.232 | E12: 23.705 | F12: 14.291 | G12: 27.395 | H12: 339.6 | I12: 627.59 | J12: 0.0010257292 | K12: FALSE | L12: FALSE | M12: FALSE
A13: 8 | B13: 1:28.579 | C13: 88.579 | D13: 23.128 | E13: 23.606 | F13: 14.303 | G13: 27.542 | H13: 344 | I13: 716.169 | J13: 0.0010252199 | K13: FALSE | L13: FALSE | M13: FALSE
A14: 9 | B14: 1:28.605 | C14: 88.605 | D14: 23.246 | E14: 23.702 | F14: 14.235 | G14: 27.422 | H14: 342.9 | I14: 804.774 | J14: 0.0010255208 | K14: FALSE | L14: FALSE | M14: FALSE
A15: 10 | B15: 1:28.580 | C15: 88.58 | D15: 23.118 | E15: 23.657 | F15: 14.242 | G15: 27.563 | H15: 342.9 | I15: 893.354 | J15: 0.0010252315 | K15: FALSE | L15: FALSE | M15: FALSE
A16: 11 | B16: 1:28.934 | C16: 88.934 | D16: 23.357 | E16: 23.749 | F16: 14.247 | G16: 27.581 | H16: 339.6 | I16: 982.288 | J16: 0.0010293287 | K16: FALSE | L16: FALSE | M16: FALSE
A17: 12 | B17: 1:28.861 | C17: 88.861 | D17: 23.111 | E17: 23.739 | F17: 14.313 | G17: 27.698 | H17: 341.8 | I17: 1071.149 | J17: 0.0010284838 | K17: FALSE | L17: FALSE | M17: FALSE
A18: 13 | B18: 1:28.984 | C18: 88.984 | D18: 23.1 | E18: 23.744 | F18: 14.274 | G18: 27.866 | H18: 340.7 | I18: 1160.133 | J18: 0.0010299074 | K18: FALSE | L18: FALSE | M18: FALSE

Sheet Iker Lecuona
A1: 10. Iker LECUONA #27
A3: Team | B3: BK8 Gresini Racing MotoGP | C3: Manufacturer | D3: DUCATI | E3: Nationality | F3: SPA | G3: Total Laps | H3: 13 | I3: Valid Laps | J3: 12 | K3: Front Tyre | L3: Slick-Hard | M3: Rear Tyre | N3: Slick-Soft
A5: Lap | B5: Lap Time | C5: Lap Seconds | D5: T1 | E5: T2 | F5: T3 | G5: T4 | H5: Speed km/h | I5: Cumulative Seconds | J5: Excel Time | K5: Cancelled | L5: Pit Lane | M5: Partial Timing
A6: 1 | B6: 1:36.781 | C6: 96.781 | D6: 30.072 | E6: 24.495 | F6: 14.698 | G6: 27.516 | H6: 263 | I6: 96.781 | J6: 0.0011201505 | K6: FALSE | L6: FALSE | M6: FALSE
A7: 2 | B7: 1:28.925 | C7: 88.925 | D7: 23.305 | E7: 23.857 | F7: 14.311 | G7: 27.452 | H7: 323.4 | I7: 185.706 | J7: 0.0010292245 | K7: FALSE | L7: FALSE | M7: FALSE
A8: 3 | B8: 1:28.370 | C8: 88.37 | D8: 23.016 | E8: 23.642 | F8: 14.304 | G8: 27.408 | H8: 338.6 | I8: 274.076 | J8: 0.0010228009 | K8: FALSE | L8: FALSE | M8: FALSE
A9: 4 | B9: 1:28.638 | C9: 88.638 | D9: 22.899 | E9: 23.975 | F9: 14.25 | G9: 27.514 | H9: 347.3 | I9: 362.714 | J9: 0.0010259028 | K9: FALSE | L9: FALSE | M9: FALSE
A10: 5 | B10: 1:28.303 | C10: 88.303 | D10: 23.021 | E10: 23.622 | F10: 14.163 | G10: 27.497 | H10: 344 | I10: 451.017 | J10: 0.0010220255 | K10: FALSE | L10: FALSE | M10: FALSE
A11: 6 | B11: 1:28.077 | C11: 88.077 | D11: 22.946 | E11: 23.612 | F11: 14.11 | G11: 27.409 | H11: 345 | I11: 539.094 | J11: 0.0010194097 | K11: FALSE | L11: FALSE | M11: FALSE
A12: 7 | B12: 1:28.614 | C12: 88.614 | D12: 23.212 | E12: 23.733 | F12: 14.29 | G12: 27.379 | H12: 345 | I12: 627.708 | J12: 0.001025625 | K12: FALSE | L12: FALSE | M12: FALSE
A13: 8 | B13: 1:28.542 | C13: 88.542 | D13: 23.166 | E13: 23.636 | F13: 14.332 | G13: 27.408 | H13: 341.8 | I13: 716.25 | J13: 0.0010247917 | K13: FALSE | L13: FALSE | M13: FALSE
A14: 9 | B14: 1:28.402 | C14: 88.402 | D14: 23.027 | E14: 23.599 | F14: 14.227 | G14: 27.549 | H14: 354.1 | I14: 804.652 | J14: 0.0010231713 | K14: FALSE | L14: FALSE | M14: FALSE
A15: 10 | B15: 1:28.590 | C15: 88.59 | D15: 23.049 | E15: 23.692 | F15: 14.228 | G15: 27.621 | H15: 341.8 | I15: 893.242 | J15: 0.0010253472 | K15: FALSE | L15: FALSE | M15: FALSE
A16: 11 | B16: 1:28.986 | C16: 88.986 | D16: 23.307 | E16: 23.79 | F16: 14.214 | G16: 27.675 | H16: 341.8 | I16: 982.228 | J16: 0.0010299306 | K16: FALSE | L16: FALSE | M16: FALSE
A17: 12 | B17: 1:28.783 | C17: 88.783 | D17: 23.011 | E17: 23.791 | F17: 14.268 | G17: 27.713 | H17: 341.8 | I17: 1071.011 | J17: 0.001027581 | K17: FALSE | L17: FALSE | M17: FALSE
A18: 13 | B18: 1:29.173 | C18: 89.173 | D18: 23.098 | E18: 23.726 | F18: 14.317 | G18: 28.032 | H18: 341.8 | I18: 1160.184 | J18: 0.0010320949 | K18: FALSE | L18: FALSE | M18: FALSE

Sheet Fabio Quartararo
A1: 11. Fabio QUARTARARO #20
A3: Team | B3: Monster Energy Yamaha MotoGP Team | C3: Manufacturer | D3: YAMAHA | E3: Nationality | F3: FRA | G3: Total Laps | H3: 13 | I3: Valid Laps | J3: 12 | K3: Front Tyre | L3: Slick-Hard | M3: Rear Tyre | N3: Slick-Soft
A5: Lap | B5: Lap Time | C5: Lap Seconds | D5: T1 | E5: T2 | F5: T3 | G5: T4 | H5: Speed km/h | I5: Cumulative Seconds | J5: Excel Time | K5: Cancelled | L5: Pit Lane | M5: Partial Timing
A6: 1 | B6: 1:37.116 | C6: 97.116 | D6: 30.487 | E6: 24.355 | F6: 14.559 | G6: 27.715 | H6: 254.3 | I6: 97.116 | J6: 0.0011240278 | K6: FALSE | L6: FALSE | M6: FALSE
A7: 2 | B7: 1:28.972 | C7: 88.972 | D7: 23.211 | E7: 23.952 | F7: 14.336 | G7: 27.473 | H7: 342.9 | I7: 186.088 | J7: 0.0010297685 | K7: FALSE | L7: FALSE | M7: FALSE
A8: 3 | B8: 1:28.413 | C8: 88.413 | D8: 23.035 | E8: 23.664 | F8: 14.27 | G8: 27.444 | H8: 346.1 | I8: 274.501 | J8: 0.0010232986 | K8: FALSE | L8: FALSE | M8: FALSE
A9: 4 | B9: 1:28.426 | C9: 88.426 | D9: 22.982 | E9: 23.63 | F9: 14.291 | G9: 27.523 | H9: 346.1 | I9: 362.927 | J9: 0.0010234491 | K9: FALSE | L9: FALSE | M9: FALSE
A10: 5 | B10: 1:28.435 | C10: 88.435 | D10: 23.045 | E10: 23.629 | F10: 14.233 | G10: 27.528 | H10: 348.4 | I10: 451.362 | J10: 0.0010235532 | K10: FALSE | L10: FALSE | M10: FALSE
A11: 6 | B11: 1:29.079 | C11: 89.079 | D11: 23.1 | E11: 24.008 | F11: 14.352 | G11: 27.619 | H11: 344 | I11: 540.441 | J11: 0.0010310069 | K11: FALSE | L11: FALSE | M11: FALSE
A12: 7 | B12: 1:28.631 | C12: 88.631 | D12: 23.148 | E12: 23.721 | F12: 14.228 | G12: 27.534 | H12: 344 | I12: 629.072 | J12: 0.0010258218 | K12: FALSE | L12: FALSE | M12: FALSE
A13: 8 | B13: 1:28.791 | C13: 88.791 | D13: 23.286 | E13: 23.583 | F13: 14.308 | G13: 27.614 | H13: 341.8 | I13: 717.863 | J13: 0.0010276736 | K13: FALSE | L13: FALSE | M13: FALSE
A14: 9 | B14: 1:28.514 | C14: 88.514 | D14: 23.047 | E14: 23.559 | F14: 14.332 | G14: 27.576 | H14: 341.8 | I14: 806.377 | J14: 0.0010244676 | K14: FALSE | L14: FALSE | M14: FALSE
A15: 10 | B15: 1:28.550 | C15: 88.55 | D15: 23.121 | E15: 23.617 | F15: 14.208 | G15: 27.604 | H15: 342.9 | I15: 894.927 | J15: 0.0010248843 | K15: FALSE | L15: FALSE | M15: FALSE
A16: 11 | B16: 1:28.487 | C16: 88.487 | D16: 22.978 | E16: 23.683 | F16: 14.29 | G16: 27.536 | H16: 342.9 | I16: 983.414 | J16: 0.0010241551 | K16: FALSE | L16: FALSE | M16: FALSE
A17: 12 | B17: 1:28.526 | C17: 88.526 | D17: 23.051 | E17: 23.56 | F17: 14.21 | G17: 27.705 | H17: 345 | I17: 1071.94 | J17: 0.0010246065 | K17: FALSE | L17: FALSE | M17: FALSE
A18: 13 | B18: 1:28.686 | C18: 88.686 | D18: 23.182 | E18: 23.596 | F18: 14.294 | G18: 27.614 | H18: 344 | I18: 1160.626 | J18: 0.0010264583 | K18: FALSE | L18: FALSE | M18: FALSE

Sheet Enea Bastianini
A1: 12. Enea BASTIANINI #23
A3: Team | B3: Red Bull KTM Tech3 | C3: Manufacturer | D3: KTM | E3: Nationality | F3: ITA | G3: Total Laps | H3: 13 | I3: Valid Laps | J3: 12 | K3: Front Tyre | L3: Slick-Hard | M3: Rear Tyre | N3: Slick-Soft
A5: Lap | B5: Lap Time | C5: Lap Seconds | D5: T1 | E5: T2 | F5: T3 | G5: T4 | H5: Speed km/h | I5: Cumulative Seconds | J5: Excel Time | K5: Cancelled | L5: Pit Lane | M5: Partial Timing
A6: 1 | B6: 1:36.117 | C6: 96.117 | D6: 29.813 | E6: 24.243 | F6: 14.392 | G6: 27.669 | H6: 260.4 | I6: 96.117 | J6: 0.0011124653 | K6: FALSE | L6: FALSE | M6: FALSE
A7: 2 | B7: 1:30.006 | C7: 90.006 | D7: 23.545 | E7: 24.148 | F7: 14.344 | G7: 27.969 | H7: 333.4 | I7: 186.123 | J7: 0.0010417361 | K7: FALSE | L7: FALSE | M7: FALSE
A8: 3 | B8: 1:28.619 | C8: 88.619 | D8: 23.099 | E8: 23.947 | F8: 14.244 | G8: 27.329 | H8: 342.9 | I8: 274.742 | J8: 0.0010256829 | K8: FALSE | L8: FALSE | M8: FALSE
A9: 4 | B9: 1:28.231 | C9: 88.231 | D9: 22.943 | E9: 23.629 | F9: 14.272 | G9: 27.387 | H9: 345 | I9: 362.973 | J9: 0.0010211921 | K9: FALSE | L9: FALSE | M9: FALSE
A10: 5 | B10: 1:28.419 | C10: 88.419 | D10: 23.115 | E10: 23.672 | F10: 14.267 | G10: 27.365 | H10: 347.3 | I10: 451.392 | J10: 0.0010233681 | K10: FALSE | L10: FALSE | M10: FALSE
A11: 6 | B11: 1:28.997 | C11: 88.997 | D11: 23.141 | E11: 23.816 | F11: 14.367 | G11: 27.673 | H11: 347.3 | I11: 540.389 | J11: 0.0010300579 | K11: FALSE | L11: FALSE | M11: FALSE
A12: 7 | B12: 1:29.687 | C12: 89.687 | D12: 23.042 | E12: 24.753 | F12: 14.343 | G12: 27.549 | H12: 350.6 | I12: 630.076 | J12: 0.001038044 | K12: FALSE | L12: FALSE | M12: FALSE
A13: 8 | B13: 1:28.348 | C13: 88.348 | D13: 22.916 | E13: 23.575 | F13: 14.353 | G13: 27.504 | H13: 347.3 | I13: 718.424 | J13: 0.0010225463 | K13: FALSE | L13: FALSE | M13: FALSE
A14: 9 | B14: 1:28.493 | C14: 88.493 | D14: 22.997 | E14: 23.615 | F14: 14.355 | G14: 27.526 | H14: 348.4 | I14: 806.917 | J14: 0.0010242245 | K14: FALSE | L14: FALSE | M14: FALSE
A15: 10 | B15: 1:28.394 | C15: 88.394 | D15: 22.932 | E15: 23.603 | F15: 14.376 | G15: 27.483 | H15: 351.8 | I15: 895.311 | J15: 0.0010230787 | K15: FALSE | L15: FALSE | M15: FALSE
A16: 11 | B16: 1:28.332 | C16: 88.332 | D16: 22.91 | E16: 23.671 | F16: 14.317 | G16: 27.434 | H16: 350.6 | I16: 983.643 | J16: 0.0010223611 | K16: FALSE | L16: FALSE | M16: FALSE
A17: 12 | B17: 1:28.414 | C17: 88.414 | D17: 22.949 | E17: 23.708 | F17: 14.25 | G17: 27.507 | H17: 354.1 | I17: 1072.057 | J17: 0.0010233102 | K17: FALSE | L17: FALSE | M17: FALSE
A18: 13 | B18: 1:28.791 | C18: 88.791 | D18: 23.193 | E18: 23.775 | F18: 14.248 | G18: 27.575 | H18: 352.9 | I18: 1160.848 | J18: 0.0010276736 | K18: FALSE | L18: FALSE | M18: FALSE

Sheet Alex Rins
A1: 13. Alex RINS #42
A3: Team | B3: Monster Energy Yamaha MotoGP Team | C3: Manufacturer | D3: YAMAHA | E3: Nationality | F3: SPA | G3: Total Laps | H3: 13 | I3: Valid Laps | J3: 12 | K3: Front Tyre | L3: Slick-Hard | M3: Rear Tyre | N3: Slick-Soft
A5: Lap | B5: Lap Time | C5: Lap Seconds | D5: T1 | E5: T2 | F5: T3 | G5: T4 | H5: Speed km/h | I5: Cumulative Seconds | J5: Excel Time | K5: Cancelled | L5: Pit Lane | M5: Partial Timing
A6: 1 | B6: 1:37.848 | C6: 97.848 | D6: 30.807 | E6: 24.672 | F6: 14.604 | G6: 27.765 | H6: 261.7 | I6: 97.848 | J6: 0.0011325 | K6: FALSE | L6: FALSE | M6: FALSE
A7: 2 | B7: 1:29.995 | C7: 89.995 | D7: 23.774 | E7: 24.148 | F7: 14.566 | G7: 27.507 | H7: 321.5 | I7: 187.843 | J7: 0.0010416088 | K7: FALSE | L7: FALSE | M7: FALSE
A8: 3 | B8: 1:28.826 | C8: 88.826 | D8: 23.13 | E8: 23.967 | F8: 14.317 | G8: 27.412 | H8: 342.9 | I8: 276.669 | J8: 0.0010280787 | K8: FALSE | L8: FALSE | M8: FALSE
A9: 4 | B9: 1:28.467 | C9: 88.467 | D9: 23.125 | E9: 23.588 | F9: 14.261 | G9: 27.493 | H9: 344 | I9: 365.136 | J9: 0.0010239236 | K9: FALSE | L9: FALSE | M9: FALSE
A10: 5 | B10: 1:28.586 | C10: 88.586 | D10: 22.932 | E10: 23.712 | F10: 14.329 | G10: 27.613 | H10: 346.1 | I10: 453.722 | J10: 0.0010253009 | K10: FALSE | L10: FALSE | M10: FALSE
A11: 6 | B11: 1:28.494 | C11: 88.494 | D11: 23.114 | E11: 23.645 | F11: 14.197 | G11: 27.538 | H11: 339.6 | I11: 542.216 | J11: 0.0010242361 | K11: FALSE | L11: FALSE | M11: FALSE
A12: 7 | B12: 1:28.266 | C12: 88.266 | D12: 23.021 | E12: 23.52 | F12: 14.251 | G12: 27.474 | H12: 340.7 | I12: 630.482 | J12: 0.0010215972 | K12: FALSE | L12: FALSE | M12: FALSE
A13: 8 | B13: 1:28.332 | C13: 88.332 | D13: 22.945 | E13: 23.624 | F13: 14.374 | G13: 27.389 | H13: 344 | I13: 718.814 | J13: 0.0010223611 | K13: FALSE | L13: FALSE | M13: FALSE
A14: 9 | B14: 1:28.150 | C14: 88.15 | D14: 22.958 | E14: 23.589 | F14: 14.277 | G14: 27.326 | H14: 344 | I14: 806.964 | J14: 0.0010202546 | K14: FALSE | L14: FALSE | M14: FALSE
A15: 10 | B15: 1:28.386 | C15: 88.386 | D15: 22.955 | E15: 23.656 | F15: 14.338 | G15: 27.437 | H15: 346.1 | I15: 895.35 | J15: 0.0010229861 | K15: FALSE | L15: FALSE | M15: FALSE
A16: 11 | B16: 1:28.336 | C16: 88.336 | D16: 22.926 | E16: 23.691 | F16: 14.366 | G16: 27.353 | H16: 342.9 | I16: 983.686 | J16: 0.0010224074 | K16: FALSE | L16: FALSE | M16: FALSE
A17: 12 | B17: 1:28.577 | C17: 88.577 | D17: 23.086 | E17: 23.81 | F17: 14.264 | G17: 27.417 | H17: 334.4 | I17: 1072.263 | J17: 0.0010251968 | K17: FALSE | L17: FALSE | M17: FALSE
A18: 13 | B18: 1:28.716 | C18: 88.716 | D18: 23.102 | E18: 23.809 | F18: 14.236 | G18: 27.569 | H18: 346.1 | I18: 1160.979 | J18: 0.0010268056 | K18: FALSE | L18: FALSE | M18: FALSE

Sheet Franco Morbidelli
A1: 14. Franco MORBIDELLI #21
A3: Team | B3: Pertamina Enduro VR46 Racing Team | C3: Manufacturer | D3: DUCATI | E3: Nationality | F3: ITA | G3: Total Laps | H3: 13 | I3: Valid Laps | J3: 12 | K3: Front Tyre | L3: Slick-Hard | M3: Rear Tyre | N3: Slick-Soft
A5: Lap | B5: Lap Time | C5: Lap Seconds | D5: T1 | E5: T2 | F5: T3 | G5: T4 | H5: Speed km/h | I5: Cumulative Seconds | J5: Excel Time | K5: Cancelled | L5: Pit Lane | M5: Partial Timing
A6: 1 | B6: 1:37.683 | C6: 97.683 | D6: 30.745 | E6: 24.666 | F6: 14.554 | G6: 27.718 | H6: 264.2 | I6: 97.683 | J6: 0.0011305903 | K6: FALSE | L6: FALSE | M6: FALSE
A7: 2 | B7: 1:29.304 | C7: 89.304 | D7: 23.615 | E7: 23.761 | F7: 14.435 | G7: 27.493 | H7: 321.5 | I7: 186.987 | J7: 0.0010336111 | K7: FALSE | L7: FALSE | M7: FALSE
A8: 3 | B8: 1:29.650 | C8: 89.65 | D8: 23.639 | E8: 23.976 | F8: 14.52 | G8: 27.515 | H8: 325.4 | I8: 276.637 | J8: 0.0010376157 | K8: FALSE | L8: FALSE | M8: FALSE
A9: 4 | B9: 1:29.345 | C9: 89.345 | D9: 23.605 | E9: 23.823 | F9: 14.426 | G9: 27.491 | H9: 332.3 | I9: 365.982 | J9: 0.0010340856 | K9: FALSE | L9: FALSE | M9: FALSE
A10: 5 | B10: 1:29.062 | C10: 89.062 | D10: 23.368 | E10: 23.7 | F10: 14.403 | G10: 27.591 | H10: 332.3 | I10: 455.044 | J10: 0.0010308102 | K10: FALSE | L10: FALSE | M10: FALSE
A11: 6 | B11: 1:29.098 | C11: 89.098 | D11: 23.581 | E11: 23.589 | F11: 14.349 | G11: 27.579 | H11: 328.3 | I11: 544.142 | J11: 0.0010312269 | K11: FALSE | L11: FALSE | M11: FALSE
A12: 7 | B12: 1:29.075 | C12: 89.075 | D12: 23.356 | E12: 23.71 | F12: 14.442 | G12: 27.567 | H12: 339.6 | I12: 633.217 | J12: 0.0010309606 | K12: FALSE | L12: FALSE | M12: FALSE
A13: 8 | B13: 1:29.160 | C13: 89.16 | D13: 23.298 | E13: 23.52 | F13: 14.768 | G13: 27.574 | H13: 336.5 | I13: 722.377 | J13: 0.0010319444 | K13: FALSE | L13: FALSE | M13: FALSE
A14: 9 | B14: 1:29.016 | C14: 89.016 | D14: 23.502 | E14: 23.612 | F14: 14.32 | G14: 27.582 | H14: 337.5 | I14: 811.393 | J14: 0.0010302778 | K14: FALSE | L14: FALSE | M14: FALSE
A15: 10 | B15: 1:28.950 | C15: 88.95 | D15: 23.39 | E15: 23.576 | F15: 14.338 | G15: 27.646 | H15: 337.5 | I15: 900.343 | J15: 0.0010295139 | K15: FALSE | L15: FALSE | M15: FALSE
A16: 11 | B16: 1:28.950 | C16: 88.95 | D16: 23.403 | E16: 23.612 | F16: 14.331 | G16: 27.604 | H16: 339.6 | I16: 989.293 | J16: 0.0010295139 | K16: FALSE | L16: FALSE | M16: FALSE
A17: 12 | B17: 1:29.287 | C17: 89.287 | D17: 23.667 | E17: 23.619 | F17: 14.305 | G17: 27.696 | H17: 338.6 | I17: 1078.58 | J17: 0.0010334144 | K17: FALSE | L17: FALSE | M17: FALSE
A18: 13 | B18: 1:29.108 | C18: 89.108 | D18: 23.452 | E18: 23.559 | F18: 14.364 | G18: 27.733 | H18: 338.6 | I18: 1167.688 | J18: 0.0010313426 | K18: FALSE | L18: FALSE | M18: FALSE

Sheet Augusto Fernandez
A1: 15. Augusto FERNANDEZ #47
A3: Team | B3: Yamaha Factory Racing | C3: Manufacturer | D3: YAMAHA | E3: Nationality | F3: SPA | G3: Total Laps | H3: 13 | I3: Valid Laps | J3: 12 | K3: Front Tyre | L3: Slick-Hard | M3: Rear Tyre | N3: Slick-Soft
A5: Lap | B5: Lap Time | C5: Lap Seconds | D5: T1 | E5: T2 | F5: T3 | G5: T4 | H5: Speed km/h | I5: Cumulative Seconds | J5: Excel Time | K5: Cancelled | L5: Pit Lane | M5: Partial Timing
A6: 1 | B6: 1:37.638 | C6: 97.638 | D6: 30.308 | E6: 24.939 | F6: 14.602 | G6: 27.789 | H6: 252 | I6: 97.638 | J6: 0.0011300694 | K6: FALSE | L6: FALSE | M6: FALSE
A7: 2 | B7: 1:30.647 | C7: 90.647 | D7: 23.772 | E7: 24.265 | F7: 14.763 | G7: 27.847 | H7: 316.8 | I7: 188.285 | J7: 0.0010491551 | K7: FALSE | L7: FALSE | M7: FALSE
A8: 3 | B8: 1:30.143 | C8: 90.143 | D8: 23.561 | E8: 24.006 | F8: 14.48 | G8: 28.096 | H8: 328.3 | I8: 278.428 | J8: 0.0010433218 | K8: FALSE | L8: FALSE | M8: FALSE
A9: 4 | B9: 1:30.223 | C9: 90.223 | D9: 23.65 | E9: 23.994 | F9: 14.478 | G9: 28.101 | H9: 328.3 | I9: 368.651 | J9: 0.0010442477 | K9: FALSE | L9: FALSE | M9: FALSE
A10: 5 | B10: 1:30.112 | C10: 90.112 | D10: 23.563 | E10: 23.988 | F10: 14.549 | G10: 28.012 | H10: 330.3 | I10: 458.763 | J10: 0.001042963 | K10: FALSE | L10: FALSE | M10: FALSE
A11: 6 | B11: 1:30.411 | C11: 90.411 | D11: 23.677 | E11: 24.101 | F11: 14.536 | G11: 28.097 | H11: 333.4 | I11: 549.174 | J11: 0.0010464236 | K11: FALSE | L11: FALSE | M11: FALSE
A12: 7 | B12: 1:30.784 | C12: 90.784 | D12: 23.734 | E12: 24.065 | F12: 14.525 | G12: 28.46 | H12: 334.4 | I12: 639.958 | J12: 0.0010507407 | K12: FALSE | L12: FALSE | M12: FALSE
A13: 8 | B13: 1:30.844 | C13: 90.844 | D13: 23.682 | E13: 24.057 | F13: 14.849 | G13: 28.256 | H13: 333.4 | I13: 730.802 | J13: 0.0010514352 | K13: FALSE | L13: FALSE | M13: FALSE
A14: 9 | B14: 1:30.911 | C14: 90.911 | D14: 23.81 | E14: 24.187 | F14: 14.577 | G14: 28.337 | H14: 330.3 | I14: 821.713 | J14: 0.0010522106 | K14: FALSE | L14: FALSE | M14: FALSE
A15: 10 | B15: 1:31.211 | C15: 91.211 | D15: 24.022 | E15: 24.221 | F15: 14.717 | G15: 28.251 | H15: 330.3 | I15: 912.924 | J15: 0.0010556829 | K15: FALSE | L15: FALSE | M15: FALSE
A16: 11 | B16: 1:31.143 | C16: 91.143 | D16: 23.91 | E16: 24.276 | F16: 14.633 | G16: 28.324 | H16: 332.3 | I16: 1004.067 | J16: 0.0010548958 | K16: FALSE | L16: FALSE | M16: FALSE
A17: 12 | B17: 1:31.879 | C17: 91.879 | D17: 24.123 | E17: 24.44 | F17: 14.811 | G17: 28.505 | H17: 331.3 | I17: 1095.946 | J17: 0.0010634144 | K17: FALSE | L17: FALSE | M17: FALSE
A18: 13 | B18: 1:31.410 | C18: 91.41 | D18: 23.973 | E18: 24.322 | F18: 14.714 | G18: 28.401 | H18: 331.3 | I18: 1187.356 | J18: 0.0010579861 | K18: FALSE | L18: FALSE | M18: FALSE

Sheet Raul Fernandez
A1: 16. Raul FERNANDEZ #25
A3: Team | B3: SuperFile Trackhouse MotoGP Team | C3: Manufacturer | D3: APRILIA | E3: Nationality | F3: SPA | G3: Total Laps | H3: 8 | I3: Valid Laps | J3: 7 | K3: Front Tyre | L3: Slick-Hard | M3: Rear Tyre | N3: Slick-Soft
A5: Lap | B5: Lap Time | C5: Lap Seconds | D5: T1 | E5: T2 | F5: T3 | G5: T4 | H5: Speed km/h | I5: Cumulative Seconds | J5: Excel Time | K5: Cancelled | L5: Pit Lane | M5: Partial Timing
A6: 1 | B6: 1:36.114 | C6: 96.114 | D6: 29.742 | E6: 24.466 | F6: 14.343 | G6: 27.563 | H6: 247.9 | I6: 96.114 | J6: 0.0011124306 | K6: FALSE | L6: FALSE | M6: FALSE
A7: 2 | B7: 1:28.330 | C7: 88.33 | D7: 23.333 | E7: 23.646 | F7: 14.138 | G7: 27.213 | H7: 339.6 | I7: 184.444 | J7: 0.001022338 | K7: FALSE | L7: FALSE | M7: FALSE
A8: 3 | B8: 1:28.303 | C8: 88.303 | D8: 23.062 | E8: 23.658 | F8: 14.169 | G8: 27.414 | H8: 341.8 | I8: 272.747 | J8: 0.0010220255 | K8: FALSE | L8: FALSE | M8: FALSE
A9: 4 | B9: 1:28.640 | C9: 88.64 | D9: 23.063 | E9: 23.97 | F9: 14.151 | G9: 27.456 | H9: 344 | I9: 361.387 | J9: 0.0010259259 | K9: FALSE | L9: FALSE | M9: FALSE
A10: 5 | B10: 1:28.273 | C10: 88.273 | D10: 23.012 | E10: 23.63 | F10: 14.228 | G10: 27.403 | H10: 346.1 | I10: 449.66 | J10: 0.0010216782 | K10: FALSE | L10: FALSE | M10: FALSE
A11: 6 | B11: 1:29.166 | C11: 89.166 | D11: 23.061 | E11: 23.803 | F11: 14.323 | G11: 27.979 | H11: 341.8 | I11: 538.826 | J11: 0.0010320139 | K11: FALSE | L11: FALSE | M11: FALSE
A12: 7 | B12: 1:28.215 | C12: 88.215 | D12: 23.01 | E12: 23.555 | F12: 14.164 | G12: 27.486 | H12: 346.1 | I12: 627.041 | J12: 0.0010210069 | K12: FALSE | L12: FALSE | M12: FALSE
A13: 8 | B13: 1:28.993 | C13: 88.993 | D13: 23.208 | E13: 23.689 | F13: 14.513 | G13: 27.583 | H13: 344 | I13: 716.034 | J13: 0.0010300116 | K13: FALSE | L13: FALSE | M13: FALSE

Sheet Jorge Martin
A1: 17. Jorge MARTIN #89
A3: Team | B3: Aprilia Racing | C3: Manufacturer | D3: APRILIA | E3: Nationality | F3: SPA | G3: Total Laps | H3: 7 | I3: Valid Laps | J3: 6 | K3: Front Tyre | L3: Slick-Hard | M3: Rear Tyre | N3: Slick-Soft
A5: Lap | B5: Lap Time | C5: Lap Seconds | D5: T1 | E5: T2 | F5: T3 | G5: T4 | H5: Speed km/h | I5: Cumulative Seconds | J5: Excel Time | K5: Cancelled | L5: Pit Lane | M5: Partial Timing
A6: 1 | B6: 1:33.747 | C6: 93.747 | D6: 28.66 | E6: 23.67 | F6: 14.137 | G6: 27.28 | H6: 251.4 | I6: 93.747 | J6: 0.0010850347 | K6: FALSE | L6: FALSE | M6: FALSE
A7: 2 | B7: 1:28.573 | C7: 88.573 | D7: 23.299 | E7: 23.513 | F7: 14.118 | G7: 27.643 | H7: 331.3 | I7: 182.32 | J7: 0.0010251505 | K7: FALSE | L7: FALSE | M7: FALSE
A8: 3 | B8: 1:28.256 | C8: 88.256 | D8: 22.914 | E8: 23.717 | F8: 14.276 | G8: 27.349 | H8: 347.3 | I8: 270.576 | J8: 0.0010214815 | K8: FALSE | L8: FALSE | M8: FALSE
A9: 4 | B9: 1:27.229 | C9: 87.229 | D9: 22.782 | E9: 23.221 | F9: 14.055 | G9: 27.171 | H9: 342.9 | I9: 357.805 | J9: 0.0010095949 | K9: FALSE | L9: FALSE | M9: FALSE
A10: 5 | B10: 1:28.055 | C10: 88.055 | D10: 22.789 | E10: 23.862 | F10: 14.148 | G10: 27.256 | H10: 342.9 | I10: 445.86 | J10: 0.0010191551 | K10: FALSE | L10: FALSE | M10: FALSE
A11: 6 | B11: 1:28.035 | C11: 88.035 | D11: 22.984 | E11: 23.629 | F11: 14.107 | G11: 27.315 | H11: 346.1 | I11: 533.895 | J11: 0.0010189236 | K11: FALSE | L11: FALSE | M11: FALSE
A12: 7 | B12: 1:27.692 | C12: 87.692 | D12: 22.9 | E12: 23.467 | F12: 14.035 | G12: 27.29 | H12: 345 | I12: 621.587 | J12: 0.0010149537 | K12: FALSE | L12: FALSE | M12: FALSE

Sheet Maverick Viñales
A1: 18. Maverick VIÑALES #12
A3: Team | B3: Red Bull KTM Tech3 | C3: Manufacturer | D3: KTM | E3: Nationality | F3: SPA | G3: Total Laps | H3: 6 | I3: Valid Laps | J3: 5 | K3: Front Tyre | L3: Slick-Hard | M3: Rear Tyre | N3: Slick-Soft
A5: Lap | B5: Lap Time | C5: Lap Seconds | D5: T1 | E5: T2 | F5: T3 | G5: T4 | H5: Speed km/h | I5: Cumulative Seconds | J5: Excel Time | K5: Cancelled | L5: Pit Lane | M5: Partial Timing
A6: 1 | B6: 1:37.401 | C6: 97.401 | D6: 30.148 | E6: 24.957 | F6: 14.587 | G6: 27.709 | H6: 266.2 | I6: 97.401 | J6: 0.0011273264 | K6: FALSE | L6: FALSE | M6: FALSE
A7: 2 | B7: 1:29.128 | C7: 89.128 | D7: 23.256 | E7: 23.906 | F7: 14.388 | G7: 27.578 | H7: 329.3 | I7: 186.529 | J7: 0.0010315741 | K7: FALSE | L7: FALSE | M7: FALSE
A8: 3 | B8: 1:29.134 | C8: 89.134 | D8: 23.119 | E8: 24.105 | F8: 14.284 | G8: 27.626 | H8: 347.3 | I8: 275.663 | J8: 0.0010316435 | K8: FALSE | L8: FALSE | M8: FALSE
A9: 4 | B9: 1:29.158 | C9: 89.158 | D9: 23.345 | E9: 23.768 | F9: 14.344 | G9: 27.701 | H9: 346.1 | I9: 364.821 | J9: 0.0010319213 | K9: FALSE | L9: FALSE | M9: FALSE
A10: 5 | B10: 1:28.843 | C10: 88.843 | D10: 23.122 | E10: 23.751 | F10: 14.305 | G10: 27.665 | H10: 345 | I10: 453.664 | J10: 0.0010282755 | K10: FALSE | L10: FALSE | M10: FALSE
A11: 6 | B11: 1:29.249 | C11: 89.249 | D11: 23.376 | E11: 23.884 | F11: 14.308 | G11: 27.681 | H11: 344 | I11: 542.913 | J11: 0.0010329745 | K11: FALSE | L11: FALSE | M11: FALSE

Sheet Johann Zarco
A1: 19. Johann ZARCO #5
A3: Team | B3: Castrol Honda LCR | C3: Manufacturer | D3: HONDA | E3: Nationality | F3: FRA | G3: Total Laps | H3: 3 | I3: Valid Laps | J3: 2 | K3: Front Tyre | L3: Slick-Medium | M3: Rear Tyre | N3: Slick-Soft
A5: Lap | B5: Lap Time | C5: Lap Seconds | D5: T1 | E5: T2 | F5: T3 | G5: T4 | H5: Speed km/h | I5: Cumulative Seconds | J5: Excel Time | K5: Cancelled | L5: Pit Lane | M5: Partial Timing
A6: 1 | B6: 1:34.075 | C6: 94.075 | D6: 28.845 | E6: 23.923 | F6: 14.084 | G6: 27.223 | H6: 246.8 | I6: 94.075 | J6: 0.001088831 | K6: FALSE | L6: FALSE | M6: FALSE
A7: 2 | B7: 1:28.297 | C7: 88.297 | D7: 23.144 | E7: 23.723 | F7: 14.058 | G7: 27.372 | H7: 341.8 | I7: 182.372 | J7: 0.001021956 | K7: FALSE | L7: FALSE | M7: FALSE
A8: 3 | B8: 1:28.936 | C8: 88.936 | D8: 23.087 | E8: 24.065 | F8: 14.211 | G8: 27.573 | H8: 328.3 | I8: 271.308 | J8: 0.0010293519 | K8: FALSE | L8: FALSE | M8: FALSE

Sheet Francesco Bagnaia
A1: 20. Francesco BAGNAIA #63
A3: Team | B3: Ducati Lenovo Team | C3: Manufacturer | D3: DUCATI | E3: Nationality | F3: ITA | G3: Total Laps | H3: 2 | I3: Valid Laps | J3: 1 | K3: Front Tyre | L3: Slick-Hard | M3: Rear Tyre | N3: Slick-Soft
A5: Lap | B5: Lap Time | C5: Lap Seconds | D5: T1 | E5: T2 | F5: T3 | G5: T4 | H5: Speed km/h | I5: Cumulative Seconds | J5: Excel Time | K5: Cancelled | L5: Pit Lane | M5: Partial Timing
A6: 1 | B6: 1:36.702 | C6: 96.702 | D6: 30.135 | E6: 24.516 | F6: 14.538 | G6: 27.513 | H6: 261.1 | I6: 96.702 | J6: 0.0011192361 | K6: FALSE | L6: FALSE | M6: FALSE
A7: 2 | B7: 1:35.476 | C7: 95.476 | D7: 23.223 | E7: 24.196 | F7: 19.438 | G7: 28.619 | H7: 329.3 | I7: 192.178 | J7: 0.0011050463 | K7: FALSE | L7: FALSE | M7: FALSE

Sheet Race Data
A1: Rider | B1: Number | C1: Position | D1: Team | E1: Manufacturer | F1: Nationality | G1: Total Laps | H1: Valid Laps | I1: Lap | J1: Lap Time | K1: Lap Seconds | L1: T1 | M1: T2 | N1: T3 | O1: T4 | P1: Speed km/h | Q1: Cumulative Seconds | R1: Cancelled | S1: Pit Lane | T1: Partial Timing
A2: Marc MARQUEZ | B2: 93 | C2: 1 | D2: Ducati Lenovo Team | E2: DUCATI | F2: SPA | G2: 13 | H2: 12 | I2: 1 | J2: 1:33.677 | K2: 93.677 | L2: 28.524 | M2: 23.568 | N2: 14.132 | O2: 27.453 | P2: 244 | Q2: 93.677 | R2: FALSE | S2: FALSE | T2: FALSE
A3: Marc MARQUEZ | B3: 93 | C3: 1 | D3: Ducati Lenovo Team | E3: DUCATI | F3: SPA | G3: 13 | H3: 12 | I3: 2 | J3: 1:28.386 | K3: 88.386 | L3: 23.147 | M3: 23.584 | N3: 14.162 | O3: 27.493 | P3: 342.9 | Q3: 182.063 | R3: FALSE | S3: FALSE | T3: FALSE
A4: Marc MARQUEZ | B4: 93 | C4: 1 | D4: Ducati Lenovo Team | E4: DUCATI | F4: SPA | G4: 13 | H4: 12 | I4: 3 | J4: 1:28.637 | K4: 88.637 | L4: 23.026 | M4: 23.761 | N4: 14.303 | O4: 27.547 | P4: 342.9 | Q4: 270.7 | R4: FALSE | S4: FALSE | T4: FALSE
A5: Marc MARQUEZ | B5: 93 | C5: 1 | D5: Ducati Lenovo Team | E5: DUCATI | F5: SPA | G5: 13 | H5: 12 | I5: 4 | J5: 1:27.290 | K5: 87.29 | L5: 22.79 | M5: 23.315 | N5: 14.026 | O5: 27.159 | P5: 347.3 | Q5: 357.99 | R5: FALSE | S5: FALSE | T5: FALSE
A6: Marc MARQUEZ | B6: 93 | C6: 1 | D6: Ducati Lenovo Team | E6: DUCATI | F6: SPA | G6: 13 | H6: 12 | I6: 5 | J6: 1:27.800 | K6: 87.8 | L6: 22.712 | M6: 23.417 | N6: 14.168 | O6: 27.503 | P6: 348.4 | Q6: 445.79 | R6: FALSE | S6: FALSE | T6: FALSE
A7: Marc MARQUEZ | B7: 93 | C7: 1 | D7: Ducati Lenovo Team | E7: DUCATI | F7: SPA | G7: 13 | H7: 12 | I7: 6 | J7: 1:28.016 | K7: 88.016 | L7: 22.963 | M7: 23.581 | N7: 14.098 | O7: 27.374 | P7: 342.9 | Q7: 533.806 | R7: FALSE | S7: FALSE | T7: FALSE
A8: Marc MARQUEZ | B8: 93 | C8: 1 | D8: Ducati Lenovo Team | E8: DUCATI | F8: SPA | G8: 13 | H8: 12 | I8: 7 | J8: 1:27.707 | K8: 87.707 | L8: 22.886 | M8: 23.365 | N8: 14.071 | O8: 27.385 | P8: 342.9 | Q8: 621.513 | R8: FALSE | S8: FALSE | T8: FALSE
A9: Marc MARQUEZ | B9: 93 | C9: 1 | D9: Ducati Lenovo Team | E9: DUCATI | F9: SPA | G9: 13 | H9: 12 | I9: 8 | J9: 1:28.251 | K9: 88.251 | L9: 22.89 | M9: 23.833 | N9: 14.178 | O9: 27.35 | P9: 345 | Q9: 709.764 | R9: FALSE | S9: FALSE | T9: FALSE
A10: Marc MARQUEZ | B10: 93 | C10: 1 | D10: Ducati Lenovo Team | E10: DUCATI | F10: SPA | G10: 13 | H10: 12 | I10: 9 | J10: 1:28.039 | K10: 88.039 | L10: 22.993 | M10: 23.49 | N10: 14.148 | O10: 27.408 | P10: 344 | Q10: 797.803 | R10: FALSE | S10: FALSE | T10: FALSE
A11: Marc MARQUEZ | B11: 93 | C11: 1 | D11: Ducati Lenovo Team | E11: DUCATI | F11: SPA | G11: 13 | H11: 12 | I11: 10 | J11: 1:27.866 | K11: 87.866 | L11: 22.883 | M11: 23.419 | N11: 14.064 | O11: 27.5 | P11: 344 | Q11: 885.669 | R11: FALSE | S11: FALSE | T11: FALSE
A12: Marc MARQUEZ | B12: 93 | C12: 1 | D12: Ducati Lenovo Team | E12: DUCATI | F12: SPA | G12: 13 | H12: 12 | I12: 11 | J12: 1:27.916 | K12: 87.916 | L12: 22.902 | M12: 23.414 | N12: 14.148 | O12: 27.452 | P12: 344 | Q12: 973.585 | R12: FALSE | S12: FALSE | T12: FALSE
A13: Marc MARQUEZ | B13: 93 | C13: 1 | D13: Ducati Lenovo Team | E13: DUCATI | F13: SPA | G13: 13 | H13: 12 | I13: 12 | J13: 1:27.937 | K13: 87.937 | L13: 22.837 | M13: 23.427 | N13: 14.135 | O13: 27.538 | P13: 342.9 | Q13: 1061.522 | R13: FALSE | S13: FALSE | T13: FALSE
... A222: Francesco BAGNAIA | B222: 63 | C222: 20 | D222: Ducati Lenovo Team | E222: DUCATI | F222: ITA | G222: 2 | H222: 1 | I222: 2 | J222: 1:35.476 | K222: 95.476 | L222: 23.223 | M222: 24.196 | N222: 19.438 | O222: 28.619 | P222: 329.3 | Q222: 192.178 | R222: FALSE | S222: FALSE | T222: FALSE

Sheet Race Progress
A1: RED BULL GRAND PRIX OF AUSTRALIA - Rider Lap Time Analysis
A2: Phillip Island | B2: Phillip Island, Saturday, October 24, 2026
A3: Show | B3: Rider | C3: Color | E3: Lap | F3: Marc MARQUEZ | G3: Alex MARQUEZ | H3: Fabio DI GIANNANTONIO | I3: Marco BEZZECCHI | J3: Pedro ACOSTA | K3: Ai OGURA | L3: Brad BINDER | M3: Jack MILLER | N3: Diogo MOREIRA | O3: Iker LECUONA | P3: Fabio QUARTARARO | Q3: Enea BASTIANINI | R3: Alex RINS | S3: Franco MORBIDELLI | T3: Augusto FERNANDEZ | U3: Raul FERNANDEZ | V3: Jorge MARTIN | W3: Maverick VIÑALES | X3: Johann ZARCO | Y3: Francesco BAGNAIA
A4: TRUE | B4: Marc MARQUEZ | C4: #A0B73A | E4: 1 | F4: =IF($A$4,'Marc Marquez'!J6,NA()) -> 0.0010842245 | G4: =IF($A$5,'Alex Marquez'!J6,NA()) -> 0.0010894213 | H4: =IF($A$6,'Fabio Di Giannantonio'!J6,NA()) -> 0.0011039352 | I4: =IF($A$7,'Marco Bezzecchi'!J6,NA()) -> 0.0011127199 | J4: =IF($A$8,'Pedro Acosta'!J6,NA()) -> 0.0010938773 | K4: =IF($A$9,'Ai Ogura'!J6,NA()) -> 0.0011161343 | L4: =IF($A$10,'Brad Binder'!J6,NA()) -> 0.0011023611 | M4: =IF($A$11,'Jack Miller'!J6,NA()) -> 0.0010981134 | N4: =IF($A$12,'Diogo Moreira'!J6,NA()) -> 0.0011032407 | O4: =IF($A$13,'Iker Lecuona'!J6,NA()) -> 0.0011201505 | P4: =IF($A$14,'Fabio Quartararo'!J6,NA()) -> 0.0011240278 | Q4: =IF($A$15,'Enea Bastianini'!J6,NA()) -> 0.0011124653 | R4: =IF($A$16,'Alex Rins'!J6,NA()) -> 0.0011325 | S4: =IF($A$17,'Franco Morbidelli'!J6,NA()) -> 0.0011305903 | T4: =IF($A$18,'Augusto Fernandez'!J6,NA()) -> 0.0011300694 | U4: =IF($A$19,'Raul Fernandez'!J6,NA()) -> 0.0011124306 | V4: =IF($A$20,'Jorge Martin'!J6,NA()) -> 0.0010850347 | W4: =IF($A$21,'Maverick Viñales'!J6,NA()) -> 0.0011273264 | X4: =IF($A$22,'Johann Zarco'!J6,NA()) -> 0.001088831 | Y4: =IF($A$23,'Francesco Bagnaia'!J6,NA()) -> 0.0011192361
A5: TRUE | B5: Alex MARQUEZ | C5: #CD28E0 | E5: 2 | F5: =IF($A$4,'Marc Marquez'!J7,NA()) -> 0.0010229861 | G5: =IF($A$5,'Alex Marquez'!J7,NA()) -> 0.0010203241 | H5: =IF($A$6,'Fabio Di Giannantonio'!J7,NA()) -> 0.0010243287 | I5: =IF($A$7,'Marco Bezzecchi'!J7,NA()) -> 0.0010178704 | J5: =IF($A$8,'Pedro Acosta'!J7,NA()) -> 0.0010175231 | K5: =IF($A$9,'Ai Ogura'!J7,NA()) -> 0.0010295023 | L5: =IF($A$10,'Brad Binder'!J7,NA()) -> 0.0010215278 | M5: =IF($A$11,'Jack Miller'!J7,NA()) -> 0.0010236227 | N5: =IF($A$12,'Diogo Moreira'!J7,NA()) -> 0.0010246065 | O5: =IF($A$13,'Iker Lecuona'!J7,NA()) -> 0.0010292245 | P5: =IF($A$14,'Fabio Quartararo'!J7,NA()) -> 0.0010297685 | Q5: =IF($A$15,'Enea Bastianini'!J7,NA()) -> 0.0010417361 | R5: =IF($A$16,'Alex Rins'!J7,NA()) -> 0.0010416088 | S5: =IF($A$17,'Franco Morbidelli'!J7,NA()) -> 0.0010336111 | T5: =IF($A$18,'Augusto Fernandez'!J7,NA()) -> 0.0010491551 | U5: =IF($A$19,'Raul Fernandez'!J7,NA()) -> 0.001022338 | V5: =IF($A$20,'Jorge Martin'!J7,NA()) -> 0.0010251505 | W5: =IF($A$21,'Maverick Viñales'!J7,NA()) -> 0.0010315741 | X5: =IF($A$22,'Johann Zarco'!J7,NA()) -> 0.001021956 | Y5: =IF($A$23,'Francesco Bagnaia'!J7,NA()) -> 0.0011050463
A6: TRUE | B6: Fabio DI GIANNANTONIO | C6: #47E0A4 | E6: 3 | F6: =IF($A$4,'Marc Marquez'!J8,NA()) -> 0.0010258912 | G6: =IF($A$5,'Alex Marquez'!J8,NA()) -> 0.001028669 | H6: =IF($A$6,'Fabio Di Giannantonio'!J8,NA()) -> 0.0010186111 | I6: =IF($A$7,'Marco Bezzecchi'!J8,NA()) -> 0.0010217593 | J6: =IF($A$8,'Pedro Acosta'!J8,NA()) -> 0.0010269097 | K6: =IF($A$9,'Ai Ogura'!J8,NA()) -> 0.0010234722 | L6: =IF($A$10,'Brad Binder'!J8,NA()) -> 0.0010224306 | M6: =IF($A$11,'Jack Miller'!J8,NA()) -> 0.0010209722 | N6: =IF($A$12,'Diogo Moreira'!J8,NA()) -> 0.001024213 | O6: =IF($A$13,'Iker Lecuona'!J8,NA()) -> 0.0010228009 | P6: =IF($A$14,'Fabio Quartararo'!J8,NA()) -> 0.0010232986 | Q6: =IF($A$15,'Enea Bastianini'!J8,NA()) -> 0.0010256829 | R6: =IF($A$16,'Alex Rins'!J8,NA()) -> 0.0010280787 | S6: =IF($A$17,'Franco Morbidelli'!J8,NA()) -> 0.0010376157 | T6: =IF($A$18,'Augusto Fernandez'!J8,NA()) -> 0.0010433218 | U6: =IF($A$19,'Raul Fernandez'!J8,NA()) -> 0.0010220255 | V6: =IF($A$20,'Jorge Martin'!J8,NA()) -> 0.0010214815 | W6: =IF($A$21,'Maverick Viñales'!J8,NA()) -> 0.0010316435 | X6: =IF($A$22,'Johann Zarco'!J8,NA()) -> 0.0010293519 | Y6: =NA() -> #N/A
A7: TRUE | B7: Marco BEZZECCHI | C7: #B75021 | E7: 4 | F7: =IF($A$4,'Marc Marquez'!J9,NA()) -> 0.0010103009 | G7: =IF($A$5,'Alex Marquez'!J9,NA()) -> 0.0010206713 | H7: =IF($A$6,'Fabio Di Giannantonio'!J9,NA()) -> 0.0010186921 | I7: =IF($A$7,'Marco Bezzecchi'!J9,NA()) -> 0.0010214699 | J7: =IF($A$8,'Pedro Acosta'!J9,NA()) -> 0.0010209838 | K7: =IF($A$9,'Ai Ogura'!J9,NA()) -> 0.0010200347 | L7: =IF($A$10,'Brad Binder'!J9,NA()) -> 0.0010261227 | M7: =IF($A$11,'Jack Miller'!J9,NA()) -> 0.0010226157 | N7: =IF($A$12,'Diogo Moreira'!J9,NA()) -> 0.0010228009 | O7: =IF($A$13,'Iker Lecuona'!J9,NA()) -> 0.0010259028 | P7: =IF($A$14,'Fabio Quartararo'!J9,NA()) -> 0.0010234491 | Q7: =IF($A$15,'Enea Bastianini'!J9,NA()) -> 0.0010211921 | R7: =IF($A$16,'Alex Rins'!J9,NA()) -> 0.0010239236 | S7: =IF($A$17,'Franco Morbidelli'!J9,NA()) -> 0.0010340856 | T7: =IF($A$18,'Augusto Fernandez'!J9,NA()) -> 0.0010442477 | U7: =IF($A$19,'Raul Fernandez'!J9,NA()) -> 0.0010259259 | V7: =IF($A$20,'Jorge Martin'!J9,NA()) -> 0.0010095949 | W7: =IF($A$21,'Maverick Viñales'!J9,NA()) -> 0.0010319213 | X7: =NA() -> #N/A | Y7: =NA() -> #N/A
A8: TRUE | B8: Pedro ACOSTA | C8: #4B47E0 | E8: 5 | F8: =IF($A$4,'Marc Marquez'!J10,NA()) -> 0.0010162037 | G8: =IF($A$5,'Alex Marquez'!J10,NA()) -> 0.0010159375 | H8: =IF($A$6,'Fabio Di Giannantonio'!J10,NA()) -> 0.0010173727 | I8: =IF($A$7,'Marco Bezzecchi'!J10,NA()) -> 0.0010199884 | J8: =IF($A$8,'Pedro Acosta'!J10,NA()) -> 0.0010206944 | K8: =IF($A$9,'Ai Ogura'!J10,NA()) -> 0.0010187153 | L8: =IF($A$10,'Brad Binder'!J10,NA()) -> 0.0010260995 | M8: =IF($A$11,'Jack Miller'!J10,NA()) -> 0.0010284028 | N8: =IF($A$12,'Diogo Moreira'!J10,NA()) -> 0.0010268171 | O8: =IF($A$13,'Iker Lecuona'!J10,NA()) -> 0.0010220255 | P8: =IF($A$14,'Fabio Quartararo'!J10,NA()) -> 0.0010235532 | Q8: =IF($A$15,'Enea Bastianini'!J10,NA()) -> 0.0010233681 | R8: =IF($A$16,'Alex Rins'!J10,NA()) -> 0.0010253009 | S8: =IF($A$17,'Franco Morbidelli'!J10,NA()) -> 0.0010308102 | T8: =IF($A$18,'Augusto Fernandez'!J10,NA()) -> 0.001042963 | U8: =IF($A$19,'Raul Fernandez'!J10,NA()) -> 0.0010216782 | V8: =IF($A$20,'Jorge Martin'!J10,NA()) -> 0.0010191551 | W8: =IF($A$21,'Maverick Viñales'!J10,NA()) -> 0.0010282755 | X8: =NA() -> #N/A | Y8: =NA() -> #N/A
A9: TRUE | B9: Ai OGURA | C9: #5AE028 | E9: 6 | F9: =IF($A$4,'Marc Marquez'!J11,NA()) -> 0.0010187037 | G9: =IF($A$5,'Alex Marquez'!J11,NA()) -> 0.0010124769 | H9: =IF($A$6,'Fabio Di Giannantonio'!J11,NA()) -> 0.0010190394 | I9: =IF($A$7,'Marco Bezzecchi'!J11,NA()) -> 0.0010148611 | J9: =IF($A$8,'Pedro Acosta'!J11,NA()) -> 0.0010227662 | K9: =IF($A$9,'Ai Ogura'!J11,NA()) -> 0.0010303356 | L9: =IF($A$10,'Brad Binder'!J11,NA()) -> 0.0010195833 | M9: =IF($A$11,'Jack Miller'!J11,NA()) -> 0.0010235417 | N9: =IF($A$12,'Diogo Moreira'!J11,NA()) -> 0.0010363657 | O9: =IF($A$13,'Iker Lecuona'!J11,NA()) -> 0.0010194097 | P9: =IF($A$14,'Fabio Quartararo'!J11,NA()) -> 0.0010310069 | Q9: =IF($A$15,'Enea Bastianini'!J11,NA()) -> 0.0010300579 | R9: =IF($A$16,'Alex Rins'!J11,NA()) -> 0.0010242361 | S9: =IF($A$17,'Franco Morbidelli'!J11,NA()) -> 0.0010312269 | T9: =IF($A$18,'Augusto Fernandez'!J11,NA()) -> 0.0010464236 | U9: =IF($A$19,'Raul Fernandez'!J11,NA()) -> 0.0010320139 | V9: =IF($A$20,'Jorge Martin'!J11,NA()) -> 0.0010189236 | W9: =IF($A$21,'Maverick Viñales'!J11,NA()) -> 0.0010329745 | X9: =NA() -> #N/A | Y9: =NA() -> #N/A
