Workbook

Sheet Marco Bezzecchi
A1: Marco BEZZECCHI #72 - Position 1
A3: Team | B3: Aprilia Racing | C3: Manufacturer | D3: APRILIA | E3: Total Laps | F3: 27 | G3: Valid Laps | H3: 26
A5: Lap | B5: Lap Time | C5: Lap Seconds | D5: T1 | E5: T2 | F5: T3 | G5: T4 | H5: Speed km/h | I5: Cumulative Seconds | J5: Excel Time
A6: 1 | B6: 1:34.554 | C6: 94.554 | D6: 29.024 | E6: 18.764 | F6: 19.477 | G6: 27.289 | H6: 252.9 | I6: 94.554 | J6: 0.001094375
A7: 2 | B7: 1:30.770 | C7: 90.77 | D7: 25.377 | E7: 18.654 | F7: 19.571 | G7: 27.168 | H7: 312.1 | I7: 185.324 | J7: 0.0010505787
A8: 3 | B8: 1:30.402 | C8: 90.402 | D8: 25.313 | E8: 18.579 | F8: 19.264 | G8: 27.246 | H8: 310.3 | I8: 275.726 | J8: 0.0010463194
A9: 4 | B9: 1:30.367 | C9: 90.367 | D9: 25.191 | E9: 18.654 | F9: 19.313 | G9: 27.209 | H9: 313.9 | I9: 366.093 | J9: 0.0010459144
A10: 5 | B10: 1:30.087 | C10: 90.087 | D10: 25.146 | E10: 18.546 | F10: 19.201 | G10: 27.194 | H10: 314.8 | I10: 456.18 | J10: 0.0010426736
A11: 6 | B11: 1:30.380 | C11: 90.38 | D11: 25.246 | E11: 18.635 | F11: 19.241 | G11: 27.258 | H11: 311.2 | I11: 546.56 | J11: 0.0010460648
A12: 7 | B12: 1:30.190 | C12: 90.19 | D12: 25.088 | E12: 18.509 | F12: 19.321 | G12: 27.272 | H12: 313.9 | I12: 636.75 | J12: 0.0010438657
A13: 8 | B13: 1:30.132 | C13: 90.132 | D13: 25.142 | E13: 18.612 | F13: 19.287 | G13: 27.091 | H13: 314.8 | I13: 726.882 | J13: 0.0010431944
A14: 9 | B14: 1:30.192 | C14: 90.192 | D14: 25.109 | E14: 18.621 | F14: 19.259 | G14: 27.203 | H14: 313.9 | I14: 817.074 | J14: 0.0010438889
A15: 10 | B15: 1:30.310 | C15: 90.31 | D15: 25.221 | E15: 18.594 | F15: 19.232 | G15: 27.263 | H15: 310.3 | I15: 907.384 | J15: 0.0010452546
A16: 11 | B16: 1:29.991 | C16: 89.991 | D16: 25.035 | E16: 18.595 | F16: 19.178 | G16: 27.183 | H16: 313.9 | I16: 997.375 | J16: 0.0010415625
A17: 12 | B17: 1:30.110 | C17: 90.11 | D17: 25.092 | E17: 18.565 | F17: 19.281 | G17: 27.172 | H17: 312.1 | I17: 1087.485 | J17: 0.0010429398
... A32: 27 | B32: 1:31.494 | C32: 91.494 | D32: 25.319 | E32: 18.838 | F32: 19.54 | G32: 27.797 | H32: 313 | I32: 2446.582 | J32: 0.0010589583

Sheet Raul Fernandez
A1: Raul FERNANDEZ #25 - Position 2
A3: Team | B3: SuperFile Trackhouse MotoGP Team | C3: Manufacturer | D3: APRILIA | E3: Total Laps | F3: 27 | G3: Valid Laps | H3: 26
A5: Lap | B5: Lap Time | C5: Lap Seconds | D5: T1 | E5: T2 | F5: T3 | G5: T4 | H5: Speed km/h | I5: Cumulative Seconds | J5: Excel Time
A6: 1 | B6: 1:34.004 | C6: 94.004 | D6: 28.682 | E6: 18.654 | F6: 19.393 | G6: 27.275 | H6: 252.3 | I6: 94.004 | J6: 0.0010880093
A7: 2 | B7: 1:30.421 | C7: 90.421 | D7: 25.259 | E7: 18.545 | F7: 19.328 | G7: 27.289 | H7: 306.8 | I7: 184.425 | J7: 0.0010465394
A8: 3 | B8: 1:30.586 | C8: 90.586 | D8: 25.284 | E8: 18.685 | F8: 19.204 | G8: 27.413 | H8: 308.5 | I8: 275.011 | J8: 0.0010484491
A9: 4 | B9: 1:30.335 | C9: 90.335 | D9: 25.2 | E9: 18.574 | F9: 19.275 | G9: 27.286 | H9: 308.5 | I9: 365.346 | J9: 0.001045544
A10: 5 | B10: 1:30.027 | C10: 90.027 | D10: 25.132 | E10: 18.545 | F10: 19.218 | G10: 27.132 | H10: 307.6 | I10: 455.373 | J10: 0.0010419792
A11: 6 | B11: 1:30.355 | C11: 90.355 | D11: 25.223 | E11: 18.62 | F11: 19.285 | G11: 27.227 | H11: 306.8 | I11: 545.728 | J11: 0.0010457755
A12: 7 | B12: 1:30.548 | C12: 90.548 | D12: 25.32 | E12: 18.589 | F12: 19.32 | G12: 27.319 | H12: 307.6 | I12: 636.276 | J12: 0.0010480093
A13: 8 | B13: 1:30.071 | C13: 90.071 | D13: 25.189 | E13: 18.528 | F13: 19.203 | G13: 27.151 | H13: 308.5 | I13: 726.347 | J13: 0.0010424884
A14: 9 | B14: 1:30.274 | C14: 90.274 | D14: 25.264 | E14: 18.545 | F14: 19.234 | G14: 27.231 | H14: 307.6 | I14: 816.621 | J14: 0.001044838
A15: 10 | B15: 1:30.242 | C15: 90.242 | D15: 25.154 | E15: 18.525 | F15: 19.266 | G15: 27.297 | H15: 306.8 | I15: 906.863 | J15: 0.0010444676
A16: 11 | B16: 1:30.075 | C16: 90.075 | D16: 25.051 | E16: 18.637 | F16: 19.186 | G16: 27.201 | H16: 308.5 | I16: 996.938 | J16: 0.0010425347
A17: 12 | B17: 1:30.088 | C17: 90.088 | D17: 25.167 | E17: 18.522 | F17: 19.184 | G17: 27.215 | H17: 307.6 | I17: 1087.026 | J17: 0.0010426852
... A32: 27 | B32: 1:32.424 | C32: 92.424 | D32: 25.477 | E32: 18.993 | F32: 19.551 | G32: 28.403 | H32: 307.6 | I32: 2450.842 | J32: 0.0010697222

Sheet Jorge Martin
A1: Jorge MARTIN #89 - Position 3
A3: Team | B3: Aprilia Racing | C3: Manufacturer | D3: APRILIA | E3: Total Laps | F3: 27 | G3: Valid Laps | H3: 26
A5: Lap | B5: Lap Time | C5: Lap Seconds | D5: T1 | E5: T2 | F5: T3 | G5: T4 | H5: Speed km/h | I5: Cumulative Seconds | J5: Excel Time
A6: 1 | B6: 1:35.908 | C6: 95.908 | D6: 29.637 | E6: 19.113 | F6: 19.518 | G6: 27.64 | H6: 261.5 | I6: 95.908 | J6: 0.0011100463
A7: 2 | B7: 1:30.973 | C7: 90.973 | D7: 25.647 | E7: 18.571 | F7: 19.391 | G7: 27.364 | H7: 294.2 | I7: 186.881 | J7: 0.0010529282
A8: 3 | B8: 1:30.372 | C8: 90.372 | D8: 25.195 | E8: 18.472 | F8: 19.413 | G8: 27.292 | H8: 313.9 | I8: 277.253 | J8: 0.0010459722
A9: 4 | B9: 1:30.436 | C9: 90.436 | D9: 25.183 | E9: 18.696 | F9: 19.294 | G9: 27.263 | H9: 313.9 | I9: 367.689 | J9: 0.001046713
A10: 5 | B10: 1:30.275 | C10: 90.275 | D10: 25.271 | E10: 18.52 | F10: 19.252 | G10: 27.232 | H10: 313.9 | I10: 457.964 | J10: 0.0010448495
A11: 6 | B11: 1:30.144 | C11: 90.144 | D11: 25.097 | E11: 18.453 | F11: 19.383 | G11: 27.211 | H11: 313 | I11: 548.108 | J11: 0.0010433333
A12: 7 | B12: 1:30.231 | C12: 90.231 | D12: 25.061 | E12: 18.485 | F12: 19.273 | G12: 27.412 | H12: 314.8 | I12: 638.339 | J12: 0.0010443403
A13: 8 | B13: 1:30.458 | C13: 90.458 | D13: 25.208 | E13: 18.579 | F13: 19.3 | G13: 27.371 | H13: 313 | I13: 728.797 | J13: 0.0010469676
A14: 9 | B14: 1:30.323 | C14: 90.323 | D14: 25.217 | E14: 18.493 | F14: 19.385 | G14: 27.228 | H14: 312.1 | I14: 819.12 | J14: 0.0010454051
A15: 10 | B15: 1:30.212 | C15: 90.212 | D15: 25.139 | E15: 18.523 | F15: 19.24 | G15: 27.31 | H15: 313.9 | I15: 909.332 | J15: 0.0010441204
A16: 11 | B16: 1:30.308 | C16: 90.308 | D16: 25.136 | E16: 18.521 | F16: 19.297 | G16: 27.354 | H16: 313.9 | I16: 999.64 | J16: 0.0010452315
A17: 12 | B17: 1:30.347 | C17: 90.347 | D17: 25.157 | E17: 18.555 | F17: 19.302 | G17: 27.333 | H17: 312.1 | I17: 1089.987 | J17: 0.0010456829
... A32: 27 | B32: 1:32.963 | C32: 92.963 | D32: 25.566 | E32: 19.132 | F32: 19.738 | G32: 28.527 | H32: 314.8 | I32: 2453.472 | J32: 0.0010759606

Sheet Ai Ogura
A1: Ai OGURA #79 - Position 4
A3: Team | B3: SuperFile Trackhouse MotoGP Team | C3: Manufacturer | D3: APRILIA | E3: Total Laps | F3: 27 | G3: Valid Laps | H3: 26
A5: Lap | B5: Lap Time | C5: Lap Seconds | D5: T1 | E5: T2 | F5: T3 | G5: T4 | H5: Speed km/h | I5: Cumulative Seconds | J5: Excel Time
A6: 1 | B6: 1:36.868 | C6: 96.868 | D6: 29.964 | E6: 19.069 | F6: 19.757 | G6: 28.078 | H6: 262.7 | I6: 96.868 | J6: 0.0011211574
A7: 2 | B7: 1:31.326 | C7: 91.326 | D7: 25.573 | E7: 18.686 | F7: 19.56 | G7: 27.507 | H7: 302.5 | I7: 188.194 | J7: 0.0010570139
A8: 3 | B8: 1:30.956 | C8: 90.956 | D8: 25.441 | E8: 18.684 | F8: 19.409 | G8: 27.422 | H8: 310.3 | I8: 279.15 | J8: 0.0010527315
A9: 4 | B9: 1:30.659 | C9: 90.659 | D9: 25.324 | E9: 18.555 | F9: 19.358 | G9: 27.422 | H9: 306.8 | I9: 369.809 | J9: 0.001049294
A10: 5 | B10: 1:30.694 | C10: 90.694 | D10: 25.307 | E10: 18.656 | F10: 19.382 | G10: 27.349 | H10: 310.3 | I10: 460.503 | J10: 0.0010496991
A11: 6 | B11: 1:30.428 | C11: 90.428 | D11: 25.328 | E11: 18.562 | F11: 19.332 | G11: 27.206 | H11: 311.2 | I11: 550.931 | J11: 0.0010466204
A12: 7 | B12: 1:30.464 | C12: 90.464 | D12: 25.21 | E12: 18.549 | F12: 19.392 | G12: 27.313 | H12: 313.9 | I12: 641.395 | J12: 0.001047037
A13: 8 | B13: 1:30.301 | C13: 90.301 | D13: 25.234 | E13: 18.545 | F13: 19.322 | G13: 27.2 | H13: 313 | I13: 731.696 | J13: 0.0010451505
A14: 9 | B14: 1:30.737 | C14: 90.737 | D14: 25.298 | E14: 18.532 | F14: 19.589 | G14: 27.318 | H14: 311.2 | I14: 822.433 | J14: 0.0010501968
A15: 10 | B15: 1:30.457 | C15: 90.457 | D15: 25.285 | E15: 18.486 | F15: 19.34 | G15: 27.346 | H15: 313.9 | I15: 912.89 | J15: 0.001046956
A16: 11 | B16: 1:30.477 | C16: 90.477 | D16: 25.173 | E16: 18.545 | F16: 19.427 | G16: 27.332 | H16: 313 | I16: 1003.367 | J16: 0.0010471875
A17: 12 | B17: 1:30.343 | C17: 90.343 | D17: 25.256 | E17: 18.464 | F17: 19.308 | G17: 27.315 | H17: 313 | I17: 1093.71 | J17: 0.0010456366
... A32: 27 | B32: 1:30.816 | C32: 90.816 | D32: 25.251 | E32: 18.647 | F32: 19.455 | G32: 27.463 | H32: 314.8 | I32: 2455.96 | J32: 0.0010511111

Sheet Pedro Acosta
A1: Pedro ACOSTA #37 - Position 5
A3: Team | B3: Red Bull KTM Factory Racing | C3: Manufacturer | D3: KTM | E3: Total Laps | F3: 27 | G3: Valid Laps | H3: 26
A5: Lap | B5: Lap Time | C5: Lap Seconds | D5: T1 | E5: T2 | F5: T3 | G5: T4 | H5: Speed km/h | I5: Cumulative Seconds | J5: Excel Time
A6: 1 | B6: 1:36.690 | C6: 96.69 | D6: 30.242 | E6: 19.202 | F6: 19.608 | G6: 27.638 | H6: 266.6 | I6: 96.69 | J6: 0.0011190972
A7: 2 | B7: 1:30.768 | C7: 90.768 | D7: 25.348 | E7: 18.783 | F7: 19.435 | G7: 27.202 | H7: 306.8 | I7: 187.458 | J7: 0.0010505556
A8: 3 | B8: 1:30.546 | C8: 90.546 | D8: 25.298 | E8: 18.751 | F8: 19.276 | G8: 27.221 | H8: 311.2 | I8: 278.004 | J8: 0.0010479861
A9: 4 | B9: 1:30.254 | C9: 90.254 | D9: 25.126 | E9: 18.77 | F9: 19.204 | G9: 27.154 | H9: 314.8 | I9: 368.258 | J9: 0.0010446065
A10: 5 | B10: 1:30.372 | C10: 90.372 | D10: 25.151 | E10: 18.745 | F10: 19.273 | G10: 27.203 | H10: 307.6 | I10: 458.63 | J10: 0.0010459722
A11: 6 | B11: 1:30.256 | C11: 90.256 | D11: 25.198 | E11: 18.676 | F11: 19.19 | G11: 27.192 | H11: 311.2 | I11: 548.886 | J11: 0.0010446296
A12: 7 | B12: 1:30.572 | C12: 90.572 | D12: 25.105 | E12: 18.629 | F12: 19.636 | G12: 27.202 | H12: 311.2 | I12: 639.458 | J12: 0.001048287
A13: 8 | B13: 1:30.545 | C13: 90.545 | D13: 25.096 | E13: 18.9 | F13: 19.334 | G13: 27.215 | H13: 314.8 | I13: 730.003 | J13: 0.0010479745
A14: 9 | B14: 1:30.363 | C14: 90.363 | D14: 25.114 | E14: 18.777 | F14: 19.253 | G14: 27.219 | H14: 315.7 | I14: 820.366 | J14: 0.0010458681
A15: 10 | B15: 1:30.285 | C15: 90.285 | D15: 25.078 | E15: 18.76 | F15: 19.222 | G15: 27.225 | H15: 313 | I15: 910.651 | J15: 0.0010449653
A16: 11 | B16: 1:30.331 | C16: 90.331 | D16: 25.096 | E16: 18.935 | F16: 19.23 | G16: 27.07 | H16: 315.7 | I16: 1000.982 | J16: 0.0010454977
A17: 12 | B17: 1:30.172 | C17: 90.172 | D17: 24.944 | E17: 18.801 | F17: 19.205 | G17: 27.222 | H17: 314.8 | I17: 1091.154 | J17: 0.0010436574
... A32: 27 | B32: 1:30.623 | C32: 90.623 | D32: 25.085 | E32: 18.799 | F32: 19.343 | G32: 27.396 | H32: 314.8 | I32: 2456.074 | J32: 0.0010488773

Sheet Marc Marquez
A1: Marc MARQUEZ #93 - Position 6
A3: Team | B3: Ducati Lenovo Team | C3: Manufacturer | D3: DUCATI | E3: Total Laps | F3: 27 | G3: Valid Laps | H3: 26
A5: Lap | B5: Lap Time | C5: Lap Seconds | D5: T1 | E5: T2 | F5: T3 | G5: T4 | H5: Speed km/h | I5: Cumulative Seconds | J5: Excel Time
A6: 1 | B6: 1:35.148 | C6: 95.148 | D6: 29.179 | E6: 19.066 | F6: 19.543 | G6: 27.36 | H6: 263.4 | I6: 95.148 | J6: 0.00110125
A7: 2 | B7: 1:31.124 | C7: 91.124 | D7: 25.341 | E7: 18.951 | F7: 19.416 | G7: 27.416 | H7: 313 | I7: 186.272 | J7: 0.0010546759
A8: 3 | B8: 1:31.264 | C8: 91.264 | D8: 25.34 | E8: 18.899 | F8: 19.636 | G8: 27.389 | H8: 313 | I8: 277.536 | J8: 0.0010562963
A9: 4 | B9: 1:30.541 | C9: 90.541 | D9: 25.209 | E9: 18.785 | F9: 19.299 | G9: 27.248 | H9: 310.3 | I9: 368.077 | J9: 0.0010479282
A10: 5 | B10: 1:30.405 | C10: 90.405 | D10: 25.15 | E10: 18.716 | F10: 19.231 | G10: 27.308 | H10: 313.9 | I10: 458.482 | J10: 0.0010463542
A11: 6 | B11: 1:30.229 | C11: 90.229 | D11: 25.084 | E11: 18.713 | F11: 19.183 | G11: 27.249 | H11: 314.8 | I11: 548.711 | J11: 0.0010443171
A12: 7 | B12: 1:31.097 | C12: 91.097 | D12: 25.109 | E12: 18.754 | F12: 19.822 | G12: 27.412 | H12: 315.7 | I12: 639.808 | J12: 0.0010543634
A13: 8 | B13: 1:30.480 | C13: 90.48 | D13: 25.232 | E13: 18.704 | F13: 19.323 | G13: 27.221 | H13: 313 | I13: 730.288 | J13: 0.0010472222
A14: 9 | B14: 1:30.370 | C14: 90.37 | D14: 25.16 | E14: 18.717 | F14: 19.339 | G14: 27.154 | H14: 313.9 | I14: 820.658 | J14: 0.0010459491
A15: 10 | B15: 1:30.390 | C15: 90.39 | D15: 25.07 | E15: 18.731 | F15: 19.279 | G15: 27.31 | H15: 312.1 | I15: 911.048 | J15: 0.0010461806
A16: 11 | B16: 1:30.371 | C16: 90.371 | D16: 25.136 | E16: 18.74 | F16: 19.303 | G16: 27.192 | H16: 313 | I16: 1001.419 | J16: 0.0010459606
A17: 12 | B17: 1:30.398 | C17: 90.398 | D17: 25.138 | E17: 18.723 | F17: 19.256 | G17: 27.281 | H17: 313.9 | I17: 1091.817 | J17: 0.0010462731
... A32: 27 | B32: 1:31.533 | C32: 91.533 | D32: 25.28 | E32: 18.897 | F32: 19.534 | G32: 27.822 | H32: 308.5 | I32: 2457.36 | J32: 0.0010594097

Sheet Alex Marquez
A1: Alex MARQUEZ #73 - Position 7
A3: Team | B3: BK8 Gresini Racing MotoGP | C3: Manufacturer | D3: DUCATI | E3: Total Laps | F3: 27 | G3: Valid Laps | H3: 25
A5: Lap | B5: Lap Time | C5: Lap Seconds | D5: T1 | E5: T2 | F5: T3 | G5: T4 | H5: Speed km/h | I5: Cumulative Seconds | J5: Excel Time
A6: 1 | B6: 1:36.434 | C6: 96.434 | D6: 30.046 | E6: 19.129 | F6: 19.608 | G6: 27.651 | H6: 265.3 | I6: 96.434 | J6: 0.0011161343
A7: 2 | B7: 1:31.404 | C7: 91.404 | D7: 25.443 | E7: 18.903 | F7: 19.656 | G7: 27.402 | H7: 309.4 | I7: 187.838 | J7: 0.0010579167
A8: 3 | B8: 1:30.876 | C8: 90.876 | D8: 25.297 | E8: 18.819 | F8: 19.333 | G8: 27.427 | H8: 312.1 | I8: 278.714 | J8: 0.0010518056
A9: 4 | B9: 1:30.597 | C9: 90.597 | D9: 25.277 | E9: 18.773 | F9: 19.28 | G9: 27.267 | H9: 311.2 | I9: 369.311 | J9: 0.0010485764
A10: 5 | B10: 1:30.514 | C10: 90.514 | D10: 25.171 | E10: 18.792 | F10: 19.219 | G10: 27.332 | H10: 313.9 | I10: 459.825 | J10: 0.0010476157
A11: 6 | B11: 1:30.314 | C11: 90.314 | D11: 25.212 | E11: 18.596 | F11: 19.185 | G11: 27.321 | H11: 312.1 | I11: 550.139 | J11: 0.0010453009
A12: 7 | B12: 1:30.670 | C12: 90.67 | D12: 25.24 | E12: 18.681 | F12: 19.346 | G12: 27.403 | H12: 305.9 | I12: 640.809 | J12: 0.0010494213
A13: 8 | B13: 1:30.639 | C13: 90.639 | D13: 25.326 | E13: 18.654 | F13: 19.257 | G13: 27.402 | H13: 311.2 | I13: 731.448 | J13: 0.0010490625
A14: 9 | B14: 1:30.586 | C14: 90.586 | D14: 25.246 | E14: 18.701 | F14: 19.341 | G14: 27.298 | H14: 316.7 | I14: 822.034 | J14: 0.0010484491
A15: 10 | B15: 1:30.285 | C15: 90.285 | D15: 25.118 | E15: 18.543 | F15: 19.22 | G15: 27.404 | H15: 312.1 | I15: 912.319 | J15: 0.0010449653
A16: 11 | B16: 1:30.756 | C16: 90.756 | D16: 25.145 | E16: 18.739 | F16: 19.355 | G16: 27.517 | H16: 313.9 | I16: 1003.075 | J16: 0.0010504167
A17: 12 | B17: 1:30.452 | C17: 90.452 | D17: 25.103 | E17: 18.637 | F17: 19.322 | G17: 27.39 | H17: 314.8 | I17: 1093.527 | J17: 0.0010468981
... A32: 27 | B32: 1:32.291 | C32: 92.291 | D32: 25.556 | E32: 19.118 | F32: 19.63 | G32: 27.987 | H32: 315.7 | I32: 2463.403 | J32: 0.0010681829

Sheet Fabio Di Giannantonio
A1: Fabio DI GIANNANTONIO #49 - Position 8
A3: Team | B3: Pertamina Enduro VR46 Racing Team | C3: Manufacturer | D3: DUCATI | E3: Total Laps | F3: 27 | G3: Valid Laps | H3: 25
A5: Lap | B5: Lap Time | C5: Lap Seconds | D5: T1 | E5: T2 | F5: T3 | G5: T4 | H5: Speed km/h | I5: Cumulative Seconds | J5: Excel Time
A6: 1 | B6: 1:35.782 | C6: 95.782 | D6: 29.336 | E6: 19.083 | F6: 19.557 | G6: 27.806 | H6: 251.7 | I6: 95.782 | J6: 0.001108588
A7: 2 | B7: 1:31.491 | C7: 91.491 | D7: 25.895 | E7: 18.775 | F7: 19.44 | G7: 27.381 | H7: 297.5 | I7: 187.273 | J7: 0.0010589236
A8: 3 | B8: 1:30.893 | C8: 90.893 | D8: 25.3 | E8: 18.64 | F8: 19.448 | G8: 27.505 | H8: 307.6 | I8: 278.166 | J8: 0.0010520023
A9: 4 | B9: 1:30.631 | C9: 90.631 | D9: 25.298 | E9: 18.692 | F9: 19.351 | G9: 27.29 | H9: 305.9 | I9: 368.797 | J9: 0.0010489699
A10: 5 | B10: 1:30.473 | C10: 90.473 | D10: 25.248 | E10: 18.676 | F10: 19.313 | G10: 27.236 | H10: 310.3 | I10: 459.27 | J10: 0.0010471412
A11: 6 | B11: 1:30.404 | C11: 90.404 | D11: 25.228 | E11: 18.61 | F11: 19.274 | G11: 27.292 | H11: 310.3 | I11: 549.674 | J11: 0.0010463426
A12: 7 | B12: 1:30.390 | C12: 90.39 | D12: 25.162 | E12: 18.518 | F12: 19.337 | G12: 27.373 | H12: 313 | I12: 640.064 | J12: 0.0010461806
A13: 8 | B13: 1:30.664 | C13: 90.664 | D13: 25.317 | E13: 18.647 | F13: 19.377 | G13: 27.323 | H13: 300.8 | I13: 730.728 | J13: 0.0010493519
A14: 9 | B14: 1:30.555 | C14: 90.555 | D14: 25.242 | E14: 18.725 | F14: 19.319 | G14: 27.269 | H14: 309.4 | I14: 821.283 | J14: 0.0010480903
A15: 10 | B15: 1:30.461 | C15: 90.461 | D15: 25.165 | E15: 18.699 | F15: 19.342 | G15: 27.255 | H15: 313 | I15: 911.744 | J15: 0.0010470023
A16: 11 | B16: 1:30.256 | C16: 90.256 | D16: 25.105 | E16: 18.653 | F16: 19.258 | G16: 27.24 | H16: 312.1 | I16: 1002 | J16: 0.0010446296
A17: 12 | B17: 1:30.244 | C17: 90.244 | D17: 25.145 | E17: 18.631 | F17: 19.264 | G17: 27.204 | H17: 310.3 | I17: 1092.244 | J17: 0.0010444907
... A32: 27 | B32: 1:31.987 | C32: 91.987 | D32: 25.703 | E32: 19.024 | F32: 19.623 | G32: 27.637 | H32: 308.5 | I32: 2466.422 | J32: 0.0010646644

Sheet Fabio Quartararo
A1: Fabio QUARTARARO #20 - Position 9
A3: Team | B3: Monster Energy Yamaha MotoGP Team | C3: Manufacturer | D3: YAMAHA | E3: Total Laps | F3: 27 | G3: Valid Laps | H3: 24
A5: Lap | B5: Lap Time | C5: Lap Seconds | D5: T1 | E5: T2 | F5: T3 | G5: T4 | H5: Speed km/h | I5: Cumulative Seconds | J5: Excel Time
A6: 1 | B6: 1:37.410 | C6: 97.41 | D6: 30.489 | E6: 19.347 | F6: 19.798 | G6: 27.776 | H6: 265.3 | I6: 97.41 | J6: 0.0011274306
A7: 2 | B7: 1:32.006 | C7: 92.006 | D7: 25.745 | E7: 19.073 | F7: 19.617 | G7: 27.571 | H7: 300.8 | I7: 189.416 | J7: 0.0010648843
A8: 3 | B8: 1:31.362 | C8: 91.362 | D8: 25.456 | E8: 18.844 | F8: 19.476 | G8: 27.586 | H8: 305.9 | I8: 280.778 | J8: 0.0010574306
A9: 4 | B9: 1:31.300 | C9: 91.3 | D9: 25.361 | E9: 18.856 | F9: 19.518 | G9: 27.565 | H9: 307.6 | I9: 372.078 | J9: 0.001056713
A10: 5 | B10: 1:31.213 | C10: 91.213 | D10: 25.385 | E10: 18.91 | F10: 19.463 | G10: 27.455 | H10: 306.8 | I10: 463.291 | J10: 0.001055706
A11: 6 | B11: 1:31.144 | C11: 91.144 | D11: 25.442 | E11: 18.949 | F11: 19.414 | G11: 27.339 | H11: 307.6 | I11: 554.435 | J11: 0.0010549074
A12: 7 | B12: 1:31.030 | C12: 91.03 | D12: 25.308 | E12: 18.845 | F12: 19.365 | G12: 27.512 | H12: 309.4 | I12: 645.465 | J12: 0.001053588
A13: 8 | B13: 1:31.001 | C13: 91.001 | D13: 25.357 | E13: 18.963 | F13: 19.339 | G13: 27.342 | H13: 307.6 | I13: 736.466 | J13: 0.0010532523
A14: 9 | B14: 1:30.950 | C14: 90.95 | D14: 25.293 | E14: 18.85 | F14: 19.396 | G14: 27.411 | H14: 307.6 | I14: 827.416 | J14: 0.001052662
A15: 10 | B15: 1:30.802 | C15: 90.802 | D15: 25.268 | E15: 18.85 | F15: 19.312 | G15: 27.372 | H15: 307.6 | I15: 918.218 | J15: 0.0010509491
A16: 11 | B16: 1:30.822 | C16: 90.822 | D16: 25.244 | E16: 18.875 | F16: 19.394 | G16: 27.309 | H16: 310.3 | I16: 1009.04 | J16: 0.0010511806
A17: 12 | B17: 1:30.999 | C17: 90.999 | D17: 25.352 | E17: 18.9 | F17: 19.391 | G17: 27.356 | H17: 308.5 | I17: 1100.039 | J17: 0.0010532292
... A32: 27 | B32: 1:31.418 | C32: 91.418 | D32: 25.306 | E32: 18.982 | F32: 19.569 | G32: 27.561 | H32: 311.2 | I32: 2466.581 | J32: 0.0010580787

Sheet Enea Bastianini
A1: Enea BASTIANINI #23 - Position 10
A3: Team | B3: Red Bull KTM Tech3 | C3: Manufacturer | D3: KTM | E3: Total Laps | F3: 27 | G3: Valid Laps | H3: 26
A5: Lap | B5: Lap Time | C5: Lap Seconds | D5: T1 | E5: T2 | F5: T3 | G5: T4 | H5: Speed km/h | I5: Cumulative Seconds | J5: Excel Time
A6: 1 | B6: 1:37.771 | C6: 97.771 | D6: 30.713 | E6: 19.42 | F6: 19.749 | G6: 27.889 | H6: 269.3 | I6: 97.771 | J6: 0.0011316088
A7: 2 | B7: 1:32.141 | C7: 92.141 | D7: 25.633 | E7: 19.083 | F7: 19.63 | G7: 27.795 | H7: 301.6 | I7: 189.912 | J7: 0.0010664468
A8: 3 | B8: 1:31.679 | C8: 91.679 | D8: 25.495 | E8: 18.973 | F8: 19.54 | G8: 27.671 | H8: 300.8 | I8: 281.591 | J8: 0.0010610995
A9: 4 | B9: 1:31.131 | C9: 91.131 | D9: 25.275 | E9: 18.892 | F9: 19.414 | G9: 27.55 | H9: 313 | I9: 372.722 | J9: 0.0010547569
A10: 5 | B10: 1:31.089 | C10: 91.089 | D10: 25.378 | E10: 18.872 | F10: 19.414 | G10: 27.425 | H10: 312.1 | I10: 463.811 | J10: 0.0010542708
A11: 6 | B11: 1:31.265 | C11: 91.265 | D11: 25.394 | E11: 18.863 | F11: 19.489 | G11: 27.519 | H11: 312.1 | I11: 555.076 | J11: 0.0010563079
A12: 7 | B12: 1:31.127 | C12: 91.127 | D12: 25.28 | E12: 18.74 | F12: 19.395 | G12: 27.712 | H12: 306.8 | I12: 646.203 | J12: 0.0010547106
A13: 8 | B13: 1:30.958 | C13: 90.958 | D13: 25.234 | E13: 18.847 | F13: 19.417 | G13: 27.46 | H13: 313 | I13: 737.161 | J13: 0.0010527546
A14: 9 | B14: 1:31.198 | C14: 91.198 | D14: 25.252 | E14: 18.894 | F14: 19.504 | G14: 27.548 | H14: 308.5 | I14: 828.359 | J14: 0.0010555324
A15: 10 | B15: 1:31.153 | C15: 91.153 | D15: 25.242 | E15: 18.941 | F15: 19.432 | G15: 27.538 | H15: 313 | I15: 919.512 | J15: 0.0010550116
A16: 11 | B16: 1:32.083 | C16: 92.083 | D16: 25.129 | E16: 20.009 | F16: 19.431 | G16: 27.514 | H16: 314.8 | I16: 1011.595 | J16: 0.0010657755
A17: 12 | B17: 1:31.210 | C17: 91.21 | D17: 25.43 | E17: 18.973 | F17: 19.379 | G17: 27.428 | H17: 309.4 | I17: 1102.805 | J17: 0.0010556713
... A32: 27 | B32: 1:31.151 | C32: 91.151 | D32: 25.203 | E32: 18.913 | F32: 19.487 | G32: 27.548 | H32: 314.8 | I32: 2467.693 | J32: 0.0010549884

Sheet Brad Binder
A1: Brad BINDER #33 - Position 11
A3: Team | B3: Red Bull KTM Factory Racing | C3: Manufacturer | D3: KTM | E3: Total Laps | F3: 27 | G3: Valid Laps | H3: 26
A5: Lap | B5: Lap Time | C5: Lap Seconds | D5: T1 | E5: T2 | F5: T3 | G5: T4 | H5: Speed km/h | I5: Cumulative Seconds | J5: Excel Time
A6: 1 | B6: 1:37.605 | C6: 97.605 | D6: 30.589 | E6: 19.419 | F6: 19.747 | G6: 27.85 | H6: 270.6 | I6: 97.605 | J6: 0.0011296875
A7: 2 | B7: 1:31.996 | C7: 91.996 | D7: 25.641 | E7: 19.113 | F7: 19.651 | G7: 27.591 | H7: 300 | I7: 189.601 | J7: 0.0010647685
A8: 3 | B8: 1:31.349 | C8: 91.349 | D8: 25.444 | E8: 18.879 | F8: 19.461 | G8: 27.565 | H8: 300 | I8: 280.95 | J8: 0.0010572801
A9: 4 | B9: 1:31.286 | C9: 91.286 | D9: 25.401 | E9: 18.827 | F9: 19.449 | G9: 27.609 | H9: 304.2 | I9: 372.236 | J9: 0.0010565509
A10: 5 | B10: 1:31.207 | C10: 91.207 | D10: 25.38 | E10: 18.871 | F10: 19.442 | G10: 27.514 | H10: 304.2 | I10: 463.443 | J10: 0.0010556366
A11: 6 | B11: 1:31.444 | C11: 91.444 | D11: 25.469 | E11: 18.797 | F11: 19.702 | G11: 27.476 | H11: 313 | I11: 554.887 | J11: 0.0010583796
A12: 7 | B12: 1:30.955 | C12: 90.955 | D12: 25.276 | E12: 18.757 | F12: 19.372 | G12: 27.55 | H12: 311.2 | I12: 645.842 | J12: 0.0010527199
A13: 8 | B13: 1:31.050 | C13: 91.05 | D13: 25.327 | E13: 18.747 | F13: 19.473 | G13: 27.503 | H13: 312.1 | I13: 736.892 | J13: 0.0010538194
A14: 9 | B14: 1:30.916 | C14: 90.916 | D14: 25.286 | E14: 18.846 | F14: 19.281 | G14: 27.503 | H14: 312.1 | I14: 827.808 | J14: 0.0010522685
A15: 10 | B15: 1:30.836 | C15: 90.836 | D15: 25.275 | E15: 18.773 | F15: 19.353 | G15: 27.435 | H15: 313 | I15: 918.644 | J15: 0.0010513426
A16: 11 | B16: 1:30.768 | C16: 90.768 | D16: 25.225 | E16: 18.871 | F16: 19.325 | G16: 27.347 | H16: 314.8 | I16: 1009.412 | J16: 0.0010505556
A17: 12 | B17: 1:31.058 | C17: 91.058 | D17: 25.264 | E17: 18.987 | F17: 19.386 | G17: 27.421 | H17: 314.8 | I17: 1100.47 | J17: 0.001053912
... A32: 27 | B32: 1:31.421 | C32: 91.421 | D32: 25.245 | E32: 18.851 | F32: 19.515 | G32: 27.81 | H32: 315.7 | I32: 2468.494 | J32: 0.0010581134

Sheet Luca Marini
A1: Luca MARINI #10 - Position 12
A3: Team | B3: Honda HRC Castrol | C3: Manufacturer | D3: HONDA | E3: Total Laps | F3: 27 | G3: Valid Laps | H3: 25
A5: Lap | B5: Lap Time | C5: Lap Seconds | D5: T1 | E5: T2 | F5: T3 | G5: T4 | H5: Speed km/h | I5: Cumulative Seconds | J5: Excel Time
A6: 1 | B6: 1:37.028 | C6: 97.028 | D6: 30.177 | E6: 19.193 | F6: 19.834 | G6: 27.824 | H6: 275.5 | I6: 97.028 | J6: 0.0011230093
A7: 2 | B7: 1:31.595 | C7: 91.595 | D7: 25.552 | E7: 18.88 | F7: 19.532 | G7: 27.631 | H7: 300.8 | I7: 188.623 | J7: 0.0010601273
A8: 3 | B8: 1:31.170 | C8: 91.17 | D8: 25.329 | E8: 18.764 | F8: 19.418 | G8: 27.659 | H8: 311.2 | I8: 279.793 | J8: 0.0010552083
A9: 4 | B9: 1:31.266 | C9: 91.266 | D9: 25.418 | E9: 18.845 | F9: 19.419 | G9: 27.584 | H9: 308.5 | I9: 371.059 | J9: 0.0010563194
A10: 5 | B10: 1:30.914 | C10: 90.914 | D10: 25.232 | E10: 18.718 | F10: 19.49 | G10: 27.474 | H10: 313 | I10: 461.973 | J10: 0.0010522454
A11: 6 | B11: 1:30.947 | C11: 90.947 | D11: 25.266 | E11: 18.712 | F11: 19.4 | G11: 27.569 | H11: 314.8 | I11: 552.92 | J11: 0.0010526273
A12: 7 | B12: 1:31.051 | C12: 91.051 | D12: 25.194 | E12: 18.713 | F12: 19.466 | G12: 27.678 | H12: 315.7 | I12: 643.971 | J12: 0.001053831
A13: 8 | B13: 1:30.987 | C13: 90.987 | D13: 25.218 | E13: 18.836 | F13: 19.404 | G13: 27.529 | H13: 313.9 | I13: 734.958 | J13: 0.0010530903
A14: 9 | B14: 1:31.178 | C14: 91.178 | D14: 25.244 | E14: 18.766 | F14: 19.515 | G14: 27.653 | H14: 313.9 | I14: 826.136 | J14: 0.0010553009
A15: 10 | B15: 1:31.140 | C15: 91.14 | D15: 25.288 | E15: 18.745 | F15: 19.467 | G15: 27.64 | H15: 313 | I15: 917.276 | J15: 0.0010548611
A16: 11 | B16: 1:31.070 | C16: 91.07 | D16: 25.261 | E16: 18.796 | F16: 19.46 | G16: 27.553 | H16: 313 | I16: 1008.346 | J16: 0.0010540509
A17: 12 | B17: 1:31.190 | C17: 91.19 | D17: 25.331 | E17: 18.719 | F17: 19.534 | G17: 27.606 | H17: 313.9 | I17: 1099.536 | J17: 0.0010554398
... A32: 27 | B32: 1:31.586 | C32: 91.586 | D32: 25.331 | E32: 18.894 | F32: 19.534 | G32: 27.827 | H32: 313.9 | I32: 2469.238 | J32: 0.0010600231

Sheet Johann Zarco
A1: Johann ZARCO #5 - Position 13
A3: Team | B3: Castrol Honda LCR | C3: Manufacturer | D3: HONDA | E3: Total Laps | F3: 27 | G3: Valid Laps | H3: 25
A5: Lap | B5: Lap Time | C5: Lap Seconds | D5: T1 | E5: T2 | F5: T3 | G5: T4 | H5: Speed km/h | I5: Cumulative Seconds | J5: Excel Time
A6: 1 | B6: 1:37.852 | C6: 97.852 | D6: 30.862 | E6: 19.511 | F6: 19.814 | G6: 27.665 | H6: 270 | I6: 97.852 | J6: 0.0011325463
A7: 2 | B7: 1:32.326 | C7: 92.326 | D7: 25.697 | E7: 19.06 | F7: 19.799 | G7: 27.77 | H7: 299.1 | I7: 190.178 | J7: 0.001068588
A8: 3 | B8: 1:31.689 | C8: 91.689 | D8: 25.671 | E8: 18.908 | F8: 19.49 | G8: 27.62 | H8: 292.6 | I8: 281.867 | J8: 0.0010612153
A9: 4 | B9: 1:31.375 | C9: 91.375 | D9: 25.52 | E9: 18.986 | F9: 19.411 | G9: 27.458 | H9: 291.1 | I9: 373.242 | J9: 0.001057581
A10: 5 | B10: 1:31.059 | C10: 91.059 | D10: 25.354 | E10: 18.791 | F10: 19.382 | G10: 27.532 | H10: 307.6 | I10: 464.301 | J10: 0.0010539236
A11: 6 | B11: 1:31.123 | C11: 91.123 | D11: 25.448 | E11: 18.747 | F11: 19.469 | G11: 27.459 | H11: 308.5 | I11: 555.424 | J11: 0.0010546644
A12: 7 | B12: 1:31.403 | C12: 91.403 | D12: 25.357 | E12: 18.763 | F12: 19.361 | G12: 27.922 | H12: 300 | I12: 646.827 | J12: 0.0010579051
A13: 8 | B13: 1:31.127 | C13: 91.127 | D13: 25.339 | E13: 18.831 | F13: 19.377 | G13: 27.58 | H13: 311.2 | I13: 737.954 | J13: 0.0010547106
A14: 9 | B14: 1:30.988 | C14: 90.988 | D14: 25.459 | E14: 18.779 | F14: 19.348 | G14: 27.402 | H14: 310.3 | I14: 828.942 | J14: 0.0010531019
A15: 10 | B15: 1:31.078 | C15: 91.078 | D15: 25.411 | E15: 18.798 | F15: 19.443 | G15: 27.426 | H15: 301.6 | I15: 920.02 | J15: 0.0010541435
A16: 11 | B16: 1:30.974 | C16: 90.974 | D16: 25.361 | E16: 18.928 | F16: 19.348 | G16: 27.337 | H16: 300 | I16: 1010.994 | J16: 0.0010529398
A17: 12 | B17: 1:31.360 | C17: 91.36 | D17: 25.868 | E17: 18.803 | F17: 19.285 | G17: 27.404 | H17: 310.3 | I17: 1102.354 | J17: 0.0010574074
... A32: 27 | B32: 1:32.662 | C32: 92.662 | D32: 25.412 | E32: 19.212 | F32: 19.773 | G32: 28.265 | H32: 313 | I32: 2472.842 | J32: 0.0010724769

Sheet Franco Morbidelli
A1: Franco MORBIDELLI #21 - Position 14
A3: Team | B3: Pertamina Enduro VR46 Racing Team | C3: Manufacturer | D3: DUCATI | E3: Total Laps | F3: 27 | G3: Valid Laps | H3: 24
A5: Lap | B5: Lap Time | C5: Lap Seconds | D5: T1 | E5: T2 | F5: T3 | G5: T4 | H5: Speed km/h | I5: Cumulative Seconds | J5: Excel Time
A6: 1 | B6: 1:38.936 | C6: 98.936 | D6: 31.005 | E6: 19.756 | F6: 20.057 | G6: 28.118 | H6: 263.4 | I6: 98.936 | J6: 0.0011450926
A7: 2 | B7: 1:32.814 | C7: 92.814 | D7: 26.466 | E7: 19.104 | F7: 19.609 | G7: 27.635 | H7: 309.4 | I7: 191.75 | J7: 0.0010742361
A8: 3 | B8: 1:31.826 | C8: 91.826 | D8: 25.491 | E8: 19.029 | F8: 19.572 | G8: 27.734 | H8: 302.5 | I8: 283.576 | J8: 0.0010628009
A9: 4 | B9: 1:31.715 | C9: 91.715 | D9: 25.62 | E9: 19.084 | F9: 19.476 | G9: 27.535 | H9: 300.8 | I9: 375.291 | J9: 0.0010615162
A10: 5 | B10: 1:31.334 | C10: 91.334 | D10: 25.444 | E10: 18.857 | F10: 19.51 | G10: 27.523 | H10: 305.9 | I10: 466.625 | J10: 0.0010571065
A11: 6 | B11: 1:30.934 | C11: 90.934 | D11: 25.327 | E11: 18.795 | F11: 19.438 | G11: 27.374 | H11: 313.9 | I11: 557.559 | J11: 0.0010524769
A12: 7 | B12: 1:30.938 | C12: 90.938 | D12: 25.261 | E12: 18.742 | F12: 19.431 | G12: 27.504 | H12: 312.1 | I12: 648.497 | J12: 0.0010525231
A13: 8 | B13: 1:30.622 | C13: 90.622 | D13: 25.248 | E13: 18.693 | F13: 19.375 | G13: 27.306 | H13: 313 | I13: 739.119 | J13: 0.0010488657
A14: 9 | B14: 1:30.812 | C14: 90.812 | D14: 25.228 | E14: 18.765 | F14: 19.371 | G14: 27.448 | H14: 312.1 | I14: 829.931 | J14: 0.0010510648
A15: 10 | B15: 1:30.948 | C15: 90.948 | D15: 25.419 | E15: 18.723 | F15: 19.46 | G15: 27.346 | H15: 303.3 | I15: 920.879 | J15: 0.0010526389
A16: 11 | B16: 1:31.523 | C16: 91.523 | D16: 25.388 | E16: 18.966 | F16: 19.729 | G16: 27.44 | H16: 302.5 | I16: 1012.402 | J16: 0.001059294
A17: 12 | B17: 1:31.261 | C17: 91.261 | D17: 25.48 | E17: 18.942 | F17: 19.376 | G17: 27.463 | H17: 305.9 | I17: 1103.663 | J17: 0.0010562616
... A32: 27 | B32: 1:31.069 | C32: 91.069 | D32: 25.286 | E32: 18.905 | F32: 19.389 | G32: 27.489 | H32: 311.2 | I32: 2474.594 | J32: 0.0010540394

Sheet Alex Rins
A1: Alex RINS #42 - Position 15
A3: Team | B3: Monster Energy Yamaha MotoGP Team | C3: Manufacturer | D3: YAMAHA | E3: Total Laps | F3: 27 | G3: Valid Laps | H3: 26
A5: Lap | B5: Lap Time | C5: Lap Seconds | D5: T1 | E5: T2 | F5: T3 | G5: T4 | H5: Speed km/h | I5: Cumulative Seconds | J5: Excel Time
A6: 1 | B6: 1:38.110 | C6: 98.11 | D6: 30.803 | E6: 19.487 | F6: 19.799 | G6: 28.021 | H6: 268.6 | I6: 98.11 | J6: 0.0011355324
A7: 2 | B7: 1:31.983 | C7: 91.983 | D7: 25.644 | E7: 18.972 | F7: 19.544 | G7: 27.823 | H7: 304.2 | I7: 190.093 | J7: 0.0010646181
A8: 3 | B8: 1:31.677 | C8: 91.677 | D8: 25.592 | E8: 18.781 | F8: 19.557 | G8: 27.747 | H8: 303.3 | I8: 281.77 | J8: 0.0010610764
A9: 4 | B9: 1:31.151 | C9: 91.151 | D9: 25.462 | E9: 18.701 | F9: 19.481 | G9: 27.507 | H9: 305.9 | I9: 372.921 | J9: 0.0010549884
A10: 5 | B10: 1:31.141 | C10: 91.141 | D10: 25.458 | E10: 18.742 | F10: 19.505 | G10: 27.436 | H10: 301.6 | I10: 464.062 | J10: 0.0010548727
A11: 6 | B11: 1:31.190 | C11: 91.19 | D11: 25.467 | E11: 18.647 | F11: 19.624 | G11: 27.452 | H11: 307.6 | I11: 555.252 | J11: 0.0010554398
A12: 7 | B12: 1:31.149 | C12: 91.149 | D12: 25.386 | E12: 18.647 | F12: 19.442 | G12: 27.674 | H12: 306.8 | I12: 646.401 | J12: 0.0010549653
A13: 8 | B13: 1:31.299 | C13: 91.299 | D13: 25.598 | E13: 18.724 | F13: 19.385 | G13: 27.592 | H13: 303.3 | I13: 737.7 | J13: 0.0010567014
A14: 9 | B14: 1:30.963 | C14: 90.963 | D14: 25.446 | E14: 18.65 | F14: 19.427 | G14: 27.44 | H14: 305.9 | I14: 828.663 | J14: 0.0010528125
A15: 10 | B15: 1:31.228 | C15: 91.228 | D15: 25.506 | E15: 18.877 | F15: 19.424 | G15: 27.421 | H15: 305.9 | I15: 919.891 | J15: 0.0010558796
A16: 11 | B16: 1:30.954 | C16: 90.954 | D16: 25.324 | E16: 18.918 | F16: 19.365 | G16: 27.347 | H16: 307.6 | I16: 1010.845 | J16: 0.0010527083
A17: 12 | B17: 1:31.178 | C17: 91.178 | D17: 25.685 | E17: 18.749 | F17: 19.375 | G17: 27.369 | H17: 307.6 | I17: 1102.023 | J17: 0.0010553009
... A32: 27 | B32: 1:31.768 | C32: 91.768 | D32: 25.565 | E32: 18.894 | F32: 19.59 | G32: 27.719 | H32: 305.9 | I32: 2478.244 | J32: 0.0010621296

Sheet Diogo Moreira
A1: Diogo MOREIRA #11 - Position 16
A3: Team | B3: Pro Honda LCR | C3: Manufacturer | D3: HONDA | E3: Total Laps | F3: 27 | G3: Valid Laps | H3: 23
A5: Lap | B5: Lap Time | C5: Lap Seconds | D5: T1 | E5: T2 | F5: T3 | G5: T4 | H5: Speed km/h | I5: Cumulative Seconds | J5: Excel Time
A6: 1 | B6: 1:38.988 | C6: 98.988 | D6: 31.195 | E6: 19.725 | F6: 19.888 | G6: 28.18 | H6: 272.7 | I6: 98.988 | J6: 0.0011456944
A7: 2 | B7: 1:32.032 | C7: 92.032 | D7: 26.04 | E7: 19.002 | F7: 19.45 | G7: 27.54 | H7: 311.2 | I7: 191.02 | J7: 0.0010651852
A8: 3 | B8: 1:31.594 | C8: 91.594 | D8: 25.593 | E8: 19.052 | F8: 19.473 | G8: 27.476 | H8: 308.5 | I8: 282.614 | J8: 0.0010601157
A9: 4 | B9: 1:31.254 | C9: 91.254 | D9: 25.448 | E9: 18.989 | F9: 19.402 | G9: 27.415 | H9: 305 | I9: 373.868 | J9: 0.0010561806
A10: 5 | B10: 1:31.139 | C10: 91.139 | D10: 25.306 | E10: 19.109 | F10: 19.396 | G10: 27.328 | H10: 305.9 | I10: 465.007 | J10: 0.0010548495
A11: 6 | B11: 1:30.970 | C11: 90.97 | D11: 25.33 | E11: 18.944 | F11: 19.401 | G11: 27.295 | H11: 307.6 | I11: 555.977 | J11: 0.0010528935
A12: 7 | B12: 1:31.303 | C12: 91.303 | D12: 25.349 | E12: 18.81 | F12: 19.448 | G12: 27.696 | H12: 304.2 | I12: 647.28 | J12: 0.0010567477
A13: 8 | B13: 1:31.104 | C13: 91.104 | D13: 25.335 | E13: 18.877 | F13: 19.459 | G13: 27.433 | H13: 310.3 | I13: 738.384 | J13: 0.0010544444
A14: 9 | B14: 1:31.140 | C14: 91.14 | D14: 25.391 | E14: 18.882 | F14: 19.468 | G14: 27.399 | H14: 311.2 | I14: 829.524 | J14: 0.0010548611
A15: 10 | B15: 1:31.146 | C15: 91.146 | D15: 25.363 | E15: 18.945 | F15: 19.394 | G15: 27.444 | H15: 307.6 | I15: 920.67 | J15: 0.0010549306
A16: 11 | B16: 1:31.471 | C16: 91.471 | D16: 25.302 | E16: 19.251 | F16: 19.483 | G16: 27.435 | H16: 311.2 | I16: 1012.141 | J16: 0.0010586921
A17: 12 | B17: 1:31.118 | C17: 91.118 | D17: 25.331 | E17: 18.96 | F17: 19.422 | G17: 27.405 | H17: 308.5 | I17: 1103.259 | J17: 0.0010546065
... A32: 27 | B32: 1:32.895 | C32: 92.895 | D32: 25.626 | E32: 19.296 | F32: 19.667 | G32: 28.306 | H32: 309.4 | I32: 2480.75 | J32: 0.0010751736

Sheet Maverick Viñales
A1: Maverick VIÑALES #12 - Position 17
A3: Team | B3: Red Bull KTM Tech3 | C3: Manufacturer | D3: KTM | E3: Total Laps | F3: 27 | G3: Valid Laps | H3: 22
A5: Lap | B5: Lap Time | C5: Lap Seconds | D5: T1 | E5: T2 | F5: T3 | G5: T4 | H5: Speed km/h | I5: Cumulative Seconds | J5: Excel Time
A6: 1 | B6: 1:39.496 | C6: 99.496 | D6: 31.379 | E6: 19.873 | F6: 19.999 | G6: 28.245 | H6: 270.6 | I6: 99.496 | J6: 0.0011515741
A7: 2 | B7: 1:34.989 | C7: 94.989 | D7: 27.723 | E7: 19.577 | F7: 19.72 | G7: 27.969 | H7: 313 | I7: 194.485 | J7: 0.0010994097
A8: 3 | B8: 1:32.570 | C8: 92.57 | D8: 25.777 | E8: 19.115 | F8: 19.716 | G8: 27.962 | H8: 308.5 | I8: 287.055 | J8: 0.001071412
A9: 4 | B9: 1:32.162 | C9: 92.162 | D9: 25.574 | E9: 19.2 | F9: 19.593 | G9: 27.795 | H9: 311.2 | I9: 379.217 | J9: 0.0010666898
A10: 5 | B10: 1:32.270 | C10: 92.27 | D10: 25.431 | E10: 19.369 | F10: 19.659 | G10: 27.811 | H10: 311.2 | I10: 471.487 | J10: 0.0010679398
A11: 6 | B11: 1:32.617 | C11: 92.617 | D11: 25.795 | E11: 19.26 | F11: 19.545 | G11: 28.017 | H11: 310.3 | I11: 564.104 | J11: 0.001071956
A12: 7 | B12: 1:32.616 | C12: 92.616 | D12: 25.951 | E12: 19.121 | F12: 19.735 | G12: 27.809 | H12: 311.2 | I12: 656.72 | J12: 0.0010719444
A13: 8 | B13: 1:31.905 | C13: 91.905 | D13: 25.462 | E13: 19.084 | F13: 19.482 | G13: 27.877 | H13: 310.3 | I13: 748.625 | J13: 0.0010637153
A14: 9 | B14: 1:32.086 | C14: 92.086 | D14: 25.461 | E14: 18.989 | F14: 19.833 | G14: 27.803 | H14: 310.3 | I14: 840.711 | J14: 0.0010658102
A15: 10 | B15: 1:31.660 | C15: 91.66 | D15: 25.423 | E15: 18.989 | F15: 19.568 | G15: 27.68 | H15: 309.4 | I15: 932.371 | J15: 0.0010608796
A16: 11 | B16: 1:31.754 | C16: 91.754 | D16: 25.404 | E16: 19.043 | F16: 19.592 | G16: 27.715 | H16: 311.2 | I16: 1024.125 | J16: 0.0010619676
A17: 12 | B17: 1:31.690 | C17: 91.69 | D17: 25.37 | E17: 18.932 | F17: 19.599 | G17: 27.789 | H17: 310.3 | I17: 1115.815 | J17: 0.0010612269
... A32: 27 | B32: 1:37.633 | C32: 97.633 | D32: 26.516 | E32: 20.217 | F32: 20.81 | G32: 30.09 | H32: 308.5 | I32: 2502.178 | J32: 0.0011300116

Sheet Toprak Razgatlioglu
A1: Toprak RAZGATLIOGLU #7 - Position 18
A3: Team | B3: Prima Pramac Yamaha MotoGP | C3: Manufacturer | D3: YAMAHA | E3: Total Laps | F3: 8 | G3: Valid Laps | H3: 5
A5: Lap | B5: Lap Time | C5: Lap Seconds | D5: T1 | E5: T2 | F5: T3 | G5: T4 | H5: Speed km/h | I5: Cumulative Seconds | J5: Excel Time
A6: 1 | B6: 1:38.990 | C6: 98.99 | D6: 31.274 | E6: 19.732 | F6: 20.034 | G6: 27.95 | H6: 269.3 | I6: 98.99 | J6: 0.0011457176
A7: 2 | B7: 1:32.334 | C7: 92.334 | D7: 25.911 | E7: 19.163 | F7: 19.677 | G7: 27.583 | H7: 298.3 | I7: 191.324 | J7: 0.0010686806
A8: 3 | B8: 1:32.082 | C8: 92.082 | D8: 25.575 | E8: 19.062 | F8: 19.535 | G8: 27.91 | H8: 305 | I8: 283.406 | J8: 0.0010657639
A9: 4 | B9: 1:31.586 | C9: 91.586 | D9: 25.578 | E9: 18.983 | F9: 19.463 | G9: 27.562 | H9: 309.4 | I9: 374.992 | J9: 0.0010600231
A10: 5 | B10: 1:32.053 | C10: 92.053 | D10: 25.432 | E10: 19.088 | F10: 19.897 | G10: 27.636 | H10: 309.4 | I10: 467.045 | J10: 0.0010654282
A11: 6 | B11: 1:31.879 | C11: 91.879 | D11: 25.586 | E11: 19.018 | F11: 19.567 | G11: 27.708 | H11: 306.8 | I11: 558.924 | J11: 0.0010634144
A12: 7 | B12: 1:32.021 | C12: 92.021 | D12: 25.587 | E12: 18.96 | F12: 19.588 | G12: 27.886 | H12: 305.9 | I12: 650.945 | J12: 0.0010650579
A13: 8 | B13: 1:34.761 | C13: 94.761 | D13: 25.649 | E13: 19.231 | F13: 20.207 | G13: 29.674 | H13: 305.9 | I13: 745.706 | J13: 0.0010967708

Sheet Francesco Bagnaia
A1: Francesco BAGNAIA #63 - Position 19
A3: Team | B3: Ducati Lenovo Team | C3: Manufacturer | D3: DUCATI | E3: Total Laps | F3: 5 | G3: Valid Laps | H3: 4
A5: Lap | B5: Lap Time | C5: Lap Seconds | D5: T1 | E5: T2 | F5: T3 | G5: T4 | H5: Speed km/h | I5: Cumulative Seconds | J5: Excel Time
A6: 1 | B6: 1:37.315 | C6: 97.315 | D6: 30.359 | E6: 19.373 | F6: 19.776 | G6: 27.807 | H6: 270.6 | I6: 97.315 | J6: 0.001126331
A7: 2 | B7: 1:31.946 | C7: 91.946 | D7: 25.724 | E7: 19.097 | F7: 19.509 | G7: 27.616 | H7: 300 | I7: 189.261 | J7: 0.0010641898
A8: 3 | B8: 1:31.338 | C8: 91.338 | D8: 25.377 | E8: 18.801 | F8: 19.53 | G8: 27.63 | H8: 312.1 | I8: 280.599 | J8: 0.0010571528
A9: 4 | B9: 1:31.277 | C9: 91.277 | D9: 25.283 | E9: 18.933 | F9: 19.498 | G9: 27.563 | H9: 316.7 | I9: 371.876 | J9: 0.0010564468
A10: 5 | B10: 1:31.072 | C10: 91.072 | D10: 25.194 | E10: 18.818 | F10: 19.431 | G10: 27.629 | H10: 316.7 | I10: 462.948 | J10: 0.0010540741

Sheet Jack Miller
A1: Jack MILLER #43 - Position 20
A3: Team | B3: Prima Pramac Yamaha MotoGP | C3: Manufacturer | D3: YAMAHA | E3: Total Laps | F3: 5 | G3: Valid Laps | H3: 4
A5: Lap | B5: Lap Time | C5: Lap Seconds | D5: T1 | E5: T2 | F5: T3 | G5: T4 | H5: Speed km/h | I5: Cumulative Seconds | J5: Excel Time
A6: 1 | B6: 1:38.195 | C6: 98.195 | D6: 31.115 | E6: 19.549 | F6: 19.746 | G6: 27.785 | H6: 266.6 | I6: 98.195 | J6: 0.0011365162
A7: 2 | B7: 1:32.129 | C7: 92.129 | D7: 25.806 | E7: 19.052 | F7: 19.593 | G7: 27.678 | H7: 300 | I7: 190.324 | J7: 0.0010663079
A8: 3 | B8: 1:31.824 | C8: 91.824 | D8: 25.737 | E8: 18.989 | F8: 19.476 | G8: 27.622 | H8: 291.1 | I8: 282.148 | J8: 0.0010627778
A9: 4 | B9: 1:31.398 | C9: 91.398 | D9: 25.539 | E9: 18.863 | F9: 19.537 | G9: 27.459 | H9: 301.6 | I9: 373.546 | J9: 0.0010578472
A10: 5 | B10: 1:32.043 | C10: 92.043 | D10: 25.407 | E10: 19.641 | F10: 19.487 | G10: 27.508 | H10: 307.6 | I10: 465.589 | J10: 0.0010653125

Sheet Fermin Aldeguer
A1: Fermin ALDEGUER #54 - Position 21
A3: Team | B3: BK8 Gresini Racing MotoGP | C3: Manufacturer | D3: DUCATI | E3: Total Laps | F3: 1 | G3: Valid Laps | H3: 0
A5: Lap | B5: Lap Time | C5: Lap Seconds | D5: T1 | E5: T2 | F5: T3 | G5: T4 | H5: Speed km/h | I5: Cumulative Seconds | J5: Excel Time
A6: 1 | B6: 1:35.719 | C6: 95.719 | D6: 29.51 | E6: 19.081 | F6: 19.581 | G6: 27.547 | H6: 262.7 | I6: 95.719 | J6: 0.0011078588

Sheet Race Data
A1: Rider | B1: Number | C1: Position | D1: Lap | E1: Lap Time | F1: Lap Seconds | G1: T1 | H1: T2 | I1: T3 | J1: T4 | K1: Speed km/h | L1: Cumulative Seconds | M1: Cancelled | N1: Pit Lane
A2: Marco BEZZECCHI | B2: 72 | C2: 1 | D2: 1 | E2: 1:34.554 | F2: 94.554 | G2: 29.024 | H2: 18.764 | I2: 19.477 | J2: 27.289 | K2: 252.9 | L2: 94.554 | M2: FALSE | N2: FALSE
A3: Marco BEZZECCHI | B3: 72 | C3: 1 | D3: 2 | E3: 1:30.770 | F3: 90.77 | G3: 25.377 | H3: 18.654 | I3: 19.571 | J3: 27.168 | K3: 312.1 | L3: 185.324 | M3: FALSE | N3: FALSE
A4: Marco BEZZECCHI | B4: 72 | C4: 1 | D4: 3 | E4: 1:30.402 | F4: 90.402 | G4: 25.313 | H4: 18.579 | I4: 19.264 | J4: 27.246 | K4: 310.3 | L4: 275.726 | M4: FALSE | N4: FALSE
A5: Marco BEZZECCHI | B5: 72 | C5: 1 | D5: 4 | E5: 1:30.367 | F5: 90.367 | G5: 25.191 | H5: 18.654 | I5: 19.313 | J5: 27.209 | K5: 313.9 | L5: 366.093 | M5: FALSE | N5: FALSE
A6: Marco BEZZECCHI | B6: 72 | C6: 1 | D6: 5 | E6: 1:30.087 | F6: 90.087 | G6: 25.146 | H6: 18.546 | I6: 19.201 | J6: 27.194 | K6: 314.8 | L6: 456.18 | M6: FALSE | N6: FALSE
A7: Marco BEZZECCHI | B7: 72 | C7: 1 | D7: 6 | E7: 1:30.380 | F7: 90.38 | G7: 25.246 | H7: 18.635 | I7: 19.241 | J7: 27.258 | K7: 311.2 | L7: 546.56 | M7: FALSE | N7: FALSE
A8: Marco BEZZECCHI | B8: 72 | C8: 1 | D8: 7 | E8: 1:30.190 | F8: 90.19 | G8: 25.088 | H8: 18.509 | I8: 19.321 | J8: 27.272 | K8: 313.9 | L8: 636.75 | M8: FALSE | N8: FALSE
A9: Marco BEZZECCHI | B9: 72 | C9: 1 | D9: 8 | E9: 1:30.132 | F9: 90.132 | G9: 25.142 | H9: 18.612 | I9: 19.287 | J9: 27.091 | K9: 314.8 | L9: 726.882 | M9: FALSE | N9: FALSE
A10: Marco BEZZECCHI | B10: 72 | C10: 1 | D10: 9 | E10: 1:30.192 | F10: 90.192 | G10: 25.109 | H10: 18.621 | I10: 19.259 | J10: 27.203 | K10: 313.9 | L10: 817.074 | M10: FALSE | N10: FALSE
A11: Marco BEZZECCHI | B11: 72 | C11: 1 | D11: 10 | E11: 1:30.310 | F11: 90.31 | G11: 25.221 | H11: 18.594 | I11: 19.232 | J11: 27.263 | K11: 310.3 | L11: 907.384 | M11: FALSE | N11: FALSE
A12: Marco BEZZECCHI | B12: 72 | C12: 1 | D12: 11 | E12: 1:29.991 | F12: 89.991 | G12: 25.035 | H12: 18.595 | I12: 19.178 | J12: 27.183 | K12: 313.9 | L12: 997.375 | M12: FALSE | N12: FALSE
A13: Marco BEZZECCHI | B13: 72 | C13: 1 | D13: 12 | E13: 1:30.110 | F13: 90.11 | G13: 25.092 | H13: 18.565 | I13: 19.281 | J13: 27.172 | K13: 312.1 | L13: 1087.485 | M13: FALSE | N13: FALSE
... A479: Fermin ALDEGUER | B479: 54 | C479: 21 | D479: 1 | E479: 1:35.719 | F479: 95.719 | G479: 29.51 | H479: 19.081 | I479: 19.581 | J479: 27.547 | K479: 262.7 | L479: 95.719 | M479: FALSE | N479: FALSE

Sheet Race Progress
A1: MotoGP - Rider Lap Time Analysis
A3: Show | B3: Rider | C3: Color | E3: Lap | F3: Marco BEZZECCHI | G3: Raul FERNANDEZ | H3: Jorge MARTIN | I3: Ai OGURA | J3: Pedro ACOSTA | K3: Marc MARQUEZ | L3: Alex MARQUEZ | M3: Fabio DI GIANNANTONIO | N3: Fabio QUARTARARO | O3: Enea BASTIANINI | P3: Brad BINDER | Q3: Luca MARINI | R3: Johann ZARCO | S3: Franco MORBIDELLI | T3: Alex RINS | U3: Diogo MOREIRA | V3: Maverick VIÑALES | W3: Toprak RAZGATLIOGLU | X3: Francesco BAGNAIA | Y3: Jack MILLER | Z3: Fermin ALDEGUER
A4: TRUE | B4: Marco BEZZECCHI | C4: #0070C0 | E4: 1 | F4: =IF($A$4,'Marco Bezzecchi'!J6,NA()) -> 0.001094375 | G4: =IF($A$5,'Raul Fernandez'!J6,NA()) -> 0.0010880093 | H4: =IF($A$6,'Jorge Martin'!J6,NA()) -> 0.0011100463 | I4: =IF($A$7,'Ai Ogura'!J6,NA()) -> 0.0011211574 | J4: =IF($A$8,'Pedro Acosta'!J6,NA()) -> 0.0011190972 | K4: =IF($A$9,'Marc Marquez'!J6,NA()) -> 0.00110125 | L4: =IF($A$10,'Alex Marquez'!J6,NA()) -> 0.0011161343 | M4: =IF($A$11,'Fabio Di Giannantonio'!J6,NA()) -> 0.001108588 | N4: =IF($A$12,'Fabio Quartararo'!J6,NA()) -> 0.0011274306 | O4: =IF($A$13,'Enea Bastianini'!J6,NA()) -> 0.0011316088 | P4: =IF($A$14,'Brad Binder'!J6,NA()) -> 0.0011296875 | Q4: =IF($A$15,'Luca Marini'!J6,NA()) -> 0.0011230093 | R4: =IF($A$16,'Johann Zarco'!J6,NA()) -> 0.0011325463 | S4: =IF($A$17,'Franco Morbidelli'!J6,NA()) -> 0.0011450926 | T4: =IF($A$18,'Alex Rins'!J6,NA()) -> 0.0011355324 | U4: =IF($A$19,'Diogo Moreira'!J6,NA()) -> 0.0011456944 | V4: =IF($A$20,'Maverick Viñales'!J6,NA()) -> 0.0011515741 | W4: =IF($A$21,'Toprak Razgatlioglu'!J6,NA()) -> 0.0011457176 | X4: =IF($A$22,'Francesco Bagnaia'!J6,NA()) -> 0.001126331 | Y4: =IF($A$23,'Jack Miller'!J6,NA()) -> 0.0011365162 | Z4: =IF($A$24,'Fermin Aldeguer'!J6,NA()) -> 0.0011078588
A5: TRUE | B5: Raul FERNANDEZ | C5: #C00000 | E5: 2 | F5: =IF($A$4,'Marco Bezzecchi'!J7,NA()) -> 0.0010505787 | G5: =IF($A$5,'Raul Fernandez'!J7,NA()) -> 0.0010465394 | H5: =IF($A$6,'Jorge Martin'!J7,NA()) -> 0.0010529282 | I5: =IF($A$7,'Ai Ogura'!J7,NA()) -> 0.0010570139 | J5: =IF($A$8,'Pedro Acosta'!J7,NA()) -> 0.0010505556 | K5: =IF($A$9,'Marc Marquez'!J7,NA()) -> 0.0010546759 | L5: =IF($A$10,'Alex Marquez'!J7,NA()) -> 0.0010579167 | M5: =IF($A$11,'Fabio Di Giannantonio'!J7,NA()) -> 0.0010589236 | N5: =IF($A$12,'Fabio Quartararo'!J7,NA()) -> 0.0010648843 | O5: =IF($A$13,'Enea Bastianini'!J7,NA()) -> 0.0010664468 | P5: =IF($A$14,'Brad Binder'!J7,NA()) -> 0.0010647685 | Q5: =IF($A$15,'Luca Marini'!J7,NA()) -> 0.0010601273 | R5: =IF($A$16,'Johann Zarco'!J7,NA()) -> 0.001068588 | S5: =IF($A$17,'Franco Morbidelli'!J7,NA()) -> 0.0010742361 | T5: =IF($A$18,'Alex Rins'!J7,NA()) -> 0.0010646181 | U5: =IF($A$19,'Diogo Moreira'!J7,NA()) -> 0.0010651852 | V5: =IF($A$20,'Maverick Viñales'!J7,NA()) -> 0.0010994097 | W5: =IF($A$21,'Toprak Razgatlioglu'!J7,NA()) -> 0.0010686806 | X5: =IF($A$22,'Francesco Bagnaia'!J7,NA()) -> 0.0010641898 | Y5: =IF($A$23,'Jack Miller'!J7,NA()) -> 0.0010663079 | Z5: =NA() -> #N/A
A6: TRUE | B6: Jorge MARTIN | C6: #00A651 | E6: 3 | F6: =IF($A$4,'Marco Bezzecchi'!J8,NA()) -> 0.0010463194 | G6: =IF($A$5,'Raul Fernandez'!J8,NA()) -> 0.0010484491 | H6: =IF($A$6,'Jorge Martin'!J8,NA()) -> 0.0010459722 | I6: =IF($A$7,'Ai Ogura'!J8,NA()) -> 0.0010527315 | J6: =IF($A$8,'Pedro Acosta'!J8,NA()) -> 0.0010479861 | K6: =IF($A$9,'Marc Marquez'!J8,NA()) -> 0.0010562963 | L6: =IF($A$10,'Alex Marquez'!J8,NA()) -> 0.0010518056 | M6: =IF($A$11,'Fabio Di Giannantonio'!J8,NA()) -> 0.0010520023 | N6: =IF($A$12,'Fabio Quartararo'!J8,NA()) -> 0.0010574306 | O6: =IF($A$13,'Enea Bastianini'!J8,NA()) -> 0.0010610995 | P6: =IF($A$14,'Brad Binder'!J8,NA()) -> 0.0010572801 | Q6: =IF($A$15,'Luca Marini'!J8,NA()) -> 0.0010552083 | R6: =IF($A$16,'Johann Zarco'!J8,NA()) -> 0.0010612153 | S6: =IF($A$17,'Franco Morbidelli'!J8,NA()) -> 0.0010628009 | T6: =IF($A$18,'Alex Rins'!J8,NA()) -> 0.0010610764 | U6: =IF($A$19,'Diogo Moreira'!J8,NA()) -> 0.0010601157 | V6: =IF($A$20,'Maverick Viñales'!J8,NA()) -> 0.001071412 | W6: =IF($A$21,'Toprak Razgatlioglu'!J8,NA()) -> 0.0010657639 | X6: =IF($A$22,'Francesco Bagnaia'!J8,NA()) -> 0.0010571528 | Y6: =IF($A$23,'Jack Miller'!J8,NA()) -> 0.0010627778 | Z6: =NA() -> #N/A
A7: TRUE | B7: Ai OGURA | C7: #7030A0 | E7: 4 | F7: =IF($A$4,'Marco Bezzecchi'!J9,NA()) -> 0.0010459144 | G7: =IF($A$5,'Raul Fernandez'!J9,NA()) -> 0.001045544 | H7: =IF($A$6,'Jorge Martin'!J9,NA()) -> 0.001046713 | I7: =IF($A$7,'Ai Ogura'!J9,NA()) -> 0.001049294 | J7: =IF($A$8,'Pedro Acosta'!J9,NA()) -> 0.0010446065 | K7: =IF($A$9,'Marc Marquez'!J9,NA()) -> 0.0010479282 | L7: =IF($A$10,'Alex Marquez'!J9,NA()) -> 0.0010485764 | M7: =IF($A$11,'Fabio Di Giannantonio'!J9,NA()) -> 0.0010489699 | N7: =IF($A$12,'Fabio Quartararo'!J9,NA()) -> 0.001056713 | O7: =IF($A$13,'Enea Bastianini'!J9,NA()) -> 0.0010547569 | P7: =IF($A$14,'Brad Binder'!J9,NA()) -> 0.0010565509 | Q7: =IF($A$15,'Luca Marini'!J9,NA()) -> 0.0010563194 | R7: =IF($A$16,'Johann Zarco'!J9,NA()) -> 0.001057581 | S7: =IF($A$17,'Franco Morbidelli'!J9,NA()) -> 0.0010615162 | T7: =IF($A$18,'Alex Rins'!J9,NA()) -> 0.0010549884 | U7: =IF($A$19,'Diogo Moreira'!J9,NA()) -> 0.0010561806 | V7: =IF($A$20,'Maverick Viñales'!J9,NA()) -> 0.0010666898 | W7: =IF($A$21,'Toprak Razgatlioglu'!J9,NA()) -> 0.0010600231 | X7: =IF($A$22,'Francesco Bagnaia'!J9,NA()) -> 0.0010564468 | Y7: =IF($A$23,'Jack Miller'!J9,NA()) -> 0.0010578472 | Z7: =NA() -> #N/A
A8: TRUE | B8: Pedro ACOSTA | C8: #ED7D31 | E8: 5 | F8: =IF($A$4,'Marco Bezzecchi'!J10,NA()) -> 0.0010426736 | G8: =IF($A$5,'Raul Fernandez'!J10,NA()) -> 0.0010419792 | H8: =IF($A$6,'Jorge Martin'!J10,NA()) -> 0.0010448495 | I8: =IF($A$7,'Ai Ogura'!J10,NA()) -> 0.0010496991 | J8: =IF($A$8,'Pedro Acosta'!J10,NA()) -> 0.0010459722 | K8: =IF($A$9,'Marc Marquez'!J10,NA()) -> 0.0010463542 | L8: =IF($A$10,'Alex Marquez'!J10,NA()) -> 0.0010476157 | M8: =IF($A$11,'Fabio Di Giannantonio'!J10,NA()) -> 0.0010471412 | N8: =IF($A$12,'Fabio Quartararo'!J10,NA()) -> 0.001055706 | O8: =IF($A$13,'Enea Bastianini'!J10,NA()) -> 0.0010542708 | P8: =IF($A$14,'Brad Binder'!J10,NA()) -> 0.0010556366 | Q8: =IF($A$15,'Luca Marini'!J10,NA()) -> 0.0010522454 | R8: =IF($A$16,'Johann Zarco'!J10,NA()) -> 0.0010539236 | S8: =IF($A$17,'Franco Morbidelli'!J10,NA()) -> 0.0010571065 | T8: =IF($A$18,'Alex Rins'!J10,NA()) -> 0.0010548727 | U8: =IF($A$19,'Diogo Moreira'!J10,NA()) -> 0.0010548495 | V8: =IF($A$20,'Maverick Viñales'!J10,NA()) -> 0.0010679398 | W8: =IF($A$21,'Toprak Razgatlioglu'!J10,NA()) -> 0.0010654282 | X8: =IF($A$22,'Francesco Bagnaia'!J10,NA()) -> 0.0010540741 | Y8: =IF($A$23,'Jack Miller'!J10,NA()) -> 0.0010653125 | Z8: =NA() -> #N/A
A9: TRUE | B9: Marc MARQUEZ | C9: #5B9BD5 | E9: 6 | F9: =IF($A$4,'Marco Bezzecchi'!J11,NA()) -> 0.0010460648 | G9: =IF($A$5,'Raul Fernandez'!J11,NA()) -> 0.0010457755 | H9: =IF($A$6,'Jorge Martin'!J11,NA()) -> 0.0010433333 | I9: =IF($A$7,'Ai Ogura'!J11,NA()) -> 0.0010466204 | J9: =IF($A$8,'Pedro Acosta'!J11,NA()) -> 0.0010446296 | K9: =IF($A$9,'Marc Marquez'!J11,NA()) -> 0.0010443171 | L9: =IF($A$10,'Alex Marquez'!J11,NA()) -> 0.0010453009 | M9: =IF($A$11,'Fabio Di Giannantonio'!J11,NA()) -> 0.0010463426 | N9: =IF($A$12,'Fabio Quartararo'!J11,NA()) -> 0.0010549074 | O9: =IF($A$13,'Enea Bastianini'!J11,NA()) -> 0.0010563079 | P9: =IF($A$14,'Brad Binder'!J11,NA()) -> 0.0010583796 | Q9: =IF($A$15,'Luca Marini'!J11,NA()) -> 0.0010526273 | R9: =IF($A$16,'Johann Zarco'!J11,NA()) -> 0.0010546644 | S9: =IF($A$17,'Franco Morbidelli'!J11,NA()) -> 0.0010524769 | T9: =IF($A$18,'Alex Rins'!J11,NA()) -> 0.0010554398 | U9: =IF($A$19,'Diogo Moreira'!J11,NA()) -> 0.0010528935 | V9: =IF($A$20,'Maverick Viñales'!J11,NA()) -> 0.001071956 | W9: =IF($A$21,'Toprak Razgatlioglu'!J11,NA()) -> 0.0010634144 | X9: =NA() -> #N/A | Y9: =NA() -> #N/A | Z9: =NA() -> #N/A
A10: TRUE | B10: Alex MARQUEZ | C10: #A5A5A5 | E10: 7 | F10: =IF($A$4,'Marco Bezzecchi'!J12,NA()) -> 0.0010438657 | G10: =IF($A$5,'Raul Fernandez'!J12,NA()) -> 0.0010480093 | H10: =IF($A$6,'Jorge Martin'!J12,NA()) -> 0.0010443403 | I10: =IF($A$7,'Ai Ogura'!J12,NA()) -> 0.001047037 | J10: =IF($A$8,'Pedro Acosta'!J12,NA()) -> 0.001048287 | K10: =IF($A$9,'Marc Marquez'!J12,NA()) -> 0.0010543634 | L10: =IF($A$10,'Alex Marquez'!J12,NA()) -> 0.0010494213 | M10: =IF($A$11,'Fabio Di Giannantonio'!J12,NA()) -> 0.0010461806 | N10: =IF($A$12,'Fabio Quartararo'!J12,NA()) -> 0.001053588 | O10: =IF($A$13,'Enea Bastianini'!J12,NA()) -> 0.0010547106 | P10: =IF($A$14,'Brad Binder'!J12,NA()) -> 0.0010527199 | Q10: =IF($A$15,'Luca Marini'!J12,NA()) -> 0.001053831 | R10: =IF($A$16,'Johann Zarco'!J12,NA()) -> 0.0010579051 | S10: =IF($A$17,'Franco Morbidelli'!J12,NA()) -> 0.0010525231 | T10: =IF($A$18,'Alex Rins'!J12,NA()) -> 0.0010549653 | U10: =IF($A$19,'Diogo Moreira'!J12,NA()) -> 0.0010567477 | V10: =IF($A$20,'Maverick Viñales'!J12,NA()) -> 0.0010719444 | W10: =IF($A$21,'Toprak Razgatlioglu'!J12,NA()) -> 0.0010650579 | X10: =NA() -> #N/A | Y10: =NA() -> #N/A | Z10: =NA() -> #N/A
A11: TRUE | B11: Fabio DI GIANNANTONIO | C11: #FFC000 | E11: 8 | F11: =IF($A$4,'Marco Bezzecchi'!J13,NA()) -> 0.0010431944 | G11: =IF($A$5,'Raul Fernandez'!J13,NA()) -> 0.0010424884 | H11: =IF($A$6,'Jorge Martin'!J13,NA()) -> 0.0010469676 | I11: =IF($A$7,'Ai Ogura'!J13,NA()) -> 0.0010451505 | J11: =IF($A$8,'Pedro Acosta'!J13,NA()) -> 0.0010479745 | K11: =IF($A$9,'Marc Marquez'!J13,NA()) -> 0.0010472222 | L11: =IF($A$10,'Alex Marquez'!J13,NA()) -> 0.0010490625 | M11: =IF($A$11,'Fabio Di Giannantonio'!J13,NA()) -> 0.0010493519 | N11: =IF($A$12,'Fabio Quartararo'!J13,NA()) -> 0.0010532523 | O11: =IF($A$13,'Enea Bastianini'!J13,NA()) -> 0.0010527546 | P11: =IF($A$14,'Brad Binder'!J13,NA()) -> 0.0010538194 | Q11: =IF($A$15,'Luca Marini'!J13,NA()) -> 0.0010530903 | R11: =IF($A$16,'Johann Zarco'!J13,NA()) -> 0.0010547106 | S11: =IF($A$17,'Franco Morbidelli'!J13,NA()) -> 0.0010488657 | T11: =IF($A$18,'Alex Rins'!J13,NA()) -> 0.0010567014 | U11: =IF($A$19,'Diogo Moreira'!J13,NA()) -> 0.0010544444 | V11: =IF($A$20,'Maverick Viñales'!J13,NA()) -> 0.0010637153 | W11: =IF($A$21,'Toprak Razgatlioglu'!J13,NA()) -> 0.0010967708 | X11: =NA() -> #N/A | Y11: =NA() -> #N/A | Z11: =NA() -> #N/A
A12: TRUE | B12: Fabio QUARTARARO | C12: #4472C4 | E12: 9 | F12: =IF($A$4,'Marco Bezzecchi'!J14,NA()) -> 0.0010438889 | G12: =IF($A$5,'Raul Fernandez'!J14,NA()) -> 0.001044838 | H12: =IF($A$6,'Jorge Martin'!J14,NA()) -> 0.0010454051 | I12: =IF($A$7,'Ai Ogura'!J14,NA()) -> 0.0010501968 | J12: =IF($A$8,'Pedro Acosta'!J14,NA()) -> 0.0010458681 | K12: =IF($A$9,'Marc Marquez'!J14,NA()) -> 0.0010459491 | L12: =IF($A$10,'Alex Marquez'!J14,NA()) -> 0.0010484491 | M12: =IF($A$11,'Fabio Di Giannantonio'!J14,NA()) -> 0.0010480903 | N12: =IF($A$12,'Fabio Quartararo'!J14,NA()) -> 0.001052662 | O12: =IF($A$13,'Enea Bastianini'!J14,NA()) -> 0.0010555324 | P12: =IF($A$14,'Brad Binder'!J14,NA()) -> 0.0010522685 | Q12: =IF($A$15,'Luca Marini'!J14,NA()) -> 0.0010553009 | R12: =IF($A$16,'Johann Zarco'!J14,NA()) -> 0.0010531019 | S12: =IF($A$17,'Franco Morbidelli'!J14,NA()) -> 0.0010510648 | T12: =IF($A$18,'Alex Rins'!J14,NA()) -> 0.0010528125 | U12: =IF($A$19,'Diogo Moreira'!J14,NA()) -> 0.0010548611 | V12: =IF($A$20,'Maverick Viñales'!J14,NA()) -> 0.0010658102 | W12: =NA() -> #N/A | X12: =NA() -> #N/A | Y12: =NA() -> #N/A | Z12: =NA() -> #N/A
A13: TRUE | B13: Enea BASTIANINI | C13: #70AD47 | E13: 10 | F13: =IF($A$4,'Marco Bezzecchi'!J15,NA()) -> 0.0010452546 | G13: =IF($A$5,'Raul Fernandez'!J15,NA()) -> 0.0010444676 | H13: =IF($A$6,'Jorge Martin'!J15,NA()) -> 0.0010441204 | I13: =IF($A$7,'Ai Ogura'!J15,NA()) -> 0.001046956 | J13: =IF($A$8,'Pedro Acosta'!J15,NA()) -> 0.0010449653 | K13: =IF($A$9,'Marc Marquez'!J15,NA()) -> 0.0010461806 | L13: =IF($A$10,'Alex Marquez'!J15,NA()) -> 0.0010449653 | M13: =IF($A$11,'Fabio Di Giannantonio'!J15,NA()) -> 0.0010470023 | N13: =IF($A$12,'Fabio Quartararo'!J15,NA()) -> 0.0010509491 | O13: =IF($A$13,'Enea Bastianini'!J15,NA()) -> 0.0010550116 | P13: =IF($A$14,'Brad Binder'!J15,NA()) -> 0.0010513426 | Q13: =IF($A$15,'Luca Marini'!J15,NA()) -> 0.0010548611 | R13: =IF($A$16,'Johann Zarco'!J15,NA()) -> 0.0010541435 | S13: =IF($A$17,'Franco Morbidelli'!J15,NA()) -> 0.0010526389 | T13: =IF($A$18,'Alex Rins'!J15,NA()) -> 0.0010558796 | U13: =IF($A$19,'Diogo Moreira'!J15,NA()) -> 0.0010549306 | V13: =IF($A$20,'Maverick Viñales'!J15,NA()) -> 0.0010608796 | W13: =NA() -> #N/A | X13: =NA() -> #N/A | Y13: =NA() -> #N/A | Z13: =NA() -> #N/A
A14: TRUE | B14: Brad BINDER | C14: #264478 | E14: 11 | F14: =IF($A$4,'Marco Bezzecchi'!J16,NA()) -> 0.0010415625 | G14: =IF($A$5,'Raul Fernandez'!J16,NA()) -> 0.0010425347 | H14: =IF($A$6,'Jorge Martin'!J16,NA()) -> 0.0010452315 | I14: =IF($A$7,'Ai Ogura'!J16,NA()) -> 0.0010471875 | J14: =IF($A$8,'Pedro Acosta'!J16,NA()) -> 0.0010454977 | K14: =IF($A$9,'Marc Marquez'!J16,NA()) -> 0.0010459606 | L14: =IF($A$10,'Alex Marquez'!J16,NA()) -> 0.0010504167 | M14: =IF($A$11,'Fabio Di Giannantonio'!J16,NA()) -> 0.0010446296 | N14: =IF($A$12,'Fabio Quartararo'!J16,NA()) -> 0.0010511806 | O14: =IF($A$13,'Enea Bastianini'!J16,NA()) -> 0.0010657755 | P14: =IF($A$14,'Brad Binder'!J16,NA()) -> 0.0010505556 | Q14: =IF($A$15,'Luca Marini'!J16,NA()) -> 0.0010540509 | R14: =IF($A$16,'Johann Zarco'!J16,NA()) -> 0.0010529398 | S14: =IF($A$17,'Franco Morbidelli'!J16,NA()) -> 0.001059294 | T14: =IF($A$18,'Alex Rins'!J16,NA()) -> 0.0010527083 | U14: =IF($A$19,'Diogo Moreira'!J16,NA()) -> 0.0010586921 | V14: =IF($A$20,'Maverick Viñales'!J16,NA()) -> 0.0010619676 | W14: =NA() -> #N/A | X14: =NA() -> #N/A | Y14: =NA() -> #N/A | Z14: =NA() -> #N/A
A15: TRUE | B15: Luca MARINI | C15: #9E480E | E15: 12 | F15: =IF($A$4,'Marco Bezzecchi'!J17,NA()) -> 0.0010429398 | G15: =IF($A$5,'Raul Fernandez'!J17,NA()) -> 0.0010426852 | H15: =IF($A$6,'Jorge Martin'!J17,NA()) -> 0.0010456829 | I15: =IF($A$7,'Ai Ogura'!J17,NA()) -> 0.0010456366 | J15: =IF($A$8,'Pedro Acosta'!J17,NA()) -> 0.0010436574 | K15: =IF($A$9,'Marc Marquez'!J17,NA()) -> 0.0010462731 | L15: =IF($A$10,'Alex Marquez'!J17,NA()) -> 0.0010468981 | M15: =IF($A$11,'Fabio Di Giannantonio'!J17,NA()) -> 0.0010444907 | N15: =IF($A$12,'Fabio Quartararo'!J17,NA()) -> 0.0010532292 | O15: =IF($A$13,'Enea Bastianini'!J17,NA()) -> 0.0010556713 | P15: =IF($A$14,'Brad Binder'!J17,NA()) -> 0.001053912 | Q15: =IF($A$15,'Luca Marini'!J17,NA()) -> 0.0010554398 | R15: =IF($A$16,'Johann Zarco'!J17,NA()) -> 0.0010574074 | S15: =IF($A$17,'Franco Morbidelli'!J17,NA()) -> 0.0010562616 | T15: =IF($A$18,'Alex Rins'!J17,NA()) -> 0.0010553009 | U15: =IF($A$19,'Diogo Moreira'!J17,NA()) -> 0.0010546065 | V15: =IF($A$20,'Maverick Viñales'!J17,NA()) -> 0.0010612269 | W15: =NA() -> #N/A | X15: =NA() -> #N/A | Y15: =NA() -> #N/A | Z15: =NA() -> #N/A
A16: TRUE | B16: Johann ZARCO | C16: #636363 | E16: 13 | F16: =IF($A$4,'Marco Bezzecchi'!J18,NA()) -> 0.0010433796 | G16: =IF($A$5,'Raul Fernandez'!J18,NA()) -> 0.0010449421 | H16: =IF($A$6,'Jorge Martin'!J18,NA()) -> 0.0010450463 | I16: =IF($A$7,'Ai Ogura'!J18,NA()) -> 0.0010524884 | J16: =IF($A$8,'Pedro Acosta'!J18,NA()) -> 0.0010614583 | K16: =IF($A$9,'Marc Marquez'!J18,NA()) -> 0.0010515162 | L16: =IF($A$10,'Alex Marquez'!J18,NA()) -> 0.0010562847 | M16: =IF($A$11,'Fabio Di Giannantonio'!J18,NA()) -> 0.001061794 | N16: =IF($A$12,'Fabio Quartararo'!J18,NA()) -> 0.0010550926 | O16: =IF($A$13,'Enea Bastianini'!J18,NA()) -> 0.0010521759 | P16: =IF($A$14,'Brad Binder'!J18,NA()) -> 0.0010546991 | Q16: =IF($A$15,'Luca Marini'!J18,NA()) -> 0.0010537269 | R16: =IF($A$16,'Johann Zarco'!J18,NA()) -> 0.0010551505 | S16: =IF($A$17,'Franco Morbidelli'!J18,NA()) -> 0.001056713 | T16: =IF($A$18,'Alex Rins'!J18,NA()) -> 0.0010573727 | U16: =IF($A$19,'Diogo Moreira'!J18,NA()) -> 0.0010587616 | V16: =IF($A$20,'Maverick Viñales'!J18,NA()) -> 0.0010701273 | W16: =NA() -> #N/A | X16: =NA() -> #N/A | Y16: =NA() -> #N/A | Z16: =NA() -> #N/A
A17: TRUE | B17: Franco MORBIDELLI | C17: #997300 | E17: 14 | F17: =IF($A$4,'Marco Bezzecchi'!J19,NA()) -> 0.0010438194 | G17: =IF($A$5,'Raul Fernandez'!J19,NA()) -> 0.0010419444 | H17: =IF($A$6,'Jorge Martin'!J19,NA()) -> 0.0010447106 | I17: =IF($A$7,'Ai Ogura'!J19,NA()) -> 0.0010475116 | J17: =IF($A$8,'Pedro Acosta'!J19,NA()) -> 0.0010500347 | K17: =IF($A$9,'Marc Marquez'!J19,NA()) -> 0.0010512731 | L17: =IF($A$10,'Alex Marquez'!J19,NA()) -> 0.0010534375 | M17: =IF($A$11,'Fabio Di Giannantonio'!J19,NA()) -> 0.0010482176 | N17: =IF($A$12,'Fabio Quartararo'!J19,NA()) -> 0.0010520949 | O17: =IF($A$13,'Enea Bastianini'!J19,NA()) -> 0.0010578125 | P17: =IF($A$14,'Brad Binder'!J19,NA()) -> 0.0010548727 | Q17: =IF($A$15,'Luca Marini'!J19,NA()) -> 0.0010532986 | R17: =IF($A$16,'Johann Zarco'!J19,NA()) -> 0.0010631366 | S17: =IF($A$17,'Franco Morbidelli'!J19,NA()) -> 0.0010592708 | T17: =IF($A$18,'Alex Rins'!J19,NA()) -> 0.0010696412 | U17: =IF($A$19,'Diogo Moreira'!J19,NA()) -> 0.0010593171 | V17: =IF($A$20,'Maverick Viñales'!J19,NA()) -> 0.0010710301 | W17: =NA() -> #N/A | X17: =NA() -> #N/A | Y17: =NA() -> #N/A | Z17: =NA() -> #N/A
