Workbook

Sheet Marc Marquez
A1: 1. Marc MARQUEZ #93
A3: Team | B3: Ducati Lenovo Team | C3: Manufacturer | D3: DUCATI | E3: Nationality | F3: SPA | G3: Total Laps | H3: 21 | I3: Valid Laps | J3: 20 | K3: Front Tyre | L3: Slick-Medium | M3: Rear Tyre | N3: Slick-Medium
A5: Lap | B5: Lap Time | C5: Lap Seconds | D5: T1 | E5: T2 | F5: T3 | G5: T4 | H5: Speed km/h | I5: Cumulative Seconds | J5: Excel Time | K5: Cancelled | L5: Pit Lane | M5: Partial Timing
A6: 1 | B6: 1:59.409 | C6: 119.409 | D6: 39.947 | E6: 22.202 | F6: 27.272 | G6: 29.988 | H6: 242.1 | I6: 119.409 | J6: 0.0013820486 | K6: FALSE | L6: FALSE | M6: FALSE
A7: 2 | B7: 1:54.189 | C7: 114.189 | D7: 34.875 | E7: 22.09 | F7: 27.289 | G7: 29.935 | H7: 319.5 | I7: 233.598 | J7: 0.0013216319 | K7: FALSE | L7: FALSE | M7: FALSE
A8: 3 | B8: 1:53.613 | C8: 113.613 | D8: 34.751 | E8: 21.969 | F8: 27.19 | G8: 29.703 | H8: 320.4 | I8: 347.211 | J8: 0.0013149653 | K8: FALSE | L8: FALSE | M8: FALSE
A9: 4 | B9: 1:53.639 | C9: 113.639 | D9: 34.871 | E9: 21.861 | F9: 27.222 | G9: 29.685 | H9: 319.5 | I9: 460.85 | J9: 0.0013152662 | K9: FALSE | L9: FALSE | M9: FALSE
A10: 5 | B10: 1:53.907 | C10: 113.907 | D10: 34.878 | E10: 21.838 | F10: 27.313 | G10: 29.878 | H10: 319.5 | I10: 574.757 | J10: 0.0013183681 | K10: FALSE | L10: FALSE | M10: FALSE
A11: 6 | B11: 1:53.642 | C11: 113.642 | D11: 34.906 | E11: 21.861 | F11: 27.18 | G11: 29.695 | H11: 319.5 | I11: 688.399 | J11: 0.0013153009 | K11: FALSE | L11: FALSE | M11: FALSE
A12: 7 | B12: 1:53.437 | C12: 113.437 | D12: 34.752 | E12: 21.798 | F12: 27.168 | G12: 29.719 | H12: 319.5 | I12: 801.836 | J12: 0.0013129282 | K12: FALSE | L12: FALSE | M12: FALSE
A13: 8 | B13: 1:53.648 | C13: 113.648 | D13: 34.796 | E13: 21.871 | F13: 27.259 | G13: 29.722 | H13: 319.5 | I13: 915.484 | J13: 0.0013153704 | K13: FALSE | L13: FALSE | M13: FALSE
A14: 9 | B14: 1:53.507 | C14: 113.507 | D14: 34.702 | E14: 21.92 | F14: 27.296 | G14: 29.589 | H14: 320.4 | I14: 1028.991 | J14: 0.0013137384 | K14: FALSE | L14: FALSE | M14: FALSE
A15: 10 | B15: 1:53.449 | C15: 113.449 | D15: 34.706 | E15: 21.885 | F15: 27.234 | G15: 29.624 | H15: 320.4 | I15: 1142.44 | J15: 0.0013130671 | K15: FALSE | L15: FALSE | M15: FALSE
A16: 11 | B16: 1:53.619 | C16: 113.619 | D16: 34.694 | E16: 21.978 | F16: 27.208 | G16: 29.739 | H16: 322.3 | I16: 1256.059 | J16: 0.0013150347 | K16: FALSE | L16: FALSE | M16: FALSE
A17: 12 | B17: 1:53.842 | C17: 113.842 | D17: 34.882 | E17: 21.982 | F17: 27.297 | G17: 29.681 | H17: 321.4 | I17: 1369.901 | J17: 0.0013176157 | K17: FALSE | L17: FALSE | M17: FALSE
... A26: 21 | B26: 1:53.734 | C26: 113.734 | D26: 34.835 | E26: 21.915 | F26: 27.2 | G26: 29.784 | H26: 317.6 | I26: 2391.297 | J26: 0.0013163657 | K26: FALSE | L26: FALSE | M26: FALSE

Sheet Ai Ogura
A1: 2. Ai OGURA #79
A3: Team | B3: SuperFile Trackhouse MotoGP Team | C3: Manufacturer | D3: APRILIA | E3: Nationality | F3: JPN | G3: Total Laps | H3: 21 | I3: Valid Laps | J3: 20 | K3: Front Tyre | L3: Slick-Medium | M3: Rear Tyre | N3: Slick-Medium
A5: Lap | B5: Lap Time | C5: Lap Seconds | D5: T1 | E5: T2 | F5: T3 | G5: T4 | H5: Speed km/h | I5: Cumulative Seconds | J5: Excel Time | K5: Cancelled | L5: Pit Lane | M5: Partial Timing
A6: 1 | B6: 1:59.208 | C6: 119.208 | D6: 39.759 | E6: 22.191 | F6: 27.259 | G6: 29.999 | H6: 240 | I6: 119.208 | J6: 0.0013797222 | K6: FALSE | L6: FALSE | M6: FALSE
A7: 2 | B7: 1:54.473 | C7: 114.473 | D7: 34.893 | E7: 22.023 | F7: 27.386 | G7: 30.171 | H7: 314.8 | I7: 233.681 | J7: 0.001324919 | K7: FALSE | L7: FALSE | M7: FALSE
A8: 3 | B8: 1:54.233 | C8: 114.233 | D8: 34.986 | E8: 22.01 | F8: 27.379 | G8: 29.858 | H8: 320.4 | I8: 347.914 | J8: 0.0013221412 | K8: FALSE | L8: FALSE | M8: FALSE
A9: 4 | B9: 1:53.709 | C9: 113.709 | D9: 34.819 | E9: 21.993 | F9: 27.289 | G9: 29.608 | H9: 319.5 | I9: 461.623 | J9: 0.0013160764 | K9: FALSE | L9: FALSE | M9: FALSE
A10: 5 | B10: 1:53.713 | C10: 113.713 | D10: 34.74 | E10: 21.97 | F10: 27.29 | G10: 29.713 | H10: 318.5 | I10: 575.336 | J10: 0.0013161227 | K10: FALSE | L10: FALSE | M10: FALSE
A11: 6 | B11: 1:53.647 | C11: 113.647 | D11: 34.823 | E11: 21.942 | F11: 27.186 | G11: 29.696 | H11: 317.6 | I11: 688.983 | J11: 0.0013153588 | K11: FALSE | L11: FALSE | M11: FALSE
A12: 7 | B12: 1:53.630 | C12: 113.63 | D12: 34.723 | E12: 21.915 | F12: 27.256 | G12: 29.736 | H12: 318.5 | I12: 802.613 | J12: 0.001315162 | K12: FALSE | L12: FALSE | M12: FALSE
A13: 8 | B13: 1:53.692 | C13: 113.692 | D13: 34.768 | E13: 21.87 | F13: 27.313 | G13: 29.741 | H13: 317.6 | I13: 916.305 | J13: 0.0013158796 | K13: FALSE | L13: FALSE | M13: FALSE
A14: 9 | B14: 1:53.550 | C14: 113.55 | D14: 34.711 | E14: 21.943 | F14: 27.269 | G14: 29.627 | H14: 319.5 | I14: 1029.855 | J14: 0.0013142361 | K14: FALSE | L14: FALSE | M14: FALSE
A15: 10 | B15: 1:53.513 | C15: 113.513 | D15: 34.709 | E15: 21.988 | F15: 27.245 | G15: 29.571 | H15: 319.5 | I15: 1143.368 | J15: 0.0013138079 | K15: FALSE | L15: FALSE | M15: FALSE
A16: 11 | B16: 1:53.491 | C16: 113.491 | D16: 34.601 | E16: 21.982 | F16: 27.291 | G16: 29.617 | H16: 319.5 | I16: 1256.859 | J16: 0.0013135532 | K16: FALSE | L16: FALSE | M16: FALSE
A17: 12 | B17: 1:53.724 | C17: 113.724 | D17: 34.668 | E17: 21.942 | F17: 27.245 | G17: 29.869 | H17: 319.5 | I17: 1370.583 | J17: 0.00131625 | K17: FALSE | L17: FALSE | M17: FALSE
... A26: 21 | B26: 1:53.353 | C26: 113.353 | D26: 34.623 | E26: 21.879 | F26: 27.214 | G26: 29.637 | H26: 319.5 | I26: 2391.718 | J26: 0.001311956 | K26: FALSE | L26: FALSE | M26: FALSE

Sheet Francesco Bagnaia
A1: 3. Francesco BAGNAIA #63
A3: Team | B3: Ducati Lenovo Team | C3: Manufacturer | D3: DUCATI | E3: Nationality | F3: ITA | G3: Total Laps | H3: 21 | I3: Valid Laps | J3: 20 | K3: Front Tyre | L3: Slick-Medium | M3: Rear Tyre | N3: Slick-Medium
A5: Lap | B5: Lap Time | C5: Lap Seconds | D5: T1 | E5: T2 | F5: T3 | G5: T4 | H5: Speed km/h | I5: Cumulative Seconds | J5: Excel Time | K5: Cancelled | L5: Pit Lane | M5: Partial Timing
A6: 1 | B6: 1:59.282 | C6: 119.282 | D6: 40.023 | E6: 22.06 | F6: 27.206 | G6: 29.993 | H6: 241.6 | I6: 119.282 | J6: 0.0013805787 | K6: FALSE | L6: FALSE | M6: FALSE
A7: 2 | B7: 1:53.886 | C7: 113.886 | D7: 34.938 | E7: 22.046 | F7: 27.146 | G7: 29.756 | H7: 317.6 | I7: 233.168 | J7: 0.001318125 | K7: FALSE | L7: FALSE | M7: FALSE
A8: 3 | B8: 1:53.540 | C8: 113.54 | D8: 34.742 | E8: 21.965 | F8: 27.16 | G8: 29.673 | H8: 316.7 | I8: 346.708 | J8: 0.0013141204 | K8: FALSE | L8: FALSE | M8: FALSE
A9: 4 | B9: 1:53.772 | C9: 113.772 | D9: 34.828 | E9: 21.877 | F9: 27.297 | G9: 29.77 | H9: 315.7 | I9: 460.48 | J9: 0.0013168056 | K9: FALSE | L9: FALSE | M9: FALSE
A10: 5 | B10: 1:53.682 | C10: 113.682 | D10: 34.863 | E10: 21.797 | F10: 27.305 | G10: 29.717 | H10: 317.6 | I10: 574.162 | J10: 0.0013157639 | K10: FALSE | L10: FALSE | M10: FALSE
A11: 6 | B11: 1:53.531 | C11: 113.531 | D11: 34.839 | E11: 21.881 | F11: 27.142 | G11: 29.669 | H11: 316.7 | I11: 687.693 | J11: 0.0013140162 | K11: FALSE | L11: FALSE | M11: FALSE
A12: 7 | B12: 1:53.586 | C12: 113.586 | D12: 34.798 | E12: 21.937 | F12: 27.134 | G12: 29.717 | H12: 317.6 | I12: 801.279 | J12: 0.0013146528 | K12: FALSE | L12: FALSE | M12: FALSE
A13: 8 | B13: 1:53.690 | C13: 113.69 | D13: 34.815 | E13: 21.946 | F13: 27.222 | G13: 29.707 | H13: 315.7 | I13: 914.969 | J13: 0.0013158565 | K13: FALSE | L13: FALSE | M13: FALSE
A14: 9 | B14: 1:53.667 | C14: 113.667 | D14: 34.797 | E14: 21.952 | F14: 27.293 | G14: 29.625 | H14: 317.6 | I14: 1028.636 | J14: 0.0013155903 | K14: FALSE | L14: FALSE | M14: FALSE
A15: 10 | B15: 1:53.587 | C15: 113.587 | D15: 34.842 | E15: 21.886 | F15: 27.154 | G15: 29.705 | H15: 316.7 | I15: 1142.223 | J15: 0.0013146644 | K15: FALSE | L15: FALSE | M15: FALSE
A16: 11 | B16: 1:53.619 | C16: 113.619 | D16: 34.752 | E16: 21.988 | F16: 27.203 | G16: 29.676 | H16: 319.5 | I16: 1255.842 | J16: 0.0013150347 | K16: FALSE | L16: FALSE | M16: FALSE
A17: 12 | B17: 1:53.510 | C17: 113.51 | D17: 34.796 | E17: 21.924 | F17: 27.184 | G17: 29.606 | H17: 318.5 | I17: 1369.352 | J17: 0.0013137731 | K17: FALSE | L17: FALSE | M17: FALSE
... A26: 21 | B26: 1:53.827 | C26: 113.827 | D26: 34.791 | E26: 21.987 | F26: 27.306 | G26: 29.743 | H26: 321.4 | I26: 2393.552 | J26: 0.0013174421 | K26: FALSE | L26: FALSE | M26: FALSE

Sheet Fabio Di Giannantonio
A1: 4. Fabio DI GIANNANTONIO #49
A3: Team | B3: Pertamina Enduro VR46 Racing Team | C3: Manufacturer | D3: DUCATI | E3: Nationality | F3: ITA | G3: Total Laps | H3: 21 | I3: Valid Laps | J3: 19 | K3: Front Tyre | L3: Slick-Medium | M3: Rear Tyre | N3: Slick-Medium
A5: Lap | B5: Lap Time | C5: Lap Seconds | D5: T1 | E5: T2 | F5: T3 | G5: T4 | H5: Speed km/h | I5: Cumulative Seconds | J5: Excel Time | K5: Cancelled | L5: Pit Lane | M5: Partial Timing
A6: 1 | B6: 1:59.896 | C6: 119.896 | D6: 40.399 | E6: 22.342 | F6: 27.208 | G6: 29.947 | H6: 241.6 | I6: 119.896 | J6: 0.0013876852 | K6: FALSE | L6: FALSE | M6: FALSE
A7: 2 | B7: 1:54.402 | C7: 114.402 | D7: 34.899 | E7: 22.144 | F7: 27.321 | G7: 30.038 | H7: 313.9 | I7: 234.298 | J7: 0.0013240972 | K7: FALSE | L7: FALSE | M7: FALSE
A8: 3 | B8: 1:53.955 | C8: 113.955 | D8: 35.022 | E8: 21.971 | F8: 27.342 | G8: 29.62 | H8: 309.4 | I8: 348.253 | J8: 0.0013189236 | K8: FALSE | L8: FALSE | M8: FALSE
A9: 4 | B9: 1:54.001 | C9: 114.001 | D9: 34.879 | E9: 22.005 | F9: 27.347 | G9: 29.77 | H9: 313.9 | I9: 462.254 | J9: 0.001319456 | K9: FALSE | L9: FALSE | M9: FALSE
A10: 5 | B10: 1:53.680 | C10: 113.68 | D10: 34.773 | E10: 21.944 | F10: 27.273 | G10: 29.69 | H10: 316.7 | I10: 575.934 | J10: 0.0013157407 | K10: FALSE | L10: FALSE | M10: FALSE
A11: 6 | B11: 1:53.823 | C11: 113.823 | D11: 34.795 | E11: 22.024 | F11: 27.329 | G11: 29.675 | H11: 318.5 | I11: 689.757 | J11: 0.0013173958 | K11: FALSE | L11: FALSE | M11: FALSE
A12: 7 | B12: 1:53.816 | C12: 113.816 | D12: 34.741 | E12: 22.017 | F12: 27.34 | G12: 29.718 | H12: 321.4 | I12: 803.573 | J12: 0.0013173148 | K12: FALSE | L12: FALSE | M12: FALSE
A13: 8 | B13: 1:54.232 | C13: 114.232 | D13: 34.657 | E13: 21.979 | F13: 27.758 | G13: 29.838 | H13: 321.4 | I13: 917.805 | J13: 0.0013221296 | K13: FALSE | L13: FALSE | M13: FALSE
A14: 9 | B14: 1:54.058 | C14: 114.058 | D14: 34.971 | E14: 22.069 | F14: 27.377 | G14: 29.641 | H14: 320.4 | I14: 1031.863 | J14: 0.0013201157 | K14: FALSE | L14: FALSE | M14: FALSE
A15: 10 | B15: 1:53.809 | C15: 113.809 | D15: 34.807 | E15: 21.894 | F15: 27.345 | G15: 29.763 | H15: 320.4 | I15: 1145.672 | J15: 0.0013172338 | K15: FALSE | L15: FALSE | M15: FALSE
A16: 11 | B16: 1:53.836 | C16: 113.836 | D16: 34.798 | E16: 21.968 | F16: 27.394 | G16: 29.676 | H16: 315.7 | I16: 1259.508 | J16: 0.0013175463 | K16: FALSE | L16: FALSE | M16: FALSE
A17: 12 | B17: 1:53.627 | C17: 113.627 | D17: 34.758 | E17: 21.918 | F17: 27.323 | G17: 29.628 | H17: 318.5 | I17: 1373.135 | J17: 0.0013151273 | K17: TRUE | L17: FALSE | M17: FALSE
... A26: 21 | B26: 1:53.122 | C26: 113.122 | D26: 34.513 | E26: 21.825 | F26: 27.231 | G26: 29.553 | H26: 322.3 | I26: 2393.721 | J26: 0.0013092824 | K26: FALSE | L26: FALSE | M26: FALSE

Sheet Joan Mir
A1: 5. Joan MIR #36
A3: Team | B3: Honda HRC Castrol | C3: Manufacturer | D3: HONDA | E3: Nationality | F3: SPA | G3: Total Laps | H3: 21 | I3: Valid Laps | J3: 19 | K3: Front Tyre | L3: Slick-Medium | M3: Rear Tyre | N3: Slick-Soft
A5: Lap | B5: Lap Time | C5: Lap Seconds | D5: T1 | E5: T2 | F5: T3 | G5: T4 | H5: Speed km/h | I5: Cumulative Seconds | J5: Excel Time | K5: Cancelled | L5: Pit Lane | M5: Partial Timing
A6: 1 | B6: 2:00.775 | C6: 120.775 | D6: 41.026 | E6: 22.163 | F6: 27.386 | G6: 30.2 | H6: 246.5 | I6: 120.775 | J6: 0.0013978588 | K6: FALSE | L6: FALSE | M6: FALSE
A7: 2 | B7: 1:54.356 | C7: 114.356 | D7: 35.069 | E7: 22.052 | F7: 27.331 | G7: 29.904 | H7: 317.6 | I7: 235.131 | J7: 0.0013235648 | K7: TRUE | L7: FALSE | M7: FALSE
A8: 3 | B8: 1:54.129 | C8: 114.129 | D8: 34.891 | E8: 21.955 | F8: 27.301 | G8: 29.982 | H8: 316.7 | I8: 349.26 | J8: 0.0013209375 | K8: FALSE | L8: FALSE | M8: FALSE
A9: 4 | B9: 1:54.312 | C9: 114.312 | D9: 34.987 | E9: 22.001 | F9: 27.412 | G9: 29.912 | H9: 317.6 | I9: 463.572 | J9: 0.0013230556 | K9: FALSE | L9: FALSE | M9: FALSE
A10: 5 | B10: 1:54.238 | C10: 114.238 | D10: 35.001 | E10: 22.076 | F10: 27.318 | G10: 29.843 | H10: 314.8 | I10: 577.81 | J10: 0.0013221991 | K10: FALSE | L10: FALSE | M10: FALSE
A11: 6 | B11: 1:54.087 | C11: 114.087 | D11: 34.992 | E11: 21.919 | F11: 27.39 | G11: 29.786 | H11: 314.8 | I11: 691.897 | J11: 0.0013204514 | K11: FALSE | L11: FALSE | M11: FALSE
A12: 7 | B12: 1:53.991 | C12: 113.991 | D12: 34.882 | E12: 21.94 | F12: 27.283 | G12: 29.886 | H12: 315.7 | I12: 805.888 | J12: 0.0013193403 | K12: FALSE | L12: FALSE | M12: FALSE
A13: 8 | B13: 1:54.372 | C13: 114.372 | D13: 35.041 | E13: 21.982 | F13: 27.406 | G13: 29.943 | H13: 315.7 | I13: 920.26 | J13: 0.00132375 | K13: FALSE | L13: FALSE | M13: FALSE
A14: 9 | B14: 1:53.984 | C14: 113.984 | D14: 34.94 | E14: 22.033 | F14: 27.271 | G14: 29.74 | H14: 316.7 | I14: 1034.244 | J14: 0.0013192593 | K14: FALSE | L14: FALSE | M14: FALSE
A15: 10 | B15: 1:53.874 | C15: 113.874 | D15: 34.839 | E15: 21.939 | F15: 27.266 | G15: 29.83 | H15: 316.7 | I15: 1148.118 | J15: 0.0013179861 | K15: FALSE | L15: FALSE | M15: FALSE
A16: 11 | B16: 1:53.880 | C16: 113.88 | D16: 34.829 | E16: 22.023 | F16: 27.225 | G16: 29.803 | H16: 316.7 | I16: 1261.998 | J16: 0.0013180556 | K16: FALSE | L16: FALSE | M16: FALSE
A17: 12 | B17: 1:54.124 | C17: 114.124 | D17: 35.045 | E17: 21.991 | F17: 27.203 | G17: 29.885 | H17: 317.6 | I17: 1376.122 | J17: 0.0013208796 | K17: FALSE | L17: FALSE | M17: FALSE
... A26: 21 | B26: 1:54.579 | C26: 114.579 | D26: 35.06 | E26: 22.101 | F26: 27.429 | G26: 29.989 | H26: 317.6 | I26: 2404.107 | J26: 0.0013261458 | K26: FALSE | L26: FALSE | M26: FALSE

Sheet Fermin Aldeguer
A1: 6. Fermin ALDEGUER #54
A3: Team | B3: BK8 Gresini Racing MotoGP | C3: Manufacturer | D3: DUCATI | E3: Nationality | F3: SPA | G3: Total Laps | H3: 21 | I3: Valid Laps | J3: 17 | K3: Front Tyre | L3: Slick-Medium | M3: Rear Tyre | N3: Slick-Medium
A5: Lap | B5: Lap Time | C5: Lap Seconds | D5: T1 | E5: T2 | F5: T3 | G5: T4 | H5: Speed km/h | I5: Cumulative Seconds | J5: Excel Time | K5: Cancelled | L5: Pit Lane | M5: Partial Timing
A6: 1 | B6: 2:01.044 | C6: 121.044 | D6: 41.116 | E6: 22.222 | F6: 27.529 | G6: 30.177 | H6: 247.7 | I6: 121.044 | J6: 0.0014009722 | K6: FALSE | L6: FALSE | M6: FALSE
A7: 2 | B7: 1:54.454 | C7: 114.454 | D7: 35.018 | E7: 22.009 | F7: 27.345 | G7: 30.082 | H7: 313.9 | I7: 235.498 | J7: 0.0013246991 | K7: FALSE | L7: FALSE | M7: FALSE
A8: 3 | B8: 1:54.281 | C8: 114.281 | D8: 35.223 | E8: 21.982 | F8: 27.309 | G8: 29.767 | H8: 323.3 | I8: 349.779 | J8: 0.0013226968 | K8: FALSE | L8: FALSE | M8: FALSE
A9: 4 | B9: 1:54.403 | C9: 114.403 | D9: 34.922 | E9: 22.131 | F9: 27.407 | G9: 29.943 | H9: 318.5 | I9: 464.182 | J9: 0.0013241088 | K9: TRUE | L9: FALSE | M9: FALSE
A10: 5 | B10: 1:54.197 | C10: 114.197 | D10: 35.021 | E10: 22.172 | F10: 27.297 | G10: 29.707 | H10: 317.6 | I10: 578.379 | J10: 0.0013217245 | K10: FALSE | L10: FALSE | M10: FALSE
A11: 6 | B11: 1:54.302 | C11: 114.302 | D11: 35.141 | E11: 22.064 | F11: 27.317 | G11: 29.78 | H11: 318.5 | I11: 692.681 | J11: 0.0013229398 | K11: FALSE | L11: FALSE | M11: FALSE
A12: 7 | B12: 1:54.038 | C12: 114.038 | D12: 34.902 | E12: 22.066 | F12: 27.319 | G12: 29.751 | H12: 318.5 | I12: 806.719 | J12: 0.0013198843 | K12: TRUE | L12: FALSE | M12: FALSE
A13: 8 | B13: 1:53.944 | C13: 113.944 | D13: 34.931 | E13: 22.006 | F13: 27.286 | G13: 29.721 | H13: 317.6 | I13: 920.663 | J13: 0.0013187963 | K13: FALSE | L13: FALSE | M13: FALSE
A14: 9 | B14: 1:54.046 | C14: 114.046 | D14: 34.905 | E14: 22.066 | F14: 27.362 | G14: 29.713 | H14: 318.5 | I14: 1034.709 | J14: 0.0013199769 | K14: FALSE | L14: FALSE | M14: FALSE
A15: 10 | B15: 1:53.839 | C15: 113.839 | D15: 34.845 | E15: 22.018 | F15: 27.364 | G15: 29.612 | H15: 319.5 | I15: 1148.548 | J15: 0.001317581 | K15: TRUE | L15: FALSE | M15: FALSE
A16: 11 | B16: 1:53.960 | C16: 113.96 | D16: 34.794 | E16: 22.101 | F16: 27.313 | G16: 29.752 | H16: 320.4 | I16: 1262.508 | J16: 0.0013189815 | K16: FALSE | L16: FALSE | M16: FALSE
A17: 12 | B17: 1:53.983 | C17: 113.983 | D17: 34.809 | E17: 22.03 | F17: 27.326 | G17: 29.818 | H17: 319.5 | I17: 1376.491 | J17: 0.0013192477 | K17: FALSE | L17: FALSE | M17: FALSE
... A26: 21 | B26: 1:55.244 | C26: 115.244 | D26: 35.052 | E26: 22.357 | F26: 27.544 | G26: 30.291 | H26: 318.5 | I26: 2406.171 | J26: 0.0013338426 | K26: FALSE | L26: FALSE | M26: FALSE

Sheet Raul Fernandez
A1: 7. Raul FERNANDEZ #25
A3: Team | B3: SuperFile Trackhouse MotoGP Team | C3: Manufacturer | D3: APRILIA | E3: Nationality | F3: SPA | G3: Total Laps | H3: 21 | I3: Valid Laps | J3: 19 | K3: Front Tyre | L3: Slick-Medium | M3: Rear Tyre | N3: Slick-Medium
A5: Lap | B5: Lap Time | C5: Lap Seconds | D5: T1 | E5: T2 | F5: T3 | G5: T4 | H5: Speed km/h | I5: Cumulative Seconds | J5: Excel Time | K5: Cancelled | L5: Pit Lane | M5: Partial Timing
A6: 1 | B6: 2:00.840 | C6: 120.84 | D6: 40.671 | E6: 22.231 | F6: 27.898 | G6: 30.04 | H6: 241.6 | I6: 120.84 | J6: 0.0013986111 | K6: FALSE | L6: FALSE | M6: FALSE
A7: 2 | B7: 1:54.829 | C7: 114.829 | D7: 35.358 | E7: 22.107 | F7: 27.389 | G7: 29.975 | H7: 309.4 | I7: 235.669 | J7: 0.0013290394 | K7: FALSE | L7: FALSE | M7: FALSE
A8: 3 | B8: 1:54.682 | C8: 114.682 | D8: 35.14 | E8: 22.161 | F8: 27.472 | G8: 29.909 | H8: 319.5 | I8: 350.351 | J8: 0.001327338 | K8: FALSE | L8: FALSE | M8: FALSE
A9: 4 | B9: 1:54.424 | C9: 114.424 | D9: 34.943 | E9: 22.054 | F9: 27.613 | G9: 29.814 | H9: 316.7 | I9: 464.775 | J9: 0.0013243519 | K9: FALSE | L9: FALSE | M9: FALSE
A10: 5 | B10: 1:54.388 | C10: 114.388 | D10: 34.985 | E10: 22.068 | F10: 27.408 | G10: 29.927 | H10: 318.5 | I10: 579.163 | J10: 0.0013239352 | K10: FALSE | L10: FALSE | M10: FALSE
A11: 6 | B11: 1:54.177 | C11: 114.177 | D11: 34.984 | E11: 22.024 | F11: 27.437 | G11: 29.732 | H11: 316.7 | I11: 693.34 | J11: 0.0013214931 | K11: FALSE | L11: FALSE | M11: FALSE
A12: 7 | B12: 1:54.510 | C12: 114.51 | D12: 35.021 | E12: 22.082 | F12: 27.478 | G12: 29.929 | H12: 316.7 | I12: 807.85 | J12: 0.0013253472 | K12: TRUE | L12: FALSE | M12: FALSE
A13: 8 | B13: 1:54.409 | C13: 114.409 | D13: 35.118 | E13: 22.063 | F13: 27.45 | G13: 29.778 | H13: 315.7 | I13: 922.259 | J13: 0.0013241782 | K13: FALSE | L13: FALSE | M13: FALSE
A14: 9 | B14: 1:54.641 | C14: 114.641 | D14: 35.142 | E14: 22.073 | F14: 27.529 | G14: 29.897 | H14: 315.7 | I14: 1036.9 | J14: 0.0013268634 | K14: FALSE | L14: FALSE | M14: FALSE
A15: 10 | B15: 1:54.416 | C15: 114.416 | D15: 35.066 | E15: 22.066 | F15: 27.474 | G15: 29.81 | H15: 314.8 | I15: 1151.316 | J15: 0.0013242593 | K15: FALSE | L15: FALSE | M15: FALSE
A16: 11 | B16: 1:54.420 | C16: 114.42 | D16: 35.035 | E16: 22.105 | F16: 27.561 | G16: 29.719 | H16: 319.5 | I16: 1265.736 | J16: 0.0013243056 | K16: FALSE | L16: FALSE | M16: FALSE
A17: 12 | B17: 1:54.422 | C17: 114.422 | D17: 35.002 | E17: 22.06 | F17: 27.439 | G17: 29.921 | H17: 320.4 | I17: 1380.158 | J17: 0.0013243287 | K17: FALSE | L17: FALSE | M17: FALSE
... A26: 21 | B26: 1:55.588 | C26: 115.588 | D26: 35.261 | E26: 22.212 | F26: 27.736 | G26: 30.379 | H26: 312.1 | I26: 2409.954 | J26: 0.0013378241 | K26: FALSE | L26: FALSE | M26: FALSE

Sheet Luca Marini
A1: 8. Luca MARINI #10
A3: Team | B3: Honda HRC Castrol | C3: Manufacturer | D3: HONDA | E3: Nationality | F3: ITA | G3: Total Laps | H3: 21 | I3: Valid Laps | J3: 19 | K3: Front Tyre | L3: Slick-Medium | M3: Rear Tyre | N3: Slick-Medium
A5: Lap | B5: Lap Time | C5: Lap Seconds | D5: T1 | E5: T2 | F5: T3 | G5: T4 | H5: Speed km/h | I5: Cumulative Seconds | J5: Excel Time | K5: Cancelled | L5: Pit Lane | M5: Partial Timing
A6: 1 | B6: 2:01.709 | C6: 121.709 | D6: 41.445 | E6: 22.309 | F6: 27.673 | G6: 30.282 | H6: 251.1 | I6: 121.709 | J6: 0.001408669 | K6: FALSE | L6: FALSE | M6: FALSE
A7: 2 | B7: 1:54.952 | C7: 114.952 | D7: 35.408 | E7: 22.254 | F7: 27.491 | G7: 29.799 | H7: 313.9 | I7: 236.661 | J7: 0.001330463 | K7: FALSE | L7: FALSE | M7: FALSE
A8: 3 | B8: 1:54.441 | C8: 114.441 | D8: 35.046 | E8: 22.057 | F8: 27.504 | G8: 29.834 | H8: 318.5 | I8: 351.102 | J8: 0.0013245486 | K8: FALSE | L8: FALSE | M8: FALSE
A9: 4 | B9: 1:54.754 | C9: 114.754 | D9: 35.182 | E9: 22.092 | F9: 27.573 | G9: 29.907 | H9: 314.8 | I9: 465.856 | J9: 0.0013281713 | K9: FALSE | L9: FALSE | M9: FALSE
A10: 5 | B10: 1:54.679 | C10: 114.679 | D10: 35.155 | E10: 22.07 | F10: 27.47 | G10: 29.984 | H10: 311.2 | I10: 580.535 | J10: 0.0013273032 | K10: FALSE | L10: FALSE | M10: FALSE
A11: 6 | B11: 1:54.670 | C11: 114.67 | D11: 35.164 | E11: 22.119 | F11: 27.482 | G11: 29.905 | H11: 310.3 | I11: 695.205 | J11: 0.0013271991 | K11: FALSE | L11: FALSE | M11: FALSE
A12: 7 | B12: 1:54.426 | C12: 114.426 | D12: 35.061 | E12: 22.013 | F12: 27.434 | G12: 29.918 | H12: 315.7 | I12: 809.631 | J12: 0.001324375 | K12: FALSE | L12: FALSE | M12: FALSE
A13: 8 | B13: 1:54.468 | C13: 114.468 | D13: 35.122 | E13: 22.058 | F13: 27.414 | G13: 29.874 | H13: 315.7 | I13: 924.099 | J13: 0.0013248611 | K13: FALSE | L13: FALSE | M13: FALSE
A14: 9 | B14: 1:54.424 | C14: 114.424 | D14: 35.153 | E14: 22.086 | F14: 27.447 | G14: 29.738 | H14: 316.7 | I14: 1038.523 | J14: 0.0013243519 | K14: FALSE | L14: FALSE | M14: FALSE
A15: 10 | B15: 1:54.222 | C15: 114.222 | D15: 35.015 | E15: 22.034 | F15: 27.404 | G15: 29.769 | H15: 317.6 | I15: 1152.745 | J15: 0.0013220139 | K15: FALSE | L15: FALSE | M15: FALSE
A16: 11 | B16: 1:54.265 | C16: 114.265 | D16: 34.974 | E16: 22.016 | F16: 27.45 | G16: 29.825 | H16: 318.5 | I16: 1267.01 | J16: 0.0013225116 | K16: FALSE | L16: FALSE | M16: FALSE
A17: 12 | B17: 1:54.296 | C17: 114.296 | D17: 35.078 | E17: 22.032 | F17: 27.398 | G17: 29.788 | H17: 317.6 | I17: 1381.306 | J17: 0.0013228704 | K17: FALSE | L17: FALSE | M17: FALSE
... A26: 21 | B26: 1:54.612 | C26: 114.612 | D26: 35.059 | E26: 22.046 | F26: 27.527 | G26: 29.98 | H26: 315.7 | I26: 2412.562 | J26: 0.0013265278 | K26: FALSE | L26: FALSE | M26: FALSE

Sheet Jorge Martin
A1: 9. Jorge MARTIN #89
A3: Team | B3: Aprilia Racing | C3: Manufacturer | D3: APRILIA | E3: Nationality | F3: SPA | G3: Total Laps | H3: 21 | I3: Valid Laps | J3: 17 | K3: Front Tyre | L3: Slick-Medium | M3: Rear Tyre | N3: Slick-Medium
A5: Lap | B5: Lap Time | C5: Lap Seconds | D5: T1 | E5: T2 | F5: T3 | G5: T4 | H5: Speed km/h | I5: Cumulative Seconds | J5: Excel Time | K5: Cancelled | L5: Pit Lane | M5: Partial Timing
A6: 1 | B6: 2:00.735 | C6: 120.735 | D6: 40.753 | E6: 22.33 | F6: 27.588 | G6: 30.064 | H6: 247.7 | I6: 120.735 | J6: 0.0013973958 | K6: FALSE | L6: FALSE | M6: FALSE
A7: 2 | B7: 1:54.688 | C7: 114.688 | D7: 34.951 | E7: 22.092 | F7: 27.562 | G7: 30.083 | H7: 319.5 | I7: 235.423 | J7: 0.0013274074 | K7: FALSE | L7: FALSE | M7: FALSE
A8: 3 | B8: 1:54.104 | C8: 114.104 | D8: 35.004 | E8: 21.938 | F8: 27.289 | G8: 29.873 | H8: 320.4 | I8: 349.527 | J8: 0.0013206481 | K8: FALSE | L8: FALSE | M8: FALSE
A9: 4 | B9: 1:54.332 | C9: 114.332 | D9: 34.888 | E9: 22.174 | F9: 27.424 | G9: 29.846 | H9: 319.5 | I9: 463.859 | J9: 0.001323287 | K9: FALSE | L9: FALSE | M9: FALSE
A10: 5 | B10: 1:56.104 | C10: 116.104 | D10: 35.194 | E10: 23.567 | F10: 27.461 | G10: 29.882 | H10: 317.6 | I10: 579.963 | J10: 0.0013437963 | K10: TRUE | L10: FALSE | M10: FALSE
A11: 6 | B11: 1:55.928 | C11: 115.928 | D11: 34.933 | E11: 23.5 | F11: 27.673 | G11: 29.822 | H11: 318.5 | I11: 695.891 | J11: 0.0013417593 | K11: TRUE | L11: FALSE | M11: FALSE
A12: 7 | B12: 1:55.172 | C12: 115.172 | D12: 35.146 | E12: 22.362 | F12: 27.629 | G12: 30.035 | H12: 318.5 | I12: 811.063 | J12: 0.0013330093 | K12: TRUE | L12: FALSE | M12: FALSE
A13: 8 | B13: 1:54.575 | C13: 114.575 | D13: 34.992 | E13: 22.202 | F13: 27.514 | G13: 29.867 | H13: 320.4 | I13: 925.638 | J13: 0.0013260995 | K13: FALSE | L13: FALSE | M13: FALSE
A14: 9 | B14: 1:54.656 | C14: 114.656 | D14: 35.006 | E14: 22.264 | F14: 27.618 | G14: 29.768 | H14: 319.5 | I14: 1040.294 | J14: 0.001327037 | K14: FALSE | L14: FALSE | M14: FALSE
A15: 10 | B15: 1:54.542 | C15: 114.542 | D15: 35.1 | E15: 22.104 | F15: 27.494 | G15: 29.844 | H15: 318.5 | I15: 1154.836 | J15: 0.0013257176 | K15: FALSE | L15: FALSE | M15: FALSE
A16: 11 | B16: 1:54.191 | C16: 114.191 | D16: 34.907 | E16: 22.021 | F16: 27.448 | G16: 29.815 | H16: 321.4 | I16: 1269.027 | J16: 0.0013216551 | K16: FALSE | L16: FALSE | M16: FALSE
A17: 12 | B17: 1:53.934 | C17: 113.934 | D17: 34.79 | E17: 22.113 | F17: 27.339 | G17: 29.692 | H17: 318.5 | I17: 1382.961 | J17: 0.0013186806 | K17: FALSE | L17: FALSE | M17: FALSE
... A26: 21 | B26: 1:54.383 | C26: 114.383 | D26: 34.95 | E26: 22.074 | F26: 27.532 | G26: 29.827 | H26: 318.5 | I26: 2412.698 | J26: 0.0013238773 | K26: FALSE | L26: FALSE | M26: FALSE

Sheet Enea Bastianini
A1: 10. Enea BASTIANINI #23
A3: Team | B3: Red Bull KTM Tech3 | C3: Manufacturer | D3: KTM | E3: Nationality | F3: ITA | G3: Total Laps | H3: 21 | I3: Valid Laps | J3: 20 | K3: Front Tyre | L3: Slick-Medium | M3: Rear Tyre | N3: Slick-Medium
A5: Lap | B5: Lap Time | C5: Lap Seconds | D5: T1 | E5: T2 | F5: T3 | G5: T4 | H5: Speed km/h | I5: Cumulative Seconds | J5: Excel Time | K5: Cancelled | L5: Pit Lane | M5: Partial Timing
A6: 1 | B6: 2:02.073 | C6: 122.073 | D6: 41.769 | E6: 22.661 | F6: 27.527 | G6: 30.116 | H6: 247.1 | I6: 122.073 | J6: 0.0014128819 | K6: FALSE | L6: FALSE | M6: FALSE
A7: 2 | B7: 1:54.749 | C7: 114.749 | D7: 35.205 | E7: 22.2 | F7: 27.454 | G7: 29.89 | H7: 311.2 | I7: 236.822 | J7: 0.0013281134 | K7: FALSE | L7: FALSE | M7: FALSE
A8: 3 | B8: 1:54.708 | C8: 114.708 | D8: 35.035 | E8: 22.243 | F8: 27.478 | G8: 29.952 | H8: 314.8 | I8: 351.53 | J8: 0.0013276389 | K8: FALSE | L8: FALSE | M8: FALSE
A9: 4 | B9: 1:54.695 | C9: 114.695 | D9: 35.114 | E9: 22.182 | F9: 27.482 | G9: 29.917 | H9: 312.1 | I9: 466.225 | J9: 0.0013274884 | K9: FALSE | L9: FALSE | M9: FALSE
A10: 5 | B10: 1:54.751 | C10: 114.751 | D10: 35.093 | E10: 22.159 | F10: 27.51 | G10: 29.989 | H10: 318.5 | I10: 580.976 | J10: 0.0013281366 | K10: FALSE | L10: FALSE | M10: FALSE
A11: 6 | B11: 1:54.679 | C11: 114.679 | D11: 35.149 | E11: 22.143 | F11: 27.496 | G11: 29.891 | H11: 319.5 | I11: 695.655 | J11: 0.0013273032 | K11: FALSE | L11: FALSE | M11: FALSE
A12: 7 | B12: 1:55.098 | C12: 115.098 | D12: 35.392 | E12: 22.202 | F12: 27.505 | G12: 29.999 | H12: 316.7 | I12: 810.753 | J12: 0.0013321528 | K12: FALSE | L12: FALSE | M12: FALSE
A13: 8 | B13: 1:54.531 | C13: 114.531 | D13: 35.044 | E13: 22.171 | F13: 27.454 | G13: 29.862 | H13: 319.5 | I13: 925.284 | J13: 0.0013255903 | K13: FALSE | L13: FALSE | M13: FALSE
A14: 9 | B14: 1:54.728 | C14: 114.728 | D14: 35.088 | E14: 22.161 | F14: 27.592 | G14: 29.887 | H14: 316.7 | I14: 1040.012 | J14: 0.0013278704 | K14: FALSE | L14: FALSE | M14: FALSE
A15: 10 | B15: 1:54.969 | C15: 114.969 | D15: 35.087 | E15: 22.234 | F15: 27.657 | G15: 29.991 | H15: 312.1 | I15: 1154.981 | J15: 0.0013306597 | K15: FALSE | L15: FALSE | M15: FALSE
A16: 11 | B16: 1:54.677 | C16: 114.677 | D16: 35.116 | E16: 22.194 | F16: 27.538 | G16: 29.829 | H16: 317.6 | I16: 1269.658 | J16: 0.0013272801 | K16: FALSE | L16: FALSE | M16: FALSE
A17: 12 | B17: 1:54.657 | C17: 114.657 | D17: 35.031 | E17: 22.248 | F17: 27.416 | G17: 29.962 | H17: 319.5 | I17: 1384.315 | J17: 0.0013270486 | K17: FALSE | L17: FALSE | M17: FALSE
... A26: 21 | B26: 1:54.273 | C26: 114.273 | D26: 35.007 | E26: 22.008 | F26: 27.475 | G26: 29.783 | H26: 322.3 | I26: 2413.57 | J26: 0.0013226042 | K26: FALSE | L26: FALSE | M26: FALSE

Sheet Diogo Moreira
A1: 11. Diogo MOREIRA #11
A3: Team | B3: Pro Honda LCR | C3: Manufacturer | D3: HONDA | E3: Nationality | F3: BRA | G3: Total Laps | H3: 21 | I3: Valid Laps | J3: 18 | K3: Front Tyre | L3: Slick-Medium | M3: Rear Tyre | N3: Slick-Medium
A5: Lap | B5: Lap Time | C5: Lap Seconds | D5: T1 | E5: T2 | F5: T3 | G5: T4 | H5: Speed km/h | I5: Cumulative Seconds | J5: Excel Time | K5: Cancelled | L5: Pit Lane | M5: Partial Timing
A6: 1 | B6: 1:59.640 | C6: 119.64 | D6: 40.262 | E6: 22.063 | F6: 27.334 | G6: 29.981 | H6: 246 | I6: 119.64 | J6: 0.0013847222 | K6: FALSE | L6: FALSE | M6: FALSE
A7: 2 | B7: 1:54.588 | C7: 114.588 | D7: 35.056 | E7: 22.112 | F7: 27.321 | G7: 30.099 | H7: 317.6 | I7: 234.228 | J7: 0.00132625 | K7: FALSE | L7: FALSE | M7: FALSE
A8: 3 | B8: 1:54.415 | C8: 114.415 | D8: 35.208 | E8: 22.015 | F8: 27.343 | G8: 29.849 | H8: 314.8 | I8: 348.643 | J8: 0.0013242477 | K8: FALSE | L8: FALSE | M8: FALSE
A9: 4 | B9: 1:54.729 | C9: 114.729 | D9: 34.984 | E9: 22.131 | F9: 27.463 | G9: 30.151 | H9: 316.7 | I9: 463.372 | J9: 0.0013278819 | K9: FALSE | L9: FALSE | M9: FALSE
A10: 5 | B10: 1:54.944 | C10: 114.944 | D10: 35.055 | E10: 22.097 | F10: 27.767 | G10: 30.025 | H10: 315.7 | I10: 578.316 | J10: 0.0013303704 | K10: FALSE | L10: FALSE | M10: FALSE
A11: 6 | B11: 1:54.784 | C11: 114.784 | D11: 35.333 | E11: 22.116 | F11: 27.352 | G11: 29.983 | H11: 317.6 | I11: 693.1 | J11: 0.0013285185 | K11: FALSE | L11: FALSE | M11: FALSE
A12: 7 | B12: 1:54.626 | C12: 114.626 | D12: 35.03 | E12: 22.153 | F12: 27.423 | G12: 30.02 | H12: 318.5 | I12: 807.726 | J12: 0.0013266898 | K12: FALSE | L12: FALSE | M12: FALSE
A13: 8 | B13: 1:54.440 | C13: 114.44 | D13: 35.086 | E13: 22.037 | F13: 27.383 | G13: 29.934 | H13: 316.7 | I13: 922.166 | J13: 0.001324537 | K13: FALSE | L13: FALSE | M13: FALSE
A14: 9 | B14: 1:54.610 | C14: 114.61 | D14: 35.011 | E14: 22.154 | F14: 27.506 | G14: 29.939 | H14: 317.6 | I14: 1036.776 | J14: 0.0013265046 | K14: FALSE | L14: FALSE | M14: FALSE
A15: 10 | B15: 1:54.332 | C15: 114.332 | D15: 35.009 | E15: 22.097 | F15: 27.363 | G15: 29.863 | H15: 316.7 | I15: 1151.108 | J15: 0.001323287 | K15: TRUE | L15: FALSE | M15: FALSE
A16: 11 | B16: 1:54.553 | C16: 114.553 | D16: 35.122 | E16: 22.066 | F16: 27.512 | G16: 29.853 | H16: 318.5 | I16: 1265.661 | J16: 0.0013258449 | K16: FALSE | L16: FALSE | M16: FALSE
A17: 12 | B17: 1:55.086 | C17: 115.086 | D17: 35.409 | E17: 22.135 | F17: 27.487 | G17: 30.055 | H17: 317.6 | I17: 1380.747 | J17: 0.0013320139 | K17: TRUE | L17: FALSE | M17: FALSE
... A26: 21 | B26: 1:55.077 | C26: 115.077 | D26: 35.336 | E26: 22.083 | F26: 27.538 | G26: 30.12 | H26: 316.7 | I26: 2414.178 | J26: 0.0013319097 | K26: FALSE | L26: FALSE | M26: FALSE

Sheet Brad Binder
A1: 12. Brad BINDER #33
A3: Team | B3: Red Bull KTM Factory Racing | C3: Manufacturer | D3: KTM | E3: Nationality | F3: RSA | G3: Total Laps | H3: 21 | I3: Valid Laps | J3: 20 | K3: Front Tyre | L3: Slick-Medium | M3: Rear Tyre | N3: Slick-Medium
A5: Lap | B5: Lap Time | C5: Lap Seconds | D5: T1 | E5: T2 | F5: T3 | G5: T4 | H5: Speed km/h | I5: Cumulative Seconds | J5: Excel Time | K5: Cancelled | L5: Pit Lane | M5: Partial Timing
A6: 1 | B6: 2:02.326 | C6: 122.326 | D6: 41.628 | E6: 22.572 | F6: 27.613 | G6: 30.513 | H6: 258.9 | I6: 122.326 | J6: 0.0014158102 | K6: FALSE | L6: FALSE | M6: FALSE
A7: 2 | B7: 1:54.899 | C7: 114.899 | D7: 35.177 | E7: 22.147 | F7: 27.447 | G7: 30.128 | H7: 313.9 | I7: 237.225 | J7: 0.0013298495 | K7: FALSE | L7: FALSE | M7: FALSE
A8: 3 | B8: 1:54.526 | C8: 114.526 | D8: 35.105 | E8: 21.979 | F8: 27.441 | G8: 30.001 | H8: 318.5 | I8: 351.751 | J8: 0.0013255324 | K8: FALSE | L8: FALSE | M8: FALSE
A9: 4 | B9: 1:54.689 | C9: 114.689 | D9: 35.071 | E9: 22.199 | F9: 27.483 | G9: 29.936 | H9: 315.7 | I9: 466.44 | J9: 0.001327419 | K9: FALSE | L9: FALSE | M9: FALSE
A10: 5 | B10: 1:54.771 | C10: 114.771 | D10: 35.176 | E10: 22.163 | F10: 27.473 | G10: 29.959 | H10: 316.7 | I10: 581.211 | J10: 0.0013283681 | K10: FALSE | L10: FALSE | M10: FALSE
A11: 6 | B11: 1:55.004 | C11: 115.004 | D11: 35.142 | E11: 22.206 | F11: 27.638 | G11: 30.018 | H11: 317.6 | I11: 696.215 | J11: 0.0013310648 | K11: FALSE | L11: FALSE | M11: FALSE
A12: 7 | B12: 1:54.949 | C12: 114.949 | D12: 35.139 | E12: 22.194 | F12: 27.554 | G12: 30.062 | H12: 318.5 | I12: 811.164 | J12: 0.0013304282 | K12: FALSE | L12: FALSE | M12: FALSE
A13: 8 | B13: 1:54.786 | C13: 114.786 | D13: 35.082 | E13: 22.187 | F13: 27.483 | G13: 30.034 | H13: 312.1 | I13: 925.95 | J13: 0.0013285417 | K13: FALSE | L13: FALSE | M13: FALSE
A14: 9 | B14: 1:54.689 | C14: 114.689 | D14: 35.078 | E14: 22.172 | F14: 27.498 | G14: 29.941 | H14: 318.5 | I14: 1040.639 | J14: 0.001327419 | K14: FALSE | L14: FALSE | M14: FALSE
A15: 10 | B15: 1:54.583 | C15: 114.583 | D15: 35.05 | E15: 22.09 | F15: 27.488 | G15: 29.955 | H15: 319.5 | I15: 1155.222 | J15: 0.0013261921 | K15: FALSE | L15: FALSE | M15: FALSE
A16: 11 | B16: 1:54.669 | C16: 114.669 | D16: 35.056 | E16: 22.141 | F16: 27.558 | G16: 29.914 | H16: 321.4 | I16: 1269.891 | J16: 0.0013271875 | K16: FALSE | L16: FALSE | M16: FALSE
A17: 12 | B17: 1:54.559 | C17: 114.559 | D17: 34.967 | E17: 22.223 | F17: 27.479 | G17: 29.89 | H17: 319.5 | I17: 1384.45 | J17: 0.0013259144 | K17: FALSE | L17: FALSE | M17: FALSE
... A26: 21 | B26: 1:54.270 | C26: 114.27 | D26: 34.93 | E26: 21.983 | F26: 27.365 | G26: 29.992 | H26: 322.3 | I26: 2414.239 | J26: 0.0013225694 | K26: FALSE | L26: FALSE | M26: FALSE

Sheet Franco Morbidelli
A1: 13. Franco MORBIDELLI #21
A3: Team | B3: Pertamina Enduro VR46 Racing Team | C3: Manufacturer | D3: DUCATI | E3: Nationality | F3: ITA | G3: Total Laps | H3: 21 | I3: Valid Laps | J3: 20 | K3: Front Tyre | L3: Slick-Medium | M3: Rear Tyre | N3: Slick-Medium
A5: Lap | B5: Lap Time | C5: Lap Seconds | D5: T1 | E5: T2 | F5: T3 | G5: T4 | H5: Speed km/h | I5: Cumulative Seconds | J5: Excel Time | K5: Cancelled | L5: Pit Lane | M5: Partial Timing
A6: 1 | B6: 2:01.366 | C6: 121.366 | D6: 41.351 | E6: 22.228 | F6: 27.659 | G6: 30.128 | H6: 242.1 | I6: 121.366 | J6: 0.0014046991 | K6: FALSE | L6: FALSE | M6: FALSE
A7: 2 | B7: 1:54.814 | C7: 114.814 | D7: 35.085 | E7: 22.195 | F7: 27.48 | G7: 30.054 | H7: 314.8 | I7: 236.18 | J7: 0.0013288657 | K7: FALSE | L7: FALSE | M7: FALSE
A8: 3 | B8: 1:54.773 | C8: 114.773 | D8: 35.165 | E8: 22.08 | F8: 27.467 | G8: 30.061 | H8: 313.9 | I8: 350.953 | J8: 0.0013283912 | K8: FALSE | L8: FALSE | M8: FALSE
A9: 4 | B9: 1:54.830 | C9: 114.83 | D9: 35.194 | E9: 22.084 | F9: 27.571 | G9: 29.981 | H9: 314.8 | I9: 465.783 | J9: 0.0013290509 | K9: FALSE | L9: FALSE | M9: FALSE
A10: 5 | B10: 1:54.612 | C10: 114.612 | D10: 35.04 | E10: 22.104 | F10: 27.443 | G10: 30.025 | H10: 316.7 | I10: 580.395 | J10: 0.0013265278 | K10: FALSE | L10: FALSE | M10: FALSE
A11: 6 | B11: 1:55.026 | C11: 115.026 | D11: 35.098 | E11: 22.151 | F11: 27.483 | G11: 30.294 | H11: 315.7 | I11: 695.421 | J11: 0.0013313194 | K11: FALSE | L11: FALSE | M11: FALSE
A12: 7 | B12: 1:54.850 | C12: 114.85 | D12: 35.219 | E12: 22.117 | F12: 27.545 | G12: 29.969 | H12: 316.7 | I12: 810.271 | J12: 0.0013292824 | K12: FALSE | L12: FALSE | M12: FALSE
A13: 8 | B13: 1:54.876 | C13: 114.876 | D13: 35.129 | E13: 22.139 | F13: 27.562 | G13: 30.046 | H13: 316.7 | I13: 925.147 | J13: 0.0013295833 | K13: FALSE | L13: FALSE | M13: FALSE
A14: 9 | B14: 1:54.757 | C14: 114.757 | D14: 35.121 | E14: 22.185 | F14: 27.54 | G14: 29.911 | H14: 317.6 | I14: 1039.904 | J14: 0.001328206 | K14: FALSE | L14: FALSE | M14: FALSE
A15: 10 | B15: 1:54.622 | C15: 114.622 | D15: 35.066 | E15: 22.07 | F15: 27.534 | G15: 29.952 | H15: 317.6 | I15: 1154.526 | J15: 0.0013266435 | K15: FALSE | L15: FALSE | M15: FALSE
A16: 11 | B16: 1:54.941 | C16: 114.941 | D16: 35.002 | E16: 22.052 | F16: 27.752 | G16: 30.135 | H16: 316.7 | I16: 1269.467 | J16: 0.0013303356 | K16: FALSE | L16: FALSE | M16: FALSE
A17: 12 | B17: 1:54.484 | C17: 114.484 | D17: 34.975 | E17: 22.129 | F17: 27.452 | G17: 29.928 | H17: 318.5 | I17: 1383.951 | J17: 0.0013250463 | K17: FALSE | L17: FALSE | M17: FALSE
... A26: 21 | B26: 1:54.444 | C26: 114.444 | D26: 34.957 | E26: 22.078 | F26: 27.41 | G26: 29.999 | H26: 316.7 | I26: 2416.3 | J26: 0.0013245833 | K26: FALSE | L26: FALSE | M26: FALSE

Sheet Toprak Razgatlioglu
A1: 14. Toprak RAZGATLIOGLU #7
A3: Team | B3: Prima Pramac Yamaha MotoGP | C3: Manufacturer | D3: YAMAHA | E3: Nationality | F3: TUR | G3: Total Laps | H3: 21 | I3: Valid Laps | J3: 16 | K3: Front Tyre | L3: Slick-Medium | M3: Rear Tyre | N3: Slick-Medium
A5: Lap | B5: Lap Time | C5: Lap Seconds | D5: T1 | E5: T2 | F5: T3 | G5: T4 | H5: Speed km/h | I5: Cumulative Seconds | J5: Excel Time | K5: Cancelled | L5: Pit Lane | M5: Partial Timing
A6: 1 | B6: 2:02.587 | C6: 122.587 | D6: 41.896 | E6: 22.698 | F6: 27.704 | G6: 30.289 | H6: 258.3 | I6: 122.587 | J6: 0.001418831 | K6: FALSE | L6: FALSE | M6: FALSE
A7: 2 | B7: 1:55.220 | C7: 115.22 | D7: 35.222 | E7: 22.321 | F7: 27.667 | G7: 30.01 | H7: 311.2 | I7: 237.807 | J7: 0.0013335648 | K7: FALSE | L7: FALSE | M7: FALSE
A8: 3 | B8: 1:54.788 | C8: 114.788 | D8: 35.103 | E8: 22.217 | F8: 27.512 | G8: 29.956 | H8: 313 | I8: 352.595 | J8: 0.0013285648 | K8: FALSE | L8: FALSE | M8: FALSE
A9: 4 | B9: 1:55.143 | C9: 115.143 | D9: 35.17 | E9: 22.284 | F9: 27.597 | G9: 30.092 | H9: 312.1 | I9: 467.738 | J9: 0.0013326736 | K9: FALSE | L9: FALSE | M9: FALSE
A10: 5 | B10: 1:54.966 | C10: 114.966 | D10: 35.153 | E10: 22.207 | F10: 27.468 | G10: 30.138 | H10: 311.2 | I10: 582.704 | J10: 0.001330625 | K10: FALSE | L10: FALSE | M10: FALSE
A11: 6 | B11: 1:54.880 | C11: 114.88 | D11: 35.165 | E11: 22.237 | F11: 27.545 | G11: 29.933 | H11: 312.1 | I11: 697.584 | J11: 0.0013296296 | K11: FALSE | L11: FALSE | M11: FALSE
A12: 7 | B12: 1:55.102 | C12: 115.102 | D12: 35.225 | E12: 22.215 | F12: 27.577 | G12: 30.085 | H12: 313 | I12: 812.686 | J12: 0.0013321991 | K12: FALSE | L12: FALSE | M12: FALSE
A13: 8 | B13: 1:54.960 | C13: 114.96 | D13: 35.217 | E13: 22.236 | F13: 27.487 | G13: 30.02 | H13: 312.1 | I13: 927.646 | J13: 0.0013305556 | K13: FALSE | L13: FALSE | M13: FALSE
A14: 9 | B14: 1:54.604 | C14: 114.604 | D14: 35.114 | E14: 22.211 | F14: 27.453 | G14: 29.826 | H14: 313.9 | I14: 1042.25 | J14: 0.0013264352 | K14: FALSE | L14: FALSE | M14: FALSE
A15: 10 | B15: 1:54.595 | C15: 114.595 | D15: 35.163 | E15: 22.146 | F15: 27.455 | G15: 29.831 | H15: 314.8 | I15: 1156.845 | J15: 0.001326331 | K15: TRUE | L15: FALSE | M15: FALSE
A16: 11 | B16: 1:54.520 | C16: 114.52 | D16: 35.053 | E16: 22.122 | F16: 27.455 | G16: 29.89 | H16: 313.9 | I16: 1271.365 | J16: 0.001325463 | K16: FALSE | L16: FALSE | M16: FALSE
A17: 12 | B17: 1:54.885 | C17: 114.885 | D17: 35.235 | E17: 22.205 | F17: 27.521 | G17: 29.924 | H17: 314.8 | I17: 1386.25 | J17: 0.0013296875 | K17: FALSE | L17: FALSE | M17: FALSE
... A26: 21 | B26: 1:54.813 | C26: 114.813 | D26: 35.081 | E26: 22.121 | F26: 27.577 | G26: 30.034 | H26: 316.7 | I26: 2417.103 | J26: 0.0013288542 | K26: FALSE | L26: FALSE | M26: FALSE

Sheet Maverick Viñales
A1: 15. Maverick VIÑALES #12
A3: Team | B3: Red Bull KTM Tech3 | C3: Manufacturer | D3: KTM | E3: Nationality | F3: SPA | G3: Total Laps | H3: 21 | I3: Valid Laps | J3: 19 | K3: Front Tyre | L3: Slick-Medium | M3: Rear Tyre | N3: Slick-Medium
A5: Lap | B5: Lap Time | C5: Lap Seconds | D5: T1 | E5: T2 | F5: T3 | G5: T4 | H5: Speed km/h | I5: Cumulative Seconds | J5: Excel Time | K5: Cancelled | L5: Pit Lane | M5: Partial Timing
A6: 1 | B6: 2:01.936 | C6: 121.936 | D6: 41.533 | E6: 22.578 | F6: 27.583 | G6: 30.242 | H6: 246.5 | I6: 121.936 | J6: 0.0014112963 | K6: FALSE | L6: FALSE | M6: FALSE
A7: 2 | B7: 1:55.431 | C7: 115.431 | D7: 35.672 | E7: 22.221 | F7: 27.497 | G7: 30.041 | H7: 315.7 | I7: 237.367 | J7: 0.0013360069 | K7: FALSE | L7: FALSE | M7: FALSE
A8: 3 | B8: 1:54.694 | C8: 114.694 | D8: 35.09 | E8: 22.033 | F8: 27.57 | G8: 30.001 | H8: 317.6 | I8: 352.061 | J8: 0.0013274769 | K8: FALSE | L8: FALSE | M8: FALSE
A9: 4 | B9: 1:54.700 | C9: 114.7 | D9: 35.064 | E9: 22.254 | F9: 27.426 | G9: 29.956 | H9: 317.6 | I9: 466.761 | J9: 0.0013275463 | K9: FALSE | L9: FALSE | M9: FALSE
A10: 5 | B10: 1:54.648 | C10: 114.648 | D10: 35.04 | E10: 22.143 | F10: 27.48 | G10: 29.985 | H10: 316.7 | I10: 581.409 | J10: 0.0013269444 | K10: FALSE | L10: FALSE | M10: FALSE
A11: 6 | B11: 1:55.269 | C11: 115.269 | D11: 35.161 | E11: 22.176 | F11: 27.692 | G11: 30.24 | H11: 319.5 | I11: 696.678 | J11: 0.0013341319 | K11: TRUE | L11: FALSE | M11: FALSE
A12: 7 | B12: 1:54.716 | C12: 114.716 | D12: 35.078 | E12: 22.041 | F12: 27.589 | G12: 30.008 | H12: 316.7 | I12: 811.394 | J12: 0.0013277315 | K12: FALSE | L12: FALSE | M12: FALSE
A13: 8 | B13: 1:54.641 | C13: 114.641 | D13: 35.196 | E13: 22.081 | F13: 27.466 | G13: 29.898 | H13: 314.8 | I13: 926.035 | J13: 0.0013268634 | K13: FALSE | L13: FALSE | M13: FALSE
A14: 9 | B14: 1:54.810 | C14: 114.81 | D14: 35.18 | E14: 22.204 | F14: 27.506 | G14: 29.92 | H14: 316.7 | I14: 1040.845 | J14: 0.0013288194 | K14: FALSE | L14: FALSE | M14: FALSE
A15: 10 | B15: 1:54.577 | C15: 114.577 | D15: 35.055 | E15: 22.091 | F15: 27.48 | G15: 29.951 | H15: 319.5 | I15: 1155.422 | J15: 0.0013261227 | K15: FALSE | L15: FALSE | M15: FALSE
A16: 11 | B16: 1:55.123 | C16: 115.123 | D16: 35.139 | E16: 22.311 | F16: 27.669 | G16: 30.004 | H16: 318.5 | I16: 1270.545 | J16: 0.0013324421 | K16: FALSE | L16: FALSE | M16: FALSE
A17: 12 | B17: 1:54.579 | C17: 114.579 | D17: 35.146 | E17: 22.136 | F17: 27.456 | G17: 29.841 | H17: 317.6 | I17: 1385.124 | J17: 0.0013261458 | K17: FALSE | L17: FALSE | M17: FALSE
... A26: 21 | B26: 1:55.541 | C26: 115.541 | D26: 35.077 | E26: 22.18 | F26: 27.522 | G26: 30.762 | H26: 318.5 | I26: 2417.657 | J26: 0.0013372801 | K26: FALSE | L26: FALSE | M26: FALSE

Sheet Jack Miller
A1: 16. Jack MILLER #43
A3: Team | B3: Prima Pramac Yamaha MotoGP | C3: Manufacturer | D3: YAMAHA | E3: Nationality | F3: AUS | G3: Total Laps | H3: 21 | I3: Valid Laps | J3: 20 | K3: Front Tyre | L3: Slick-Medium | M3: Rear Tyre | N3: Slick-Medium
A5: Lap | B5: Lap Time | C5: Lap Seconds | D5: T1 | E5: T2 | F5: T3 | G5: T4 | H5: Speed km/h | I5: Cumulative Seconds | J5: Excel Time | K5: Cancelled | L5: Pit Lane | M5: Partial Timing
A6: 1 | B6: 2:02.781 | C6: 122.781 | D6: 41.933 | E6: 22.786 | F6: 27.765 | G6: 30.297 | H6: 251.1 | I6: 122.781 | J6: 0.0014210764 | K6: FALSE | L6: FALSE | M6: FALSE
A7: 2 | B7: 1:55.291 | C7: 115.291 | D7: 35.316 | E7: 22.346 | F7: 27.515 | G7: 30.114 | H7: 310.3 | I7: 238.072 | J7: 0.0013343866 | K7: FALSE | L7: FALSE | M7: FALSE
A8: 3 | B8: 1:54.897 | C8: 114.897 | D8: 35.157 | E8: 22.192 | F8: 27.532 | G8: 30.016 | H8: 313.9 | I8: 352.969 | J8: 0.0013298264 | K8: FALSE | L8: FALSE | M8: FALSE
A9: 4 | B9: 1:55.001 | C9: 115.001 | D9: 35.164 | E9: 22.161 | F9: 27.58 | G9: 30.096 | H9: 314.8 | I9: 467.97 | J9: 0.0013310301 | K9: FALSE | L9: FALSE | M9: FALSE
A10: 5 | B10: 1:55.025 | C10: 115.025 | D10: 35.269 | E10: 22.199 | F10: 27.536 | G10: 30.021 | H10: 313.9 | I10: 582.995 | J10: 0.0013313079 | K10: FALSE | L10: FALSE | M10: FALSE
A11: 6 | B11: 1:55.555 | C11: 115.555 | D11: 35.364 | E11: 22.238 | F11: 27.673 | G11: 30.28 | H11: 314.8 | I11: 698.55 | J11: 0.0013374421 | K11: FALSE | L11: FALSE | M11: FALSE
A12: 7 | B12: 1:55.153 | C12: 115.153 | D12: 35.259 | E12: 22.22 | F12: 27.52 | G12: 30.154 | H12: 311.2 | I12: 813.703 | J12: 0.0013327894 | K12: FALSE | L12: FALSE | M12: FALSE
A13: 8 | B13: 1:54.896 | C13: 114.896 | D13: 35.19 | E13: 22.183 | F13: 27.515 | G13: 30.008 | H13: 313 | I13: 928.599 | J13: 0.0013298148 | K13: FALSE | L13: FALSE | M13: FALSE
A14: 9 | B14: 1:54.915 | C14: 114.915 | D14: 35.266 | E14: 22.167 | F14: 27.487 | G14: 29.995 | H14: 313.9 | I14: 1043.514 | J14: 0.0013300347 | K14: FALSE | L14: FALSE | M14: FALSE
A15: 10 | B15: 1:54.965 | C15: 114.965 | D15: 35.228 | E15: 22.163 | F15: 27.449 | G15: 30.125 | H15: 313 | I15: 1158.479 | J15: 0.0013306134 | K15: FALSE | L15: FALSE | M15: FALSE
A16: 11 | B16: 1:55.024 | C16: 115.024 | D16: 35.186 | E16: 22.214 | F16: 27.546 | G16: 30.078 | H16: 313 | I16: 1273.503 | J16: 0.0013312963 | K16: FALSE | L16: FALSE | M16: FALSE
A17: 12 | B17: 1:54.908 | C17: 114.908 | D17: 35.193 | E17: 22.188 | F17: 27.455 | G17: 30.072 | H17: 313 | I17: 1388.411 | J17: 0.0013299537 | K17: FALSE | L17: FALSE | M17: FALSE
... A26: 21 | B26: 1:55.169 | C26: 115.169 | D26: 35.263 | E26: 22.23 | F26: 27.541 | G26: 30.135 | H26: 311.2 | I26: 2424.418 | J26: 0.0013329745 | K26: FALSE | L26: FALSE | M26: FALSE

Sheet Cal Crutchlow
A1: 17. Cal CRUTCHLOW #35
A3: Team | B3: Castrol Honda LCR | C3: Manufacturer | D3: HONDA | E3: Nationality | F3: GBR | G3: Total Laps | H3: 21 | I3: Valid Laps | J3: 18 | K3: Front Tyre | L3: Slick-Medium | M3: Rear Tyre | N3: Slick-Medium
A5: Lap | B5: Lap Time | C5: Lap Seconds | D5: T1 | E5: T2 | F5: T3 | G5: T4 | H5: Speed km/h | I5: Cumulative Seconds | J5: Excel Time | K5: Cancelled | L5: Pit Lane | M5: Partial Timing
A6: 1 | B6: 2:03.136 | C6: 123.136 | D6: 42.012 | E6: 23.059 | F6: 27.859 | G6: 30.206 | H6: 257.7 | I6: 123.136 | J6: 0.0014251852 | K6: FALSE | L6: FALSE | M6: FALSE
A7: 2 | B7: 1:55.231 | C7: 115.231 | D7: 35.236 | E7: 22.281 | F7: 27.65 | G7: 30.064 | H7: 314.8 | I7: 238.367 | J7: 0.0013336921 | K7: FALSE | L7: FALSE | M7: FALSE
A8: 3 | B8: 1:55.113 | C8: 115.113 | D8: 35.222 | E8: 22.217 | F8: 27.532 | G8: 30.142 | H8: 314.8 | I8: 353.48 | J8: 0.0013323264 | K8: FALSE | L8: FALSE | M8: FALSE
A9: 4 | B9: 1:55.036 | C9: 115.036 | D9: 35.237 | E9: 22.177 | F9: 27.532 | G9: 30.09 | H9: 316.7 | I9: 468.516 | J9: 0.0013314352 | K9: FALSE | L9: FALSE | M9: FALSE
A10: 5 | B10: 1:54.910 | C10: 114.91 | D10: 35.177 | E10: 22.163 | F10: 27.572 | G10: 29.998 | H10: 315.7 | I10: 583.426 | J10: 0.0013299769 | K10: FALSE | L10: FALSE | M10: FALSE
A11: 6 | B11: 1:55.454 | C11: 115.454 | D11: 35.358 | E11: 22.231 | F11: 27.725 | G11: 30.14 | H11: 314.8 | I11: 698.88 | J11: 0.0013362731 | K11: TRUE | L11: FALSE | M11: FALSE
A12: 7 | B12: 1:55.383 | C12: 115.383 | D12: 35.387 | E12: 22.22 | F12: 27.653 | G12: 30.123 | H12: 314.8 | I12: 814.263 | J12: 0.0013354514 | K12: FALSE | L12: FALSE | M12: FALSE
A13: 8 | B13: 1:55.986 | C13: 115.986 | D13: 35.399 | E13: 22.222 | F13: 27.728 | G13: 30.637 | H13: 316.7 | I13: 930.249 | J13: 0.0013424306 | K13: FALSE | L13: FALSE | M13: FALSE
A14: 9 | B14: 1:55.571 | C14: 115.571 | D14: 35.529 | E14: 22.246 | F14: 27.766 | G14: 30.03 | H14: 311.2 | I14: 1045.82 | J14: 0.0013376273 | K14: FALSE | L14: FALSE | M14: FALSE
A15: 10 | B15: 1:55.323 | C15: 115.323 | D15: 35.349 | E15: 22.329 | F15: 27.575 | G15: 30.07 | H15: 316.7 | I15: 1161.143 | J15: 0.0013347569 | K15: FALSE | L15: FALSE | M15: FALSE
A16: 11 | B16: 1:55.200 | C16: 115.2 | D16: 35.268 | E16: 22.206 | F16: 27.611 | G16: 30.115 | H16: 315.7 | I16: 1276.343 | J16: 0.0013333333 | K16: FALSE | L16: FALSE | M16: FALSE
A17: 12 | B17: 1:55.347 | C17: 115.347 | D17: 35.433 | E17: 22.255 | F17: 27.548 | G17: 30.111 | H17: 316.7 | I17: 1391.69 | J17: 0.0013350347 | K17: FALSE | L17: FALSE | M17: FALSE
... A26: 21 | B26: 1:57.420 | C26: 117.42 | D26: 35.769 | E26: 22.63 | F26: 28.208 | G26: 30.813 | H26: 312.1 | I26: 2436.081 | J26: 0.0013590278 | K26: FALSE | L26: FALSE | M26: FALSE

Sheet Pedro Acosta
A1: 18. Pedro ACOSTA #37
A3: Team | B3: Red Bull KTM Factory Racing | C3: Manufacturer | D3: KTM | E3: Nationality | F3: SPA | G3: Total Laps | H3: 20 | I3: Valid Laps | J3: 16 | K3: Front Tyre | L3: Slick-Medium | M3: Rear Tyre | N3: Slick-Medium
A5: Lap | B5: Lap Time | C5: Lap Seconds | D5: T1 | E5: T2 | F5: T3 | G5: T4 | H5: Speed km/h | I5: Cumulative Seconds | J5: Excel Time | K5: Cancelled | L5: Pit Lane | M5: Partial Timing
A6: 1 | B6: 1:59.723 | C6: 119.723 | D6: 40.468 | E6: 22.095 | F6: 27.263 | G6: 29.897 | H6: 245.4 | I6: 119.723 | J6: 0.0013856829 | K6: FALSE | L6: FALSE | M6: FALSE
A7: 2 | B7: 1:54.443 | C7: 114.443 | D7: 34.836 | E7: 22.019 | F7: 27.412 | G7: 30.176 | H7: 319.5 | I7: 234.166 | J7: 0.0013245718 | K7: FALSE | L7: FALSE | M7: FALSE
A8: 3 | B8: 1:54.002 | C8: 114.002 | D8: 34.898 | E8: 21.984 | F8: 27.284 | G8: 29.836 | H8: 317.6 | I8: 348.168 | J8: 0.0013194676 | K8: FALSE | L8: FALSE | M8: FALSE
A9: 4 | B9: 1:53.916 | C9: 113.916 | D9: 34.835 | E9: 21.967 | F9: 27.354 | G9: 29.76 | H9: 320.4 | I9: 462.084 | J9: 0.0013184722 | K9: FALSE | L9: FALSE | M9: FALSE
A10: 5 | B10: 1:53.539 | C10: 113.539 | D10: 34.767 | E10: 21.904 | F10: 27.196 | G10: 29.672 | H10: 317.6 | I10: 575.623 | J10: 0.0013141088 | K10: FALSE | L10: FALSE | M10: FALSE
A11: 6 | B11: 1:53.734 | C11: 113.734 | D11: 34.792 | E11: 21.987 | F11: 27.241 | G11: 29.714 | H11: 316.7 | I11: 689.357 | J11: 0.0013163657 | K11: FALSE | L11: FALSE | M11: FALSE
A12: 7 | B12: 1:53.631 | C12: 113.631 | D12: 34.748 | E12: 21.947 | F12: 27.237 | G12: 29.699 | H12: 318.5 | I12: 802.988 | J12: 0.0013151736 | K12: FALSE | L12: FALSE | M12: FALSE
A13: 8 | B13: 1:53.882 | C13: 113.882 | D13: 34.85 | E13: 21.955 | F13: 27.354 | G13: 29.723 | H13: 317.6 | I13: 916.87 | J13: 0.0013180787 | K13: TRUE | L13: FALSE | M13: FALSE
A14: 9 | B14: 1:54.121 | C14: 114.121 | D14: 34.982 | E14: 22.082 | F14: 27.347 | G14: 29.71 | H14: 318.5 | I14: 1030.991 | J14: 0.0013208449 | K14: FALSE | L14: FALSE | M14: FALSE
A15: 10 | B15: 1:54.556 | C15: 114.556 | D15: 34.851 | E15: 21.982 | F15: 27.823 | G15: 29.9 | H15: 316.7 | I15: 1145.547 | J15: 0.0013258796 | K15: FALSE | L15: FALSE | M15: FALSE
A16: 11 | B16: 1:53.789 | C16: 113.789 | D16: 34.79 | E16: 21.955 | F16: 27.342 | G16: 29.702 | H16: 316.7 | I16: 1259.336 | J16: 0.0013170023 | K16: FALSE | L16: FALSE | M16: FALSE
A17: 12 | B17: 1:53.667 | C17: 113.667 | D17: 34.733 | E17: 21.938 | F17: 27.179 | G17: 29.817 | H17: 315.7 | I17: 1373.003 | J17: 0.0013155903 | K17: FALSE | L17: FALSE | M17: FALSE
... A25: 20 | B25: 1:54.059 | C25: 114.059 | D25: 34.826 | E25: 22.007 | F25: 27.323 | G25: 29.903 | H25: 314.8 | I25: 2288.751 | J25: 0.0013201273 | K25: FALSE | L25: FALSE | M25: FALSE

Sheet Alex Rins
A1: 19. Alex RINS #42
A3: Team | B3: Monster Energy Yamaha MotoGP Team | C3: Manufacturer | D3: YAMAHA | E3: Nationality | F3: SPA | G3: Total Laps | H3: 17 | I3: Valid Laps | J3: 15 | K3: Front Tyre | L3: Slick-Medium | M3: Rear Tyre | N3: Slick-Medium
A5: Lap | B5: Lap Time | C5: Lap Seconds | D5: T1 | E5: T2 | F5: T3 | G5: T4 | H5: Speed km/h | I5: Cumulative Seconds | J5: Excel Time | K5: Cancelled | L5: Pit Lane | M5: Partial Timing
A6: 1 | B6: 2:02.489 | C6: 122.489 | D6: 41.735 | E6: 22.606 | F6: 27.674 | G6: 30.474 | H6: 255.9 | I6: 122.489 | J6: 0.0014176968 | K6: FALSE | L6: FALSE | M6: FALSE
A7: 2 | B7: 1:55.164 | C7: 115.164 | D7: 35.156 | E7: 22.331 | F7: 27.72 | G7: 29.957 | H7: 312.1 | I7: 237.653 | J7: 0.0013329167 | K7: FALSE | L7: FALSE | M7: FALSE
A8: 3 | B8: 1:54.848 | C8: 114.848 | D8: 35.02 | E8: 22.274 | F8: 27.463 | G8: 30.091 | H8: 317.6 | I8: 352.501 | J8: 0.0013292593 | K8: FALSE | L8: FALSE | M8: FALSE
A9: 4 | B9: 1:55.147 | C9: 115.147 | D9: 35.067 | E9: 22.346 | F9: 27.529 | G9: 30.205 | H9: 317.6 | I9: 467.648 | J9: 0.0013327199 | K9: FALSE | L9: FALSE | M9: FALSE
A10: 5 | B10: 1:55.094 | C10: 115.094 | D10: 35.007 | E10: 22.129 | F10: 27.402 | G10: 30.556 | H10: 315.7 | I10: 582.742 | J10: 0.0013321065 | K10: FALSE | L10: FALSE | M10: FALSE
A11: 6 | B11: 1:55.927 | C11: 115.927 | D11: 35.412 | E11: 22.107 | F11: 28.127 | G11: 30.281 | H11: 313 | I11: 698.669 | J11: 0.0013417477 | K11: FALSE | L11: FALSE | M11: FALSE
A12: 7 | B12: 1:55.244 | C12: 115.244 | D12: 35.258 | E12: 22.246 | F12: 27.57 | G12: 30.17 | H12: 310.3 | I12: 813.913 | J12: 0.0013338426 | K12: FALSE | L12: FALSE | M12: FALSE
A13: 8 | B13: 1:56.160 | C13: 116.16 | D13: 35.229 | E13: 22.215 | F13: 28.215 | G13: 30.501 | H13: 316.7 | I13: 930.073 | J13: 0.0013444444 | K13: FALSE | L13: FALSE | M13: FALSE
A14: 9 | B14: 1:55.059 | C14: 115.059 | D14: 35.256 | E14: 22.181 | F14: 27.635 | G14: 29.987 | H14: 313.9 | I14: 1045.132 | J14: 0.0013317014 | K14: FALSE | L14: FALSE | M14: FALSE
A15: 10 | B15: 1:54.834 | C15: 114.834 | D15: 35.031 | E15: 22.123 | F15: 27.604 | G15: 30.076 | H15: 315.7 | I15: 1159.966 | J15: 0.0013290972 | K15: FALSE | L15: FALSE | M15: FALSE
A16: 11 | B16: 1:55.399 | C16: 115.399 | D16: 35.193 | E16: 22.119 | F16: 27.511 | G16: 30.576 | H16: 316.7 | I16: 1275.365 | J16: 0.0013356366 | K16: FALSE | L16: FALSE | M16: FALSE
A17: 12 | B17: 1:54.889 | C17: 114.889 | D17: 35.016 | E17: 22.11 | F17: 27.553 | G17: 30.21 | H17: 314.8 | I17: 1390.254 | J17: 0.0013297338 | K17: FALSE | L17: FALSE | M17: FALSE
... A22: 17 | B22: 2:13.660 | C22: 133.66 | D22: 35.289 | E22: 22.633 | F22: 29.01 | G22: 46.728 | H22: 313 | I22: 1984.025 | J22: 0.0015469907 | K22: FALSE | L22: TRUE | M22: FALSE

Sheet Fabio Quartararo
A1: 20. Fabio QUARTARARO #20
A3: Team | B3: Monster Energy Yamaha MotoGP Team | C3: Manufacturer | D3: YAMAHA | E3: Nationality | F3: FRA | G3: Total Laps | H3: 1 | I3: Valid Laps | J3: 0 | K3: Front Tyre | L3: Slick-Medium | M3: Rear Tyre | N3: Slick-Medium
A5: Lap | B5: Lap Time | C5: Lap Seconds | D5: T1 | E5: T2 | F5: T3 | G5: T4 | H5: Speed km/h | I5: Cumulative Seconds | J5: Excel Time | K5: Cancelled | L5: Pit Lane | M5: Partial Timing
A6: 1 | B6: 2:01.824 | C6: 121.824 | D6: 41.568 | E6: 22.354 | F6: 27.631 | G6: 30.271 | H6: 249.4 | I6: 121.824 | J6: 0.00141 | K6: FALSE | L6: FALSE | M6: FALSE

Sheet Race Data
A1: Rider | B1: Number | C1: Position | D1: Team | E1: Manufacturer | F1: Nationality | G1: Total Laps | H1: Valid Laps | I1: Lap | J1: Lap Time | K1: Lap Seconds | L1: T1 | M1: T2 | N1: T3 | O1: T4 | P1: Speed km/h | Q1: Cumulative Seconds | R1: Cancelled | S1: Pit Lane | T1: Partial Timing
A2: Marc MARQUEZ | B2: 93 | C2: 1 | D2: Ducati Lenovo Team | E2: DUCATI | F2: SPA | G2: 21 | H2: 20 | I2: 1 | J2: 1:59.409 | K2: 119.409 | L2: 39.947 | M2: 22.202 | N2: 27.272 | O2: 29.988 | P2: 242.1 | Q2: 119.409 | R2: FALSE | S2: FALSE | T2: FALSE
A3: Marc MARQUEZ | B3: 93 | C3: 1 | D3: Ducati Lenovo Team | E3: DUCATI | F3: SPA | G3: 21 | H3: 20 | I3: 2 | J3: 1:54.189 | K3: 114.189 | L3: 34.875 | M3: 22.09 | N3: 27.289 | O3: 29.935 | P3: 319.5 | Q3: 233.598 | R3: FALSE | S3: FALSE | T3: FALSE
A4: Marc MARQUEZ | B4: 93 | C4: 1 | D4: Ducati Lenovo Team | E4: DUCATI | F4: SPA | G4: 21 | H4: 20 | I4: 3 | J4: 1:53.613 | K4: 113.613 | L4: 34.751 | M4: 21.969 | N4: 27.19 | O4: 29.703 | P4: 320.4 | Q4: 347.211 | R4: FALSE | S4: FALSE | T4: FALSE
A5: Marc MARQUEZ | B5: 93 | C5: 1 | D5: Ducati Lenovo Team | E5: DUCATI | F5: SPA | G5: 21 | H5: 20 | I5: 4 | J5: 1:53.639 | K5: 113.639 | L5: 34.871 | M5: 21.861 | N5: 27.222 | O5: 29.685 | P5: 319.5 | Q5: 460.85 | R5: FALSE | S5: FALSE | T5: FALSE
A6: Marc MARQUEZ | B6: 93 | C6: 1 | D6: Ducati Lenovo Team | E6: DUCATI | F6: SPA | G6: 21 | H6: 20 | I6: 5 | J6: 1:53.907 | K6: 113.907 | L6: 34.878 | M6: 21.838 | N6: 27.313 | O6: 29.878 | P6: 319.5 | Q6: 574.757 | R6: FALSE | S6: FALSE | T6: FALSE
A7: Marc MARQUEZ | B7: 93 | C7: 1 | D7: Ducati Lenovo Team | E7: DUCATI | F7: SPA | G7: 21 | H7: 20 | I7: 6 | J7: 1:53.642 | K7: 113.642 | L7: 34.906 | M7: 21.861 | N7: 27.18 | O7: 29.695 | P7: 319.5 | Q7: 688.399 | R7: FALSE | S7: FALSE | T7: FALSE
A8: Marc MARQUEZ | B8: 93 | C8: 1 | D8: Ducati Lenovo Team | E8: DUCATI | F8: SPA | G8: 21 | H8: 20 | I8: 7 | J8: 1:53.437 | K8: 113.437 | L8: 34.752 | M8: 21.798 | N8: 27.168 | O8: 29.719 | P8: 319.5 | Q8: 801.836 | R8: FALSE | S8: FALSE | T8: FALSE
A9: Marc MARQUEZ | B9: 93 | C9: 1 | D9: Ducati Lenovo Team | E9: DUCATI | F9: SPA | G9: 21 | H9: 20 | I9: 8 | J9: 1:53.648 | K9: 113.648 | L9: 34.796 | M9: 21.871 | N9: 27.259 | O9: 29.722 | P9: 319.5 | Q9: 915.484 | R9: FALSE | S9: FALSE | T9: FALSE
A10: Marc MARQUEZ | B10: 93 | C10: 1 | D10: Ducati Lenovo Team | E10: DUCATI | F10: SPA | G10: 21 | H10: 20 | I10: 9 | J10: 1:53.507 | K10: 113.507 | L10: 34.702 | M10: 21.92 | N10: 27.296 | O10: 29.589 | P10: 320.4 | Q10: 1028.991 | R10: FALSE | S10: FALSE | T10: FALSE
A11: Marc MARQUEZ | B11: 93 | C11: 1 | D11: Ducati Lenovo Team | E11: DUCATI | F11: SPA | G11: 21 | H11: 20 | I11: 10 | J11: 1:53.449 | K11: 113.449 | L11: 34.706 | M11: 21.885 | N11: 27.234 | O11: 29.624 | P11: 320.4 | Q11: 1142.44 | R11: FALSE | S11: FALSE | T11: FALSE
A12: Marc MARQUEZ | B12: 93 | C12: 1 | D12: Ducati Lenovo Team | E12: DUCATI | F12: SPA | G12: 21 | H12: 20 | I12: 11 | J12: 1:53.619 | K12: 113.619 | L12: 34.694 | M12: 21.978 | N12: 27.208 | O12: 29.739 | P12: 322.3 | Q12: 1256.059 | R12: FALSE | S12: FALSE | T12: FALSE
A13: Marc MARQUEZ | B13: 93 | C13: 1 | D13: Ducati Lenovo Team | E13: DUCATI | F13: SPA | G13: 21 | H13: 20 | I13: 12 | J13: 1:53.842 | K13: 113.842 | L13: 34.882 | M13: 21.982 | N13: 27.297 | O13: 29.681 | P13: 321.4 | Q13: 1369.901 | R13: FALSE | S13: FALSE | T13: FALSE
... A396: Fabio QUARTARARO | B396: 20 | C396: 20 | D396: Monster Energy Yamaha MotoGP Team | E396: YAMAHA | F396: FRA | G396: 1 | H396: 0 | I396: 1 | J396: 2:01.824 | K396: 121.824 | L396: 41.568 | M396: 22.354 | N396: 27.631 | O396: 30.271 | P396: 249.4 | Q396: 121.824 | R396: FALSE | S396: FALSE | T396: FALSE

Sheet Race Progress
A1: MONSTER ENERGY GRAND PRIX OF CZECHIA i3 - Rider Lap Time Analysis
A2: CREDITAS Autodrom Brno | B2: Brno, Sunday, June 21, 2026
A3: Show | B3: Rider | C3: Color | E3: Lap | F3: Marc MARQUEZ | G3: Ai OGURA | H3: Francesco BAGNAIA | I3: Fabio DI GIANNANTONIO | J3: Joan MIR | K3: Fermin ALDEGUER | L3: Raul FERNANDEZ | M3: Luca MARINI | N3: Jorge MARTIN | O3: Enea BASTIANINI | P3: Diogo MOREIRA | Q3: Brad BINDER | R3: Franco MORBIDELLI | S3: Toprak RAZGATLIOGLU | T3: Maverick VIÑALES | U3: Jack MILLER | V3: Cal CRUTCHLOW | W3: Pedro ACOSTA | X3: Alex RINS | Y3: Fabio QUARTARARO
A4: TRUE | B4: Marc MARQUEZ | C4: #A0B73A | E4: 1 | F4: =IF($A$4,'Marc Marquez'!J6,NA()) -> #N/A | G4: =IF($A$5,'Ai Ogura'!J6,NA()) -> #N/A | H4: =IF($A$6,'Francesco Bagnaia'!J6,NA()) -> #N/A | I4: =IF($A$7,'Fabio Di Giannantonio'!J6,NA()) -> #N/A | J4: =IF($A$8,'Joan Mir'!J6,NA()) -> #N/A | K4: =IF($A$9,'Fermin Aldeguer'!J6,NA()) -> #N/A | L4: =IF($A$10,'Raul Fernandez'!J6,NA()) -> #N/A | M4: =IF($A$11,'Luca Marini'!J6,NA()) -> #N/A | N4: =IF($A$12,'Jorge Martin'!J6,NA()) -> #N/A | O4: =IF($A$13,'Enea Bastianini'!J6,NA()) -> #N/A | P4: =IF($A$14,'Diogo Moreira'!J6,NA()) -> #N/A | Q4: =IF($A$15,'Brad Binder'!J6,NA()) -> #N/A | R4: =IF($A$16,'Franco Morbidelli'!J6,NA()) -> #N/A | S4: =IF($A$17,'Toprak Razgatlioglu'!J6,NA()) -> #N/A | T4: =IF($A$18,'Maverick Viñales'!J6,NA()) -> #N/A | U4: =IF($A$19,'Jack Miller'!J6,NA()) -> #N/A | V4: =IF($A$20,'Cal Crutchlow'!J6,NA()) -> #N/A | W4: =IF($A$21,'Pedro Acosta'!J6,NA()) -> #N/A | X4: =IF($A$22,'Alex Rins'!J6,NA()) -> #N/A | Y4: =IF($A$23,'Fabio Quartararo'!J6,NA()) -> #N/A
A5: TRUE | B5: Ai OGURA | C5: #CD28E0 | E5: 2 | F5: =IF($A$4,'Marc Marquez'!J7,NA()) -> #N/A | G5: =IF($A$5,'Ai Ogura'!J7,NA()) -> #N/A | H5: =IF($A$6,'Francesco Bagnaia'!J7,NA()) -> #N/A | I5: =IF($A$7,'Fabio Di Giannantonio'!J7,NA()) -> #N/A | J5: =IF($A$8,'Joan Mir'!J7,NA()) -> #N/A | K5: =IF($A$9,'Fermin Aldeguer'!J7,NA()) -> #N/A | L5: =IF($A$10,'Raul Fernandez'!J7,NA()) -> #N/A | M5: =IF($A$11,'Luca Marini'!J7,NA()) -> #N/A | N5: =IF($A$12,'Jorge Martin'!J7,NA()) -> #N/A | O5: =IF($A$13,'Enea Bastianini'!J7,NA()) -> #N/A | P5: =IF($A$14,'Diogo Moreira'!J7,NA()) -> #N/A | Q5: =IF($A$15,'Brad Binder'!J7,NA()) -> #N/A | R5: =IF($A$16,'Franco Morbidelli'!J7,NA()) -> #N/A | S5: =IF($A$17,'Toprak Razgatlioglu'!J7,NA()) -> #N/A | T5: =IF($A$18,'Maverick Viñales'!J7,NA()) -> #N/A | U5: =IF($A$19,'Jack Miller'!J7,NA()) -> #N/A | V5: =IF($A$20,'Cal Crutchlow'!J7,NA()) -> #N/A | W5: =IF($A$21,'Pedro Acosta'!J7,NA()) -> #N/A | X5: =IF($A$22,'Alex Rins'!J7,NA()) -> #N/A | Y5: =NA() -> #N/A
