Workbook

Sheet Marco Bezzecchi
A1: 1. Marco BEZZECCHI #72
A3: Team | B3: Aprilia Racing | C3: Manufacturer | D3: APRILIA | E3: Nationality | F3: ITA | G3: Total Laps | H3: 20 | I3: Valid Laps | J3: 19 | K3: Front Tyre | L3: Slick-Medium | M3: Rear Tyre | N3: Slick-Medium
A5: Lap | B5: Lap Time | C5: Lap Seconds | D5: T1 | E5: T2 | F5: T3 | G5: T4 | H5: Speed km/h | I5: Cumulative Seconds | J5: Excel Time | K5: Cancelled | L5: Pit Lane | M5: Partial Timing
A6: 1 | B6: 2:03.203 | C6: 123.203 | D6: 34.609 | E6: 30.024 | F6: 34.247 | G6: 24.323 | H6: 332.7 | I6: 123.203 | J6: 0.0014259606 | K6: FALSE | L6: FALSE | M6: FALSE
A7: 2 | B7: 2:02.426 | C7: 122.426 | D7: 34.401 | E7: 29.604 | F7: 34.103 | G7: 24.318 | H7: 335.9 | I7: 245.629 | J7: 0.0014169676 | K7: FALSE | L7: FALSE | M7: FALSE
A8: 3 | B8: 2:02.324 | C8: 122.324 | D8: 34.472 | E8: 29.577 | F8: 33.992 | G8: 24.283 | H8: 335.9 | I8: 367.953 | J8: 0.001415787 | K8: FALSE | L8: FALSE | M8: FALSE
A9: 4 | B9: 2:02.360 | C9: 122.36 | D9: 34.488 | E9: 29.473 | F9: 34.067 | G9: 24.332 | H9: 336.9 | I9: 490.313 | J9: 0.0014162037 | K9: FALSE | L9: FALSE | M9: FALSE
A10: 5 | B10: 2:02.157 | C10: 122.157 | D10: 34.303 | E10: 29.467 | F10: 33.973 | G10: 24.414 | H10: 338 | I10: 612.47 | J10: 0.0014138542 | K10: FALSE | L10: FALSE | M10: FALSE
A11: 6 | B11: 2:02.114 | C11: 122.114 | D11: 34.407 | E11: 29.468 | F11: 33.909 | G11: 24.33 | H11: 339.1 | I11: 734.584 | J11: 0.0014133565 | K11: FALSE | L11: FALSE | M11: FALSE
A12: 7 | B12: 2:02.295 | C12: 122.295 | D12: 34.371 | E12: 29.549 | F12: 33.88 | G12: 24.495 | H12: 340.2 | I12: 856.879 | J12: 0.0014154514 | K12: FALSE | L12: FALSE | M12: FALSE
A13: 8 | B13: 2:02.633 | C13: 122.633 | D13: 34.572 | E13: 29.61 | F13: 33.92 | G13: 24.531 | H13: 340.2 | I13: 979.512 | J13: 0.0014193634 | K13: FALSE | L13: FALSE | M13: FALSE
A14: 9 | B14: 2:02.718 | C14: 122.718 | D14: 34.62 | E14: 29.732 | F14: 33.936 | G14: 24.43 | H14: 340.2 | I14: 1102.23 | J14: 0.0014203472 | K14: FALSE | L14: FALSE | M14: FALSE
A15: 10 | B15: 2:02.115 | C15: 122.115 | D15: 34.272 | E15: 29.582 | F15: 33.888 | G15: 24.373 | H15: 340.2 | I15: 1224.345 | J15: 0.0014133681 | K15: FALSE | L15: FALSE | M15: FALSE
A16: 11 | B16: 2:02.470 | C16: 122.47 | D16: 34.481 | E16: 29.53 | F16: 34.053 | G16: 24.406 | H16: 339.1 | I16: 1346.815 | J16: 0.0014174769 | K16: FALSE | L16: FALSE | M16: FALSE
A17: 12 | B17: 2:02.440 | C17: 122.44 | D17: 34.414 | E17: 29.652 | F17: 33.951 | G17: 24.423 | H17: 340.2 | I17: 1469.255 | J17: 0.0014171296 | K17: FALSE | L17: FALSE | M17: FALSE
... A25: 20 | B25: 2:02.899 | C25: 122.899 | D25: 34.578 | E25: 29.626 | F25: 34.106 | G25: 24.589 | H25: 340.2 | I25: 2450.653 | J25: 0.0014224421 | K25: FALSE | L25: FALSE | M25: FALSE

Sheet Jorge Martin
A1: 2. Jorge MARTIN #89
A3: Team | B3: Aprilia Racing | C3: Manufacturer | D3: APRILIA | E3: Nationality | F3: SPA | G3: Total Laps | H3: 20 | I3: Valid Laps | J3: 19 | K3: Front Tyre | L3: Slick-Medium | M3: Rear Tyre | N3: Slick-Medium
A5: Lap | B5: Lap Time | C5: Lap Seconds | D5: T1 | E5: T2 | F5: T3 | G5: T4 | H5: Speed km/h | I5: Cumulative Seconds | J5: Excel Time | K5: Cancelled | L5: Pit Lane | M5: Partial Timing
A6: 1 | B6: 2:03.611 | C6: 123.611 | D6: 35.001 | E6: 30.014 | F6: 34.265 | G6: 24.331 | H6: 339.1 | I6: 123.611 | J6: 0.0014306829 | K6: FALSE | L6: FALSE | M6: FALSE
A7: 2 | B7: 2:02.459 | C7: 122.459 | D7: 34.449 | E7: 29.441 | F7: 34.18 | G7: 24.389 | H7: 340.2 | I7: 246.07 | J7: 0.0014173495 | K7: FALSE | L7: FALSE | M7: FALSE
A8: 3 | B8: 2:02.408 | C8: 122.408 | D8: 34.579 | E8: 29.465 | F8: 34.027 | G8: 24.337 | H8: 339.1 | I8: 368.478 | J8: 0.0014167593 | K8: FALSE | L8: FALSE | M8: FALSE
A9: 4 | B9: 2:02.256 | C9: 122.256 | D9: 34.427 | E9: 29.4 | F9: 34.032 | G9: 24.397 | H9: 340.2 | I9: 490.734 | J9: 0.001415 | K9: FALSE | L9: FALSE | M9: FALSE
A10: 5 | B10: 2:02.564 | C10: 122.564 | D10: 34.58 | E10: 29.416 | F10: 34.16 | G10: 24.408 | H10: 339.1 | I10: 613.298 | J10: 0.0014185648 | K10: FALSE | L10: FALSE | M10: FALSE
A11: 6 | B11: 2:02.433 | C11: 122.433 | D11: 34.518 | E11: 29.664 | F11: 33.961 | G11: 24.29 | H11: 340.2 | I11: 735.731 | J11: 0.0014170486 | K11: FALSE | L11: FALSE | M11: FALSE
A12: 7 | B12: 2:03.313 | C12: 123.313 | D12: 35.316 | E12: 29.582 | F12: 33.95 | G12: 24.465 | H12: 339.1 | I12: 859.044 | J12: 0.0014272338 | K12: FALSE | L12: FALSE | M12: FALSE
A13: 8 | B13: 2:02.335 | C13: 122.335 | D13: 34.425 | E13: 29.505 | F13: 33.948 | G13: 24.457 | H13: 339.1 | I13: 981.379 | J13: 0.0014159144 | K13: FALSE | L13: FALSE | M13: FALSE
A14: 9 | B14: 2:02.386 | C14: 122.386 | D14: 34.575 | E14: 29.401 | F14: 34.021 | G14: 24.389 | H14: 339.1 | I14: 1103.765 | J14: 0.0014165046 | K14: FALSE | L14: FALSE | M14: FALSE
A15: 10 | B15: 2:02.754 | C15: 122.754 | D15: 34.606 | E15: 29.639 | F15: 34.013 | G15: 24.496 | H15: 341.3 | I15: 1226.519 | J15: 0.0014207639 | K15: FALSE | L15: FALSE | M15: FALSE
A16: 11 | B16: 2:02.358 | C16: 122.358 | D16: 34.552 | E16: 29.457 | F16: 33.929 | G16: 24.42 | H16: 341.3 | I16: 1348.877 | J16: 0.0014161806 | K16: FALSE | L16: FALSE | M16: FALSE
A17: 12 | B17: 2:02.417 | C17: 122.417 | D17: 34.625 | E17: 29.463 | F17: 33.975 | G17: 24.354 | H17: 340.2 | I17: 1471.294 | J17: 0.0014168634 | K17: FALSE | L17: FALSE | M17: FALSE
... A25: 20 | B25: 2:03.736 | C25: 123.736 | D25: 34.798 | E25: 29.699 | F25: 34.347 | G25: 24.892 | H25: 340.2 | I25: 2452.689 | J25: 0.0014321296 | K25: FALSE | L25: FALSE | M25: FALSE

Sheet Pedro Acosta
A1: 3. Pedro ACOSTA #37
A3: Team | B3: Red Bull KTM Factory Racing | C3: Manufacturer | D3: KTM | E3: Nationality | F3: SPA | G3: Total Laps | H3: 20 | I3: Valid Laps | J3: 18 | K3: Front Tyre | L3: Slick-Medium | M3: Rear Tyre | N3: Slick-Medium
A5: Lap | B5: Lap Time | C5: Lap Seconds | D5: T1 | E5: T2 | F5: T3 | G5: T4 | H5: Speed km/h | I5: Cumulative Seconds | J5: Excel Time | K5: Cancelled | L5: Pit Lane | M5: Partial Timing
A6: 1 | B6: 2:03.423 | C6: 123.423 | D6: 34.459 | E6: 30.366 | F6: 34.238 | G6: 24.36 | H6: 332.7 | I6: 123.423 | J6: 0.0014285069 | K6: FALSE | L6: FALSE | M6: FALSE
A7: 2 | B7: 2:02.410 | C7: 122.41 | D7: 34.395 | E7: 29.55 | F7: 34.128 | G7: 24.337 | H7: 335.9 | I7: 245.833 | J7: 0.0014167824 | K7: FALSE | L7: FALSE | M7: FALSE
A8: 3 | B8: 2:02.393 | C8: 122.393 | D8: 34.601 | E8: 29.405 | F8: 34.108 | G8: 24.279 | H8: 334.8 | I8: 368.226 | J8: 0.0014165856 | K8: FALSE | L8: FALSE | M8: FALSE
A9: 4 | B9: 2:02.359 | C9: 122.359 | D9: 34.483 | E9: 29.446 | F9: 34.031 | G9: 24.399 | H9: 336.9 | I9: 490.585 | J9: 0.0014161921 | K9: FALSE | L9: FALSE | M9: FALSE
A10: 5 | B10: 2:02.299 | C10: 122.299 | D10: 34.383 | E10: 29.468 | F10: 34.045 | G10: 24.403 | H10: 335.9 | I10: 612.884 | J10: 0.0014154977 | K10: FALSE | L10: FALSE | M10: FALSE
A11: 6 | B11: 2:02.663 | C11: 122.663 | D11: 34.598 | E11: 29.666 | F11: 34.031 | G11: 24.368 | H11: 333.7 | I11: 735.547 | J11: 0.0014197106 | K11: FALSE | L11: FALSE | M11: FALSE
A12: 7 | B12: 2:02.524 | C12: 122.524 | D12: 34.486 | E12: 29.549 | F12: 33.968 | G12: 24.521 | H12: 335.9 | I12: 858.071 | J12: 0.0014181019 | K12: FALSE | L12: FALSE | M12: FALSE
A13: 8 | B13: 2:02.534 | C13: 122.534 | D13: 34.616 | E13: 29.478 | F13: 33.931 | G13: 24.509 | H13: 335.9 | I13: 980.605 | J13: 0.0014182176 | K13: FALSE | L13: FALSE | M13: FALSE
A14: 9 | B14: 2:02.446 | C14: 122.446 | D14: 34.531 | E14: 29.554 | F14: 33.968 | G14: 24.393 | H14: 336.9 | I14: 1103.051 | J14: 0.0014171991 | K14: FALSE | L14: FALSE | M14: FALSE
A15: 10 | B15: 2:02.451 | C15: 122.451 | D15: 34.598 | E15: 29.5 | F15: 33.972 | G15: 24.381 | H15: 335.9 | I15: 1225.502 | J15: 0.0014172569 | K15: FALSE | L15: FALSE | M15: FALSE
A16: 11 | B16: 2:02.645 | C16: 122.645 | D16: 34.666 | E16: 29.465 | F16: 34.033 | G16: 24.481 | H16: 336.9 | I16: 1348.147 | J16: 0.0014195023 | K16: FALSE | L16: FALSE | M16: FALSE
A17: 12 | B17: 2:02.283 | C17: 122.283 | D17: 34.434 | E17: 29.521 | F17: 33.969 | G17: 24.359 | H17: 338 | I17: 1470.43 | J17: 0.0014153125 | K17: FALSE | L17: FALSE | M17: FALSE
... A25: 20 | B25: 2:03.738 | C25: 123.738 | D25: 34.996 | E25: 29.776 | F25: 34.243 | G25: 24.723 | H25: 335.9 | I25: 2455.15 | J25: 0.0014321528 | K25: FALSE | L25: FALSE | M25: FALSE

Sheet Fabio Di Giannantonio
A1: 4. Fabio DI GIANNANTONIO #49
A3: Team | B3: Pertamina Enduro VR46 Racing Team | C3: Manufacturer | D3: DUCATI | E3: Nationality | F3: ITA | G3: Total Laps | H3: 20 | I3: Valid Laps | J3: 18 | K3: Front Tyre | L3: Slick-Medium | M3: Rear Tyre | N3: Slick-Medium
A5: Lap | B5: Lap Time | C5: Lap Seconds | D5: T1 | E5: T2 | F5: T3 | G5: T4 | H5: Speed km/h | I5: Cumulative Seconds | J5: Excel Time | K5: Cancelled | L5: Pit Lane | M5: Partial Timing
A6: 1 | B6: 2:04.148 | C6: 124.148 | D6: 35.272 | E6: 29.98 | F6: 34.463 | G6: 24.433 | H6: 339.1 | I6: 124.148 | J6: 0.0014368981 | K6: FALSE | L6: FALSE | M6: FALSE
A7: 2 | B7: 2:03.184 | C7: 123.184 | D7: 34.922 | E7: 29.905 | F7: 34.056 | G7: 24.301 | H7: 332.7 | I7: 247.332 | J7: 0.0014257407 | K7: FALSE | L7: FALSE | M7: FALSE
A8: 3 | B8: 2:02.222 | C8: 122.222 | D8: 34.328 | E8: 29.565 | F8: 33.999 | G8: 24.33 | H8: 335.9 | I8: 369.554 | J8: 0.0014146065 | K8: FALSE | L8: FALSE | M8: FALSE
A9: 4 | B9: 2:02.179 | C9: 122.179 | D9: 34.351 | E9: 29.56 | F9: 33.881 | G9: 24.387 | H9: 336.9 | I9: 491.733 | J9: 0.0014141088 | K9: FALSE | L9: FALSE | M9: FALSE
A10: 5 | B10: 2:02.436 | C10: 122.436 | D10: 34.413 | E10: 29.609 | F10: 34.014 | G10: 24.4 | H10: 336.9 | I10: 614.169 | J10: 0.0014170833 | K10: FALSE | L10: FALSE | M10: FALSE
A11: 6 | B11: 2:02.336 | C11: 122.336 | D11: 34.316 | E11: 29.625 | F11: 34.025 | G11: 24.37 | H11: 339.1 | I11: 736.505 | J11: 0.0014159259 | K11: FALSE | L11: FALSE | M11: FALSE
A12: 7 | B12: 2:02.925 | C12: 122.925 | D12: 34.661 | E12: 29.807 | F12: 33.994 | G12: 24.463 | H12: 341.3 | I12: 859.43 | J12: 0.0014227431 | K12: FALSE | L12: FALSE | M12: FALSE
A13: 8 | B13: 2:02.571 | C13: 122.571 | D13: 34.429 | E13: 29.597 | F13: 34.101 | G13: 24.444 | H13: 339.1 | I13: 982.001 | J13: 0.0014186458 | K13: FALSE | L13: FALSE | M13: FALSE
A14: 9 | B14: 2:02.443 | C14: 122.443 | D14: 34.405 | E14: 29.624 | F14: 33.933 | G14: 24.481 | H14: 341.3 | I14: 1104.444 | J14: 0.0014171644 | K14: FALSE | L14: FALSE | M14: FALSE
A15: 10 | B15: 2:02.808 | C15: 122.808 | D15: 34.53 | E15: 29.613 | F15: 34.143 | G15: 24.522 | H15: 338 | I15: 1227.252 | J15: 0.0014213889 | K15: FALSE | L15: FALSE | M15: FALSE
A16: 11 | B16: 2:02.437 | C16: 122.437 | D16: 34.419 | E16: 29.636 | F16: 34.03 | G16: 24.352 | H16: 339.1 | I16: 1349.689 | J16: 0.0014170949 | K16: FALSE | L16: FALSE | M16: FALSE
A17: 12 | B17: 2:02.710 | C17: 122.71 | D17: 34.418 | E17: 29.765 | F17: 34.04 | G17: 24.487 | H17: 341.3 | I17: 1472.399 | J17: 0.0014202546 | K17: FALSE | L17: FALSE | M17: FALSE
... A25: 20 | B25: 2:03.404 | C25: 123.404 | D25: 34.695 | E25: 29.877 | F25: 34.281 | G25: 24.551 | H25: 338 | I25: 2457.625 | J25: 0.001428287 | K25: FALSE | L25: FALSE | M25: FALSE

Sheet Marc Marquez
A1: 5. Marc MARQUEZ #93
A3: Team | B3: Ducati Lenovo Team | C3: Manufacturer | D3: DUCATI | E3: Nationality | F3: SPA | G3: Total Laps | H3: 20 | I3: Valid Laps | J3: 19 | K3: Front Tyre | L3: Slick-Medium | M3: Rear Tyre | N3: Slick-Medium
A5: Lap | B5: Lap Time | C5: Lap Seconds | D5: T1 | E5: T2 | F5: T3 | G5: T4 | H5: Speed km/h | I5: Cumulative Seconds | J5: Excel Time | K5: Cancelled | L5: Pit Lane | M5: Partial Timing
A6: 1 | B6: 2:04.330 | C6: 124.33 | D6: 35.157 | E6: 29.94 | F6: 34.465 | G6: 24.768 | H6: 336.9 | I6: 124.33 | J6: 0.0014390046 | K6: FALSE | L6: FALSE | M6: FALSE
A7: 2 | B7: 2:03.976 | C7: 123.976 | D7: 35.04 | E7: 30.227 | F7: 34.273 | G7: 24.436 | H7: 341.3 | I7: 248.306 | J7: 0.0014349074 | K7: FALSE | L7: FALSE | M7: FALSE
A8: 3 | B8: 2:02.887 | C8: 122.887 | D8: 34.717 | E8: 29.63 | F8: 34.093 | G8: 24.447 | H8: 342.4 | I8: 371.193 | J8: 0.0014223032 | K8: FALSE | L8: FALSE | M8: FALSE
A9: 4 | B9: 2:05.392 | C9: 125.392 | D9: 34.444 | E9: 29.582 | F9: 36.737 | G9: 24.629 | H9: 346.9 | I9: 496.585 | J9: 0.0014512963 | K9: FALSE | L9: FALSE | M9: FALSE
A10: 5 | B10: 2:02.888 | C10: 122.888 | D10: 34.542 | E10: 29.672 | F10: 34.232 | G10: 24.442 | H10: 343.5 | I10: 619.473 | J10: 0.0014223148 | K10: FALSE | L10: FALSE | M10: FALSE
A11: 6 | B11: 2:02.461 | C11: 122.461 | D11: 34.412 | E11: 29.482 | F11: 34.137 | G11: 24.43 | H11: 344.7 | I11: 741.934 | J11: 0.0014173727 | K11: FALSE | L11: FALSE | M11: FALSE
A12: 7 | B12: 2:02.266 | C12: 122.266 | D12: 34.363 | E12: 29.54 | F12: 33.95 | G12: 24.413 | H12: 342.4 | I12: 864.2 | J12: 0.0014151157 | K12: FALSE | L12: FALSE | M12: FALSE
A13: 8 | B13: 2:02.358 | C13: 122.358 | D13: 34.483 | E13: 29.412 | F13: 33.974 | G13: 24.489 | H13: 342.4 | I13: 986.558 | J13: 0.0014161806 | K13: FALSE | L13: FALSE | M13: FALSE
A14: 9 | B14: 2:02.485 | C14: 122.485 | D14: 34.685 | E14: 29.506 | F14: 33.858 | G14: 24.436 | H14: 342.4 | I14: 1109.043 | J14: 0.0014176505 | K14: FALSE | L14: FALSE | M14: FALSE
A15: 10 | B15: 2:02.529 | C15: 122.529 | D15: 34.495 | E15: 29.547 | F15: 33.985 | G15: 24.502 | H15: 341.3 | I15: 1231.572 | J15: 0.0014181597 | K15: FALSE | L15: FALSE | M15: FALSE
A16: 11 | B16: 2:02.184 | C16: 122.184 | D16: 34.387 | E16: 29.368 | F16: 33.917 | G16: 24.512 | H16: 342.4 | I16: 1353.756 | J16: 0.0014141667 | K16: FALSE | L16: FALSE | M16: FALSE
A17: 12 | B17: 2:02.133 | C17: 122.133 | D17: 34.423 | E17: 29.419 | F17: 33.92 | G17: 24.371 | H17: 344.7 | I17: 1475.889 | J17: 0.0014135764 | K17: FALSE | L17: FALSE | M17: FALSE
... A25: 20 | B25: 2:02.457 | C25: 122.457 | D25: 34.578 | E25: 29.417 | F25: 33.973 | G25: 24.489 | H25: 342.4 | I25: 2458.753 | J25: 0.0014173264 | K25: FALSE | L25: FALSE | M25: FALSE

Sheet Enea Bastianini
A1: 6. Enea BASTIANINI #23
A3: Team | B3: Red Bull KTM Tech3 | C3: Manufacturer | D3: KTM | E3: Nationality | F3: ITA | G3: Total Laps | H3: 20 | I3: Valid Laps | J3: 19 | K3: Front Tyre | L3: Slick-Medium | M3: Rear Tyre | N3: Slick-Medium
A5: Lap | B5: Lap Time | C5: Lap Seconds | D5: T1 | E5: T2 | F5: T3 | G5: T4 | H5: Speed km/h | I5: Cumulative Seconds | J5: Excel Time | K5: Cancelled | L5: Pit Lane | M5: Partial Timing
A6: 1 | B6: 2:06.004 | C6: 126.004 | D6: 36.311 | E6: 30.295 | F6: 34.881 | G6: 24.517 | H6: 339.1 | I6: 126.004 | J6: 0.0014583796 | K6: FALSE | L6: FALSE | M6: FALSE
A7: 2 | B7: 2:03.416 | C7: 123.416 | D7: 34.744 | E7: 30.361 | F7: 33.905 | G7: 24.406 | H7: 343.5 | I7: 249.42 | J7: 0.0014284259 | K7: FALSE | L7: FALSE | M7: FALSE
A8: 3 | B8: 2:03.452 | C8: 123.452 | D8: 34.624 | E8: 29.687 | F8: 34.689 | G8: 24.452 | H8: 336.9 | I8: 372.872 | J8: 0.0014288426 | K8: FALSE | L8: FALSE | M8: FALSE
A9: 4 | B9: 2:02.280 | C9: 122.28 | D9: 34.457 | E9: 29.523 | F9: 33.913 | G9: 24.387 | H9: 335.9 | I9: 495.152 | J9: 0.0014152778 | K9: FALSE | L9: FALSE | M9: FALSE
A10: 5 | B10: 2:02.399 | C10: 122.399 | D10: 34.513 | E10: 29.505 | F10: 33.994 | G10: 24.387 | H10: 336.9 | I10: 617.551 | J10: 0.0014166551 | K10: FALSE | L10: FALSE | M10: FALSE
A11: 6 | B11: 2:02.259 | C11: 122.259 | D11: 34.42 | E11: 29.613 | F11: 33.901 | G11: 24.325 | H11: 339.1 | I11: 739.81 | J11: 0.0014150347 | K11: FALSE | L11: FALSE | M11: FALSE
A12: 7 | B12: 2:02.502 | C12: 122.502 | D12: 34.479 | E12: 29.584 | F12: 34.032 | G12: 24.407 | H12: 341.3 | I12: 862.312 | J12: 0.0014178472 | K12: FALSE | L12: FALSE | M12: FALSE
A13: 8 | B13: 2:02.315 | C13: 122.315 | D13: 34.366 | E13: 29.526 | F13: 33.937 | G13: 24.486 | H13: 342.4 | I13: 984.627 | J13: 0.0014156829 | K13: FALSE | L13: FALSE | M13: FALSE
A14: 9 | B14: 2:02.506 | C14: 122.506 | D14: 34.615 | E14: 29.51 | F14: 34.04 | G14: 24.341 | H14: 340.2 | I14: 1107.133 | J14: 0.0014178935 | K14: FALSE | L14: FALSE | M14: FALSE
A15: 10 | B15: 2:02.698 | C15: 122.698 | D15: 34.387 | E15: 29.618 | F15: 34.21 | G15: 24.483 | H15: 336.9 | I15: 1229.831 | J15: 0.0014201157 | K15: FALSE | L15: FALSE | M15: FALSE
A16: 11 | B16: 2:02.385 | C16: 122.385 | D16: 34.443 | E16: 29.483 | F16: 34.037 | G16: 24.422 | H16: 338 | I16: 1352.216 | J16: 0.0014164931 | K16: FALSE | L16: FALSE | M16: FALSE
A17: 12 | B17: 2:02.602 | C17: 122.602 | D17: 34.524 | E17: 29.575 | F17: 33.995 | G17: 24.508 | H17: 341.3 | I17: 1474.818 | J17: 0.0014190046 | K17: FALSE | L17: FALSE | M17: FALSE
... A25: 20 | B25: 2:02.461 | C25: 122.461 | D25: 34.625 | E25: 29.386 | F25: 34.067 | G25: 24.383 | H25: 345.8 | I25: 2458.896 | J25: 0.0014173727 | K25: FALSE | L25: FALSE | M25: FALSE

Sheet Alex Marquez
A1: 7. Alex MARQUEZ #73
A3: Team | B3: BK8 Gresini Racing MotoGP | C3: Manufacturer | D3: DUCATI | E3: Nationality | F3: SPA | G3: Total Laps | H3: 20 | I3: Valid Laps | J3: 17 | K3: Front Tyre | L3: Slick-Medium | M3: Rear Tyre | N3: Slick-Medium
A5: Lap | B5: Lap Time | C5: Lap Seconds | D5: T1 | E5: T2 | F5: T3 | G5: T4 | H5: Speed km/h | I5: Cumulative Seconds | J5: Excel Time | K5: Cancelled | L5: Pit Lane | M5: Partial Timing
A6: 1 | B6: 2:04.724 | C6: 124.724 | D6: 35.7 | E6: 29.853 | F6: 34.725 | G6: 24.446 | H6: 330.6 | I6: 124.724 | J6: 0.0014435648 | K6: FALSE | L6: FALSE | M6: FALSE
A7: 2 | B7: 2:03.939 | C7: 123.939 | D7: 35.018 | E7: 30.125 | F7: 34.354 | G7: 24.442 | H7: 338 | I7: 248.663 | J7: 0.0014344792 | K7: FALSE | L7: FALSE | M7: FALSE
A8: 3 | B8: 2:02.826 | C8: 122.826 | D8: 34.595 | E8: 29.586 | F8: 34.306 | G8: 24.339 | H8: 341.3 | I8: 371.489 | J8: 0.0014215972 | K8: FALSE | L8: FALSE | M8: FALSE
A9: 4 | B9: 2:02.856 | C9: 122.856 | D9: 34.39 | E9: 29.802 | F9: 34.256 | G9: 24.408 | H9: 342.4 | I9: 494.345 | J9: 0.0014219444 | K9: FALSE | L9: FALSE | M9: FALSE
A10: 5 | B10: 2:02.291 | C10: 122.291 | D10: 34.236 | E10: 29.52 | F10: 34.15 | G10: 24.385 | H10: 341.3 | I10: 616.636 | J10: 0.0014154051 | K10: FALSE | L10: FALSE | M10: FALSE
A11: 6 | B11: 2:02.674 | C11: 122.674 | D11: 34.564 | E11: 29.771 | F11: 34.018 | G11: 24.321 | H11: 339.1 | I11: 739.31 | J11: 0.001419838 | K11: FALSE | L11: FALSE | M11: FALSE
A12: 7 | B12: 2:02.149 | C12: 122.149 | D12: 34.252 | E12: 29.465 | F12: 34.092 | G12: 24.34 | H12: 342.4 | I12: 861.459 | J12: 0.0014137616 | K12: FALSE | L12: FALSE | M12: FALSE
A13: 8 | B13: 2:02.330 | C13: 122.33 | D13: 34.314 | E13: 29.472 | F13: 34.072 | G13: 24.472 | H13: 342.4 | I13: 983.789 | J13: 0.0014158565 | K13: FALSE | L13: FALSE | M13: FALSE
A14: 9 | B14: 2:02.890 | C14: 122.89 | D14: 34.377 | E14: 29.799 | F14: 34.221 | G14: 24.493 | H14: 340.2 | I14: 1106.679 | J14: 0.001422338 | K14: FALSE | L14: FALSE | M14: FALSE
A15: 10 | B15: 2:02.758 | C15: 122.758 | D15: 34.376 | E15: 29.622 | F15: 34.205 | G15: 24.555 | H15: 344.7 | I15: 1229.437 | J15: 0.0014208102 | K15: TRUE | L15: FALSE | M15: FALSE
A16: 11 | B16: 2:02.470 | C16: 122.47 | D16: 34.396 | E16: 29.51 | F16: 34.059 | G16: 24.505 | H16: 342.4 | I16: 1351.907 | J16: 0.0014174769 | K16: FALSE | L16: FALSE | M16: FALSE
A17: 12 | B17: 2:02.663 | C17: 122.663 | D17: 34.365 | E17: 29.7 | F17: 34.114 | G17: 24.484 | H17: 344.7 | I17: 1474.57 | J17: 0.0014197106 | K17: FALSE | L17: FALSE | M17: FALSE
... A25: 20 | B25: 2:03.332 | C25: 123.332 | D25: 34.706 | E25: 29.85 | F25: 34.208 | G25: 24.568 | H25: 341.3 | I25: 2461.906 | J25: 0.0014274537 | K25: TRUE | L25: FALSE | M25: FALSE

Sheet Raul Fernandez
A1: 8. Raul FERNANDEZ #25
A3: Team | B3: Trackhouse MotoGP Team | C3: Manufacturer | D3: APRILIA | E3: Nationality | F3: SPA | G3: Total Laps | H3: 20 | I3: Valid Laps | J3: 18 | K3: Front Tyre | L3: Slick-Medium | M3: Rear Tyre | N3: Slick-Medium
A5: Lap | B5: Lap Time | C5: Lap Seconds | D5: T1 | E5: T2 | F5: T3 | G5: T4 | H5: Speed km/h | I5: Cumulative Seconds | J5: Excel Time | K5: Cancelled | L5: Pit Lane | M5: Partial Timing
A6: 1 | B6: 2:05.863 | C6: 125.863 | D6: 36.137 | E6: 30.215 | F6: 35.005 | G6: 24.506 | H6: 334.8 | I6: 125.863 | J6: 0.0014567477 | K6: FALSE | L6: FALSE | M6: FALSE
A7: 2 | B7: 2:03.867 | C7: 123.867 | D7: 34.975 | E7: 29.944 | F7: 34.524 | G7: 24.424 | H7: 336.9 | I7: 249.73 | J7: 0.0014336458 | K7: FALSE | L7: FALSE | M7: FALSE
A8: 3 | B8: 2:03.390 | C8: 123.39 | D8: 34.628 | E8: 29.789 | F8: 34.441 | G8: 24.532 | H8: 338 | I8: 373.12 | J8: 0.001428125 | K8: FALSE | L8: FALSE | M8: FALSE
A9: 4 | B9: 2:03.025 | C9: 123.025 | D9: 34.537 | E9: 29.833 | F9: 34.242 | G9: 24.413 | H9: 332.7 | I9: 496.145 | J9: 0.0014239005 | K9: FALSE | L9: FALSE | M9: FALSE
A10: 5 | B10: 2:02.880 | C10: 122.88 | D10: 34.438 | E10: 30.006 | F10: 34.111 | G10: 24.325 | H10: 332.7 | I10: 619.025 | J10: 0.0014222222 | K10: TRUE | L10: FALSE | M10: FALSE
A11: 6 | B11: 2:02.560 | C11: 122.56 | D11: 34.438 | E11: 29.754 | F11: 34.04 | G11: 24.328 | H11: 335.9 | I11: 741.585 | J11: 0.0014185185 | K11: FALSE | L11: FALSE | M11: FALSE
A12: 7 | B12: 2:03.183 | C12: 123.183 | D12: 34.407 | E12: 30.048 | F12: 34.306 | G12: 24.422 | H12: 339.1 | I12: 864.768 | J12: 0.0014257292 | K12: FALSE | L12: FALSE | M12: FALSE
A13: 8 | B13: 2:02.553 | C13: 122.553 | D13: 34.518 | E13: 29.565 | F13: 34.133 | G13: 24.337 | H13: 336.9 | I13: 987.321 | J13: 0.0014184375 | K13: FALSE | L13: FALSE | M13: FALSE
A14: 9 | B14: 2:02.413 | C14: 122.413 | D14: 34.437 | E14: 29.635 | F14: 34.049 | G14: 24.292 | H14: 338 | I14: 1109.734 | J14: 0.0014168171 | K14: FALSE | L14: FALSE | M14: FALSE
A15: 10 | B15: 2:02.675 | C15: 122.675 | D15: 34.409 | E15: 29.792 | F15: 34.068 | G15: 24.406 | H15: 335.9 | I15: 1232.409 | J15: 0.0014198495 | K15: FALSE | L15: FALSE | M15: FALSE
A16: 11 | B16: 2:02.483 | C16: 122.483 | D16: 34.357 | E16: 29.524 | F16: 34.201 | G16: 24.401 | H16: 338 | I16: 1354.892 | J16: 0.0014176273 | K16: FALSE | L16: FALSE | M16: FALSE
A17: 12 | B17: 2:02.510 | C17: 122.51 | D17: 34.434 | E17: 29.591 | F17: 34.071 | G17: 24.414 | H17: 338 | I17: 1477.402 | J17: 0.0014179398 | K17: FALSE | L17: FALSE | M17: FALSE
... A25: 20 | B25: 2:04.182 | C25: 124.182 | D25: 34.899 | E25: 29.965 | F25: 34.512 | G25: 24.806 | H25: 336.9 | I25: 2463.782 | J25: 0.0014372917 | K25: FALSE | L25: FALSE | M25: FALSE

Sheet Luca Marini
A1: 9. Luca MARINI #10
A3: Team | B3: Honda HRC Castrol | C3: Manufacturer | D3: HONDA | E3: Nationality | F3: ITA | G3: Total Laps | H3: 20 | I3: Valid Laps | J3: 19 | K3: Front Tyre | L3: Slick-Medium | M3: Rear Tyre | N3: Slick-Medium
A5: Lap | B5: Lap Time | C5: Lap Seconds | D5: T1 | E5: T2 | F5: T3 | G5: T4 | H5: Speed km/h | I5: Cumulative Seconds | J5: Excel Time | K5: Cancelled | L5: Pit Lane | M5: Partial Timing
A6: 1 | B6: 2:06.495 | C6: 126.495 | D6: 36.544 | E6: 30.397 | F6: 34.739 | G6: 24.815 | H6: 344.7 | I6: 126.495 | J6: 0.0014640625 | K6: FALSE | L6: FALSE | M6: FALSE
A7: 2 | B7: 2:03.938 | C7: 123.938 | D7: 34.647 | E7: 30.651 | F7: 34.103 | G7: 24.537 | H7: 340.2 | I7: 250.433 | J7: 0.0014344676 | K7: FALSE | L7: FALSE | M7: FALSE
A8: 3 | B8: 2:03.034 | C8: 123.034 | D8: 34.655 | E8: 29.64 | F8: 34.166 | G8: 24.573 | H8: 338 | I8: 373.467 | J8: 0.0014240046 | K8: FALSE | L8: FALSE | M8: FALSE
A9: 4 | B9: 2:03.509 | C9: 123.509 | D9: 34.607 | E9: 29.789 | F9: 34.422 | G9: 24.691 | H9: 335.9 | I9: 496.976 | J9: 0.0014295023 | K9: FALSE | L9: FALSE | M9: FALSE
A10: 5 | B10: 2:03.277 | C10: 123.277 | D10: 35.079 | E10: 29.688 | F10: 34.035 | G10: 24.475 | H10: 341.3 | I10: 620.253 | J10: 0.0014268171 | K10: FALSE | L10: FALSE | M10: FALSE
A11: 6 | B11: 2:02.719 | C11: 122.719 | D11: 34.52 | E11: 29.711 | F11: 33.997 | G11: 24.491 | H11: 338 | I11: 742.972 | J11: 0.0014203588 | K11: FALSE | L11: FALSE | M11: FALSE
A12: 7 | B12: 2:02.851 | C12: 122.851 | D12: 34.515 | E12: 29.734 | F12: 34.065 | G12: 24.537 | H12: 339.1 | I12: 865.823 | J12: 0.0014218866 | K12: FALSE | L12: FALSE | M12: FALSE
A13: 8 | B13: 2:02.789 | C13: 122.789 | D13: 34.583 | E13: 29.624 | F13: 34.03 | G13: 24.552 | H13: 339.1 | I13: 988.612 | J13: 0.001421169 | K13: FALSE | L13: FALSE | M13: FALSE
A14: 9 | B14: 2:02.457 | C14: 122.457 | D14: 34.501 | E14: 29.497 | F14: 33.983 | G14: 24.476 | H14: 340.2 | I14: 1111.069 | J14: 0.0014173264 | K14: FALSE | L14: FALSE | M14: FALSE
A15: 10 | B15: 2:02.802 | C15: 122.802 | D15: 34.603 | E15: 29.64 | F15: 34.018 | G15: 24.541 | H15: 336.9 | I15: 1233.871 | J15: 0.0014213194 | K15: FALSE | L15: FALSE | M15: FALSE
A16: 11 | B16: 2:02.612 | C16: 122.612 | D16: 34.561 | E16: 29.452 | F16: 34.113 | G16: 24.486 | H16: 339.1 | I16: 1356.483 | J16: 0.0014191204 | K16: FALSE | L16: FALSE | M16: FALSE
A17: 12 | B17: 2:02.682 | C17: 122.682 | D17: 34.583 | E17: 29.547 | F17: 34.02 | G17: 24.532 | H17: 339.1 | I17: 1479.165 | J17: 0.0014199306 | K17: FALSE | L17: FALSE | M17: FALSE
... A25: 20 | B25: 2:03.685 | C25: 123.685 | D25: 34.82 | E25: 29.581 | F25: 34.307 | G25: 24.977 | H25: 344.7 | I25: 2465.124 | J25: 0.0014315394 | K25: FALSE | L25: FALSE | M25: FALSE

Sheet Francesco Bagnaia
A1: 10. Francesco BAGNAIA #63
A3: Team | B3: Ducati Lenovo Team | C3: Manufacturer | D3: DUCATI | E3: Nationality | F3: ITA | G3: Total Laps | H3: 20 | I3: Valid Laps | J3: 17 | K3: Front Tyre | L3: Slick-Medium | M3: Rear Tyre | N3: Slick-Medium
A5: Lap | B5: Lap Time | C5: Lap Seconds | D5: T1 | E5: T2 | F5: T3 | G5: T4 | H5: Speed km/h | I5: Cumulative Seconds | J5: Excel Time | K5: Cancelled | L5: Pit Lane | M5: Partial Timing
A6: 1 | B6: 2:04.501 | C6: 124.501 | D6: 35.428 | E6: 29.89 | F6: 34.608 | G6: 24.575 | H6: 341.3 | I6: 124.501 | J6: 0.0014409838 | K6: FALSE | L6: FALSE | M6: FALSE
A7: 2 | B7: 2:03.268 | C7: 123.268 | D7: 34.883 | E7: 29.944 | F7: 34.039 | G7: 24.402 | H7: 340.2 | I7: 247.769 | J7: 0.001426713 | K7: FALSE | L7: FALSE | M7: FALSE
A8: 3 | B8: 2:02.502 | C8: 122.502 | D8: 34.418 | E8: 29.712 | F8: 34.028 | G8: 24.344 | H8: 338 | I8: 370.271 | J8: 0.0014178472 | K8: FALSE | L8: FALSE | M8: FALSE
A9: 4 | B9: 2:02.573 | C9: 122.573 | D9: 34.62 | E9: 29.668 | F9: 33.845 | G9: 24.44 | H9: 339.1 | I9: 492.844 | J9: 0.001418669 | K9: FALSE | L9: FALSE | M9: FALSE
A10: 5 | B10: 2:02.454 | C10: 122.454 | D10: 34.493 | E10: 29.558 | F10: 34.027 | G10: 24.376 | H10: 338 | I10: 615.298 | J10: 0.0014172917 | K10: FALSE | L10: FALSE | M10: FALSE
A11: 6 | B11: 2:02.305 | C11: 122.305 | D11: 34.504 | E11: 29.626 | F11: 33.781 | G11: 24.394 | H11: 339.1 | I11: 737.603 | J11: 0.0014155671 | K11: FALSE | L11: FALSE | M11: FALSE
A12: 7 | B12: 2:02.296 | C12: 122.296 | D12: 34.511 | E12: 29.597 | F12: 33.787 | G12: 24.401 | H12: 341.3 | I12: 859.899 | J12: 0.001415463 | K12: FALSE | L12: FALSE | M12: FALSE
A13: 8 | B13: 2:02.344 | C13: 122.344 | D13: 34.36 | E13: 29.603 | F13: 33.877 | G13: 24.504 | H13: 342.4 | I13: 982.243 | J13: 0.0014160185 | K13: FALSE | L13: FALSE | M13: FALSE
A14: 9 | B14: 2:02.620 | C14: 122.62 | D14: 34.418 | E14: 29.653 | F14: 33.931 | G14: 24.618 | H14: 344.7 | I14: 1104.863 | J14: 0.001419213 | K14: TRUE | L14: FALSE | M14: FALSE
A15: 10 | B15: 2:02.681 | C15: 122.681 | D15: 34.61 | E15: 29.624 | F15: 33.914 | G15: 24.533 | H15: 341.3 | I15: 1227.544 | J15: 0.001419919 | K15: FALSE | L15: FALSE | M15: FALSE
A16: 11 | B16: 2:03.165 | C16: 123.165 | D16: 34.474 | E16: 29.647 | F16: 34.109 | G16: 24.935 | H16: 342.4 | I16: 1350.709 | J16: 0.0014255208 | K16: FALSE | L16: FALSE | M16: FALSE
A17: 12 | B17: 2:02.838 | C17: 122.838 | D17: 34.583 | E17: 29.767 | F17: 33.965 | G17: 24.523 | H17: 343.5 | I17: 1473.547 | J17: 0.0014217361 | K17: FALSE | L17: FALSE | M17: FALSE
... A25: 20 | B25: 2:05.299 | C25: 125.299 | D25: 35.624 | E25: 30.135 | F25: 34.326 | G25: 25.214 | H25: 340.2 | I25: 2465.197 | J25: 0.0014502199 | K25: FALSE | L25: FALSE | M25: FALSE

Sheet Fermin Aldeguer
A1: 11. Fermin ALDEGUER #54
A3: Team | B3: BK8 Gresini Racing MotoGP | C3: Manufacturer | D3: DUCATI | E3: Nationality | F3: SPA | G3: Total Laps | H3: 20 | I3: Valid Laps | J3: 18 | K3: Front Tyre | L3: Slick-Medium | M3: Rear Tyre | N3: Slick-Medium
A5: Lap | B5: Lap Time | C5: Lap Seconds | D5: T1 | E5: T2 | F5: T3 | G5: T4 | H5: Speed km/h | I5: Cumulative Seconds | J5: Excel Time | K5: Cancelled | L5: Pit Lane | M5: Partial Timing
A6: 1 | B6: 2:05.115 | C6: 125.115 | D6: 35.9 | E6: 30.251 | F6: 34.441 | G6: 24.523 | H6: 336.9 | I6: 125.115 | J6: 0.0014480903 | K6: FALSE | L6: FALSE | M6: FALSE
A7: 2 | B7: 2:03.388 | C7: 123.388 | D7: 34.799 | E7: 29.921 | F7: 34.229 | G7: 24.439 | H7: 341.3 | I7: 248.503 | J7: 0.0014281019 | K7: FALSE | L7: FALSE | M7: FALSE
A8: 3 | B8: 2:04.227 | C8: 124.227 | D8: 35.094 | E8: 29.965 | F8: 34.723 | G8: 24.445 | H8: 333.7 | I8: 372.73 | J8: 0.0014378125 | K8: FALSE | L8: FALSE | M8: FALSE
A9: 4 | B9: 2:04.106 | C9: 124.106 | D9: 34.8 | E9: 30.279 | F9: 34.342 | G9: 24.685 | H9: 334.8 | I9: 496.836 | J9: 0.001436412 | K9: TRUE | L9: FALSE | M9: FALSE
A10: 5 | B10: 2:04.079 | C10: 124.079 | D10: 35.47 | E10: 29.77 | F10: 34.324 | G10: 24.515 | H10: 339.1 | I10: 620.915 | J10: 0.0014360995 | K10: FALSE | L10: FALSE | M10: FALSE
A11: 6 | B11: 2:03.329 | C11: 123.329 | D11: 34.643 | E11: 29.848 | F11: 34.374 | G11: 24.464 | H11: 334.8 | I11: 744.244 | J11: 0.001427419 | K11: FALSE | L11: FALSE | M11: FALSE
A12: 7 | B12: 2:02.918 | C12: 122.918 | D12: 34.559 | E12: 29.706 | F12: 34.144 | G12: 24.509 | H12: 338 | I12: 867.162 | J12: 0.001422662 | K12: FALSE | L12: FALSE | M12: FALSE
A13: 8 | B13: 2:03.082 | C13: 123.082 | D13: 34.581 | E13: 29.846 | F13: 34.135 | G13: 24.52 | H13: 338 | I13: 990.244 | J13: 0.0014245602 | K13: FALSE | L13: FALSE | M13: FALSE
A14: 9 | B14: 2:02.990 | C14: 122.99 | D14: 34.711 | E14: 29.733 | F14: 34.041 | G14: 24.505 | H14: 333.7 | I14: 1113.234 | J14: 0.0014234954 | K14: FALSE | L14: FALSE | M14: FALSE
A15: 10 | B15: 2:03.283 | C15: 123.283 | D15: 34.607 | E15: 29.949 | F15: 34.092 | G15: 24.635 | H15: 331.6 | I15: 1236.517 | J15: 0.0014268866 | K15: FALSE | L15: FALSE | M15: FALSE
A16: 11 | B16: 2:02.863 | C16: 122.863 | D16: 34.654 | E16: 29.69 | F16: 33.998 | G16: 24.521 | H16: 333.7 | I16: 1359.38 | J16: 0.0014220255 | K16: FALSE | L16: FALSE | M16: FALSE
A17: 12 | B17: 2:03.471 | C17: 123.471 | D17: 34.868 | E17: 29.778 | F17: 34.178 | G17: 24.647 | H17: 334.8 | I17: 1482.851 | J17: 0.0014290625 | K17: FALSE | L17: FALSE | M17: FALSE
... A25: 20 | B25: 2:04.531 | C25: 124.531 | D25: 35.133 | E25: 30 | F25: 34.456 | G25: 24.942 | H25: 332.7 | I25: 2471.716 | J25: 0.001441331 | K25: FALSE | L25: FALSE | M25: FALSE

Sheet Brad Binder
A1: 12. Brad BINDER #33
A3: Team | B3: Red Bull KTM Factory Racing | C3: Manufacturer | D3: KTM | E3: Nationality | F3: RSA | G3: Total Laps | H3: 20 | I3: Valid Laps | J3: 19 | K3: Front Tyre | L3: Slick-Medium | M3: Rear Tyre | N3: Slick-Medium
A5: Lap | B5: Lap Time | C5: Lap Seconds | D5: T1 | E5: T2 | F5: T3 | G5: T4 | H5: Speed km/h | I5: Cumulative Seconds | J5: Excel Time | K5: Cancelled | L5: Pit Lane | M5: Partial Timing
A6: 1 | B6: 2:07.074 | C6: 127.074 | D6: 37.001 | E6: 30.277 | F6: 35.113 | G6: 24.683 | H6: 340.2 | I6: 127.074 | J6: 0.0014707639 | K6: FALSE | L6: FALSE | M6: FALSE
A7: 2 | B7: 2:04.528 | C7: 124.528 | D7: 34.85 | E7: 30.664 | F7: 34.163 | G7: 24.851 | H7: 342.4 | I7: 251.602 | J7: 0.0014412963 | K7: FALSE | L7: FALSE | M7: FALSE
A8: 3 | B8: 2:03.314 | C8: 123.314 | D8: 34.805 | E8: 29.724 | F8: 34.221 | G8: 24.564 | H8: 334.8 | I8: 374.916 | J8: 0.0014272454 | K8: FALSE | L8: FALSE | M8: FALSE
A9: 4 | B9: 2:03.698 | C9: 123.698 | D9: 34.79 | E9: 29.758 | F9: 34.541 | G9: 24.609 | H9: 334.8 | I9: 498.614 | J9: 0.0014316898 | K9: FALSE | L9: FALSE | M9: FALSE
A10: 5 | B10: 2:03.404 | C10: 123.404 | D10: 34.75 | E10: 29.653 | F10: 34.189 | G10: 24.812 | H10: 338 | I10: 622.018 | J10: 0.001428287 | K10: FALSE | L10: FALSE | M10: FALSE
A11: 6 | B11: 2:03.151 | C11: 123.151 | D11: 34.632 | E11: 29.776 | F11: 34.203 | G11: 24.54 | H11: 338 | I11: 745.169 | J11: 0.0014253588 | K11: FALSE | L11: FALSE | M11: FALSE
A12: 7 | B12: 2:02.854 | C12: 122.854 | D12: 34.72 | E12: 29.717 | F12: 33.963 | G12: 24.454 | H12: 339.1 | I12: 868.023 | J12: 0.0014219213 | K12: FALSE | L12: FALSE | M12: FALSE
A13: 8 | B13: 2:02.912 | C13: 122.912 | D13: 34.586 | E13: 29.614 | F13: 34.017 | G13: 24.695 | H13: 341.3 | I13: 990.935 | J13: 0.0014225926 | K13: FALSE | L13: FALSE | M13: FALSE
A14: 9 | B14: 2:03.258 | C14: 123.258 | D14: 34.723 | E14: 29.777 | F14: 34.14 | G14: 24.618 | H14: 339.1 | I14: 1114.193 | J14: 0.0014265972 | K14: FALSE | L14: FALSE | M14: FALSE
A15: 10 | B15: 2:03.341 | C15: 123.341 | D15: 34.768 | E15: 29.589 | F15: 34.332 | G15: 24.652 | H15: 341.3 | I15: 1237.534 | J15: 0.0014275579 | K15: FALSE | L15: FALSE | M15: FALSE
A16: 11 | B16: 2:03.451 | C16: 123.451 | D16: 34.761 | E16: 29.717 | F16: 34.302 | G16: 24.671 | H16: 342.4 | I16: 1360.985 | J16: 0.001428831 | K16: FALSE | L16: FALSE | M16: FALSE
A17: 12 | B17: 2:03.385 | C17: 123.385 | D17: 34.775 | E17: 29.697 | F17: 34.292 | G17: 24.621 | H17: 345.8 | I17: 1484.37 | J17: 0.0014280671 | K17: FALSE | L17: FALSE | M17: FALSE
... A25: 20 | B25: 2:03.853 | C25: 123.853 | D25: 34.888 | E25: 29.681 | F25: 34.464 | G25: 24.82 | H25: 336.9 | I25: 2472.715 | J25: 0.0014334838 | K25: FALSE | L25: FALSE | M25: FALSE

Sheet Diogo Moreira
A1: 13. Diogo MOREIRA #11
A3: Team | B3: Pro Honda LCR | C3: Manufacturer | D3: HONDA | E3: Nationality | F3: BRA | G3: Total Laps | H3: 20 | I3: Valid Laps | J3: 19 | K3: Front Tyre | L3: Slick-Medium | M3: Rear Tyre | N3: Slick-Medium
A5: Lap | B5: Lap Time | C5: Lap Seconds | D5: T1 | E5: T2 | F5: T3 | G5: T4 | H5: Speed km/h | I5: Cumulative Seconds | J5: Excel Time | K5: Cancelled | L5: Pit Lane | M5: Partial Timing
A6: 1 | B6: 2:06.599 | C6: 126.599 | D6: 36.444 | E6: 30.426 | F6: 35.009 | G6: 24.72 | H6: 336.9 | I6: 126.599 | J6: 0.0014652662 | K6: FALSE | L6: FALSE | M6: FALSE
A7: 2 | B7: 2:04.078 | C7: 124.078 | D7: 34.783 | E7: 30.549 | F7: 34.337 | G7: 24.409 | H7: 339.1 | I7: 250.677 | J7: 0.001436088 | K7: FALSE | L7: FALSE | M7: FALSE
A8: 3 | B8: 2:03.097 | C8: 123.097 | D8: 34.581 | E8: 29.828 | F8: 34.281 | G8: 24.407 | H8: 333.7 | I8: 373.774 | J8: 0.0014247338 | K8: FALSE | L8: FALSE | M8: FALSE
A9: 4 | B9: 2:03.425 | C9: 123.425 | D9: 34.642 | E9: 29.831 | F9: 34.363 | G9: 24.589 | H9: 335.9 | I9: 497.199 | J9: 0.0014285301 | K9: FALSE | L9: FALSE | M9: FALSE
A10: 5 | B10: 2:03.339 | C10: 123.339 | D10: 34.629 | E10: 29.81 | F10: 34.444 | G10: 24.456 | H10: 333.7 | I10: 620.538 | J10: 0.0014275347 | K10: FALSE | L10: FALSE | M10: FALSE
A11: 6 | B11: 2:02.947 | C11: 122.947 | D11: 34.498 | E11: 29.942 | F11: 33.995 | G11: 24.512 | H11: 333.7 | I11: 743.485 | J11: 0.0014229977 | K11: FALSE | L11: FALSE | M11: FALSE
A12: 7 | B12: 2:03.460 | C12: 123.46 | D12: 34.623 | E12: 29.948 | F12: 34.3 | G12: 24.589 | H12: 335.9 | I12: 866.945 | J12: 0.0014289352 | K12: FALSE | L12: FALSE | M12: FALSE
A13: 8 | B13: 2:03.093 | C13: 123.093 | D13: 34.555 | E13: 29.902 | F13: 34.066 | G13: 24.57 | H13: 335.9 | I13: 990.038 | J13: 0.0014246875 | K13: FALSE | L13: FALSE | M13: FALSE
A14: 9 | B14: 2:03.500 | C14: 123.5 | D14: 34.643 | E14: 30.067 | F14: 34.305 | G14: 24.485 | H14: 335.9 | I14: 1113.538 | J14: 0.0014293981 | K14: FALSE | L14: FALSE | M14: FALSE
A15: 10 | B15: 2:03.778 | C15: 123.778 | D15: 34.783 | E15: 29.834 | F15: 34.487 | G15: 24.674 | H15: 334.8 | I15: 1237.316 | J15: 0.0014326157 | K15: FALSE | L15: FALSE | M15: FALSE
A16: 11 | B16: 2:03.490 | C16: 123.49 | D16: 34.778 | E16: 29.8 | F16: 34.238 | G16: 24.674 | H16: 336.9 | I16: 1360.806 | J16: 0.0014292824 | K16: FALSE | L16: FALSE | M16: FALSE
A17: 12 | B17: 2:03.288 | C17: 123.288 | D17: 34.653 | E17: 29.901 | F17: 34.171 | G17: 24.563 | H17: 338 | I17: 1484.094 | J17: 0.0014269444 | K17: FALSE | L17: FALSE | M17: FALSE
... A25: 20 | B25: 2:03.355 | C25: 123.355 | D25: 34.677 | E25: 29.794 | F25: 34.208 | G25: 24.676 | H25: 336.9 | I25: 2472.854 | J25: 0.0014277199 | K25: FALSE | L25: FALSE | M25: FALSE

Sheet Franco Morbidelli
A1: 14. Franco MORBIDELLI #21
A3: Team | B3: Pertamina Enduro VR46 Racing Team | C3: Manufacturer | D3: DUCATI | E3: Nationality | F3: ITA | G3: Total Laps | H3: 20 | I3: Valid Laps | J3: 19 | K3: Front Tyre | L3: Slick-Medium | M3: Rear Tyre | N3: Slick-Medium
A5: Lap | B5: Lap Time | C5: Lap Seconds | D5: T1 | E5: T2 | F5: T3 | G5: T4 | H5: Speed km/h | I5: Cumulative Seconds | J5: Excel Time | K5: Cancelled | L5: Pit Lane | M5: Partial Timing
A6: 1 | B6: 2:07.361 | C6: 127.361 | D6: 37.136 | E6: 30.735 | F6: 34.866 | G6: 24.624 | H6: 332.7 | I6: 127.361 | J6: 0.0014740856 | K6: FALSE | L6: FALSE | M6: FALSE
A7: 2 | B7: 2:04.469 | C7: 124.469 | D7: 34.887 | E7: 30.648 | F7: 34.261 | G7: 24.673 | H7: 338 | I7: 251.83 | J7: 0.0014406134 | K7: FALSE | L7: FALSE | M7: FALSE
A8: 3 | B8: 2:03.523 | C8: 123.523 | D8: 34.792 | E8: 29.841 | F8: 34.268 | G8: 24.622 | H8: 335.9 | I8: 375.353 | J8: 0.0014296644 | K8: FALSE | L8: FALSE | M8: FALSE
A9: 4 | B9: 2:03.607 | C9: 123.607 | D9: 34.767 | E9: 29.836 | F9: 34.357 | G9: 24.647 | H9: 333.7 | I9: 498.96 | J9: 0.0014306366 | K9: FALSE | L9: FALSE | M9: FALSE
A10: 5 | B10: 2:03.310 | C10: 123.31 | D10: 34.83 | E10: 29.65 | F10: 34.251 | G10: 24.579 | H10: 338 | I10: 622.27 | J10: 0.0014271991 | K10: FALSE | L10: FALSE | M10: FALSE
A11: 6 | B11: 2:03.283 | C11: 123.283 | D11: 34.65 | E11: 29.822 | F11: 34.246 | G11: 24.565 | H11: 338 | I11: 745.553 | J11: 0.0014268866 | K11: FALSE | L11: FALSE | M11: FALSE
A12: 7 | B12: 2:02.967 | C12: 122.967 | D12: 34.717 | E12: 29.655 | F12: 34.123 | G12: 24.472 | H12: 339.1 | I12: 868.52 | J12: 0.0014232292 | K12: FALSE | L12: FALSE | M12: FALSE
A13: 8 | B13: 2:02.944 | C13: 122.944 | D13: 34.645 | E13: 29.7 | F13: 34.037 | G13: 24.562 | H13: 339.1 | I13: 991.464 | J13: 0.001422963 | K13: FALSE | L13: FALSE | M13: FALSE
A14: 9 | B14: 2:03.132 | C14: 123.132 | D14: 34.639 | E14: 29.747 | F14: 34.103 | G14: 24.643 | H14: 340.2 | I14: 1114.596 | J14: 0.0014251389 | K14: FALSE | L14: FALSE | M14: FALSE
A15: 10 | B15: 2:03.343 | C15: 123.343 | D15: 34.642 | E15: 29.822 | F15: 34.177 | G15: 24.702 | H15: 338 | I15: 1237.939 | J15: 0.001427581 | K15: FALSE | L15: FALSE | M15: FALSE
A16: 11 | B16: 2:03.286 | C16: 123.286 | D16: 34.8 | E16: 29.675 | F16: 34.223 | G16: 24.588 | H16: 339.1 | I16: 1361.225 | J16: 0.0014269213 | K16: FALSE | L16: FALSE | M16: FALSE
A17: 12 | B17: 2:03.429 | C17: 123.429 | D17: 34.78 | E17: 29.758 | F17: 34.227 | G17: 24.664 | H17: 336.9 | I17: 1484.654 | J17: 0.0014285764 | K17: FALSE | L17: FALSE | M17: FALSE
... A25: 20 | B25: 2:03.712 | C25: 123.712 | D25: 35.087 | E25: 29.793 | F25: 34.149 | G25: 24.683 | H25: 332.7 | I25: 2475.024 | J25: 0.0014318519 | K25: FALSE | L25: FALSE | M25: FALSE

Sheet Toprak Razgatlioglu
A1: 15. Toprak RAZGATLIOGLU #7
A3: Team | B3: Prima Pramac Yamaha MotoGP | C3: Manufacturer | D3: YAMAHA | E3: Nationality | F3: TUR | G3: Total Laps | H3: 20 | I3: Valid Laps | J3: 17 | K3: Front Tyre | L3: Slick-Medium | M3: Rear Tyre | N3: Slick-Medium
A5: Lap | B5: Lap Time | C5: Lap Seconds | D5: T1 | E5: T2 | F5: T3 | G5: T4 | H5: Speed km/h | I5: Cumulative Seconds | J5: Excel Time | K5: Cancelled | L5: Pit Lane | M5: Partial Timing
A6: 1 | B6: 2:07.725 | C6: 127.725 | D6: 37.147 | E6: 30.455 | F6: 35.396 | G6: 24.727 | H6: 336.9 | I6: 127.725 | J6: 0.0014782986 | K6: FALSE | L6: FALSE | M6: FALSE
A7: 2 | B7: 2:05.581 | C7: 125.581 | D7: 35.047 | E7: 31.393 | F7: 34.477 | G7: 24.664 | H7: 331.6 | I7: 253.306 | J7: 0.0014534838 | K7: TRUE | L7: FALSE | M7: FALSE
A8: 3 | B8: 2:03.318 | C8: 123.318 | D8: 34.599 | E8: 29.788 | F8: 34.372 | G8: 24.559 | H8: 334.8 | I8: 376.624 | J8: 0.0014272917 | K8: FALSE | L8: FALSE | M8: FALSE
A9: 4 | B9: 2:03.366 | C9: 123.366 | D9: 34.7 | E9: 29.788 | F9: 34.315 | G9: 24.563 | H9: 332.7 | I9: 499.99 | J9: 0.0014278472 | K9: FALSE | L9: FALSE | M9: FALSE
A10: 5 | B10: 2:03.449 | C10: 123.449 | D10: 34.868 | E10: 29.611 | F10: 34.385 | G10: 24.585 | H10: 334.8 | I10: 623.439 | J10: 0.0014288079 | K10: FALSE | L10: FALSE | M10: FALSE
A11: 6 | B11: 2:03.488 | C11: 123.488 | D11: 34.782 | E11: 29.893 | F11: 34.357 | G11: 24.456 | H11: 334.8 | I11: 746.927 | J11: 0.0014292593 | K11: FALSE | L11: FALSE | M11: FALSE
A12: 7 | B12: 2:03.422 | C12: 123.422 | D12: 34.688 | E12: 29.872 | F12: 34.31 | G12: 24.552 | H12: 334.8 | I12: 870.349 | J12: 0.0014284954 | K12: FALSE | L12: FALSE | M12: FALSE
A13: 8 | B13: 2:03.848 | C13: 123.848 | D13: 34.709 | E13: 29.7 | F13: 34.545 | G13: 24.894 | H13: 338 | I13: 994.197 | J13: 0.0014334259 | K13: FALSE | L13: FALSE | M13: FALSE
A14: 9 | B14: 2:03.428 | C14: 123.428 | D14: 34.766 | E14: 29.817 | F14: 34.258 | G14: 24.587 | H14: 334.8 | I14: 1117.625 | J14: 0.0014285648 | K14: FALSE | L14: FALSE | M14: FALSE
A15: 10 | B15: 2:03.278 | C15: 123.278 | D15: 34.665 | E15: 29.703 | F15: 34.233 | G15: 24.677 | H15: 333.7 | I15: 1240.903 | J15: 0.0014268287 | K15: FALSE | L15: FALSE | M15: FALSE
A16: 11 | B16: 2:03.071 | C16: 123.071 | D16: 34.636 | E16: 29.642 | F16: 34.23 | G16: 24.563 | H16: 336.9 | I16: 1363.974 | J16: 0.0014244329 | K16: FALSE | L16: FALSE | M16: FALSE
A17: 12 | B17: 2:03.326 | C17: 123.326 | D17: 34.628 | E17: 29.804 | F17: 34.287 | G17: 24.607 | H17: 335.9 | I17: 1487.3 | J17: 0.0014273843 | K17: FALSE | L17: FALSE | M17: FALSE
... A25: 20 | B25: 2:03.898 | C25: 123.898 | D25: 34.739 | E25: 29.767 | F25: 34.595 | G25: 24.797 | H25: 332.7 | I25: 2476.202 | J25: 0.0014340046 | K25: FALSE | L25: FALSE | M25: FALSE

Sheet Jack Miller
A1: 16. Jack MILLER #43
A3: Team | B3: Prima Pramac Yamaha MotoGP | C3: Manufacturer | D3: YAMAHA | E3: Nationality | F3: AUS | G3: Total Laps | H3: 20 | I3: Valid Laps | J3: 19 | K3: Front Tyre | L3: Slick-Medium | M3: Rear Tyre | N3: Slick-Medium
A5: Lap | B5: Lap Time | C5: Lap Seconds | D5: T1 | E5: T2 | F5: T3 | G5: T4 | H5: Speed km/h | I5: Cumulative Seconds | J5: Excel Time | K5: Cancelled | L5: Pit Lane | M5: Partial Timing
A6: 1 | B6: 2:07.538 | C6: 127.538 | D6: 37.338 | E6: 30.461 | F6: 35.12 | G6: 24.619 | H6: 339.1 | I6: 127.538 | J6: 0.0014761343 | K6: FALSE | L6: FALSE | M6: FALSE
A7: 2 | B7: 2:05.893 | C7: 125.893 | D7: 35.114 | E7: 31.516 | F7: 34.672 | G7: 24.591 | H7: 330.6 | I7: 253.431 | J7: 0.0014570949 | K7: FALSE | L7: FALSE | M7: FALSE
A8: 3 | B8: 2:03.649 | C8: 123.649 | D8: 34.884 | E8: 29.884 | F8: 34.372 | G8: 24.509 | H8: 331.6 | I8: 377.08 | J8: 0.0014311227 | K8: FALSE | L8: FALSE | M8: FALSE
A9: 4 | B9: 2:03.335 | C9: 123.335 | D9: 34.709 | E9: 29.695 | F9: 34.333 | G9: 24.598 | H9: 333.7 | I9: 500.415 | J9: 0.0014274884 | K9: FALSE | L9: FALSE | M9: FALSE
A10: 5 | B10: 2:03.580 | C10: 123.58 | D10: 34.809 | E10: 29.983 | F10: 34.281 | G10: 24.507 | H10: 336.9 | I10: 623.995 | J10: 0.0014303241 | K10: FALSE | L10: FALSE | M10: FALSE
A11: 6 | B11: 2:03.640 | C11: 123.64 | D11: 34.745 | E11: 29.948 | F11: 34.428 | G11: 24.519 | H11: 335.9 | I11: 747.635 | J11: 0.0014310185 | K11: FALSE | L11: FALSE | M11: FALSE
A12: 7 | B12: 2:03.339 | C12: 123.339 | D12: 34.683 | E12: 29.665 | F12: 34.435 | G12: 24.556 | H12: 338 | I12: 870.974 | J12: 0.0014275347 | K12: FALSE | L12: FALSE | M12: FALSE
A13: 8 | B13: 2:03.654 | C13: 123.654 | D13: 34.831 | E13: 29.737 | F13: 34.318 | G13: 24.768 | H13: 339.1 | I13: 994.628 | J13: 0.0014311806 | K13: FALSE | L13: FALSE | M13: FALSE
A14: 9 | B14: 2:03.696 | C14: 123.696 | D14: 34.848 | E14: 29.782 | F14: 34.308 | G14: 24.758 | H14: 334.8 | I14: 1118.324 | J14: 0.0014316667 | K14: FALSE | L14: FALSE | M14: FALSE
A15: 10 | B15: 2:03.344 | C15: 123.344 | D15: 34.645 | E15: 29.822 | F15: 34.266 | G15: 24.611 | H15: 332.7 | I15: 1241.668 | J15: 0.0014275926 | K15: FALSE | L15: FALSE | M15: FALSE
A16: 11 | B16: 2:03.828 | C16: 123.828 | D16: 34.681 | E16: 30.032 | F16: 34.458 | G16: 24.657 | H16: 332.7 | I16: 1365.496 | J16: 0.0014331944 | K16: FALSE | L16: FALSE | M16: FALSE
A17: 12 | B17: 2:03.415 | C17: 123.415 | D17: 34.769 | E17: 29.757 | F17: 34.264 | G17: 24.625 | H17: 333.7 | I17: 1488.911 | J17: 0.0014284144 | K17: FALSE | L17: FALSE | M17: FALSE
... A25: 20 | B25: 2:03.557 | C25: 123.557 | D25: 34.879 | E25: 29.767 | F25: 34.298 | G25: 24.613 | H25: 329.6 | I25: 2476.962 | J25: 0.0014300579 | K25: FALSE | L25: FALSE | M25: FALSE

Sheet Fabio Quartararo
A1: 17. Fabio QUARTARARO #20
A3: Team | B3: Monster Energy Yamaha MotoGP Team | C3: Manufacturer | D3: YAMAHA | E3: Nationality | F3: FRA | G3: Total Laps | H3: 20 | I3: Valid Laps | J3: 19 | K3: Front Tyre | L3: Slick-Medium | M3: Rear Tyre | N3: Slick-Medium
A5: Lap | B5: Lap Time | C5: Lap Seconds | D5: T1 | E5: T2 | F5: T3 | G5: T4 | H5: Speed km/h | I5: Cumulative Seconds | J5: Excel Time | K5: Cancelled | L5: Pit Lane | M5: Partial Timing
A6: 1 | B6: 2:06.977 | C6: 126.977 | D6: 36.919 | E6: 30.594 | F6: 34.771 | G6: 24.693 | H6: 333.7 | I6: 126.977 | J6: 0.0014696412 | K6: FALSE | L6: FALSE | M6: FALSE
A7: 2 | B7: 2:05.881 | C7: 125.881 | D7: 35.487 | E7: 31.481 | F7: 34.333 | G7: 24.58 | H7: 330.6 | I7: 252.858 | J7: 0.001456956 | K7: FALSE | L7: FALSE | M7: FALSE
A8: 3 | B8: 2:03.490 | C8: 123.49 | D8: 34.839 | E8: 29.89 | F8: 34.246 | G8: 24.515 | H8: 328.5 | I8: 376.348 | J8: 0.0014292824 | K8: FALSE | L8: FALSE | M8: FALSE
A9: 4 | B9: 2:03.419 | C9: 123.419 | D9: 34.807 | E9: 29.787 | F9: 34.226 | G9: 24.599 | H9: 329.6 | I9: 499.767 | J9: 0.0014284606 | K9: FALSE | L9: FALSE | M9: FALSE
A10: 5 | B10: 2:03.468 | C10: 123.468 | D10: 34.757 | E10: 29.704 | F10: 34.441 | G10: 24.566 | H10: 330.6 | I10: 623.235 | J10: 0.0014290278 | K10: FALSE | L10: FALSE | M10: FALSE
A11: 6 | B11: 2:03.441 | C11: 123.441 | D11: 34.813 | E11: 29.894 | F11: 34.203 | G11: 24.531 | H11: 329.6 | I11: 746.676 | J11: 0.0014287153 | K11: FALSE | L11: FALSE | M11: FALSE
A12: 7 | B12: 2:03.441 | C12: 123.441 | D12: 34.816 | E12: 29.916 | F12: 34.177 | G12: 24.532 | H12: 335.9 | I12: 870.117 | J12: 0.0014287153 | K12: FALSE | L12: FALSE | M12: FALSE
A13: 8 | B13: 2:03.624 | C13: 123.624 | D13: 34.75 | E13: 29.767 | F13: 34.454 | G13: 24.653 | H13: 335.9 | I13: 993.741 | J13: 0.0014308333 | K13: FALSE | L13: FALSE | M13: FALSE
A14: 9 | B14: 2:03.341 | C14: 123.341 | D14: 34.768 | E14: 29.815 | F14: 34.18 | G14: 24.578 | H14: 334.8 | I14: 1117.082 | J14: 0.0014275579 | K14: FALSE | L14: FALSE | M14: FALSE
A15: 10 | B15: 2:03.275 | C15: 123.275 | D15: 34.733 | E15: 29.782 | F15: 34.231 | G15: 24.529 | H15: 329.6 | I15: 1240.357 | J15: 0.001426794 | K15: FALSE | L15: FALSE | M15: FALSE
A16: 11 | B16: 2:03.237 | C16: 123.237 | D16: 34.738 | E16: 29.761 | F16: 34.159 | G16: 24.579 | H16: 334.8 | I16: 1363.594 | J16: 0.0014263542 | K16: FALSE | L16: FALSE | M16: FALSE
A17: 12 | B17: 2:03.481 | C17: 123.481 | D17: 34.853 | E17: 29.792 | F17: 34.183 | G17: 24.653 | H17: 332.7 | I17: 1487.075 | J17: 0.0014291782 | K17: FALSE | L17: FALSE | M17: FALSE
... A25: 20 | B25: 2:04.590 | C25: 124.59 | D25: 34.914 | E25: 30.155 | F25: 34.579 | G25: 24.942 | H25: 333.7 | I25: 2477.789 | J25: 0.0014420139 | K25: FALSE | L25: FALSE | M25: FALSE

Sheet Alex Rins
A1: 18. Alex RINS #42
A3: Team | B3: Monster Energy Yamaha MotoGP Team | C3: Manufacturer | D3: YAMAHA | E3: Nationality | F3: SPA | G3: Total Laps | H3: 20 | I3: Valid Laps | J3: 19 | K3: Front Tyre | L3: Slick-Medium | M3: Rear Tyre | N3: Slick-Medium
A5: Lap | B5: Lap Time | C5: Lap Seconds | D5: T1 | E5: T2 | F5: T3 | G5: T4 | H5: Speed km/h | I5: Cumulative Seconds | J5: Excel Time | K5: Cancelled | L5: Pit Lane | M5: Partial Timing
A6: 1 | B6: 2:07.887 | C6: 127.887 | D6: 37.593 | E6: 30.579 | F6: 34.919 | G6: 24.796 | H6: 340.2 | I6: 127.887 | J6: 0.0014801736 | K6: FALSE | L6: FALSE | M6: FALSE
A7: 2 | B7: 2:05.773 | C7: 125.773 | D7: 34.898 | E7: 31.712 | F7: 34.554 | G7: 24.609 | H7: 342.4 | I7: 253.66 | J7: 0.001455706 | K7: FALSE | L7: FALSE | M7: FALSE
A8: 3 | B8: 2:03.734 | C8: 123.734 | D8: 34.896 | E8: 29.929 | F8: 34.351 | G8: 24.558 | H8: 336.9 | I8: 377.394 | J8: 0.0014321065 | K8: FALSE | L8: FALSE | M8: FALSE
A9: 4 | B9: 2:03.188 | C9: 123.188 | D9: 34.777 | E9: 29.661 | F9: 34.188 | G9: 24.562 | H9: 338 | I9: 500.582 | J9: 0.001425787 | K9: FALSE | L9: FALSE | M9: FALSE
A10: 5 | B10: 2:03.084 | C10: 123.084 | D10: 34.642 | E10: 29.76 | F10: 34.107 | G10: 24.575 | H10: 335.9 | I10: 623.666 | J10: 0.0014245833 | K10: FALSE | L10: FALSE | M10: FALSE
A11: 6 | B11: 2:03.508 | C11: 123.508 | D11: 34.732 | E11: 29.879 | F11: 34.334 | G11: 24.563 | H11: 340.2 | I11: 747.174 | J11: 0.0014294907 | K11: FALSE | L11: FALSE | M11: FALSE
A12: 7 | B12: 2:03.532 | C12: 123.532 | D12: 34.669 | E12: 29.93 | F12: 34.268 | G12: 24.665 | H12: 340.2 | I12: 870.706 | J12: 0.0014297685 | K12: FALSE | L12: FALSE | M12: FALSE
A13: 8 | B13: 2:04.806 | C13: 124.806 | D13: 34.78 | E13: 29.835 | F13: 35.389 | G13: 24.802 | H13: 338 | I13: 995.512 | J13: 0.0014445139 | K13: FALSE | L13: FALSE | M13: FALSE
A14: 9 | B14: 2:04.270 | C14: 124.27 | D14: 35.262 | E14: 29.882 | F14: 34.437 | G14: 24.689 | H14: 333.7 | I14: 1119.782 | J14: 0.0014383102 | K14: FALSE | L14: FALSE | M14: FALSE
A15: 10 | B15: 2:04.209 | C15: 124.209 | D15: 34.903 | E15: 30.026 | F15: 34.622 | G15: 24.658 | H15: 332.7 | I15: 1243.991 | J15: 0.0014376042 | K15: FALSE | L15: FALSE | M15: FALSE
A16: 11 | B16: 2:03.629 | C16: 123.629 | D16: 34.823 | E16: 29.757 | F16: 34.379 | G16: 24.67 | H16: 332.7 | I16: 1367.62 | J16: 0.0014308912 | K16: FALSE | L16: FALSE | M16: FALSE
A17: 12 | B17: 2:03.805 | C17: 123.805 | D17: 34.85 | E17: 29.908 | F17: 34.374 | G17: 24.673 | H17: 333.7 | I17: 1491.425 | J17: 0.0014329282 | K17: FALSE | L17: FALSE | M17: FALSE
... A25: 20 | B25: 2:05.973 | C25: 125.973 | D25: 35.619 | E25: 30.258 | F25: 34.963 | G25: 25.133 | H25: 329.6 | I25: 2489.354 | J25: 0.0014580208 | K25: FALSE | L25: FALSE | M25: FALSE

Sheet Johann Zarco
A1: 19. Johann ZARCO #5
A3: Team | B3: Castrol Honda LCR | C3: Manufacturer | D3: HONDA | E3: Nationality | F3: FRA | G3: Total Laps | H3: 18 | I3: Valid Laps | J3: 16 | K3: Front Tyre | L3: Slick-Medium | M3: Rear Tyre | N3: Slick-Medium
A5: Lap | B5: Lap Time | C5: Lap Seconds | D5: T1 | E5: T2 | F5: T3 | G5: T4 | H5: Speed km/h | I5: Cumulative Seconds | J5: Excel Time | K5: Cancelled | L5: Pit Lane | M5: Partial Timing
A6: 1 | B6: 2:06.434 | C6: 126.434 | D6: 36.719 | E6: 30.203 | F6: 35.049 | G6: 24.463 | H6: 336.9 | I6: 126.434 | J6: 0.0014633565 | K6: FALSE | L6: FALSE | M6: FALSE
A7: 2 | B7: 3:46.246 | C7: 226.246 | D7: 34.52 | E7: 10.825 | F7: 35.902 | G7: 24.999 | H7: 322.5 | I7: 352.68 | J7: 0.002618588 | K7: FALSE | L7: FALSE | M7: FALSE
A8: 3 | B8: 2:05.063 | C8: 125.063 | D8: 35.703 | E8: 30.127 | F8: 34.585 | G8: 24.648 | H8: 334.8 | I8: 477.743 | J8: 0.0014474884 | K8: FALSE | L8: FALSE | M8: FALSE
A9: 4 | B9: 2:03.920 | C9: 123.92 | D9: 35.158 | E9: 29.864 | F9: 34.183 | G9: 24.715 | H9: 334.8 | I9: 601.663 | J9: 0.0014342593 | K9: FALSE | L9: FALSE | M9: FALSE
A10: 5 | B10: 2:02.753 | C10: 122.753 | D10: 34.704 | E10: 29.61 | F10: 34.024 | G10: 24.415 | H10: 336.9 | I10: 724.416 | J10: 0.0014207523 | K10: FALSE | L10: FALSE | M10: FALSE
A11: 6 | B11: 2:02.856 | C11: 122.856 | D11: 34.385 | E11: 29.752 | F11: 34.196 | G11: 24.523 | H11: 336.9 | I11: 847.272 | J11: 0.0014219444 | K11: FALSE | L11: FALSE | M11: FALSE
A12: 7 | B12: 2:02.705 | C12: 122.705 | D12: 34.598 | E12: 29.68 | F12: 33.919 | G12: 24.508 | H12: 336.9 | I12: 969.977 | J12: 0.0014201968 | K12: FALSE | L12: FALSE | M12: FALSE
A13: 8 | B13: 2:03.315 | C13: 123.315 | D13: 34.757 | E13: 29.962 | F13: 34.042 | G13: 24.554 | H13: 338 | I13: 1093.292 | J13: 0.0014272569 | K13: FALSE | L13: FALSE | M13: FALSE
A14: 9 | B14: 2:02.664 | C14: 122.664 | D14: 34.622 | E14: 29.546 | F14: 34.005 | G14: 24.491 | H14: 336.9 | I14: 1215.956 | J14: 0.0014197222 | K14: FALSE | L14: FALSE | M14: FALSE
A15: 10 | B15: 2:02.073 | C15: 122.073 | D15: 34.439 | E15: 29.484 | F15: 33.835 | G15: 24.315 | H15: 338 | I15: 1338.029 | J15: 0.0014128819 | K15: FALSE | L15: FALSE | M15: FALSE
A16: 11 | B16: 2:03.932 | C16: 123.932 | D16: 35.101 | E16: 29.894 | F16: 34.231 | G16: 24.706 | H16: 338 | I16: 1461.961 | J16: 0.0014343981 | K16: FALSE | L16: FALSE | M16: FALSE
A17: 12 | B17: 2:03.097 | C17: 123.097 | D17: 34.46 | E17: 29.732 | F17: 34.281 | G17: 24.624 | H17: 336.9 | I17: 1585.058 | J17: 0.0014247338 | K17: FALSE | L17: FALSE | M17: FALSE
... A23: 18 | B23: 2:11.759 | C23: 131.759 | D23: 34.615 | E23: 29.687 | F23: 34.165 | G23: 33.292 | H23: 338 | I23: 2331.967 | J23: 0.0015249884 | K23: FALSE | L23: TRUE | M23: FALSE

Sheet Ai Ogura
A1: 20. Ai OGURA #79
A3: Team | B3: Trackhouse MotoGP Team | C3: Manufacturer | D3: APRILIA | E3: Nationality | F3: JPN | G3: Total Laps | H3: 15 | I3: Valid Laps | J3: 13 | K3: Front Tyre | L3: Slick-Medium | M3: Rear Tyre | N3: Slick-Medium
A5: Lap | B5: Lap Time | C5: Lap Seconds | D5: T1 | E5: T2 | F5: T3 | G5: T4 | H5: Speed km/h | I5: Cumulative Seconds | J5: Excel Time | K5: Cancelled | L5: Pit Lane | M5: Partial Timing
A6: 1 | B6: 2:05.733 | C6: 125.733 | D6: 35.986 | E6: 30.383 | F6: 34.85 | G6: 24.514 | H6: 341.3 | I6: 125.733 | J6: 0.0014552431 | K6: FALSE | L6: FALSE | M6: FALSE
A7: 2 | B7: 2:03.429 | C7: 123.429 | D7: 34.892 | E7: 29.731 | F7: 34.303 | G7: 24.503 | H7: 344.7 | I7: 249.162 | J7: 0.0014285764 | K7: FALSE | L7: FALSE | M7: FALSE
A8: 3 | B8: 2:02.890 | C8: 122.89 | D8: 34.751 | E8: 29.618 | F8: 34.127 | G8: 24.394 | H8: 339.1 | I8: 372.052 | J8: 0.001422338 | K8: FALSE | L8: FALSE | M8: FALSE
A9: 4 | B9: 2:02.771 | C9: 122.771 | D9: 34.527 | E9: 29.543 | F9: 34.124 | G9: 24.577 | H9: 340.2 | I9: 494.823 | J9: 0.0014209606 | K9: FALSE | L9: FALSE | M9: FALSE
A10: 5 | B10: 2:02.332 | C10: 122.332 | D10: 34.365 | E10: 29.511 | F10: 34.078 | G10: 24.378 | H10: 340.2 | I10: 617.155 | J10: 0.0014158796 | K10: FALSE | L10: FALSE | M10: FALSE
A11: 6 | B11: 2:02.415 | C11: 122.415 | D11: 34.436 | E11: 29.779 | F11: 33.826 | G11: 24.374 | H11: 346.9 | I11: 739.57 | J11: 0.0014168403 | K11: FALSE | L11: FALSE | M11: FALSE
A12: 7 | B12: 2:02.258 | C12: 122.258 | D12: 34.417 | E12: 29.523 | F12: 33.944 | G12: 24.374 | H12: 342.4 | I12: 861.828 | J12: 0.0014150231 | K12: FALSE | L12: FALSE | M12: FALSE
A13: 8 | B13: 2:02.158 | C13: 122.158 | D13: 34.331 | E13: 29.518 | F13: 33.844 | G13: 24.465 | H13: 342.4 | I13: 983.986 | J13: 0.0014138657 | K13: FALSE | L13: FALSE | M13: FALSE
A14: 9 | B14: 2:02.037 | C14: 122.037 | D14: 34.383 | E14: 29.532 | F14: 33.835 | G14: 24.287 | H14: 343.5 | I14: 1106.023 | J14: 0.0014124653 | K14: FALSE | L14: FALSE | M14: FALSE
A15: 10 | B15: 2:02.328 | C15: 122.328 | D15: 34.445 | E15: 29.481 | F15: 33.987 | G15: 24.415 | H15: 343.5 | I15: 1228.351 | J15: 0.0014158333 | K15: FALSE | L15: FALSE | M15: FALSE
A16: 11 | B16: 2:02.058 | C16: 122.058 | D16: 34.264 | E16: 29.438 | F16: 33.924 | G16: 24.432 | H16: 343.5 | I16: 1350.409 | J16: 0.0014127083 | K16: FALSE | L16: FALSE | M16: FALSE
A17: 12 | B17: 2:02.294 | C17: 122.294 | D17: 34.292 | E17: 29.448 | F17: 34.009 | G17: 24.545 | H17: 345.8 | I17: 1472.703 | J17: 0.0014154398 | K17: FALSE | L17: FALSE | M17: FALSE
... A20: 15 | B20: 2:45.885 | C20: 165.885 | D20: 34.442 | E20: 31.115 | F20: 44.509 | G20: 55.819 | H20: 249.3 | I20: 1883.22 | J20: 0.0019199653 | K20: FALSE | L20: TRUE | M20: FALSE

Sheet Joan Mir
A1: 21. Joan MIR #36
A3: Team | B3: Honda HRC Castrol | C3: Manufacturer | D3: HONDA | E3: Nationality | F3: SPA | G3: Total Laps | H3: 5 | I3: Valid Laps | J3: 3 | K3: Front Tyre | L3: Slick-Medium | M3: Rear Tyre | N3: Slick-Medium
A5: Lap | B5: Lap Time | C5: Lap Seconds | D5: T1 | E5: T2 | F5: T3 | G5: T4 | H5: Speed km/h | I5: Cumulative Seconds | J5: Excel Time | K5: Cancelled | L5: Pit Lane | M5: Partial Timing
A6: 1 | B6: 2:04.609 | C6: 124.609 | D6: 35.514 | E6: 29.955 | F6: 34.643 | G6: 24.497 | H6: 330.6 | I6: 124.609 | J6: 0.0014422338 | K6: FALSE | L6: FALSE | M6: FALSE
A7: 2 | B7: 2:03.323 | C7: 123.323 | D7: 34.955 | E7: 29.93 | F7: 34.077 | G7: 24.361 | H7: 339.1 | I7: 247.932 | J7: 0.0014273495 | K7: FALSE | L7: FALSE | M7: FALSE
A8: 3 | B8: 2:02.647 | C8: 122.647 | D8: 34.5 | E8: 29.769 | F8: 33.969 | G8: 24.409 | H8: 339.1 | I8: 370.579 | J8: 0.0014195255 | K8: TRUE | L8: FALSE | M8: FALSE
A9: 4 | B9: 2:02.985 | C9: 122.985 | D9: 34.627 | E9: 29.794 | F9: 33.973 | G9: 24.591 | H9: 338 | I9: 493.564 | J9: 0.0014234375 | K9: FALSE | L9: FALSE | M9: FALSE
A10: 5 | B10: 2:02.709 | C10: 122.709 | D10: 34.538 | E10: 29.708 | F10: 33.916 | G10: 24.547 | H10: 336.9 | I10: 616.273 | J10: 0.0014202431 | K10: FALSE | L10: FALSE | M10: FALSE

Sheet Race Data
A1: Rider | B1: Number | C1: Position | D1: Team | E1: Manufacturer | F1: Nationality | G1: Total Laps | H1: Valid Laps | I1: Lap | J1: Lap Time | K1: Lap Seconds | L1: T1 | M1: T2 | N1: T3 | O1: T4 | P1: Speed km/h | Q1: Cumulative Seconds | R1: Cancelled | S1: Pit Lane | T1: Partial Timing
A2: Marco BEZZECCHI | B2: 72 | C2: 1 | D2: Aprilia Racing | E2: APRILIA | F2: ITA | G2: 20 | H2: 19 | I2: 1 | J2: 2:03.203 | K2: 123.203 | L2: 34.609 | M2: 30.024 | N2: 34.247 | O2: 24.323 | P2: 332.7 | Q2: 123.203 | R2: FALSE | S2: FALSE | T2: FALSE
A3: Marco BEZZECCHI | B3: 72 | C3: 1 | D3: Aprilia Racing | E3: APRILIA | F3: ITA | G3: 20 | H3: 19 | I3: 2 | J3: 2:02.426 | K3: 122.426 | L3: 34.401 | M3: 29.604 | N3: 34.103 | O3: 24.318 | P3: 335.9 | Q3: 245.629 | R3: FALSE | S3: FALSE | T3: FALSE
A4: Marco BEZZECCHI | B4: 72 | C4: 1 | D4: Aprilia Racing | E4: APRILIA | F4: ITA | G4: 20 | H4: 19 | I4: 3 | J4: 2:02.324 | K4: 122.324 | L4: 34.472 | M4: 29.577 | N4: 33.992 | O4: 24.283 | P4: 335.9 | Q4: 367.953 | R4: FALSE | S4: FALSE | T4: FALSE
A5: Marco BEZZECCHI | B5: 72 | C5: 1 | D5: Aprilia Racing | E5: APRILIA | F5: ITA | G5: 20 | H5: 19 | I5: 4 | J5: 2:02.360 | K5: 122.36 | L5: 34.488 | M5: 29.473 | N5: 34.067 | O5: 24.332 | P5: 336.9 | Q5: 490.313 | R5: FALSE | S5: FALSE | T5: FALSE
A6: Marco BEZZECCHI | B6: 72 | C6: 1 | D6: Aprilia Racing | E6: APRILIA | F6: ITA | G6: 20 | H6: 19 | I6: 5 | J6: 2:02.157 | K6: 122.157 | L6: 34.303 | M6: 29.467 | N6: 33.973 | O6: 24.414 | P6: 338 | Q6: 612.47 | R6: FALSE | S6: FALSE | T6: FALSE
A7: Marco BEZZECCHI | B7: 72 | C7: 1 | D7: Aprilia Racing | E7: APRILIA | F7: ITA | G7: 20 | H7: 19 | I7: 6 | J7: 2:02.114 | K7: 122.114 | L7: 34.407 | M7: 29.468 | N7: 33.909 | O7: 24.33 | P7: 339.1 | Q7: 734.584 | R7: FALSE | S7: FALSE | T7: FALSE
A8: Marco BEZZECCHI | B8: 72 | C8: 1 | D8: Aprilia Racing | E8: APRILIA | F8: ITA | G8: 20 | H8: 19 | I8: 7 | J8: 2:02.295 | K8: 122.295 | L8: 34.371 | M8: 29.549 | N8: 33.88 | O8: 24.495 | P8: 340.2 | Q8: 856.879 | R8: FALSE | S8: FALSE | T8: FALSE
A9: Marco BEZZECCHI | B9: 72 | C9: 1 | D9: Aprilia Racing | E9: APRILIA | F9: ITA | G9: 20 | H9: 19 | I9: 8 | J9: 2:02.633 | K9: 122.633 | L9: 34.572 | M9: 29.61 | N9: 33.92 | O9: 24.531 | P9: 340.2 | Q9: 979.512 | R9: FALSE | S9: FALSE | T9: FALSE
A10: Marco BEZZECCHI | B10: 72 | C10: 1 | D10: Aprilia Racing | E10: APRILIA | F10: ITA | G10: 20 | H10: 19 | I10: 9 | J10: 2:02.718 | K10: 122.718 | L10: 34.62 | M10: 29.732 | N10: 33.936 | O10: 24.43 | P10: 340.2 | Q10: 1102.23 | R10: FALSE | S10: FALSE | T10: FALSE
A11: Marco BEZZECCHI | B11: 72 | C11: 1 | D11: Aprilia Racing | E11: APRILIA | F11: ITA | G11: 20 | H11: 19 | I11: 10 | J11: 2:02.115 | K11: 122.115 | L11: 34.272 | M11: 29.582 | N11: 33.888 | O11: 24.373 | P11: 340.2 | Q11: 1224.345 | R11: FALSE | S11: FALSE | T11: FALSE
A12: Marco BEZZECCHI | B12: 72 | C12: 1 | D12: Aprilia Racing | E12: APRILIA | F12: ITA | G12: 20 | H12: 19 | I12: 11 | J12: 2:02.470 | K12: 122.47 | L12: 34.481 | M12: 29.53 | N12: 34.053 | O12: 24.406 | P12: 339.1 | Q12: 1346.815 | R12: FALSE | S12: FALSE | T12: FALSE
A13: Marco BEZZECCHI | B13: 72 | C13: 1 | D13: Aprilia Racing | E13: APRILIA | F13: ITA | G13: 20 | H13: 19 | I13: 12 | J13: 2:02.440 | K13: 122.44 | L13: 34.414 | M13: 29.652 | N13: 33.951 | O13: 24.423 | P13: 340.2 | Q13: 1469.255 | R13: FALSE | S13: FALSE | T13: FALSE
